Workbook

Sheet Start
A1: SAMPLE COPY: every row in this file is SAMPLE data. Illustrative placeholders, not results. Use conversation-tracker.xlsx for real work.
A2: =Config!$B$3&" · conversation tracker" -> Desk Drop · conversation tracker
A3: What this is: the conversation and notes log for discovery and selling, one row per conversation, keyed by the Clay row_id.
A4: It is not a status store. Status, touches, replies, next actions and do-not-contact live in the Clay tables only (CONTRACTS 6.2).
A6: After every call (ten minutes, calls/post-call-note-template.md)
A7: 1. Fill Note_Office or Note_Brand top to bottom (verbatims first, then numbers and codes), copy its 'row to paste', and paste it into the next empty log row as values only (Ctrl+Shift+V). Or type straight into the log row.
A8: 2. Write back to the Clay row: call_date, status (call_done or yes_in_principle), yes_in_principle, call_notes ('see tracker <date>'), next_action, next_action_date.
A9: 3. Set clay_updated = Y and note_minutes.
A11: Every Friday (15 minutes)
A12: 1. Export the Clay offices table (all columns) and paste it on Clay_Offices at A1. Same for brands on Clay_Brands. Type both export dates on Config.
A13: 2. Open Scorecard. Fix every FIX under Data checks (the Sync tab and the red calc_sync_issue cells show where).
A14: 3. Read the Gate 0 block, the medians, the top objections and the reply rates. If a reply-rate check says UNDER 20% (conversation replies) or an opt-out check says OPT-OUTS OVER 5%, run sending guide section 6.
A15: 4. Download pipeline_log as CSV (File > Download > CSV, this tab only) to desk-drop-outreach/exports/pipeline_log.csv and paste it into the financial model's Pipeline tab.
A16: 5. When an office signs or a brand pays: add the row on signed_offices or paid_brands, download that tab as CSV to desk-drop-outreach/handoff/.
... A28: Dates as YYYY-MM-DD. Money as plain numbers. Rows whose row_id starts with SAMPLE are ignored while include_sample = N.

Sheet Scorecard
A1: =IF((COUNTIF(Office_Log!$A$2:$A$201,"SAMPLE*")+COUNTIF(Brand_Log!$A$2:$A$201,"SAMPLE*")+COUNTIF(signed_offices!$W$2:$W$51,"SAMPLE*")+COUNTIF(paid_brands!$AC$2:$AC$51,"SAMPLE*")+COUNTIF(later_events!$C$2:$C$101,"SAMPLE*")+IFERROR(COUNTIF(INDEX(Clay_Offices!$A$2:$FZ$601,0,Sync!$C$5),"SAMPLE*"),0)+IFERROR(COUNTIF(INDEX(Clay_Brands!$A$2:$FZ$601,0,Sync!$D$5),"SAMPLE*"),0))>0,"SAMPLE: this file holds "&(COUNTIF(Office_Log!$A$2:$A$201,"SAMPLE*")+COUNTIF(Brand_Log!$A$2:$A$201,"SAMPLE*")+COUNTIF(signed_offices!$W$2:$W$51,"SAMPLE*")+COUNTIF(paid_brands!$AC$2:$AC$51,"SAMPLE*")+COUNTIF(later_events!$C$2:$C$101,"SAMPLE*")+IFERROR(COUNTIF(INDEX(Clay_Offices!$A$2:$FZ$601,0,Sync!$C$5),"SAMPLE*"),0)+IFERROR(COUNTIF(INDEX(Clay_Brands!$A$2:$FZ$601,0,Sync!$D$5),"SAMPLE*"),0))&" SAMPLE rows. Illustrative placeholders, not results. include_sample = "&Config!$B$19&IF(Config!$B$19="Y"," (SAMPLE rows are counted)"," (SAMPLE rows are ignored)"),"") -> SAMPLE: this file holds 118 SAMPLE rows. Illustrative placeholders, not results. include_sample = Y (SAMPLE rows are counted)
A2: =Config!$B$3&" · Friday scorecard" -> Desk Drop · Friday scorecard
A3: ="As of "&TEXT(Config!$B$5,"ddd yyyy-mm-dd")&". Gate 0 is "&TEXT(Config!$B$8,"ddd yyyy-mm-dd")&" (derived, founder to confirm). Counts are distinct offices or brands, by call_date." -> As of Fri 2026-12-11. Gate 0 is Fri 2026-11-13 (derived, founder to confirm). Counts are distinct offices or brands, by call_date.
A5: Measure | B5: Fri wk 1 | C5: Fri wk 2 | D5: Gate 0 | E5: As of | F5: Target | G5: How it is counted
A6: Cut-off date | B6: =Config!$B$6 -> 46325 | C6: =Config!$B$7 -> 46332 | D6: =Config!$B$8 -> 46339 | E6: =Config!$B$5 -> 46367
A7: Offices (Gate 0: at least 5 of 15 say yes in principle AND name a pantry owner AND a receiving window)
A8: Office conversations held | B8: =COUNTIFS(Office_Log!$BC$2:$BC$201,1,Office_Log!$H$2:$H$201,"<"&(B$6+1)) -> 3 | C8: =COUNTIFS(Office_Log!$BC$2:$BC$201,1,Office_Log!$H$2:$H$201,"<"&(C$6+1)) -> 7 | D8: =COUNTIFS(Office_Log!$BC$2:$BC$201,1,Office_Log!$H$2:$H$201,"<"&(D$6+1)) -> 13 | E8: =COUNTIFS(Office_Log!$BC$2:$BC$201,1,Office_Log!$H$2:$H$201,"<"&(E$6+1)) -> 14 | F8: =Config!$B$10 -> 15 | G8: Distinct offices (calc_org on Office_Log) by the cut-off. Two contacts at one company count once.
A9: Yes in principle, pantry owner named, receiving window named | B9: =COUNTIF(Office_Log!$DL$2:$DL$201,1) -> 1 | C9: =COUNTIF(Office_Log!$DM$2:$DM$201,1) -> 3 | D9: =COUNTIF(Office_Log!$DN$2:$DN$201,1) -> 5 | E9: =COUNTIF(Office_Log!$DO$2:$DO$201,1) -> 6 | F9: =Config!$B$11 -> 5 | G9: The Gate 0 count: one per office (calc_org), while its latest answer (Y, N or maybe, from any contact) by the cut-off is still Y. Under 30 or over 250 on a Tuesday: not counted (row below).
A10: Gate 0, office side | B10: =IF(B9>=Config!$B$11,"PASS",IF(B$6<Config!$B$8,"not yet",IF(OR(B8>=Config!$B$10,B$6>=Config!$B$34),"FAIL","INCOMPLETE: "&B8&" of "&Config!$B$10&" conversations"))) -> not yet | C10: =IF(C9>=Config!$B$11,"PASS",IF(C$6<Config!$B$8,"not yet",IF(OR(C8>=Config!$B$10,C$6>=Config!$B$34),"FAIL","INCOMPLETE: "&C8&" of "&Config!$B$10&" conversations"))) -> not yet | D10: =IF(D9>=Config!$B$11,"PASS",IF(D$6<Config!$B$8,"not yet",IF(OR(D8>=Config!$B$10,D$6>=Config!$B$34),"FAIL","INCOMPLETE: "&D8&" of "&Config!$B$10&" conversations"))) -> PASS | E10: =IF(E9>=Config!$B$11,"PASS",IF(E$6<Config!$B$8,"not yet",IF(OR(E8>=Config!$B$10,E$6>=Config!$B$34),"FAIL","INCOMPLETE: "&E8&" of "&Config!$B$10&" conversations"))) -> PASS | G10: PASS at the target. Before Gate 0 a shortfall is 'not yet'. From Gate 0: FAIL once 15 conversations are held; with fewer, INCOMPLETE (no failure response yet) until the final read, Fri 2026-11-27 (Config gate0_final_read), when a shortfall is FAIL.
A11: Yes in principle, any (owner or window may be missing) | B11: =COUNTIF(Office_Log!$DP$2:$DP$201,1) -> 2 | C11: =COUNTIF(Office_Log!$DQ$2:$DQ$201,1) -> 4 | D11: =COUNTIF(Office_Log!$DR$2:$DR$201,1) -> 7 | E11: =COUNTIF(Office_Log!$DS$2:$DS$201,1) -> 8 | G11: Offices whose latest answer is Y. The gap to the row above is follow-up work: get the owner and the window.
A12: Withdrawn after a yes (latest answer N or maybe): not counted | B12: =COUNTIF(Office_Log!$DT$2:$DT$201,1) -> 0 | C12: =COUNTIF(Office_Log!$DU$2:$DU$201,1) -> 0 | D12: =COUNTIF(Office_Log!$DV$2:$DV$201,1) -> 1 | E12: =COUNTIF(Office_Log!$DW$2:$DW$201,1) -> 1 | G12: Offices that said Y and later said N or maybe, by the cut-off. Set their Clay status to no or not_now.
A13: Yes with owner and window, but under 30 or over 250 on a Tuesday: not counted | B13: =COUNTIF(Office_Log!$EK$2:$EK$201,1) -> 0 | C13: =COUNTIF(Office_Log!$EL$2:$EL$201,1) -> 0 | D13: =COUNTIF(Office_Log!$EM$2:$EM$201,1) -> 0 | E13: =COUNTIF(Office_Log!$EN$2:$EN$201,1) -> 0 | G13: Plan: under 30 or over 250 on a Tuesday is excluded (Config office_floor, office_ceiling). If the number is right, it is not a participating office.
A14: Of the counted yeses: 30 to 39 on a Tuesday (your call) | B14: =COUNTIF(Office_Log!$EO$2:$EO$201,1) -> 0 | C14: =COUNTIF(Office_Log!$EP$2:$EP$201,1) -> 0 | D14: =COUNTIF(Office_Log!$EQ$2:$EQ$201,1) -> 0 | E14: =COUNTIF(Office_Log!$ER$2:$ER$201,1) -> 0 | G14: Counted above. The plan's band is 40 to 250; 30 to 39 is the founder's call before signing.
A15: Conversations with people you already know (channel warm-intro) | B15: =COUNTIFS(Office_Log!$CH$2:$CH$201,1,Office_Log!$H$2:$H$201,"<"&(B$6+1)) -> 1 | C15: =COUNTIFS(Office_Log!$CH$2:$CH$201,1,Office_Log!$H$2:$H$201,"<"&(C$6+1)) -> 1 | D15: =COUNTIFS(Office_Log!$CH$2:$CH$201,1,Office_Log!$H$2:$H$201,"<"&(D$6+1)) -> 3 | E15: =COUNTIFS(Office_Log!$CH$2:$CH$201,1,Office_Log!$H$2:$H$201,"<"&(E$6+1)) -> 3 | F15: 5 | G15: Plan Phase 0: five of the fifteen office conversations should come from your own network. Set channel = warm-intro for anyone you knew before.
A16: Said maybe at least once (someone else must agree) | B16: =COUNTIFS(Office_Log!$CB$2:$CB$201,1,Office_Log!$H$2:$H$201,"<"&(B$6+1)) -> 0 | C16: =COUNTIFS(Office_Log!$CB$2:$CB$201,1,Office_Log!$H$2:$H$201,"<"&(C$6+1)) -> 1 | D16: =COUNTIFS(Office_Log!$CB$2:$CB$201,1,Office_Log!$H$2:$H$201,"<"&(D$6+1)) -> 2 | E16: =COUNTIFS(Office_Log!$CB$2:$CB$201,1,Office_Log!$H$2:$H$201,"<"&(E$6+1)) -> 2 | G16: Plan Phase 1: 'I need to ask facilities and HR' is a maybe, not a yes.
A17: Median budget-probe answer, USD a month | B17: =IF(COUNT(Office_Log!$BJ$2:$BJ$201)=0,"none yet",MEDIAN(Office_Log!$BJ$2:$BJ$201)) -> 50 | C17: =IF(COUNT(Office_Log!$BK$2:$BK$201)=0,"none yet",MEDIAN(Office_Log!$BK$2:$BK$201)) -> 50 | D17: =IF(COUNT(Office_Log!$BL$2:$BL$201)=0,"none yet",MEDIAN(Office_Log!$BL$2:$BL$201)) -> 75 | E17: =IF(COUNT(Office_Log!$BM$2:$BM$201)=0,"none yet",MEDIAN(Office_Log!$BM$2:$BM$201)) -> 75 | G17: First numeric answer per office; a range counts at its low end; 'no budget' counts as 0; no number is left out.
A18: Offices that gave a number (0 included) | B18: =COUNT(Office_Log!$BJ$2:$BJ$201) -> 2 | C18: =COUNT(Office_Log!$BK$2:$BK$201) -> 5 | D18: =COUNT(Office_Log!$BL$2:$BL$201) -> 8 | E18: =COUNT(Office_Log!$BM$2:$BM$201) -> 8 | G18: The n behind the median.
A19: Of those, said no budget (0) | B19: =COUNTIF(Office_Log!$BJ$2:$BJ$201,0) -> 1 | C19: =COUNTIF(Office_Log!$BK$2:$BK$201,0) -> 2 | D19: =COUNTIF(Office_Log!$BL$2:$BL$201,0) -> 3 | E19: =COUNTIF(Office_Log!$BM$2:$BM$201,0) -> 3 | G19: Counted inside the median.
A20: Offices naming $100 a month or more (decision-rule input), as of | E20: =COUNTIFS(Office_Log!$BN$2:$BN$201,1,Office_Log!$H$2:$H$201,"<"&(E$6+1)) -> 4 | G20: Plan decision rule: office-paid tier is tested if at least five offices named $100 a month or more.
A21: Shortlisted offices (shortlist = Y) | B21: =COUNTIFS(Office_Log!$CF$2:$CF$201,1,Office_Log!$H$2:$H$201,"<"&(B$6+1)) -> 2 | C21: =COUNTIFS(Office_Log!$CF$2:$CF$201,1,Office_Log!$H$2:$H$201,"<"&(C$6+1)) -> 5 | D21: =COUNTIFS(Office_Log!$CF$2:$CF$201,1,Office_Log!$H$2:$H$201,"<"&(D$6+1)) -> 9 | E21: =COUNTIFS(Office_Log!$CF$2:$CF$201,1,Office_Log!$H$2:$H$201,"<"&(E$6+1)) -> 10 | F21: 8 | G21: Plan Phase 0 deliverable: a shortlist of 8 offices to pursue.
A22: Median monthly pantry spend today, USD, as of | E22: =IF(COUNT(Office_Log!$BQ$2:$BQ$201)=0,"none yet",MEDIAN(Office_Log!$BQ$2:$BQ$201)) -> 850 | F22: =COUNT(Office_Log!$BQ$2:$BQ$201) -> 8 | G22: First number per office, from Q1. Context for the budget probe.
A24: Brands (Gate 0: at least 3 of 15 say they would pay $500 or more AND the speaker controls the budget)
A25: Brand conversations held | B25: =COUNTIFS(Brand_Log!$AZ$2:$AZ$201,1,Brand_Log!$H$2:$H$201,"<"&(B$6+1)) -> 3 | C25: =COUNTIFS(Brand_Log!$AZ$2:$AZ$201,1,Brand_Log!$H$2:$H$201,"<"&(C$6+1)) -> 7 | D25: =COUNTIFS(Brand_Log!$AZ$2:$AZ$201,1,Brand_Log!$H$2:$H$201,"<"&(D$6+1)) -> 13 | E25: =COUNTIFS(Brand_Log!$AZ$2:$AZ$201,1,Brand_Log!$H$2:$H$201,"<"&(E$6+1)) -> 15 | F25: =Config!$B$12 -> 15 | G25: Distinct brands (calc_org on Brand_Log) by the cut-off. Two founders of one brand, or brands A grouped as one (company_group), count once.
A26: Would pay $500 or more and controls the budget | B26: =COUNTIF(Brand_Log!$DD$2:$DD$201,1) -> 2 | C26: =COUNTIF(Brand_Log!$DE$2:$DE$201,1) -> 3 | D26: =COUNTIF(Brand_Log!$DF$2:$DF$201,1) -> 6 | E26: =COUNTIF(Brand_Log!$DG$2:$DG$201,1) -> 7 | F26: =Config!$B$13 -> 3 | G26: The Gate 0 count, one per brand (calc_org): the higher of the two numbers is $500 or more and controls_budget = Y, while its latest answer by the cut-off, from any contact, still qualifies (a later controls_budget = N, or every number under $500, withdraws it).
A27: Gate 0, brand side | B27: =IF(B26>=Config!$B$13,"PASS",IF(B$6<Config!$B$8,"not yet",IF(OR(B25>=Config!$B$12,B$6>=Config!$B$34),"FAIL","INCOMPLETE: "&B25&" of "&Config!$B$12&" conversations"))) -> not yet | C27: =IF(C26>=Config!$B$13,"PASS",IF(C$6<Config!$B$8,"not yet",IF(OR(C25>=Config!$B$12,C$6>=Config!$B$34),"FAIL","INCOMPLETE: "&C25&" of "&Config!$B$12&" conversations"))) -> PASS | D27: =IF(D26>=Config!$B$13,"PASS",IF(D$6<Config!$B$8,"not yet",IF(OR(D25>=Config!$B$12,D$6>=Config!$B$34),"FAIL","INCOMPLETE: "&D25&" of "&Config!$B$12&" conversations"))) -> PASS | E27: =IF(E26>=Config!$B$13,"PASS",IF(E$6<Config!$B$8,"not yet",IF(OR(E25>=Config!$B$12,E$6>=Config!$B$34),"FAIL","INCOMPLETE: "&E25&" of "&Config!$B$12&" conversations"))) -> PASS | G27: PASS at the target. Before Gate 0 a shortfall is 'not yet'. From Gate 0: FAIL once 15 conversations are held; with fewer, INCOMPLETE (no failure response yet) until the final read, Fri 2026-11-27 (Config gate0_final_read), when a shortfall is FAIL.
A28: Strict read: named $500 or more BEFORE hearing $1,500, and controls the budget | B28: =COUNTIF(Brand_Log!$DH$2:$DH$201,1) -> 1 | C28: =COUNTIF(Brand_Log!$DI$2:$DI$201,1) -> 2 | D28: =COUNTIF(Brand_Log!$DJ$2:$DJ$201,1) -> 5 | E28: =COUNTIF(Brand_Log!$DK$2:$DK$201,1) -> 6 | G28: Shown so an anchored answer is not mistaken for an unprompted one. Withdrawn answers are left out here too.
A29: Withdrawn after saying $500 or more (a later call: no budget control, or a lower number): not counted | B29: =COUNTIF(Brand_Log!$DL$2:$DL$201,1) -> 0 | C29: =COUNTIF(Brand_Log!$DM$2:$DM$201,1) -> 0 | D29: =COUNTIF(Brand_Log!$DN$2:$DN$201,1) -> 0 | E29: =COUNTIF(Brand_Log!$DO$2:$DO$201,1) -> 0 | G29: Brands that qualified and later withdrew, by the cut-off. The financial model still counts them until it adopts the same rule (HANDOFF 2.3).
A30: Said $500 or more but the speaker does not control the budget | B30: =COUNTIFS(Brand_Log!$BG$2:$BG$201,1,Brand_Log!$H$2:$H$201,"<"&(B$6+1)) -> 0 | C30: =COUNTIFS(Brand_Log!$BG$2:$BG$201,1,Brand_Log!$H$2:$H$201,"<"&(C$6+1)) -> 1 | D30: =COUNTIFS(Brand_Log!$BG$2:$BG$201,1,Brand_Log!$H$2:$H$201,"<"&(D$6+1)) -> 1 | E30: =COUNTIFS(Brand_Log!$BG$2:$BG$201,1,Brand_Log!$H$2:$H$201,"<"&(E$6+1)) -> 1 | G30: Not counted for Gate 0 from that conversation. Ask for a call with the budget owner.
A31: Median brand number before $1,500 was mentioned, USD per campaign | B31: =IF(COUNT(Brand_Log!$BJ$2:$BJ$201)=0,"none yet",MEDIAN(Brand_Log!$BJ$2:$BJ$201)) -> 375 | C31: =IF(COUNT(Brand_Log!$BK$2:$BK$201)=0,"none yet",MEDIAN(Brand_Log!$BK$2:$BK$201)) -> 400 | D31: =IF(COUNT(Brand_Log!$BL$2:$BL$201)=0,"none yet",MEDIAN(Brand_Log!$BL$2:$BL$201)) -> 500 | E31: =IF(COUNT(Brand_Log!$BM$2:$BM$201)=0,"none yet",MEDIAN(Brand_Log!$BM$2:$BM$201)) -> 500 | G31: First numeric before-answer per brand; 'nothing' counts as 0; no number is left out.
A32: Brands that named a number before $1,500 | B32: =COUNT(Brand_Log!$BJ$2:$BJ$201) -> 2 | C32: =COUNT(Brand_Log!$BK$2:$BK$201) -> 6 | D32: =COUNT(Brand_Log!$BL$2:$BL$201) -> 11 | E32: =COUNT(Brand_Log!$BM$2:$BM$201) -> 13 | G32: The n behind the median.
A33: Median brand number after hearing $1,500, USD per campaign | B33: =IF(COUNT(Brand_Log!$BP$2:$BP$201)=0,"none yet",MEDIAN(Brand_Log!$BP$2:$BP$201)) -> 600 | C33: =IF(COUNT(Brand_Log!$BQ$2:$BQ$201)=0,"none yet",MEDIAN(Brand_Log!$BQ$2:$BQ$201)) -> 700 | D33: =IF(COUNT(Brand_Log!$BR$2:$BR$201)=0,"none yet",MEDIAN(Brand_Log!$BR$2:$BR$201)) -> 800 | E33: =IF(COUNT(Brand_Log!$BS$2:$BS$201)=0,"none yet",MEDIAN(Brand_Log!$BS$2:$BS$201)) -> 850 | G33: First numeric after-answer per brand.
A34: Brands that answered after hearing $1,500 | B34: =COUNT(Brand_Log!$BP$2:$BP$201) -> 3 | C34: =COUNT(Brand_Log!$BQ$2:$BQ$201) -> 6 | D34: =COUNT(Brand_Log!$BR$2:$BR$201) -> 7 | E34: =COUNT(Brand_Log!$BS$2:$BS$201) -> 8 | G34: The n behind the median.
A35: Brands qualified on a call (all seven checks Y, not excluded) | B35: =COUNTIFS(Brand_Log!$CE$2:$CE$201,1,Brand_Log!$H$2:$H$201,"<"&(B$6+1)) -> 2 | C35: =COUNTIFS(Brand_Log!$CE$2:$CE$201,1,Brand_Log!$H$2:$H$201,"<"&(C$6+1)) -> 2 | D35: =COUNTIFS(Brand_Log!$CE$2:$CE$201,1,Brand_Log!$H$2:$H$201,"<"&(D$6+1)) -> 5 | E35: =COUNTIFS(Brand_Log!$CE$2:$CE$201,1,Brand_Log!$H$2:$H$201,"<"&(E$6+1)) -> 5 | G35: From the qualifying-call columns (qual_q1 to qual_q7, qual_not_excluded). The brand's word; the founder verifies at payment.
A36: Shortlisted brands (shortlist = Y) | B36: =COUNTIFS(Brand_Log!$CG$2:$CG$201,1,Brand_Log!$H$2:$H$201,"<"&(B$6+1)) -> 2 | C36: =COUNTIFS(Brand_Log!$CG$2:$CG$201,1,Brand_Log!$H$2:$H$201,"<"&(C$6+1)) -> 3 | D36: =COUNTIFS(Brand_Log!$CG$2:$CG$201,1,Brand_Log!$H$2:$H$201,"<"&(D$6+1)) -> 6 | E36: =COUNTIFS(Brand_Log!$CG$2:$CG$201,1,Brand_Log!$H$2:$H$201,"<"&(E$6+1)) -> 7 | F36: 6 | G36: Plan Phase 0 deliverable: a shortlist of 6 brands to pursue.
A37: Median quarterly sampling budget, USD (low end), as of | E37: =IF(COUNT(Brand_Log!$BV$2:$BV$201)=0,"none yet",MEDIAN(Brand_Log!$BV$2:$BV$201)) -> 2000 | F37: =COUNT(Brand_Log!$BV$2:$BV$201) -> 15 | G37: From Q2. Context: a $600 or $1,500 campaign against what they spend now.
A39: Gate 0 overall | J39: Objection counts used for the top three (as of). Ties go to the code listed first.
A40: Gate 0 result | B40: =IF(AND(B10="PASS",B27="PASS"),"PASS",IF(OR(B10="FAIL",B27="FAIL"),"FAIL",IF(OR(LEFT(B10,10)="INCOMPLETE",LEFT(B27,10)="INCOMPLETE"),"INCOMPLETE","not yet"))) -> not yet | C40: =IF(AND(C10="PASS",C27="PASS"),"PASS",IF(OR(C10="FAIL",C27="FAIL"),"FAIL",IF(OR(LEFT(C10,10)="INCOMPLETE",LEFT(C27,10)="INCOMPLETE"),"INCOMPLETE","not yet"))) -> not yet | D40: =IF(AND(D10="PASS",D27="PASS"),"PASS",IF(OR(D10="FAIL",D27="FAIL"),"FAIL",IF(OR(LEFT(D10,10)="INCOMPLETE",LEFT(D27,10)="INCOMPLETE"),"INCOMPLETE","not yet"))) -> PASS | E40: =IF(AND(E10="PASS",E27="PASS"),"PASS",IF(OR(E10="FAIL",E27="FAIL"),"FAIL",IF(OR(LEFT(E10,10)="INCOMPLETE",LEFT(E27,10)="INCOMPLETE"),"INCOMPLETE","not yet"))) -> PASS | J40: office code | K40: office label | L40: office mentions | M40: office score | O40: brand code | P40: brand label | Q40: brand mentions | R40: brand score
A41: Sentence for the Gate 0 decision (as of) | B41: ="As of "&TEXT(E$6,"yyyy-mm-dd")&": "&E9&" of "&E8&" offices said yes with a pantry owner and a receiving window (target "&F9&"); "&E26&" of "&E25&" brands would pay $"&Config!$B$14&" or more and control the budget (target "&F26&"). Gate 0: "&E40&"." -> As of 2026-12-11: 6 of 14 offices said yes with a pantry owner and a receiving window (target 5); 7 of 15 brands would pay $500 or more and control the budget (target 3). Gate 0: PASS. | J41: needs_approval | K41: I need to ask facilities, HR or someone else | L41: =COUNTIFS(Office_Log!$BV$2:$BV$201,J41,Office_Log!$H$2:$H$201,"<"&($E$6+1))+COUNTIFS(Office_Log!$BW$2:$BW$201,J41,Office_Log!$H$2:$H$201,"<"&($E$6+1))+COUNTIFS(Office_Log!$BX$2:$BX$201,J41,Office_Log!$H$2:$H$201,"<"&($E$6+1)) -> 6 | M41: =L41-1/1000 -> 5.999 | O41: seed_ourselves | P41: We can seed offices ourselves for free | Q41: =COUNTIFS(Brand_Log!$BX$2:$BX$201,O41,Brand_Log!$H$2:$H$201,"<"&($E$6+1))+COUNTIFS(Brand_Log!$BY$2:$BY$201,O41,Brand_Log!$H$2:$H$201,"<"&($E$6+1))+COUNTIFS(Brand_Log!$BZ$2:$BZ$201,O41,Brand_Log!$H$2:$H$201,"<"&($E$6+1)) -> 3 | R41: =Q41-1/1000 -> 2.999
A42: If it fails (plan) | B42: Fewer than 3 brands: test the office-paid version for three more weeks. Fewer than 5 offices: change the cluster or the office size band, not the model. | J42: existing_vendor | K42: We already have a pantry vendor or contract | L42: =COUNTIFS(Office_Log!$BV$2:$BV$201,J42,Office_Log!$H$2:$H$201,"<"&($E$6+1))+COUNTIFS(Office_Log!$BW$2:$BW$201,J42,Office_Log!$H$2:$H$201,"<"&($E$6+1))+COUNTIFS(Office_Log!$BX$2:$BX$201,J42,Office_Log!$H$2:$H$201,"<"&($E$6+1)) -> 2 | M42: =L42-2/1000 -> 1.998 | O42: price_per_sample | P42: $600 / the price is more than we pay per sample elsewhere | Q42: =COUNTIFS(Brand_Log!$BX$2:$BX$201,O42,Brand_Log!$H$2:$H$201,"<"&($E$6+1))+COUNTIFS(Brand_Log!$BY$2:$BY$201,O42,Brand_Log!$H$2:$H$201,"<"&($E$6+1))+COUNTIFS(Brand_Log!$BZ$2:$BZ$201,O42,Brand_Log!$H$2:$H$201,"<"&($E$6+1)) -> 4 | R42: =Q42-2/1000 -> 3.998
A43: If a side is INCOMPLETE (default, founder to confirm) | B43: Do not apply the failure response above to an INCOMPLETE side yet: the plan's test (5 of 15, 3 of 15) has not been run. Keep booking discovery calls on that side and read the As of column again on Fri 2026-11-20 (set Config as_of_date). The final read is Fri 2026-11-27 (Config gate0_final_read): from then a side still short reads FAIL and the response applies, the plan's 'stretch the weeks but keep the gates'. A side that passed goes ahead meanwhile. | J43: allergy_policy | K43: Allergy or food-safety worry | L43: =COUNTIFS(Office_Log!$BV$2:$BV$201,J43,Office_Log!$H$2:$H$201,"<"&($E$6+1))+COUNTIFS(Office_Log!$BW$2:$BW$201,J43,Office_Log!$H$2:$H$201,"<"&($E$6+1))+COUNTIFS(Office_Log!$BX$2:$BX$201,J43,Office_Log!$H$2:$H$201,"<"&($E$6+1)) -> 5 | M43: =L43-3/1000 -> 4.997 | O43: free_trial | P43: Can we do a free trial first? | Q43: =COUNTIFS(Brand_Log!$BX$2:$BX$201,O43,Brand_Log!$H$2:$H$201,"<"&($E$6+1))+COUNTIFS(Brand_Log!$BY$2:$BY$201,O43,Brand_Log!$H$2:$H$201,"<"&($E$6+1))+COUNTIFS(Brand_Log!$BZ$2:$BZ$201,O43,Brand_Log!$H$2:$H$201,"<"&($E$6+1)) -> 2 | R43: =Q43-3/1000 -> 1.997
...

Sheet Office_Log
A1: row_id | B1: company | C1: org_key | D1: contact_name | E1: contact_title | F1: source | G1: channel | H1: call_date | I1: call_type | J1: q1_pantry_today_verbatim | K1: pantry_vendor | L1: uses_snack_service | M1: monthly_pantry_spend_usd | N1: monthly_pantry_spend_verbatim | O1: tuesday_headcount | P1: headcount_verbatim | Q1: q3_brands_reach_out | R1: q3_free_product_verbatim | S1: q4_yes_needs_verbatim | T1: q4_no_triggers_verbatim | U1: q5_photo_and_survey | V1: q5_verbatim | W1: budget_probe_asked | X1: budget_probe_verbatim | Y1: budget_probe_low_usd | Z1: budget_probe_high_usd | AA1: referrals_given_count | AB1: referrals_given | AC1: pantry_owner_named | AD1: pantry_owner_name | AE1: pantry_owner_title | AF1: owner_can_say_yes_alone | AG1: other_approver | AH1: receiving_window | AI1: receiving_type | AJ1: coi_required | AK1: security_notes | AL1: veto_categories | AM1: veto_verbatim | AN1: objection_1 | AO1: objection_2 | AP1: objection_3 | AQ1: objections_verbatim | AR1: yes_in_principle | AS1: yes_signals | AT1: shortlist | AU1: quote_ok_to_share | AV1: note_minutes | AW1: clay_updated | AX1: notes | AY1: calc_sync_issue | AZ1: calc_org | BA1: calc_row | BB1: calc_valid | BC1: calc_conv_first | BD1: calc_latest | BE1: calc_q_yes | BF1: calc_q_yes_first | BG1: calc_yes_incomplete | BH1: calc_bp_has | BI1: calc_bp_first | BJ1: calc_bp_w1 | BK1: calc_bp_w2 | BL1: calc_bp_g0 | BM1: calc_bp_asof | BN1: calc_bp100_first | BO1: calc_spend_has | BP1: calc_spend_first | BQ1: calc_spend_asof | BR1: calc_probe_row | BS1: calc_probe_first | BT1: calc_probe_key | BU1: calc_probe_missing_text | BV1: calc_obj1 | BW1: calc_obj2 | BX1: calc_obj3 | BY1: calc_note_min | BZ1: calc_yes_any | CA1: calc_maybe | CB1: calc_maybe_first | CC1: calc_yes_any_first | CD1: calc_bp100 | CE1: calc_short | CF1: calc_short_first | CG1: calc_warm | CH1: calc_warm_first | CI1: calc_reach | CJ1: calc_reach_first | CK1: calc_alone | CL1: calc_alone_first | CM1: calc_q5y | CN1: calc_q5y_first | CO1: calc_svc | CP1: calc_svc_first | CQ1: calc_hc_has | CR1: calc_hc_first | CS1: calc_hc_asof | CT1: calc_appr | CU1: calc_quote | CV1: calc_quote_first | CW1: calc_clay_idx | CX1: calc_clay_status | CY1: calc_clay_rank | CZ1: calc_clay_yes | DA1: calc_clay_call_date | DB1: calc_ans | DC1: calc_ylast | DD1: calc_last_w1 | DE1: calc_last_w2 | DF1: calc_last_g0 | DG1: calc_last_asof | DH1: calc_stand_w1 | DI1: calc_stand_w2 | DJ1: calc_stand_g0 | DK1: calc_stand_asof | DL1: calc_qc_w1 | DM1: calc_qc_w2 | DN1: calc_qc_g0 | DO1: calc_qc_asof | DP1: calc_yac_w1 | DQ1: calc_yac_w2 | DR1: calc_yac_g0 | DS1: calc_yac_asof | DT1: calc_wd_w1 | DU1: calc_wd_w2 | DV1: calc_wd_g0 | DW1: calc_wd_asof | DX1: calc_num_text | DY1: calc_has_time | DZ1: calc_cokey | EA1: calc_grp | EB1: calc_cogrp | EC1: calc_orgfirst | ED1: calc_orgrid | EE1: calc_rid_first | EF1: calc_multi | EG1: calc_hc_last | EH1: calc_hc_org | EI1: calc_hc_out | EJ1: calc_hc_3039 | EK1: calc_qcout_w1 | EL1: calc_qcout_w2 | EM1: calc_qcout_g0 | EN1: calc_qcout_asof | EO1: calc_qc3039_w1 | EP1: calc_qc3039_w2 | EQ1: calc_qc3039_g0 | ER1: calc_qc3039_asof
A2: SAMPLE-O-001 | B2: SAMPLE Office 01 | D2: SAMPLE Contact O01 | E2: Office Manager | F2: SAMPLE warm network | G2: warm-intro | H2: 46322 | I2: video | J2: SAMPLE: pantry answer 01 | K2: SAMPLE grocery order | L2: N | M2: 800 | N2: SAMPLE: about $800 a month | O2: 60 | P2: SAMPLE: around 60 on a Tuesday | Q2: Y | R2: SAMPLE: brands email us, we ignore most | S2: SAMPLE: allergen info and no work for me | T2: SAMPLE: anything with nuts | U2: Y | V2: SAMPLE: a photo is fine | W2: Y | X2: SAMPLE: maybe $100 to $200 a month | Y2: 100 | Z2: 200 | AA2: 1 | AB2: SAMPLE Office 30 - Office Manager | AC2: Y | AD2: SAMPLE Owner O01 | AE2: Office Manager | AF2: Y | AH2: SAMPLE Tue-Wed 9-11am | AI2: front desk | AJ2: no | AK2: SAMPLE: sign in at desk | AL2: meat-snacks | AM2: SAMPLE: no jerky | AN2: allergy_policy | AQ2: SAMPLE: allergy_policy (office 01) | AR2: Y | AS2: asked_when | AT2: Y | AU2: Y | AV2: 9 | AW2: Y | AY2: =IF(TRIM($A2)="","",IF(AND(LEFT($A2,6)="SAMPLE",Config!$B$19<>"Y"),"",IF(NOT(ISNUMBER(H2)),"call_date is blank or not a date",IF(Sync!$C$5="","Clay paste is empty or has no row_id column: paste the Clay export on Clay_Offices",IF(CW2="","row_id not found in the Clay paste: add the Clay row or fix the row_id",IF(AND(ISNUMBER(CY2),CY2>=1,CY2<=5),"Clay status is "&CX2&": set call_done or later",IF(AND(BD2=1,CZ2<>BZ2),"Clay yes_in_principle should be "&BZ2,IF(AND(BD2=1,DA2<>H2),"Clay call_date should be "&TEXT(H2,"yyyy-mm-dd"),"")))))))) | AZ2: =IF(TRIM($A2)="","",IF(TRIM(C2)<>"",SUBSTITUTE(SUBSTITUTE(SUBSTITUTE(SUBSTITUTE(SUBSTITUTE(SUBSTITUTE(LOWER(TRIM(C2)),"~",""),"*",""),"?",""),"<",""),">",""),"=",""),IF(EA2<>"",EA2,IFERROR(INDEX($EA$2:$EA$201,MATCH(DZ2,$EB$2:$EB$201,0)),DZ2)))) -> sample office 01 | BA2: =ROW() -> 2 | BB2: =IF(AND(TRIM($A2)<>"",ISNUMBER(H2)),IF(AND(LEFT($A2,6)="SAMPLE",Config!$B$19<>"Y"),0,1),0) -> 1 | BC2: =IF(BB2=1,IF(COUNTIFS($AZ$2:$AZ$201,AZ2,$BB$2:$BB$201,1,$H$2:$H$201,"<"&H2)+COUNTIFS($AZ$2:$AZ$201,AZ2,$BB$2:$BB$201,1,$H$2:$H$201,H2,$BA$2:$BA$201,"<"&BA2)=0,1,0),0) -> 1 | BD2: =IF(BB2=1,IF(COUNTIFS($A$2:$A$201,$A2,$BB$2:$BB$201,1,$H$2:$H$201,">"&H2)+COUNTIFS($A$2:$A$201,$A2,$BB$2:$BB$201,1,$H$2:$H$201,H2,$BA$2:$BA$201,">"&BA2)=0,1,0),0) -> 0 | BE2: =IF(AND(BB2=1,AR2="Y",AC2="Y",TRIM(AH2)<>""),1,0) -> 1 | BF2: =IF(BE2=1,IF(COUNTIFS($AZ$2:$AZ$201,AZ2,$BE$2:$BE$201,1,$H$2:$H$201,"<"&H2)+COUNTIFS($AZ$2:$AZ$201,AZ2,$BE$2:$BE$201,1,$H$2:$H$201,H2,$BA$2:$BA$201,"<"&BA2)=0,1,0),0) -> 1 | BG2: =IF(AND(BB2=1,AR2="Y",BE2=0),1,0) -> 0 | BH2: =IF(AND(BB2=1,ISNUMBER(Y2)),1,0) -> 1 | BI2: =IF(BH2=1,IF(COUNTIFS($AZ$2:$AZ$201,AZ2,$BH$2:$BH$201,1,$H$2:$H$201,"<"&H2)+COUNTIFS($AZ$2:$AZ$201,AZ2,$BH$2:$BH$201,1,$H$2:$H$201,H2,$BA$2:$BA$201,"<"&BA2)=0,1,0),0) -> 1 | BJ2: =IF(AND(BI2=1,INT(N(H2))<=Config!$B$6),Y2,"") -> 100 | BK2: =IF(AND(BI2=1,INT(N(H2))<=Config!$B$7),Y2,"") -> 100 | BL2: =IF(AND(BI2=1,INT(N(H2))<=Config!$B$8),Y2,"") -> 100 | BM2: =IF(AND(BI2=1,INT(N(H2))<=Config!$B$5),Y2,"") -> 100 | BN2: =IF(CD2=1,IF(COUNTIFS($AZ$2:$AZ$201,AZ2,$CD$2:$CD$201,1,$H$2:$H$201,"<"&H2)+COUNTIFS($AZ$2:$AZ$201,AZ2,$CD$2:$CD$201,1,$H$2:$H$201,H2,$BA$2:$BA$201,"<"&BA2)=0,1,0),0) -> 1 | BO2: =IF(AND(BB2=1,ISNUMBER(M2)),1,0) -> 1 | BP2: =IF(BO2=1,IF(COUNTIFS($AZ$2:$AZ$201,AZ2,$BO$2:$BO$201,1,$H$2:$H$201,"<"&H2)+COUNTIFS($AZ$2:$AZ$201,AZ2,$BO$2:$BO$201,1,$H$2:$H$201,H2,$BA$2:$BA$201,"<"&BA2)=0,1,0),0) -> 1 | BQ2: =IF(AND(BP2=1,INT(N(H2))<=Config!$B$5),M2,"") -> 800 | BR2: =IF(AND(BB2=1,OR(TRIM(X2)<>"",ISNUMBER(Y2))),1,0) -> 1 | BS2: =IF(BR2=1,IF(COUNTIFS($AZ$2:$AZ$201,AZ2,$BR$2:$BR$201,1,$H$2:$H$201,"<"&H2)+COUNTIFS($AZ$2:$AZ$201,AZ2,$BR$2:$BR$201,1,$H$2:$H$201,H2,$BA$2:$BA$201,"<"&BA2)=0,1,0),0) -> 1 | BT2: =IF(BS2=1,AZ2,"") -> sample office 01 | BU2: =IF(AND(BB2=1,W2="Y",TRIM(X2)=""),1,0) -> 0 | BV2: =IF(BB2=1,AN2&"","") -> allergy_policy | BW2: =IF(BB2=1,AO2&"","") | BX2: =IF(BB2=1,AP2&"","") | BY2: =IF(AND(BB2=1,ISNUMBER(AV2),INT(N(H2))<=Config!$B$5),AV2,"") -> 9 | BZ2: =IF(BB2=1,IF(COUNTIFS($A$2:$A$201,$A2,$DC$2:$DC$201,1,$AR$2:$AR$201,"Y")>0,"Y","N"),"") -> Y | CA2: =IF(AND(BB2=1,AR2="maybe"),1,0) -> 0 | CB2: =IF(CA2=1,IF(COUNTIFS($AZ$2:$AZ$201,AZ2,$CA$2:$CA$201,1,$H$2:$H$201,"<"&H2)+COUNTIFS($AZ$2:$AZ$201,AZ2,$CA$2:$CA$201,1,$H$2:$H$201,H2,$BA$2:$BA$201,"<"&BA2)=0,1,0),0) -> 0 | CC2: =IF(AND(BB2=1,AR2="Y"),IF(COUNTIFS($AZ$2:$AZ$201,AZ2,$AR$2:$AR$201,"Y",$BB$2:$BB$201,1,$H$2:$H$201,"<"&H2)+COUNTIFS($AZ$2:$AZ$201,AZ2,$AR$2:$AR$201,"Y",$BB$2:$BB$201,1,$H$2:$H$201,H2,$BA$2:$BA$201,"<"&BA2)=0,1,0),0) -> 1 | CD2: =IF(AND(BH2=1,N(Y2)>=Config!$B$15),1,0) -> 1 | CE2: =IF(AND(BB2=1,AT2="Y"),1,0) -> 1 | CF2: =IF(CE2=1,IF(COUNTIFS($AZ$2:$AZ$201,AZ2,$CE$2:$CE$201,1,$H$2:$H$201,"<"&H2)+COUNTIFS($AZ$2:$AZ$201,AZ2,$CE$2:$CE$201,1,$H$2:$H$201,H2,$BA$2:$BA$201,"<"&BA2)=0,1,0),0) -> 1 | CG2: =IF(AND(BB2=1,G2="warm-intro"),1,0) -> 1 | CH2: =IF(CG2=1,IF(COUNTIFS($AZ$2:$AZ$201,AZ2,$CG$2:$CG$201,1,$H$2:$H$201,"<"&H2)+COUNTIFS($AZ$2:$AZ$201,AZ2,$CG$2:$CG$201,1,$H$2:$H$201,H2,$BA$2:$BA$201,"<"&BA2)=0,1,0),0) -> 1 | CI2: =IF(AND(BB2=1,Q2="Y"),1,0) -> 1 | CJ2: =IF(CI2=1,IF(COUNTIFS($AZ$2:$AZ$201,AZ2,$CI$2:$CI$201,1,$H$2:$H$201,"<"&H2)+COUNTIFS($AZ$2:$AZ$201,AZ2,$CI$2:$CI$201,1,$H$2:$H$201,H2,$BA$2:$BA$201,"<"&BA2)=0,1,0),0) -> 1 | CK2: =IF(AND(BB2=1,AF2="Y"),1,0) -> 1 | CL2: =IF(CK2=1,IF(COUNTIFS($AZ$2:$AZ$201,AZ2,$CK$2:$CK$201,1,$H$2:$H$201,"<"&H2)+COUNTIFS($AZ$2:$AZ$201,AZ2,$CK$2:$CK$201,1,$H$2:$H$201,H2,$BA$2:$BA$201,"<"&BA2)=0,1,0),0) -> 1 | CM2: =IF(AND(BB2=1,U2="Y"),1,0) -> 1 | CN2: =IF(CM2=1,IF(COUNTIFS($AZ$2:$AZ$201,AZ2,$CM$2:$CM$201,1,$H$2:$H$201,"<"&H2)+COUNTIFS($AZ$2:$AZ$201,AZ2,$CM$2:$CM$201,1,$H$2:$H$201,H2,$BA$2:$BA$201,"<"&BA2)=0,1,0),0) -> 1 | CO2: =IF(AND(BB2=1,L2="Y"),1,0) -> 0 | CP2: =IF(CO2=1,IF(COUNTIFS($AZ$2:$AZ$201,AZ2,$CO$2:$CO$201,1,$H$2:$H$201,"<"&H2)+COUNTIFS($AZ$2:$AZ$201,AZ2,$CO$2:$CO$201,1,$H$2:$H$201,H2,$BA$2:$BA$201,"<"&BA2)=0,1,0),0) -> 0 | CQ2: =IF(AND(BB2=1,ISNUMBER(O2)),1,0) -> 1 | CR2: =IF(CQ2=1,IF(COUNTIFS($AZ$2:$AZ$201,AZ2,$CQ$2:$CQ$201,1,$H$2:$H$201,"<"&H2)+COUNTIFS($AZ$2:$AZ$201,AZ2,$CQ$2:$CQ$201,1,$H$2:$H$201,H2,$BA$2:$BA$201,"<"&BA2)=0,1,0),0) -> 1 | CS2: =IF(AND(CR2=1,INT(N(H2))<=Config!$B$5),O2,"") -> 60 | CT2: =IF(AND(BB2=1,INT(N(H2))<=Config!$B$5),AG2&"","") | CU2: =IF(AND(BB2=1,AU2="Y"),1,0) -> 1 | CV2: =IF(CU2=1,IF(COUNTIFS($AZ$2:$AZ$201,AZ2,$CU$2:$CU$201,1,$H$2:$H$201,"<"&H2)+COUNTIFS($AZ$2:$AZ$201,AZ2,$CU$2:$CU$201,1,$H$2:$H$201,H2,$BA$2:$BA$201,"<"&BA2)=0,1,0),0) -> 1 | CW2: =IF(BB2=1,IFERROR(MATCH($A2,INDEX(Clay_Offices!$A$2:$FZ$601,0,Sync!$C$5),0),""),"") -> 1 | CX2: =IF(CW2="","",IFERROR(INDEX(Clay_Offices!$A$2:$FZ$601,CW2,Sync!$C$7)&"","")) -> signed | CY2: =IF(CX2="","",IFERROR(INDEX(Lists!$K$2:$K$15,MATCH(CX2,Lists!$J$2:$J$15,0)),"")) -> 9 | CZ2: =IF(CW2="","",IFERROR(INDEX(Clay_Offices!$A$2:$FZ$601,CW2,Sync!$C$17)&"","")) -> Y | DA2: =IF(CW2="","",IFERROR(N(INDEX(Clay_Offices!$A$2:$FZ$601,CW2,Sync!$C$16)),0)) -> 46332 | DB2: =IF(AND(BB2=1,OR(AR2="Y",AR2="N",AR2="maybe")),1,0) -> 1 | DC2: =IF(AND(DB2=1),IF(COUNTIFS($A$2:$A$201,$A2,$DB$2:$DB$201,1,$H$2:$H$201,">"&H2)+COUNTIFS($A$2:$A$201,$A2,$DB$2:$DB$201,1,$H$2:$H$201,H2,$BA$2:$BA$201,">"&BA2)=0,1,0),0) -> 0 | DD2: =IF(AND(DB2=1,INT(N(H2))<=Config!$B$6),IF(COUNTIFS($AZ$2:$AZ$201,AZ2,$DB$2:$DB$201,1,$H$2:$H$201,">"&H2,$H$2:$H$201,"<"&(Config!$B$6+1))+COUNTIFS($AZ$2:$AZ$201,AZ2,$DB$2:$DB$201,1,$H$2:$H$201,H2,$BA$2:$BA$201,">"&BA2)=0,1,0),0) -> 1 | DE2: =IF(AND(DB2=1,INT(N(H2))<=Config!$B$7),IF(COUNTIFS($AZ$2:$AZ$201,AZ2,$DB$2:$DB$201,1,$H$2:$H$201,">"&H2,$H$2:$H$201,"<"&(Config!$B$7+1))+COUNTIFS($AZ$2:$AZ$201,AZ2,$DB$2:$DB$201,1,$H$2:$H$201,H2,$BA$2:$BA$201,">"&BA2)=0,1,0),0) -> 0 | DF2: =IF(AND(DB2=1,INT(N(H2))<=Config!$B$8),IF(COUNTIFS($AZ$2:$AZ$201,AZ2,$DB$2:$DB$201,1,$H$2:$H$201,">"&H2,$H$2:$H$201,"<"&(Config!$B$8+1))+COUNTIFS($AZ$2:$AZ$201,AZ2,$DB$2:$DB$201,1,$H$2:$H$201,H2,$BA$2:$BA$201,">"&BA2)=0,1,0),0) -> 0 | DG2: =IF(AND(DB2=1,INT(N(H2))<=Config!$B$5),IF(COUNTIFS($AZ$2:$AZ$201,AZ2,$DB$2:$DB$201,1,$H$2:$H$201,">"&H2,$H$2:$H$201,"<"&(Config!$B$5+1))+COUNTIFS($AZ$2:$AZ$201,AZ2,$DB$2:$DB$201,1,$H$2:$H$201,H2,$BA$2:$BA$201,">"&BA2)=0,1,0),0) -> 0 | DH2: =IF(BB2=1,IF(COUNTIFS($AZ$2:$AZ$201,AZ2,$DD$2:$DD$201,1,$AR$2:$AR$201,"Y")>0,1,0),0) -> 1 | DI2: =IF(BB2=1,IF(COUNTIFS($AZ$2:$AZ$201,AZ2,$DE$2:$DE$201,1,$AR$2:$AR$201,"Y")>0,1,0),0) -> 1 | DJ2: =IF(BB2=1,IF(COUNTIFS($AZ$2:$AZ$201,AZ2,$DF$2:$DF$201,1,$AR$2:$AR$201,"Y")>0,1,0),0) -> 1 | DK2: =IF(BB2=1,IF(COUNTIFS($AZ$2:$AZ$201,AZ2,$DG$2:$DG$201,1,$AR$2:$AR$201,"Y")>0,1,0),0) -> 1 | DL2: =IF(AND(BF2=1,INT(N(H2))<=Config!$B$6,DH2=1,EI2=0),1,0) -> 1 | DM2: =IF(AND(BF2=1,INT(N(H2))<=Config!$B$7,DI2=1,EI2=0),1,0) -> 1 | DN2: =IF(AND(BF2=1,INT(N(H2))<=Config!$B$8,DJ2=1,EI2=0),1,0) -> 1 | DO2: =IF(AND(BF2=1,INT(N(H2))<=Config!$B$5,DK2=1,EI2=0),1,0) -> 1 | DP2: =IF(AND(CC2=1,INT(N(H2))<=Config!$B$6,DH2=1,EI2=0),1,0) -> 1 | DQ2: =IF(AND(CC2=1,INT(N(H2))<=Config!$B$7,DI2=1,EI2=0),1,0) -> 1 | DR2: =IF(AND(CC2=1,INT(N(H2))<=Config!$B$8,DJ2=1,EI2=0),1,0) -> 1 | DS2: =IF(AND(CC2=1,INT(N(H2))<=Config!$B$5,DK2=1,EI2=0),1,0) -> 1 | DT2: =IF(AND(CC2=1,INT(N(H2))<=Config!$B$6,DH2=0),1,0) -> 0 | DU2: =IF(AND(CC2=1,INT(N(H2))<=Config!$B$7,DI2=0),1,0) -> 0 | DV2: =IF(AND(CC2=1,INT(N(H2))<=Config!$B$8,DJ2=0),1,0) -> 0 | DW2: =IF(AND(CC2=1,INT(N(H2))<=Config!$B$5,DK2=0),1,0) -> 0 | DX2: =IF(TRIM($A2)="",0,ISTEXT(M2)+ISTEXT(O2)+ISTEXT(Y2)+ISTEXT(Z2)+ISTEXT(AA2)+ISTEXT(AV2)) -> 0 | DY2: =IF(BB2=1,IF(H2<>INT(H2),1,0),0) -> 0 | DZ2: =IF(TRIM($A2)="","",IF(TRIM(B2)="",SUBSTITUTE(SUBSTITUTE(SUBSTITUTE(SUBSTITUTE(SUBSTITUTE(SUBSTITUTE(LOWER(TRIM($A2)),"~",""),"*",""),"?",""),"<",""),">",""),"=",""),SUBSTITUTE(SUBSTITUTE(SUBSTITUTE(SUBSTITUTE(SUBSTITUTE(SUBSTITUTE(LOWER(TRIM(B2)),"~",""),"*",""),"?",""),"<",""),">",""),"=",""))) -> sample office 01 | EA2: =IF(CW2="","",IFERROR(IF(LEFT(LOWER(TRIM(INDEX(Clay_Offices!$A$2:$FZ$601,CW2,Sync!$C$19)&"")),4)="grp-",SUBSTITUTE(SUBSTITUTE(SUBSTITUTE(SUBSTITUTE(SUBSTITUTE(SUBSTITUTE(LOWER(TRIM(INDEX(Clay_Offices!$A$2:$FZ$601,CW2,Sync!$C$19)&"")),"~",""),"*",""),"?",""),"<",""),">",""),"=",""),""),"")) | EB2: =IF(EA2<>"",DZ2,"") | EC2: =IF(BC2=1,AZ2,"") -> sample office 01 | ED2: =IF(TRIM($A2)="","",IFERROR(INDEX($A$2:$A$201,MATCH(AZ2,$EC$2:$EC$201,0))&"",$A2&"")) -> SAMPLE-O-001 | EE2: =IF(BB2=1,IF(COUNTIFS($A$2:$A$201,$A2,$BB$2:$BB$201,1,$H$2:$H$201,"<"&H2)+COUNTIFS($A$2:$A$201,$A2,$BB$2:$BB$201,1,$H$2:$H$201,H2,$BA$2:$BA$201,"<"&BA2)=0,1,0),0) -> 1 | EF2: =IF(BC2=1,IF(COUNTIFS($AZ$2:$AZ$201,AZ2,$EE$2:$EE$201,1)>1,1,0),0) -> 0 | EG2: =IF(AND(CQ2=1),IF(COUNTIFS($AZ$2:$AZ$201,AZ2,$CQ$2:$CQ$201,1,$H$2:$H$201,">"&H2)+COUNTIFS($AZ$2:$AZ$201,AZ2,$CQ$2:$CQ$201,1,$H$2:$H$201,H2,$BA$2:$BA$201,">"&BA2)=0,1,0),0) -> 0 | EH2: =IF(BB2=1,IF(COUNTIFS($AZ$2:$AZ$201,AZ2,$EG$2:$EG$201,1)=0,"",SUMIFS($O$2:$O$201,$AZ$2:$AZ$201,AZ2,$EG$2:$EG$201,1)),"") -> 62 | EI2: =IF(AND(ISNUMBER(EH2),OR(N(EH2)<Config!$B$31,N(EH2)>Config!$B$33)),1,0) -> 0 | EJ2: =IF(AND(ISNUMBER(EH2),N(EH2)>=Config!$B$31,N(EH2)<Config!$B$32),1,0) -> 0 | EK2: =IF(AND(BF2=1,INT(N(H2))<=Config!$B$6,DH2=1,EI2=1),1,0) -> 0 | EL2: =IF(AND(BF2=1,INT(N(H2))<=Config!$B$7,DI2=1,EI2=1),1,0) -> 0 | EM2: =IF(AND(BF2=1,INT(N(H2))<=Config!$B$8,DJ2=1,EI2=1),1,0) -> 0 | EN2: =IF(AND(BF2=1,INT(N(H2))<=Config!$B$5,DK2=1,EI2=1),1,0) -> 0 | EO2: =IF(AND(DL2=1,EJ2=1),1,0) -> 0 | EP2: =IF(AND(DM2=1,EJ2=1),1,0) -> 0 | EQ2: =IF(AND(DN2=1,EJ2=1),1,0) -> 0 | ER2: =IF(AND(DO2=1,EJ2=1),1,0) -> 0
A3: SAMPLE-O-002 | B3: SAMPLE Office 02 | D3: SAMPLE Contact O02 | E3: Workplace Experience Manager | F3: SAMPLE Clay offices table | G3: linkedin | H3: 46323 | I3: phone | J3: SAMPLE: pantry answer 02 | K3: SAMPLE grocery order | L3: N | M3: 400 | N3: SAMPLE: about $400 a month | O3: 45 | P3: SAMPLE: around 45 on a Tuesday | Q3: N | R3: SAMPLE: brands email us, we ignore most | S3: SAMPLE: allergen info and no work for me | T3: SAMPLE: anything with nuts | U3: Y | V3: SAMPLE: a photo is fine | W3: Y | X3: SAMPLE: honestly, no budget for that | Y3: 0 | Z3: 0 | AA3: 0 | AC3: Y | AD3: SAMPLE Owner O02 | AE3: Office Manager | AF3: Y | AI3: front desk | AJ3: no | AK3: SAMPLE: sign in at desk | AL3: chocolate-candy;sparkling-soda | AM3: SAMPLE: no jerky | AN3: existing_vendor | AO3: allergy_policy | AQ3: SAMPLE: existing_vendor / allergy_policy (office 02) | AR3: Y | AS3: asked_when | AT3: Y | AV3: 12 | AW3: Y | AY3: =IF(TRIM($A3)="","",IF(AND(LEFT($A3,6)="SAMPLE",Config!$B$19<>"Y"),"",IF(NOT(ISNUMBER(H3)),"call_date is blank or not a date",IF(Sync!$C$5="","Clay paste is empty or has no row_id column: paste the Clay export on Clay_Offices",IF(CW3="","row_id not found in the Clay paste: add the Clay row or fix the row_id",IF(AND(ISNUMBER(CY3),CY3>=1,CY3<=5),"Clay status is "&CX3&": set call_done or later",IF(AND(BD3=1,CZ3<>BZ3),"Clay yes_in_principle should be "&BZ3,IF(AND(BD3=1,DA3<>H3),"Clay call_date should be "&TEXT(H3,"yyyy-mm-dd"),"")))))))) | AZ3: =IF(TRIM($A3)="","",IF(TRIM(C3)<>"",SUBSTITUTE(SUBSTITUTE(SUBSTITUTE(SUBSTITUTE(SUBSTITUTE(SUBSTITUTE(LOWER(TRIM(C3)),"~",""),"*",""),"?",""),"<",""),">",""),"=",""),IF(EA3<>"",EA3,IFERROR(INDEX($EA$2:$EA$201,MATCH(DZ3,$EB$2:$EB$201,0)),DZ3)))) -> sample office 02 | BA3: =ROW() -> 3 | BB3: =IF(AND(TRIM($A3)<>"",ISNUMBER(H3)),IF(AND(LEFT($A3,6)="SAMPLE",Config!$B$19<>"Y"),0,1),0) -> 1 | BC3: =IF(BB3=1,IF(COUNTIFS($AZ$2:$AZ$201,AZ3,$BB$2:$BB$201,1,$H$2:$H$201,"<"&H3)+COUNTIFS($AZ$2:$AZ$201,AZ3,$BB$2:$BB$201,1,$H$2:$H$201,H3,$BA$2:$BA$201,"<"&BA3)=0,1,0),0) -> 1 | BD3: =IF(BB3=1,IF(COUNTIFS($A$2:$A$201,$A3,$BB$2:$BB$201,1,$H$2:$H$201,">"&H3)+COUNTIFS($A$2:$A$201,$A3,$BB$2:$BB$201,1,$H$2:$H$201,H3,$BA$2:$BA$201,">"&BA3)=0,1,0),0) -> 1 | BE3: =IF(AND(BB3=1,AR3="Y",AC3="Y",TRIM(AH3)<>""),1,0) -> 0 | BF3: =IF(BE3=1,IF(COUNTIFS($AZ$2:$AZ$201,AZ3,$BE$2:$BE$201,1,$H$2:$H$201,"<"&H3)+COUNTIFS($AZ$2:$AZ$201,AZ3,$BE$2:$BE$201,1,$H$2:$H$201,H3,$BA$2:$BA$201,"<"&BA3)=0,1,0),0) -> 0 | BG3: =IF(AND(BB3=1,AR3="Y",BE3=0),1,0) -> 1 | BH3: =IF(AND(BB3=1,ISNUMBER(Y3)),1,0) -> 1 | BI3: =IF(BH3=1,IF(COUNTIFS($AZ$2:$AZ$201,AZ3,$BH$2:$BH$201,1,$H$2:$H$201,"<"&H3)+COUNTIFS($AZ$2:$AZ$201,AZ3,$BH$2:$BH$201,1,$H$2:$H$201,H3,$BA$2:$BA$201,"<"&BA3)=0,1,0),0) -> 1 | BJ3: =IF(AND(BI3=1,INT(N(H3))<=Config!$B$6),Y3,"") -> 0 | BK3: =IF(AND(BI3=1,INT(N(H3))<=Config!$B$7),Y3,"") -> 0 | BL3: =IF(AND(BI3=1,INT(N(H3))<=Config!$B$8),Y3,"") -> 0 | BM3: =IF(AND(BI3=1,INT(N(H3))<=Config!$B$5),Y3,"") -> 0 | BN3: =IF(CD3=1,IF(COUNTIFS($AZ$2:$AZ$201,AZ3,$CD$2:$CD$201,1,$H$2:$H$201,"<"&H3)+COUNTIFS($AZ$2:$AZ$201,AZ3,$CD$2:$CD$201,1,$H$2:$H$201,H3,$BA$2:$BA$201,"<"&BA3)=0,1,0),0) -> 0 | BO3: =IF(AND(BB3=1,ISNUMBER(M3)),1,0) -> 1 | BP3: =IF(BO3=1,IF(COUNTIFS($AZ$2:$AZ$201,AZ3,$BO$2:$BO$201,1,$H$2:$H$201,"<"&H3)+COUNTIFS($AZ$2:$AZ$201,AZ3,$BO$2:$BO$201,1,$H$2:$H$201,H3,$BA$2:$BA$201,"<"&BA3)=0,1,0),0) -> 1 | BQ3: =IF(AND(BP3=1,INT(N(H3))<=Config!$B$5),M3,"") -> 400 | BR3: =IF(AND(BB3=1,OR(TRIM(X3)<>"",ISNUMBER(Y3))),1,0) -> 1 | BS3: =IF(BR3=1,IF(COUNTIFS($AZ$2:$AZ$201,AZ3,$BR$2:$BR$201,1,$H$2:$H$201,"<"&H3)+COUNTIFS($AZ$2:$AZ$201,AZ3,$BR$2:$BR$201,1,$H$2:$H$201,H3,$BA$2:$BA$201,"<"&BA3)=0,1,0),0) -> 1 | BT3: =IF(BS3=1,AZ3,"") -> sample office 02 | BU3: =IF(AND(BB3=1,W3="Y",TRIM(X3)=""),1,0) -> 0 | BV3: =IF(BB3=1,AN3&"","") -> existing_vendor | BW3: =IF(BB3=1,AO3&"","") -> allergy_policy | BX3: =IF(BB3=1,AP3&"","") | BY3: =IF(AND(BB3=1,ISNUMBER(AV3),INT(N(H3))<=Config!$B$5),AV3,"") -> 12 | BZ3: =IF(BB3=1,IF(COUNTIFS($A$2:$A$201,$A3,$DC$2:$DC$201,1,$AR$2:$AR$201,"Y")>0,"Y","N"),"") -> Y | CA3: =IF(AND(BB3=1,AR3="maybe"),1,0) -> 0 | CB3: =IF(CA3=1,IF(COUNTIFS($AZ$2:$AZ$201,AZ3,$CA$2:$CA$201,1,$H$2:$H$201,"<"&H3)+COUNTIFS($AZ$2:$AZ$201,AZ3,$CA$2:$CA$201,1,$H$2:$H$201,H3,$BA$2:$BA$201,"<"&BA3)=0,1,0),0) -> 0 | CC3: =IF(AND(BB3=1,AR3="Y"),IF(COUNTIFS($AZ$2:$AZ$201,AZ3,$AR$2:$AR$201,"Y",$BB$2:$BB$201,1,$H$2:$H$201,"<"&H3)+COUNTIFS($AZ$2:$AZ$201,AZ3,$AR$2:$AR$201,"Y",$BB$2:$BB$201,1,$H$2:$H$201,H3,$BA$2:$BA$201,"<"&BA3)=0,1,0),0) -> 1 | CD3: =IF(AND(BH3=1,N(Y3)>=Config!$B$15),1,0) -> 0 | CE3: =IF(AND(BB3=1,AT3="Y"),1,0) -> 1 | CF3: =IF(CE3=1,IF(COUNTIFS($AZ$2:$AZ$201,AZ3,$CE$2:$CE$201,1,$H$2:$H$201,"<"&H3)+COUNTIFS($AZ$2:$AZ$201,AZ3,$CE$2:$CE$201,1,$H$2:$H$201,H3,$BA$2:$BA$201,"<"&BA3)=0,1,0),0) -> 1 | CG3: =IF(AND(BB3=1,G3="warm-intro"),1,0) -> 0 | CH3: =IF(CG3=1,IF(COUNTIFS($AZ$2:$AZ$201,AZ3,$CG$2:$CG$201,1,$H$2:$H$201,"<"&H3)+COUNTIFS($AZ$2:$AZ$201,AZ3,$CG$2:$CG$201,1,$H$2:$H$201,H3,$BA$2:$BA$201,"<"&BA3)=0,1,0),0) -> 0 | CI3: =IF(AND(BB3=1,Q3="Y"),1,0) -> 0 | CJ3: =IF(CI3=1,IF(COUNTIFS($AZ$2:$AZ$201,AZ3,$CI$2:$CI$201,1,$H$2:$H$201,"<"&H3)+COUNTIFS($AZ$2:$AZ$201,AZ3,$CI$2:$CI$201,1,$H$2:$H$201,H3,$BA$2:$BA$201,"<"&BA3)=0,1,0),0) -> 0 | CK3: =IF(AND(BB3=1,AF3="Y"),1,0) -> 1 | CL3: =IF(CK3=1,IF(COUNTIFS($AZ$2:$AZ$201,AZ3,$CK$2:$CK$201,1,$H$2:$H$201,"<"&H3)+COUNTIFS($AZ$2:$AZ$201,AZ3,$CK$2:$CK$201,1,$H$2:$H$201,H3,$BA$2:$BA$201,"<"&BA3)=0,1,0),0) -> 1 | CM3: =IF(AND(BB3=1,U3="Y"),1,0) -> 1 | CN3: =IF(CM3=1,IF(COUNTIFS($AZ$2:$AZ$201,AZ3,$CM$2:$CM$201,1,$H$2:$H$201,"<"&H3)+COUNTIFS($AZ$2:$AZ$201,AZ3,$CM$2:$CM$201,1,$H$2:$H$201,H3,$BA$2:$BA$201,"<"&BA3)=0,1,0),0) -> 1 | CO3: =IF(AND(BB3=1,L3="Y"),1,0) -> 0 | CP3: =IF(CO3=1,IF(COUNTIFS($AZ$2:$AZ$201,AZ3,$CO$2:$CO$201,1,$H$2:$H$201,"<"&H3)+COUNTIFS($AZ$2:$AZ$201,AZ3,$CO$2:$CO$201,1,$H$2:$H$201,H3,$BA$2:$BA$201,"<"&BA3)=0,1,0),0) -> 0 | CQ3: =IF(AND(BB3=1,ISNUMBER(O3)),1,0) -> 1 | CR3: =IF(CQ3=1,IF(COUNTIFS($AZ$2:$AZ$201,AZ3,$CQ$2:$CQ$201,1,$H$2:$H$201,"<"&H3)+COUNTIFS($AZ$2:$AZ$201,AZ3,$CQ$2:$CQ$201,1,$H$2:$H$201,H3,$BA$2:$BA$201,"<"&BA3)=0,1,0),0) -> 1 | CS3: =IF(AND(CR3=1,INT(N(H3))<=Config!$B$5),O3,"") -> 45 | CT3: =IF(AND(BB3=1,INT(N(H3))<=Config!$B$5),AG3&"","") | CU3: =IF(AND(BB3=1,AU3="Y"),1,0) -> 0 | CV3: =IF(CU3=1,IF(COUNTIFS($AZ$2:$AZ$201,AZ3,$CU$2:$CU$201,1,$H$2:$H$201,"<"&H3)+COUNTIFS($AZ$2:$AZ$201,AZ3,$CU$2:$CU$201,1,$H$2:$H$201,H3,$BA$2:$BA$201,"<"&BA3)=0,1,0),0) -> 0 | CW3: =IF(BB3=1,IFERROR(MATCH($A3,INDEX(Clay_Offices!$A$2:$FZ$601,0,Sync!$C$5),0),""),"") -> 2 | CX3: =IF(CW3="","",IFERROR(INDEX(Clay_Offices!$A$2:$FZ$601,CW3,Sync!$C$7)&"","")) -> yes_in_principle | CY3: =IF(CX3="","",IFERROR(INDEX(Lists!$K$2:$K$15,MATCH(CX3,Lists!$J$2:$J$15,0)),"")) -> 7 | CZ3: =IF(CW3="","",IFERROR(INDEX(Clay_Offices!$A$2:$FZ$601,CW3,Sync!$C$17)&"","")) -> Y | DA3: =IF(CW3="","",IFERROR(N(INDEX(Clay_Offices!$A$2:$FZ$601,CW3,Sync!$C$16)),0)) -> 46323 | DB3: =IF(AND(BB3=1,OR(AR3="Y",AR3="N",AR3="maybe")),1,0) -> 1 | DC3: =IF(AND(DB3=1),IF(COUNTIFS($A$2:$A$201,$A3,$DB$2:$DB$201,1,$H$2:$H$201,">"&H3)+COUNTIFS($A$2:$A$201,$A3,$DB$2:$DB$201,1,$H$2:$H$201,H3,$BA$2:$BA$201,">"&BA3)=0,1,0),0) -> 1 | DD3: =IF(AND(DB3=1,INT(N(H3))<=Config!$B$6),IF(COUNTIFS($AZ$2:$AZ$201,AZ3,$DB$2:$DB$201,1,$H$2:$H$201,">"&H3,$H$2:$H$201,"<"&(Config!$B$6+1))+COUNTIFS($AZ$2:$AZ$201,AZ3,$DB$2:$DB$201,1,$H$2:$H$201,H3,$BA$2:$BA$201,">"&BA3)=0,1,0),0) -> 1 | DE3: =IF(AND(DB3=1,INT(N(H3))<=Config!$B$7),IF(COUNTIFS($AZ$2:$AZ$201,AZ3,$DB$2:$DB$201,1,$H$2:$H$201,">"&H3,$H$2:$H$201,"<"&(Config!$B$7+1))+COUNTIFS($AZ$2:$AZ$201,AZ3,$DB$2:$DB$201,1,$H$2:$H$201,H3,$BA$2:$BA$201,">"&BA3)=0,1,0),0) -> 1 | DF3: =IF(AND(DB3=1,INT(N(H3))<=Config!$B$8),IF(COUNTIFS($AZ$2:$AZ$201,AZ3,$DB$2:$DB$201,1,$H$2:$H$201,">"&H3,$H$2:$H$201,"<"&(Config!$B$8+1))+COUNTIFS($AZ$2:$AZ$201,AZ3,$DB$2:$DB$201,1,$H$2:$H$201,H3,$BA$2:$BA$201,">"&BA3)=0,1,0),0) -> 1 | DG3: =IF(AND(DB3=1,INT(N(H3))<=Config!$B$5),IF(COUNTIFS($AZ$2:$AZ$201,AZ3,$DB$2:$DB$201,1,$H$2:$H$201,">"&H3,$H$2:$H$201,"<"&(Config!$B$5+1))+COUNTIFS($AZ$2:$AZ$201,AZ3,$DB$2:$DB$201,1,$H$2:$H$201,H3,$BA$2:$BA$201,">"&BA3)=0,1,0),0) -> 1 | DH3: =IF(BB3=1,IF(COUNTIFS($AZ$2:$AZ$201,AZ3,$DD$2:$DD$201,1,$AR$2:$AR$201,"Y")>0,1,0),0) -> 1 | DI3: =IF(BB3=1,IF(COUNTIFS($AZ$2:$AZ$201,AZ3,$DE$2:$DE$201,1,$AR$2:$AR$201,"Y")>0,1,0),0) -> 1 | DJ3: =IF(BB3=1,IF(COUNTIFS($AZ$2:$AZ$201,AZ3,$DF$2:$DF$201,1,$AR$2:$AR$201,"Y")>0,1,0),0) -> 1 | DK3: =IF(BB3=1,IF(COUNTIFS($AZ$2:$AZ$201,AZ3,$DG$2:$DG$201,1,$AR$2:$AR$201,"Y")>0,1,0),0) -> 1 | DL3: =IF(AND(BF3=1,INT(N(H3))<=Config!$B$6,DH3=1,EI3=0),1,0) -> 0 | DM3: =IF(AND(BF3=1,INT(N(H3))<=Config!$B$7,DI3=1,EI3=0),1,0) -> 0 | DN3: =IF(AND(BF3=1,INT(N(H3))<=Config!$B$8,DJ3=1,EI3=0),1,0) -> 0 | DO3: =IF(AND(BF3=1,INT(N(H3))<=Config!$B$5,DK3=1,EI3=0),1,0) -> 0 | DP3: =IF(AND(CC3=1,INT(N(H3))<=Config!$B$6,DH3=1,EI3=0),1,0) -> 1 | DQ3: =IF(AND(CC3=1,INT(N(H3))<=Config!$B$7,DI3=1,EI3=0),1,0) -> 1 | DR3: =IF(AND(CC3=1,INT(N(H3))<=Config!$B$8,DJ3=1,EI3=0),1,0) -> 1 | DS3: =IF(AND(CC3=1,INT(N(H3))<=Config!$B$5,DK3=1,EI3=0),1,0) -> 1 | DT3: =IF(AND(CC3=1,INT(N(H3))<=Config!$B$6,DH3=0),1,0) -> 0 | DU3: =IF(AND(CC3=1,INT(N(H3))<=Config!$B$7,DI3=0),1,0) -> 0 | DV3: =IF(AND(CC3=1,INT(N(H3))<=Config!$B$8,DJ3=0),1,0) -> 0 | DW3: =IF(AND(CC3=1,INT(N(H3))<=Config!$B$5,DK3=0),1,0) -> 0 | DX3: =IF(TRIM($A3)="",0,ISTEXT(M3)+ISTEXT(O3)+ISTEXT(Y3)+ISTEXT(Z3)+ISTEXT(AA3)+ISTEXT(AV3)) -> 0 | DY3: =IF(BB3=1,IF(H3<>INT(H3),1,0),0) -> 0 | DZ3: =IF(TRIM($A3)="","",IF(TRIM(B3)="",SUBSTITUTE(SUBSTITUTE(SUBSTITUTE(SUBSTITUTE(SUBSTITUTE(SUBSTITUTE(LOWER(TRIM($A3)),"~",""),"*",""),"?",""),"<",""),">",""),"=",""),SUBSTITUTE(SUBSTITUTE(SUBSTITUTE(SUBSTITUTE(SUBSTITUTE(SUBSTITUTE(LOWER(TRIM(B3)),"~",""),"*",""),"?",""),"<",""),">",""),"=",""))) -> sample office 02 | EA3: =IF(CW3="","",IFERROR(IF(LEFT(LOWER(TRIM(INDEX(Clay_Offices!$A$2:$FZ$601,CW3,Sync!$C$19)&"")),4)="grp-",SUBSTITUTE(SUBSTITUTE(SUBSTITUTE(SUBSTITUTE(SUBSTITUTE(SUBSTITUTE(LOWER(TRIM(INDEX(Clay_Offices!$A$2:$FZ$601,CW3,Sync!$C$19)&"")),"~",""),"*",""),"?",""),"<",""),">",""),"=",""),""),"")) | EB3: =IF(EA3<>"",DZ3,"") | EC3: =IF(BC3=1,AZ3,"") -> sample office 02 | ED3: =IF(TRIM($A3)="","",IFERROR(INDEX($A$2:$A$201,MATCH(AZ3,$EC$2:$EC$201,0))&"",$A3&"")) -> SAMPLE-O-002 | EE3: =IF(BB3=1,IF(COUNTIFS($A$2:$A$201,$A3,$BB$2:$BB$201,1,$H$2:$H$201,"<"&H3)+COUNTIFS($A$2:$A$201,$A3,$BB$2:$BB$201,1,$H$2:$H$201,H3,$BA$2:$BA$201,"<"&BA3)=0,1,0),0) -> 1 | EF3: =IF(BC3=1,IF(COUNTIFS($AZ$2:$AZ$201,AZ3,$EE$2:$EE$201,1)>1,1,0),0) -> 0 | EG3: =IF(AND(CQ3=1),IF(COUNTIFS($AZ$2:$AZ$201,AZ3,$CQ$2:$CQ$201,1,$H$2:$H$201,">"&H3)+COUNTIFS($AZ$2:$AZ$201,AZ3,$CQ$2:$CQ$201,1,$H$2:$H$201,H3,$BA$2:$BA$201,">"&BA3)=0,1,0),0) -> 1 | EH3: =IF(BB3=1,IF(COUNTIFS($AZ$2:$AZ$201,AZ3,$EG$2:$EG$201,1)=0,"",SUMIFS($O$2:$O$201,$AZ$2:$AZ$201,AZ3,$EG$2:$EG$201,1)),"") -> 45 | EI3: =IF(AND(ISNUMBER(EH3),OR(N(EH3)<Config!$B$31,N(EH3)>Config!$B$33)),1,0) -> 0 | EJ3: =IF(AND(ISNUMBER(EH3),N(EH3)>=Config!$B$31,N(EH3)<Config!$B$32),1,0) -> 0 | EK3: =IF(AND(BF3=1,INT(N(H3))<=Config!$B$6,DH3=1,EI3=1),1,0) -> 0 | EL3: =IF(AND(BF3=1,INT(N(H3))<=Config!$B$7,DI3=1,EI3=1),1,0) -> 0 | EM3: =IF(AND(BF3=1,INT(N(H3))<=Config!$B$8,DJ3=1,EI3=1),1,0) -> 0 | EN3: =IF(AND(BF3=1,INT(N(H3))<=Config!$B$5,DK3=1,EI3=1),1,0) -> 0 | EO3: =IF(AND(DL3=1,EJ3=1),1,0) -> 0 | EP3: =IF(AND(DM3=1,EJ3=1),1,0) -> 0 | EQ3: =IF(AND(DN3=1,EJ3=1),1,0) -> 0 | ER3: =IF(AND(DO3=1,EJ3=1),1,0) -> 0
A4: SAMPLE-O-003 | B4: SAMPLE Office 03 | D4: SAMPLE Contact O03 | E4: Office Manager | F4: SAMPLE Clay offices table | G4: walk-in | H4: 46324 | I4: walk-in | J4: SAMPLE: pantry answer 03 | K4: SAMPLE snack service | L4: Y | O4: 120 | P4: SAMPLE: around 120 on a Tuesday | Q4: Y | R4: SAMPLE: brands email us, we ignore most | S4: SAMPLE: allergen info and no work for me | T4: SAMPLE: anything with nuts | U4: maybe | V4: SAMPLE: a photo is fine | W4: Y | X4: SAMPLE: I don't know | AA4: 0 | AC4: N | AF4: N | AG4: facilities | AI4: walk-up | AJ4: no | AL4: meat-snacks | AM4: SAMPLE: no jerky | AN4: vendor_fatigue | AQ4: SAMPLE: vendor_fatigue (office 03) | AR4: N | AV4: 8 | AW4: Y | AY4: =IF(TRIM($A4)="","",IF(AND(LEFT($A4,6)="SAMPLE",Config!$B$19<>"Y"),"",IF(NOT(ISNUMBER(H4)),"call_date is blank or not a date",IF(Sync!$C$5="","Clay paste is empty or has no row_id column: paste the Clay export on Clay_Offices",IF(CW4="","row_id not found in the Clay paste: add the Clay row or fix the row_id",IF(AND(ISNUMBER(CY4),CY4>=1,CY4<=5),"Clay status is "&CX4&": set call_done or later",IF(AND(BD4=1,CZ4<>BZ4),"Clay yes_in_principle should be "&BZ4,IF(AND(BD4=1,DA4<>H4),"Clay call_date should be "&TEXT(H4,"yyyy-mm-dd"),"")))))))) | AZ4: =IF(TRIM($A4)="","",IF(TRIM(C4)<>"",SUBSTITUTE(SUBSTITUTE(SUBSTITUTE(SUBSTITUTE(SUBSTITUTE(SUBSTITUTE(LOWER(TRIM(C4)),"~",""),"*",""),"?",""),"<",""),">",""),"=",""),IF(EA4<>"",EA4,IFERROR(INDEX($EA$2:$EA$201,MATCH(DZ4,$EB$2:$EB$201,0)),DZ4)))) -> sample office 03 | BA4: =ROW() -> 4 | BB4: =IF(AND(TRIM($A4)<>"",ISNUMBER(H4)),IF(AND(LEFT($A4,6)="SAMPLE",Config!$B$19<>"Y"),0,1),0) -> 1 | BC4: =IF(BB4=1,IF(COUNTIFS($AZ$2:$AZ$201,AZ4,$BB$2:$BB$201,1,$H$2:$H$201,"<"&H4)+COUNTIFS($AZ$2:$AZ$201,AZ4,$BB$2:$BB$201,1,$H$2:$H$201,H4,$BA$2:$BA$201,"<"&BA4)=0,1,0),0) -> 1 | BD4: =IF(BB4=1,IF(COUNTIFS($A$2:$A$201,$A4,$BB$2:$BB$201,1,$H$2:$H$201,">"&H4)+COUNTIFS($A$2:$A$201,$A4,$BB$2:$BB$201,1,$H$2:$H$201,H4,$BA$2:$BA$201,">"&BA4)=0,1,0),0) -> 1 | BE4: =IF(AND(BB4=1,AR4="Y",AC4="Y",TRIM(AH4)<>""),1,0) -> 0 | BF4: =IF(BE4=1,IF(COUNTIFS($AZ$2:$AZ$201,AZ4,$BE$2:$BE$201,1,$H$2:$H$201,"<"&H4)+COUNTIFS($AZ$2:$AZ$201,AZ4,$BE$2:$BE$201,1,$H$2:$H$201,H4,$BA$2:$BA$201,"<"&BA4)=0,1,0),0) -> 0 | BG4: =IF(AND(BB4=1,AR4="Y",BE4=0),1,0) -> 0 | BH4: =IF(AND(BB4=1,ISNUMBER(Y4)),1,0) -> 0 | BI4: =IF(BH4=1,IF(COUNTIFS($AZ$2:$AZ$201,AZ4,$BH$2:$BH$201,1,$H$2:$H$201,"<"&H4)+COUNTIFS($AZ$2:$AZ$201,AZ4,$BH$2:$BH$201,1,$H$2:$H$201,H4,$BA$2:$BA$201,"<"&BA4)=0,1,0),0) -> 0 | BJ4: =IF(AND(BI4=1,INT(N(H4))<=Config!$B$6),Y4,"") | BK4: =IF(AND(BI4=1,INT(N(H4))<=Config!$B$7),Y4,"") | BL4: =IF(AND(BI4=1,INT(N(H4))<=Config!$B$8),Y4,"") | BM4: =IF(AND(BI4=1,INT(N(H4))<=Config!$B$5),Y4,"") | BN4: =IF(CD4=1,IF(COUNTIFS($AZ$2:$AZ$201,AZ4,$CD$2:$CD$201,1,$H$2:$H$201,"<"&H4)+COUNTIFS($AZ$2:$AZ$201,AZ4,$CD$2:$CD$201,1,$H$2:$H$201,H4,$BA$2:$BA$201,"<"&BA4)=0,1,0),0) -> 0 | BO4: =IF(AND(BB4=1,ISNUMBER(M4)),1,0) -> 0 | BP4: =IF(BO4=1,IF(COUNTIFS($AZ$2:$AZ$201,AZ4,$BO$2:$BO$201,1,$H$2:$H$201,"<"&H4)+COUNTIFS($AZ$2:$AZ$201,AZ4,$BO$2:$BO$201,1,$H$2:$H$201,H4,$BA$2:$BA$201,"<"&BA4)=0,1,0),0) -> 0 | BQ4: =IF(AND(BP4=1,INT(N(H4))<=Config!$B$5),M4,"") | BR4: =IF(AND(BB4=1,OR(TRIM(X4)<>"",ISNUMBER(Y4))),1,0) -> 1 | BS4: =IF(BR4=1,IF(COUNTIFS($AZ$2:$AZ$201,AZ4,$BR$2:$BR$201,1,$H$2:$H$201,"<"&H4)+COUNTIFS($AZ$2:$AZ$201,AZ4,$BR$2:$BR$201,1,$H$2:$H$201,H4,$BA$2:$BA$201,"<"&BA4)=0,1,0),0) -> 1 | BT4: =IF(BS4=1,AZ4,"") -> sample office 03 | BU4: =IF(AND(BB4=1,W4="Y",TRIM(X4)=""),1,0) -> 0 | BV4: =IF(BB4=1,AN4&"","") -> vendor_fatigue | BW4: =IF(BB4=1,AO4&"","") | BX4: =IF(BB4=1,AP4&"","") | BY4: =IF(AND(BB4=1,ISNUMBER(AV4),INT(N(H4))<=Config!$B$5),AV4,"") -> 8 | BZ4: =IF(BB4=1,IF(COUNTIFS($A$2:$A$201,$A4,$DC$2:$DC$201,1,$AR$2:$AR$201,"Y")>0,"Y","N"),"") -> N | CA4: =IF(AND(BB4=1,AR4="maybe"),1,0) -> 0 | CB4: =IF(CA4=1,IF(COUNTIFS($AZ$2:$AZ$201,AZ4,$CA$2:$CA$201,1,$H$2:$H$201,"<"&H4)+COUNTIFS($AZ$2:$AZ$201,AZ4,$CA$2:$CA$201,1,$H$2:$H$201,H4,$BA$2:$BA$201,"<"&BA4)=0,1,0),0) -> 0 | CC4: =IF(AND(BB4=1,AR4="Y"),IF(COUNTIFS($AZ$2:$AZ$201,AZ4,$AR$2:$AR$201,"Y",$BB$2:$BB$201,1,$H$2:$H$201,"<"&H4)+COUNTIFS($AZ$2:$AZ$201,AZ4,$AR$2:$AR$201,"Y",$BB$2:$BB$201,1,$H$2:$H$201,H4,$BA$2:$BA$201,"<"&BA4)=0,1,0),0) -> 0 | CD4: =IF(AND(BH4=1,N(Y4)>=Config!$B$15),1,0) -> 0 | CE4: =IF(AND(BB4=1,AT4="Y"),1,0) -> 0 | CF4: =IF(CE4=1,IF(COUNTIFS($AZ$2:$AZ$201,AZ4,$CE$2:$CE$201,1,$H$2:$H$201,"<"&H4)+COUNTIFS($AZ$2:$AZ$201,AZ4,$CE$2:$CE$201,1,$H$2:$H$201,H4,$BA$2:$BA$201,"<"&BA4)=0,1,0),0) -> 0 | CG4: =IF(AND(BB4=1,G4="warm-intro"),1,0) -> 0 | CH4: =IF(CG4=1,IF(COUNTIFS($AZ$2:$AZ$201,AZ4,$CG$2:$CG$201,1,$H$2:$H$201,"<"&H4)+COUNTIFS($AZ$2:$AZ$201,AZ4,$CG$2:$CG$201,1,$H$2:$H$201,H4,$BA$2:$BA$201,"<"&BA4)=0,1,0),0) -> 0 | CI4: =IF(AND(BB4=1,Q4="Y"),1,0) -> 1 | CJ4: =IF(CI4=1,IF(COUNTIFS($AZ$2:$AZ$201,AZ4,$CI$2:$CI$201,1,$H$2:$H$201,"<"&H4)+COUNTIFS($AZ$2:$AZ$201,AZ4,$CI$2:$CI$201,1,$H$2:$H$201,H4,$BA$2:$BA$201,"<"&BA4)=0,1,0),0) -> 1 | CK4: =IF(AND(BB4=1,AF4="Y"),1,0) -> 0 | CL4: =IF(CK4=1,IF(COUNTIFS($AZ$2:$AZ$201,AZ4,$CK$2:$CK$201,1,$H$2:$H$201,"<"&H4)+COUNTIFS($AZ$2:$AZ$201,AZ4,$CK$2:$CK$201,1,$H$2:$H$201,H4,$BA$2:$BA$201,"<"&BA4)=0,1,0),0) -> 0 | CM4: =IF(AND(BB4=1,U4="Y"),1,0) -> 0 | CN4: =IF(CM4=1,IF(COUNTIFS($AZ$2:$AZ$201,AZ4,$CM$2:$CM$201,1,$H$2:$H$201,"<"&H4)+COUNTIFS($AZ$2:$AZ$201,AZ4,$CM$2:$CM$201,1,$H$2:$H$201,H4,$BA$2:$BA$201,"<"&BA4)=0,1,0),0) -> 0 | CO4: =IF(AND(BB4=1,L4="Y"),1,0) -> 1 | CP4: =IF(CO4=1,IF(COUNTIFS($AZ$2:$AZ$201,AZ4,$CO$2:$CO$201,1,$H$2:$H$201,"<"&H4)+COUNTIFS($AZ$2:$AZ$201,AZ4,$CO$2:$CO$201,1,$H$2:$H$201,H4,$BA$2:$BA$201,"<"&BA4)=0,1,0),0) -> 1 | CQ4: =IF(AND(BB4=1,ISNUMBER(O4)),1,0) -> 1 | CR4: =IF(CQ4=1,IF(COUNTIFS($AZ$2:$AZ$201,AZ4,$CQ$2:$CQ$201,1,$H$2:$H$201,"<"&H4)+COUNTIFS($AZ$2:$AZ$201,AZ4,$CQ$2:$CQ$201,1,$H$2:$H$201,H4,$BA$2:$BA$201,"<"&BA4)=0,1,0),0) -> 1 | CS4: =IF(AND(CR4=1,INT(N(H4))<=Config!$B$5),O4,"") -> 120 | CT4: =IF(AND(BB4=1,INT(N(H4))<=Config!$B$5),AG4&"","") -> facilities | CU4: =IF(AND(BB4=1,AU4="Y"),1,0) -> 0 | CV4: =IF(CU4=1,IF(COUNTIFS($AZ$2:$AZ$201,AZ4,$CU$2:$CU$201,1,$H$2:$H$201,"<"&H4)+COUNTIFS($AZ$2:$AZ$201,AZ4,$CU$2:$CU$201,1,$H$2:$H$201,H4,$BA$2:$BA$201,"<"&BA4)=0,1,0),0) -> 0 | CW4: =IF(BB4=1,IFERROR(MATCH($A4,INDEX(Clay_Offices!$A$2:$FZ$601,0,Sync!$C$5),0),""),"") -> 3 | CX4: =IF(CW4="","",IFERROR(INDEX(Clay_Offices!$A$2:$FZ$601,CW4,Sync!$C$7)&"","")) -> call_done | CY4: =IF(CX4="","",IFERROR(INDEX(Lists!$K$2:$K$15,MATCH(CX4,Lists!$J$2:$J$15,0)),"")) -> 6 | CZ4: =IF(CW4="","",IFERROR(INDEX(Clay_Offices!$A$2:$FZ$601,CW4,Sync!$C$17)&"","")) -> N | DA4: =IF(CW4="","",IFERROR(N(INDEX(Clay_Offices!$A$2:$FZ$601,CW4,Sync!$C$16)),0)) -> 46324 | DB4: =IF(AND(BB4=1,OR(AR4="Y",AR4="N",AR4="maybe")),1,0) -> 1 | DC4: =IF(AND(DB4=1),IF(COUNTIFS($A$2:$A$201,$A4,$DB$2:$DB$201,1,$H$2:$H$201,">"&H4)+COUNTIFS($A$2:$A$201,$A4,$DB$2:$DB$201,1,$H$2:$H$201,H4,$BA$2:$BA$201,">"&BA4)=0,1,0),0) -> 1 | DD4: =IF(AND(DB4=1,INT(N(H4))<=Config!$B$6),IF(COUNTIFS($AZ$2:$AZ$201,AZ4,$DB$2:$DB$201,1,$H$2:$H$201,">"&H4,$H$2:$H$201,"<"&(Config!$B$6+1))+COUNTIFS($AZ$2:$AZ$201,AZ4,$DB$2:$DB$201,1,$H$2:$H$201,H4,$BA$2:$BA$201,">"&BA4)=0,1,0),0) -> 1 | DE4: =IF(AND(DB4=1,INT(N(H4))<=Config!$B$7),IF(COUNTIFS($AZ$2:$AZ$201,AZ4,$DB$2:$DB$201,1,$H$2:$H$201,">"&H4,$H$2:$H$201,"<"&(Config!$B$7+1))+COUNTIFS($AZ$2:$AZ$201,AZ4,$DB$2:$DB$201,1,$H$2:$H$201,H4,$BA$2:$BA$201,">"&BA4)=0,1,0),0) -> 1 | DF4: =IF(AND(DB4=1,INT(N(H4))<=Config!$B$8),IF(COUNTIFS($AZ$2:$AZ$201,AZ4,$DB$2:$DB$201,1,$H$2:$H$201,">"&H4,$H$2:$H$201,"<"&(Config!$B$8+1))+COUNTIFS($AZ$2:$AZ$201,AZ4,$DB$2:$DB$201,1,$H$2:$H$201,H4,$BA$2:$BA$201,">"&BA4)=0,1,0),0) -> 1 | DG4: =IF(AND(DB4=1,INT(N(H4))<=Config!$B$5),IF(COUNTIFS($AZ$2:$AZ$201,AZ4,$DB$2:$DB$201,1,$H$2:$H$201,">"&H4,$H$2:$H$201,"<"&(Config!$B$5+1))+COUNTIFS($AZ$2:$AZ$201,AZ4,$DB$2:$DB$201,1,$H$2:$H$201,H4,$BA$2:$BA$201,">"&BA4)=0,1,0),0) -> 1 | DH4: =IF(BB4=1,IF(COUNTIFS($AZ$2:$AZ$201,AZ4,$DD$2:$DD$201,1,$AR$2:$AR$201,"Y")>0,1,0),0) -> 0 | DI4: =IF(BB4=1,IF(COUNTIFS($AZ$2:$AZ$201,AZ4,$DE$2:$DE$201,1,$AR$2:$AR$201,"Y")>0,1,0),0) -> 0 | DJ4: =IF(BB4=1,IF(COUNTIFS($AZ$2:$AZ$201,AZ4,$DF$2:$DF$201,1,$AR$2:$AR$201,"Y")>0,1,0),0) -> 0 | DK4: =IF(BB4=1,IF(COUNTIFS($AZ$2:$AZ$201,AZ4,$DG$2:$DG$201,1,$AR$2:$AR$201,"Y")>0,1,0),0) -> 0 | DL4: =IF(AND(BF4=1,INT(N(H4))<=Config!$B$6,DH4=1,EI4=0),1,0) -> 0 | DM4: =IF(AND(BF4=1,INT(N(H4))<=Config!$B$7,DI4=1,EI4=0),1,0) -> 0 | DN4: =IF(AND(BF4=1,INT(N(H4))<=Config!$B$8,DJ4=1,EI4=0),1,0) -> 0 | DO4: =IF(AND(BF4=1,INT(N(H4))<=Config!$B$5,DK4=1,EI4=0),1,0) -> 0 | DP4: =IF(AND(CC4=1,INT(N(H4))<=Config!$B$6,DH4=1,EI4=0),1,0) -> 0 | DQ4: =IF(AND(CC4=1,INT(N(H4))<=Config!$B$7,DI4=1,EI4=0),1,0) -> 0 | DR4: =IF(AND(CC4=1,INT(N(H4))<=Config!$B$8,DJ4=1,EI4=0),1,0) -> 0 | DS4: =IF(AND(CC4=1,INT(N(H4))<=Config!$B$5,DK4=1,EI4=0),1,0) -> 0 | DT4: =IF(AND(CC4=1,INT(N(H4))<=Config!$B$6,DH4=0),1,0) -> 0 | DU4: =IF(AND(CC4=1,INT(N(H4))<=Config!$B$7,DI4=0),1,0) -> 0 | DV4: =IF(AND(CC4=1,INT(N(H4))<=Config!$B$8,DJ4=0),1,0) -> 0 | DW4: =IF(AND(CC4=1,INT(N(H4))<=Config!$B$5,DK4=0),1,0) -> 0 | DX4: =IF(TRIM($A4)="",0,ISTEXT(M4)+ISTEXT(O4)+ISTEXT(Y4)+ISTEXT(Z4)+ISTEXT(AA4)+ISTEXT(AV4)) -> 0 | DY4: =IF(BB4=1,IF(H4<>INT(H4),1,0),0) -> 0 | DZ4: =IF(TRIM($A4)="","",IF(TRIM(B4)="",SUBSTITUTE(SUBSTITUTE(SUBSTITUTE(SUBSTITUTE(SUBSTITUTE(SUBSTITUTE(LOWER(TRIM($A4)),"~",""),"*",""),"?",""),"<",""),">",""),"=",""),SUBSTITUTE(SUBSTITUTE(SUBSTITUTE(SUBSTITUTE(SUBSTITUTE(SUBSTITUTE(LOWER(TRIM(B4)),"~",""),"*",""),"?",""),"<",""),">",""),"=",""))) -> sample office 03 | EA4: =IF(CW4="","",IFERROR(IF(LEFT(LOWER(TRIM(INDEX(Clay_Offices!$A$2:$FZ$601,CW4,Sync!$C$19)&"")),4)="grp-",SUBSTITUTE(SUBSTITUTE(SUBSTITUTE(SUBSTITUTE(SUBSTITUTE(SUBSTITUTE(LOWER(TRIM(INDEX(Clay_Offices!$A$2:$FZ$601,CW4,Sync!$C$19)&"")),"~",""),"*",""),"?",""),"<",""),">",""),"=",""),""),"")) | EB4: =IF(EA4<>"",DZ4,"") | EC4: =IF(BC4=1,AZ4,"") -> sample office 03 | ED4: =IF(TRIM($A4)="","",IFERROR(INDEX($A$2:$A$201,MATCH(AZ4,$EC$2:$EC$201,0))&"",$A4&"")) -> SAMPLE-O-003 | EE4: =IF(BB4=1,IF(COUNTIFS($A$2:$A$201,$A4,$BB$2:$BB$201,1,$H$2:$H$201,"<"&H4)+COUNTIFS($A$2:$A$201,$A4,$BB$2:$BB$201,1,$H$2:$H$201,H4,$BA$2:$BA$201,"<"&BA4)=0,1,0),0) -> 1 | EF4: =IF(BC4=1,IF(COUNTIFS($AZ$2:$AZ$201,AZ4,$EE$2:$EE$201,1)>1,1,0),0) -> 0 | EG4: =IF(AND(CQ4=1),IF(COUNTIFS($AZ$2:$AZ$201,AZ4,$CQ$2:$CQ$201,1,$H$2:$H$201,">"&H4)+COUNTIFS($AZ$2:$AZ$201,AZ4,$CQ$2:$CQ$201,1,$H$2:$H$201,H4,$BA$2:$BA$201,">"&BA4)=0,1,0),0) -> 1 | EH4: =IF(BB4=1,IF(COUNTIFS($AZ$2:$AZ$201,AZ4,$EG$2:$EG$201,1)=0,"",SUMIFS($O$2:$O$201,$AZ$2:$AZ$201,AZ4,$EG$2:$EG$201,1)),"") -> 120 | EI4: =IF(AND(ISNUMBER(EH4),OR(N(EH4)<Config!$B$31,N(EH4)>Config!$B$33)),1,0) -> 0 | EJ4: =IF(AND(ISNUMBER(EH4),N(EH4)>=Config!$B$31,N(EH4)<Config!$B$32),1,0) -> 0 | EK4: =IF(AND(BF4=1,INT(N(H4))<=Config!$B$6,DH4=1,EI4=1),1,0) -> 0 | EL4: =IF(AND(BF4=1,INT(N(H4))<=Config!$B$7,DI4=1,EI4=1),1,0) -> 0 | EM4: =IF(AND(BF4=1,INT(N(H4))<=Config!$B$8,DJ4=1,EI4=1),1,0) -> 0 | EN4: =IF(AND(BF4=1,INT(N(H4))<=Config!$B$5,DK4=1,EI4=1),1,0) -> 0 | EO4: =IF(AND(DL4=1,EJ4=1),1,0) -> 0 | EP4: =IF(AND(DM4=1,EJ4=1),1,0) -> 0 | EQ4: =IF(AND(DN4=1,EJ4=1),1,0) -> 0 | ER4: =IF(AND(DO4=1,EJ4=1),1,0) -> 0
