Workbook

Sheet Start
A1: =Config!$B$3&" · conversation tracker"
A2: What this is: the conversation and notes log for discovery and selling, one row per conversation, keyed by the Clay row_id.
A3: It is not a status store. Status, touches, replies, next actions and do-not-contact live in the Clay tables only (CONTRACTS 6.2).
A5: After every call (ten minutes, calls/post-call-note-template.md)
A6: 1. Type one row on Office_Log or Brand_Log: verbatims first, then numbers and codes.
A7: 2. Write back to the Clay row: call_date, status (call_done or yes_in_principle), yes_in_principle, call_notes ('see tracker <date>'), next_action, next_action_date.
A8: 3. Set clay_updated = Y and note_minutes.
A10: Every Friday (15 minutes)
A11: 1. Export the Clay offices table (all columns) and paste it on Clay_Offices at A1. Same for brands on Clay_Brands. Type both export dates on Config.
A12: 2. Open Scorecard. Fix every FIX under Data checks (the Sync tab and the red calc_sync_issue cells show where).
A13: 3. Read the Gate 0 block, the medians, the top objections and the reply rates. If a reply rate says UNDER 20%, run sending guide section 6.
A14: 4. Download pipeline_log as CSV (File > Download > CSV, this tab only) to desk-drop-outreach/exports/pipeline_log.csv and paste it into the financial model's Pipeline tab.
A15: 5. When an office signs or a brand pays: add the row on signed_offices or paid_brands, download that tab as CSV to desk-drop-outreach/handoff/.
... A26: Dates as YYYY-MM-DD. Money as plain numbers. Rows whose row_id starts with SAMPLE are ignored while include_sample = N.

Sheet Scorecard
A1: =IF((COUNTIF(Office_Log!$A$2:$A$201,"SAMPLE*")+COUNTIF(Brand_Log!$A$2:$A$201,"SAMPLE*")+COUNTIF(signed_offices!$W$2:$W$51,"SAMPLE*")+COUNTIF(paid_brands!$AC$2:$AC$51,"SAMPLE*")+COUNTIF(later_events!$C$2:$C$101,"SAMPLE*")+IFERROR(COUNTIF(INDEX(Clay_Offices!$A$2:$FZ$601,0,Sync!$C$5),"SAMPLE*"),0)+IFERROR(COUNTIF(INDEX(Clay_Brands!$A$2:$FZ$601,0,Sync!$D$5),"SAMPLE*"),0))>0,"SAMPLE: this file holds "&(COUNTIF(Office_Log!$A$2:$A$201,"SAMPLE*")+COUNTIF(Brand_Log!$A$2:$A$201,"SAMPLE*")+COUNTIF(signed_offices!$W$2:$W$51,"SAMPLE*")+COUNTIF(paid_brands!$AC$2:$AC$51,"SAMPLE*")+COUNTIF(later_events!$C$2:$C$101,"SAMPLE*")+IFERROR(COUNTIF(INDEX(Clay_Offices!$A$2:$FZ$601,0,Sync!$C$5),"SAMPLE*"),0)+IFERROR(COUNTIF(INDEX(Clay_Brands!$A$2:$FZ$601,0,Sync!$D$5),"SAMPLE*"),0))&" SAMPLE rows. Illustrative placeholders, not results. include_sample = "&Config!$B$19&IF(Config!$B$19="Y"," (SAMPLE rows are counted)"," (SAMPLE rows are ignored)"),"")
A2: =Config!$B$3&" · Friday scorecard"
A3: ="As of "&TEXT(Config!$B$5,"ddd yyyy-mm-dd")&". Gate 0 is "&TEXT(Config!$B$8,"ddd yyyy-mm-dd")&" (derived, founder to confirm). Counts are distinct offices or brands, by call_date."
A5: Measure | B5: Fri wk 1 | C5: Fri wk 2 | D5: Gate 0 | E5: As of | F5: Target | G5: How it is counted
A6: Cut-off date | B6: =Config!$B$6 | C6: =Config!$B$7 | D6: =Config!$B$8 | E6: =Config!$B$5
A7: Offices (Gate 0: at least 5 of 15 say yes in principle AND name a pantry owner AND a receiving window)
A8: Office conversations held | B8: =COUNTIFS(Office_Log!$AV$2:$AV$201,1,Office_Log!$G$2:$G$201,"<="&B$6) | C8: =COUNTIFS(Office_Log!$AV$2:$AV$201,1,Office_Log!$G$2:$G$201,"<="&C$6) | D8: =COUNTIFS(Office_Log!$AV$2:$AV$201,1,Office_Log!$G$2:$G$201,"<="&D$6) | E8: =COUNTIFS(Office_Log!$AV$2:$AV$201,1,Office_Log!$G$2:$G$201,"<="&E$6) | F8: =Config!$B$10 | G8: Distinct row_ids in Office_Log with a call_date on or before the cut-off.
A9: Yes in principle, pantry owner named, receiving window named | B9: =COUNTIFS(Office_Log!$AY$2:$AY$201,1,Office_Log!$G$2:$G$201,"<="&B$6) | C9: =COUNTIFS(Office_Log!$AY$2:$AY$201,1,Office_Log!$G$2:$G$201,"<="&C$6) | D9: =COUNTIFS(Office_Log!$AY$2:$AY$201,1,Office_Log!$G$2:$G$201,"<="&D$6) | E9: =COUNTIFS(Office_Log!$AY$2:$AY$201,1,Office_Log!$G$2:$G$201,"<="&E$6) | F9: =Config!$B$11 | G9: The Gate 0 count. One per office, from its first qualifying conversation.
A10: Gate 0, office side | B10: =IF(B9>=Config!$B$11,"PASS",IF(B$6<Config!$B$8,"not yet","FAIL")) | C10: =IF(C9>=Config!$B$11,"PASS",IF(C$6<Config!$B$8,"not yet","FAIL")) | D10: =IF(D9>=Config!$B$11,"PASS",IF(D$6<Config!$B$8,"not yet","FAIL")) | E10: =IF(E9>=Config!$B$11,"PASS",IF(E$6<Config!$B$8,"not yet","FAIL")) | G10: PASS once the count reaches the target. Before Gate 0 a shortfall reads 'not yet'; on or after Gate 0 it reads FAIL.
A11: Yes in principle, any (owner or window may be missing) | B11: =COUNTIFS(Office_Log!$BV$2:$BV$201,1,Office_Log!$G$2:$G$201,"<="&B$6) | C11: =COUNTIFS(Office_Log!$BV$2:$BV$201,1,Office_Log!$G$2:$G$201,"<="&C$6) | D11: =COUNTIFS(Office_Log!$BV$2:$BV$201,1,Office_Log!$G$2:$G$201,"<="&D$6) | E11: =COUNTIFS(Office_Log!$BV$2:$BV$201,1,Office_Log!$G$2:$G$201,"<="&E$6) | G11: Offices that said Y at least once. The gap to the row above is follow-up work: get the owner and the window.
A12: Said maybe at least once (someone else must agree) | B12: =COUNTIFS(Office_Log!$BU$2:$BU$201,1,Office_Log!$G$2:$G$201,"<="&B$6) | C12: =COUNTIFS(Office_Log!$BU$2:$BU$201,1,Office_Log!$G$2:$G$201,"<="&C$6) | D12: =COUNTIFS(Office_Log!$BU$2:$BU$201,1,Office_Log!$G$2:$G$201,"<="&D$6) | E12: =COUNTIFS(Office_Log!$BU$2:$BU$201,1,Office_Log!$G$2:$G$201,"<="&E$6) | G12: Plan Phase 1: 'I need to ask facilities and HR' is a maybe, not a yes.
A13: Median budget-probe answer, USD a month | B13: =IF(COUNT(Office_Log!$BC$2:$BC$201)=0,"none yet",MEDIAN(Office_Log!$BC$2:$BC$201)) | C13: =IF(COUNT(Office_Log!$BD$2:$BD$201)=0,"none yet",MEDIAN(Office_Log!$BD$2:$BD$201)) | D13: =IF(COUNT(Office_Log!$BE$2:$BE$201)=0,"none yet",MEDIAN(Office_Log!$BE$2:$BE$201)) | E13: =IF(COUNT(Office_Log!$BF$2:$BF$201)=0,"none yet",MEDIAN(Office_Log!$BF$2:$BF$201)) | G13: First numeric answer per office; a range counts at its low end; 'no budget' counts as 0; no number is left out.
A14: Offices that gave a number (0 included) | B14: =COUNT(Office_Log!$BC$2:$BC$201) | C14: =COUNT(Office_Log!$BD$2:$BD$201) | D14: =COUNT(Office_Log!$BE$2:$BE$201) | E14: =COUNT(Office_Log!$BF$2:$BF$201) | G14: The n behind the median.
A15: Of those, said no budget (0) | B15: =COUNTIF(Office_Log!$BC$2:$BC$201,0) | C15: =COUNTIF(Office_Log!$BD$2:$BD$201,0) | D15: =COUNTIF(Office_Log!$BE$2:$BE$201,0) | E15: =COUNTIF(Office_Log!$BF$2:$BF$201,0) | G15: Counted inside the median.
A16: Offices naming $100 a month or more (decision-rule input), as of | E16: =COUNTIFS(Office_Log!$BG$2:$BG$201,1,Office_Log!$G$2:$G$201,"<="&E$6) | G16: Plan decision rule: office-paid tier is tested if at least five offices named $100 a month or more.
A17: Median monthly pantry spend today, USD, as of | E17: =IF(COUNT(Office_Log!$BJ$2:$BJ$201)=0,"none yet",MEDIAN(Office_Log!$BJ$2:$BJ$201)) | F17: =COUNT(Office_Log!$BJ$2:$BJ$201) | G17: First number per office, from Q1. Context for the budget probe.
A19: Brands (Gate 0: at least 3 of 15 say they would pay $500 or more AND the speaker controls the budget)
A20: Brand conversations held | B20: =COUNTIFS(Brand_Log!$AO$2:$AO$201,1,Brand_Log!$G$2:$G$201,"<="&B$6) | C20: =COUNTIFS(Brand_Log!$AO$2:$AO$201,1,Brand_Log!$G$2:$G$201,"<="&C$6) | D20: =COUNTIFS(Brand_Log!$AO$2:$AO$201,1,Brand_Log!$G$2:$G$201,"<="&D$6) | E20: =COUNTIFS(Brand_Log!$AO$2:$AO$201,1,Brand_Log!$G$2:$G$201,"<="&E$6) | F20: =Config!$B$12 | G20: Distinct row_ids in Brand_Log with a call_date on or before the cut-off.
A21: Would pay $500 or more and controls the budget | B21: =COUNTIFS(Brand_Log!$AR$2:$AR$201,1,Brand_Log!$G$2:$G$201,"<="&B$6) | C21: =COUNTIFS(Brand_Log!$AR$2:$AR$201,1,Brand_Log!$G$2:$G$201,"<="&C$6) | D21: =COUNTIFS(Brand_Log!$AR$2:$AR$201,1,Brand_Log!$G$2:$G$201,"<="&D$6) | E21: =COUNTIFS(Brand_Log!$AR$2:$AR$201,1,Brand_Log!$G$2:$G$201,"<="&E$6) | F21: =Config!$B$13 | G21: The Gate 0 count: the higher of the before and after numbers is $500 or more, and controls_budget = Y. Same rule as the financial model.
A22: Gate 0, brand side | B22: =IF(B21>=Config!$B$13,"PASS",IF(B$6<Config!$B$8,"not yet","FAIL")) | C22: =IF(C21>=Config!$B$13,"PASS",IF(C$6<Config!$B$8,"not yet","FAIL")) | D22: =IF(D21>=Config!$B$13,"PASS",IF(D$6<Config!$B$8,"not yet","FAIL")) | E22: =IF(E21>=Config!$B$13,"PASS",IF(E$6<Config!$B$8,"not yet","FAIL")) | G22: PASS once the count reaches the target. Before Gate 0 a shortfall reads 'not yet'; on or after Gate 0 it reads FAIL.
A23: Strict read: named $500 or more BEFORE hearing $1,500, and controls the budget | B23: =COUNTIFS(Brand_Log!$AT$2:$AT$201,1,Brand_Log!$G$2:$G$201,"<="&B$6) | C23: =COUNTIFS(Brand_Log!$AT$2:$AT$201,1,Brand_Log!$G$2:$G$201,"<="&C$6) | D23: =COUNTIFS(Brand_Log!$AT$2:$AT$201,1,Brand_Log!$G$2:$G$201,"<="&D$6) | E23: =COUNTIFS(Brand_Log!$AT$2:$AT$201,1,Brand_Log!$G$2:$G$201,"<="&E$6) | G23: Shown so an anchored answer is not mistaken for an unprompted one.
A24: Said $500 or more but the speaker does not control the budget | B24: =COUNTIFS(Brand_Log!$AV$2:$AV$201,1,Brand_Log!$G$2:$G$201,"<="&B$6) | C24: =COUNTIFS(Brand_Log!$AV$2:$AV$201,1,Brand_Log!$G$2:$G$201,"<="&C$6) | D24: =COUNTIFS(Brand_Log!$AV$2:$AV$201,1,Brand_Log!$G$2:$G$201,"<="&D$6) | E24: =COUNTIFS(Brand_Log!$AV$2:$AV$201,1,Brand_Log!$G$2:$G$201,"<="&E$6) | G24: Not counted for Gate 0 from that conversation. Ask for a call with the budget owner.
A25: Median brand number before $1,500 was mentioned, USD per campaign | B25: =IF(COUNT(Brand_Log!$AY$2:$AY$201)=0,"none yet",MEDIAN(Brand_Log!$AY$2:$AY$201)) | C25: =IF(COUNT(Brand_Log!$AZ$2:$AZ$201)=0,"none yet",MEDIAN(Brand_Log!$AZ$2:$AZ$201)) | D25: =IF(COUNT(Brand_Log!$BA$2:$BA$201)=0,"none yet",MEDIAN(Brand_Log!$BA$2:$BA$201)) | E25: =IF(COUNT(Brand_Log!$BB$2:$BB$201)=0,"none yet",MEDIAN(Brand_Log!$BB$2:$BB$201)) | G25: First numeric before-answer per brand; 'nothing' counts as 0; no number is left out.
A26: Brands that named a number before $1,500 | B26: =COUNT(Brand_Log!$AY$2:$AY$201) | C26: =COUNT(Brand_Log!$AZ$2:$AZ$201) | D26: =COUNT(Brand_Log!$BA$2:$BA$201) | E26: =COUNT(Brand_Log!$BB$2:$BB$201) | G26: The n behind the median.
A27: Median brand number after hearing $1,500, USD per campaign | B27: =IF(COUNT(Brand_Log!$BE$2:$BE$201)=0,"none yet",MEDIAN(Brand_Log!$BE$2:$BE$201)) | C27: =IF(COUNT(Brand_Log!$BF$2:$BF$201)=0,"none yet",MEDIAN(Brand_Log!$BF$2:$BF$201)) | D27: =IF(COUNT(Brand_Log!$BG$2:$BG$201)=0,"none yet",MEDIAN(Brand_Log!$BG$2:$BG$201)) | E27: =IF(COUNT(Brand_Log!$BH$2:$BH$201)=0,"none yet",MEDIAN(Brand_Log!$BH$2:$BH$201)) | G27: First numeric after-answer per brand.
A28: Brands that answered after hearing $1,500 | B28: =COUNT(Brand_Log!$BE$2:$BE$201) | C28: =COUNT(Brand_Log!$BF$2:$BF$201) | D28: =COUNT(Brand_Log!$BG$2:$BG$201) | E28: =COUNT(Brand_Log!$BH$2:$BH$201) | G28: The n behind the median.
A29: Median quarterly sampling budget, USD (low end), as of | E29: =IF(COUNT(Brand_Log!$BK$2:$BK$201)=0,"none yet",MEDIAN(Brand_Log!$BK$2:$BK$201)) | F29: =COUNT(Brand_Log!$BK$2:$BK$201) | G29: From Q2. Context: a $600 or $1,500 campaign against what they spend now.
A31: Gate 0 overall
A32: Gate 0 result | B32: =IF(AND(B10="PASS",B22="PASS"),"PASS",IF(OR(B10="FAIL",B22="FAIL"),"FAIL","not yet")) | C32: =IF(AND(C10="PASS",C22="PASS"),"PASS",IF(OR(C10="FAIL",C22="FAIL"),"FAIL","not yet")) | D32: =IF(AND(D10="PASS",D22="PASS"),"PASS",IF(OR(D10="FAIL",D22="FAIL"),"FAIL","not yet")) | E32: =IF(AND(E10="PASS",E22="PASS"),"PASS",IF(OR(E10="FAIL",E22="FAIL"),"FAIL","not yet"))
A33: Sentence for the Gate 0 decision (as of) | B33: ="As of "&TEXT(E$6,"yyyy-mm-dd")&": "&E9&" of "&E8&" offices said yes with a pantry owner and a receiving window (target "&F9&"); "&E21&" of "&E20&" brands would pay $"&Config!$B$14&" or more and control the budget (target "&F21&"). Gate 0: "&E32&"."
A34: If it fails (plan) | B34: Fewer than 3 brands: test the office-paid version for three more weeks. Fewer than 5 offices: change the cluster or the office size band, not the model.
A36: Top three objections per side, as of (mentions across objection_1 to objection_3)
A37: Office | B37: Mentions | C37: First quote logged for that code
A38: Office side
A39: =IF(INDEX($L$41:$L$53,MATCH(LARGE($M$41:$M$53,1),$M$41:$M$53,0))<1,"1. none logged yet","1. "&INDEX($K$41:$K$53,MATCH(LARGE($M$41:$M$53,1),$M$41:$M$53,0))&" ("&INDEX($J$41:$J$53,MATCH(LARGE($M$41:$M$53,1),$M$41:$M$53,0))&")") | B39: =INDEX($L$41:$L$53,MATCH(LARGE($M$41:$M$53,1),$M$41:$M$53,0)) | C39: =IF(B39<1,"",IFERROR(INDEX(Office_Log!$AM$2:$AM$201,MATCH(INDEX($J$41:$J$53,MATCH(LARGE($M$41:$M$53,1),$M$41:$M$53,0)),Office_Log!$BO$2:$BO$201,0)),IFERROR(INDEX(Office_Log!$AM$2:$AM$201,MATCH(INDEX($J$41:$J$53,MATCH(LARGE($M$41:$M$53,1),$M$41:$M$53,0)),Office_Log!$BP$2:$BP$201,0)),IFERROR(INDEX(Office_Log!$AM$2:$AM$201,MATCH(INDEX($J$41:$J$53,MATCH(LARGE($M$41:$M$53,1),$M$41:$M$53,0)),Office_Log!$BQ$2:$BQ$201,0)),"")))) | J39: Objection counts used for the top three (as of). Ties go to the code listed first.
A40: =IF(INDEX($L$41:$L$53,MATCH(LARGE($M$41:$M$53,2),$M$41:$M$53,0))<1,"2. none logged yet","2. "&INDEX($K$41:$K$53,MATCH(LARGE($M$41:$M$53,2),$M$41:$M$53,0))&" ("&INDEX($J$41:$J$53,MATCH(LARGE($M$41:$M$53,2),$M$41:$M$53,0))&")") | B40: =INDEX($L$41:$L$53,MATCH(LARGE($M$41:$M$53,2),$M$41:$M$53,0)) | C40: =IF(B40<1,"",IFERROR(INDEX(Office_Log!$AM$2:$AM$201,MATCH(INDEX($J$41:$J$53,MATCH(LARGE($M$41:$M$53,2),$M$41:$M$53,0)),Office_Log!$BO$2:$BO$201,0)),IFERROR(INDEX(Office_Log!$AM$2:$AM$201,MATCH(INDEX($J$41:$J$53,MATCH(LARGE($M$41:$M$53,2),$M$41:$M$53,0)),Office_Log!$BP$2:$BP$201,0)),IFERROR(INDEX(Office_Log!$AM$2:$AM$201,MATCH(INDEX($J$41:$J$53,MATCH(LARGE($M$41:$M$53,2),$M$41:$M$53,0)),Office_Log!$BQ$2:$BQ$201,0)),"")))) | J40: office code | K40: office label | L40: office mentions | M40: office score | O40: brand code | P40: brand label | Q40: brand mentions | R40: brand score
A41: =IF(INDEX($L$41:$L$53,MATCH(LARGE($M$41:$M$53,3),$M$41:$M$53,0))<1,"3. none logged yet","3. "&INDEX($K$41:$K$53,MATCH(LARGE($M$41:$M$53,3),$M$41:$M$53,0))&" ("&INDEX($J$41:$J$53,MATCH(LARGE($M$41:$M$53,3),$M$41:$M$53,0))&")") | B41: =INDEX($L$41:$L$53,MATCH(LARGE($M$41:$M$53,3),$M$41:$M$53,0)) | C41: =IF(B41<1,"",IFERROR(INDEX(Office_Log!$AM$2:$AM$201,MATCH(INDEX($J$41:$J$53,MATCH(LARGE($M$41:$M$53,3),$M$41:$M$53,0)),Office_Log!$BO$2:$BO$201,0)),IFERROR(INDEX(Office_Log!$AM$2:$AM$201,MATCH(INDEX($J$41:$J$53,MATCH(LARGE($M$41:$M$53,3),$M$41:$M$53,0)),Office_Log!$BP$2:$BP$201,0)),IFERROR(INDEX(Office_Log!$AM$2:$AM$201,MATCH(INDEX($J$41:$J$53,MATCH(LARGE($M$41:$M$53,3),$M$41:$M$53,0)),Office_Log!$BQ$2:$BQ$201,0)),"")))) | J41: needs_approval | K41: I need to ask facilities, HR or someone else | L41: =COUNTIFS(Office_Log!$BO$2:$BO$201,J41,Office_Log!$G$2:$G$201,"<="&$E$6)+COUNTIFS(Office_Log!$BP$2:$BP$201,J41,Office_Log!$G$2:$G$201,"<="&$E$6)+COUNTIFS(Office_Log!$BQ$2:$BQ$201,J41,Office_Log!$G$2:$G$201,"<="&$E$6) | M41: =L41-1/1000 | O41: seed_ourselves | P41: We can seed offices ourselves for free | Q41: =COUNTIFS(Brand_Log!$BM$2:$BM$201,O41,Brand_Log!$G$2:$G$201,"<="&$E$6)+COUNTIFS(Brand_Log!$BN$2:$BN$201,O41,Brand_Log!$G$2:$G$201,"<="&$E$6)+COUNTIFS(Brand_Log!$BO$2:$BO$201,O41,Brand_Log!$G$2:$G$201,"<="&$E$6) | R41: =Q41-1/1000
A42: Brand side | J42: existing_vendor | K42: We already have a pantry vendor or contract | L42: =COUNTIFS(Office_Log!$BO$2:$BO$201,J42,Office_Log!$G$2:$G$201,"<="&$E$6)+COUNTIFS(Office_Log!$BP$2:$BP$201,J42,Office_Log!$G$2:$G$201,"<="&$E$6)+COUNTIFS(Office_Log!$BQ$2:$BQ$201,J42,Office_Log!$G$2:$G$201,"<="&$E$6) | M42: =L42-2/1000 | O42: price_per_sample | P42: $600 / the price is more than we pay per sample elsewhere | Q42: =COUNTIFS(Brand_Log!$BM$2:$BM$201,O42,Brand_Log!$G$2:$G$201,"<="&$E$6)+COUNTIFS(Brand_Log!$BN$2:$BN$201,O42,Brand_Log!$G$2:$G$201,"<="&$E$6)+COUNTIFS(Brand_Log!$BO$2:$BO$201,O42,Brand_Log!$G$2:$G$201,"<="&$E$6) | R42: =Q42-2/1000
A43: =IF(INDEX($Q$41:$Q$53,MATCH(LARGE($R$41:$R$53,1),$R$41:$R$53,0))<1,"1. none logged yet","1. "&INDEX($P$41:$P$53,MATCH(LARGE($R$41:$R$53,1),$R$41:$R$53,0))&" ("&INDEX($O$41:$O$53,MATCH(LARGE($R$41:$R$53,1),$R$41:$R$53,0))&")") | B43: =INDEX($Q$41:$Q$53,MATCH(LARGE($R$41:$R$53,1),$R$41:$R$53,0)) | C43: =IF(B43<1,"",IFERROR(INDEX(Brand_Log!$AE$2:$AE$201,MATCH(INDEX($O$41:$O$53,MATCH(LARGE($R$41:$R$53,1),$R$41:$R$53,0)),Brand_Log!$BM$2:$BM$201,0)),IFERROR(INDEX(Brand_Log!$AE$2:$AE$201,MATCH(INDEX($O$41:$O$53,MATCH(LARGE($R$41:$R$53,1),$R$41:$R$53,0)),Brand_Log!$BN$2:$BN$201,0)),IFERROR(INDEX(Brand_Log!$AE$2:$AE$201,MATCH(INDEX($O$41:$O$53,MATCH(LARGE($R$41:$R$53,1),$R$41:$R$53,0)),Brand_Log!$BO$2:$BO$201,0)),"")))) | J43: allergy_policy | K43: Allergy or food-safety worry | L43: =COUNTIFS(Office_Log!$BO$2:$BO$201,J43,Office_Log!$G$2:$G$201,"<="&$E$6)+COUNTIFS(Office_Log!$BP$2:$BP$201,J43,Office_Log!$G$2:$G$201,"<="&$E$6)+COUNTIFS(Office_Log!$BQ$2:$BQ$201,J43,Office_Log!$G$2:$G$201,"<="&$E$6) | M43: =L43-3/1000 | O43: free_trial | P43: Can we do a free trial first? | Q43: =COUNTIFS(Brand_Log!$BM$2:$BM$201,O43,Brand_Log!$G$2:$G$201,"<="&$E$6)+COUNTIFS(Brand_Log!$BN$2:$BN$201,O43,Brand_Log!$G$2:$G$201,"<="&$E$6)+COUNTIFS(Brand_Log!$BO$2:$BO$201,O43,Brand_Log!$G$2:$G$201,"<="&$E$6) | R43: =Q43-3/1000
A44: =IF(INDEX($Q$41:$Q$53,MATCH(LARGE($R$41:$R$53,2),$R$41:$R$53,0))<1,"2. none logged yet","2. "&INDEX($P$41:$P$53,MATCH(LARGE($R$41:$R$53,2),$R$41:$R$53,0))&" ("&INDEX($O$41:$O$53,MATCH(LARGE($R$41:$R$53,2),$R$41:$R$53,0))&")") | B44: =INDEX($Q$41:$Q$53,MATCH(LARGE($R$41:$R$53,2),$R$41:$R$53,0)) | C44: =IF(B44<1,"",IFERROR(INDEX(Brand_Log!$AE$2:$AE$201,MATCH(INDEX($O$41:$O$53,MATCH(LARGE($R$41:$R$53,2),$R$41:$R$53,0)),Brand_Log!$BM$2:$BM$201,0)),IFERROR(INDEX(Brand_Log!$AE$2:$AE$201,MATCH(INDEX($O$41:$O$53,MATCH(LARGE($R$41:$R$53,2),$R$41:$R$53,0)),Brand_Log!$BN$2:$BN$201,0)),IFERROR(INDEX(Brand_Log!$AE$2:$AE$201,MATCH(INDEX($O$41:$O$53,MATCH(LARGE($R$41:$R$53,2),$R$41:$R$53,0)),Brand_Log!$BO$2:$BO$201,0)),"")))) | J44: healthy_policy | K44: We only stock healthy items (wellness policy) | L44: =COUNTIFS(Office_Log!$BO$2:$BO$201,J44,Office_Log!$G$2:$G$201,"<="&$E$6)+COUNTIFS(Office_Log!$BP$2:$BP$201,J44,Office_Log!$G$2:$G$201,"<="&$E$6)+COUNTIFS(Office_Log!$BQ$2:$BQ$201,J44,Office_Log!$G$2:$G$201,"<="&$E$6) | M44: =L44-4/1000 | O44: what_we_get | P44: What do we actually get out of it? | Q44: =COUNTIFS(Brand_Log!$BM$2:$BM$201,O44,Brand_Log!$G$2:$G$201,"<="&$E$6)+COUNTIFS(Brand_Log!$BN$2:$BN$201,O44,Brand_Log!$G$2:$G$201,"<="&$E$6)+COUNTIFS(Brand_Log!$BO$2:$BO$201,O44,Brand_Log!$G$2:$G$201,"<="&$E$6) | R44: =Q44-4/1000
...

Sheet Office_Log
A1: row_id | B1: company | C1: contact_name | D1: contact_title | E1: source | F1: channel | G1: call_date | H1: call_type | I1: q1_pantry_today_verbatim | J1: pantry_vendor | K1: monthly_pantry_spend_usd | L1: monthly_pantry_spend_verbatim | M1: tuesday_headcount | N1: headcount_verbatim | O1: q3_free_product_verbatim | P1: q4_yes_needs_verbatim | Q1: q4_no_triggers_verbatim | R1: q5_photo_and_survey | S1: q5_verbatim | T1: budget_probe_asked | U1: budget_probe_verbatim | V1: budget_probe_low_usd | W1: budget_probe_high_usd | X1: referrals_given_count | Y1: referrals_given | Z1: pantry_owner_named | AA1: pantry_owner_name | AB1: pantry_owner_title | AC1: owner_can_say_yes_alone | AD1: receiving_window | AE1: receiving_type | AF1: coi_required | AG1: security_notes | AH1: veto_categories | AI1: veto_verbatim | AJ1: objection_1 | AK1: objection_2 | AL1: objection_3 | AM1: objections_verbatim | AN1: yes_in_principle | AO1: yes_signals | AP1: note_minutes | AQ1: clay_updated | AR1: notes | AS1: calc_sync_issue | AT1: calc_row | AU1: calc_valid | AV1: calc_conv_first | AW1: calc_latest | AX1: calc_q_yes | AY1: calc_q_yes_first | AZ1: calc_yes_incomplete | BA1: calc_bp_has | BB1: calc_bp_first | BC1: calc_bp_w1 | BD1: calc_bp_w2 | BE1: calc_bp_g0 | BF1: calc_bp_asof | BG1: calc_bp100_first | BH1: calc_spend_has | BI1: calc_spend_first | BJ1: calc_spend_asof | BK1: calc_probe_row | BL1: calc_probe_first | BM1: calc_probe_key | BN1: calc_probe_missing_text | BO1: calc_obj1 | BP1: calc_obj2 | BQ1: calc_obj3 | BR1: calc_note_min | BS1: calc_yes_any | BT1: calc_maybe | BU1: calc_maybe_first | BV1: calc_yes_any_first | BW1: calc_bp100 | BX1: calc_clay_idx | BY1: calc_clay_status | BZ1: calc_clay_rank | CA1: calc_clay_yes | CB1: calc_clay_call_date
AS2: =IF(TRIM($A2)="","",IF(AND(LEFT($A2,6)="SAMPLE",Config!$B$19<>"Y"),"",IF(NOT(ISNUMBER(G2)),"call_date is blank or not a date",IF(Sync!$C$5="","Clay paste is empty or has no row_id column: paste the Clay export on Clay_Offices",IF(BX2="","row_id not found in the Clay paste: add the Clay row or fix the row_id",IF(AND(ISNUMBER(BZ2),BZ2>=1,BZ2<=5),"Clay status is "&BY2&": set call_done or later",IF(AND(AW2=1,CA2<>BS2),"Clay yes_in_principle should be "&BS2,IF(AND(AW2=1,CB2<>G2),"Clay call_date should be "&TEXT(G2,"yyyy-mm-dd"),"")))))))) | AT2: =ROW() | AU2: =IF(AND(TRIM($A2)<>"",ISNUMBER(G2)),IF(AND(LEFT($A2,6)="SAMPLE",Config!$B$19<>"Y"),0,1),0) | AV2: =IF(AU2=1,IF(COUNTIFS($A$2:$A$201,$A2,$AU$2:$AU$201,1,$G$2:$G$201,"<"&G2)+COUNTIFS($A$2:$A$201,$A2,$AU$2:$AU$201,1,$G$2:$G$201,G2,$AT$2:$AT$201,"<"&AT2)=0,1,0),0) | AW2: =IF(AU2=1,IF(COUNTIFS($A$2:$A$201,$A2,$AU$2:$AU$201,1,$G$2:$G$201,">"&G2)+COUNTIFS($A$2:$A$201,$A2,$AU$2:$AU$201,1,$G$2:$G$201,G2,$AT$2:$AT$201,">"&AT2)=0,1,0),0) | AX2: =IF(AND(AU2=1,AN2="Y",Z2="Y",TRIM(AD2)<>""),1,0) | AY2: =IF(AX2=1,IF(COUNTIFS($A$2:$A$201,$A2,$AX$2:$AX$201,1,$G$2:$G$201,"<"&G2)+COUNTIFS($A$2:$A$201,$A2,$AX$2:$AX$201,1,$G$2:$G$201,G2,$AT$2:$AT$201,"<"&AT2)=0,1,0),0) | AZ2: =IF(AND(AU2=1,AN2="Y",AX2=0),1,0) | BA2: =IF(AND(AU2=1,ISNUMBER(V2)),1,0) | BB2: =IF(BA2=1,IF(COUNTIFS($A$2:$A$201,$A2,$BA$2:$BA$201,1,$G$2:$G$201,"<"&G2)+COUNTIFS($A$2:$A$201,$A2,$BA$2:$BA$201,1,$G$2:$G$201,G2,$AT$2:$AT$201,"<"&AT2)=0,1,0),0) | BC2: =IF(AND(BB2=1,G2<=Config!$B$6),V2,"") | BD2: =IF(AND(BB2=1,G2<=Config!$B$7),V2,"") | BE2: =IF(AND(BB2=1,G2<=Config!$B$8),V2,"") | BF2: =IF(AND(BB2=1,G2<=Config!$B$5),V2,"") | BG2: =IF(BW2=1,IF(COUNTIFS($A$2:$A$201,$A2,$BW$2:$BW$201,1,$G$2:$G$201,"<"&G2)+COUNTIFS($A$2:$A$201,$A2,$BW$2:$BW$201,1,$G$2:$G$201,G2,$AT$2:$AT$201,"<"&AT2)=0,1,0),0) | BH2: =IF(AND(AU2=1,ISNUMBER(K2)),1,0) | BI2: =IF(BH2=1,IF(COUNTIFS($A$2:$A$201,$A2,$BH$2:$BH$201,1,$G$2:$G$201,"<"&G2)+COUNTIFS($A$2:$A$201,$A2,$BH$2:$BH$201,1,$G$2:$G$201,G2,$AT$2:$AT$201,"<"&AT2)=0,1,0),0) | BJ2: =IF(AND(BI2=1,G2<=Config!$B$5),K2,"") | BK2: =IF(AND(AU2=1,OR(TRIM(U2)<>"",ISNUMBER(V2))),1,0) | BL2: =IF(BK2=1,IF(COUNTIFS($A$2:$A$201,$A2,$BK$2:$BK$201,1,$G$2:$G$201,"<"&G2)+COUNTIFS($A$2:$A$201,$A2,$BK$2:$BK$201,1,$G$2:$G$201,G2,$AT$2:$AT$201,"<"&AT2)=0,1,0),0) | BM2: =IF(BL2=1,$A2,"") | BN2: =IF(AND(AU2=1,T2="Y",TRIM(U2)=""),1,0) | BO2: =IF(AU2=1,AJ2&"","") | BP2: =IF(AU2=1,AK2&"","") | BQ2: =IF(AU2=1,AL2&"","") | BR2: =IF(AND(AU2=1,ISNUMBER(AP2),G2<=Config!$B$5),AP2,"") | BS2: =IF(AU2=1,IF(COUNTIFS($A$2:$A$201,$A2,$AN$2:$AN$201,"Y",$AU$2:$AU$201,1)>0,"Y","N"),"") | BT2: =IF(AND(AU2=1,AN2="maybe"),1,0) | BU2: =IF(BT2=1,IF(COUNTIFS($A$2:$A$201,$A2,$BT$2:$BT$201,1,$G$2:$G$201,"<"&G2)+COUNTIFS($A$2:$A$201,$A2,$BT$2:$BT$201,1,$G$2:$G$201,G2,$AT$2:$AT$201,"<"&AT2)=0,1,0),0) | BV2: =IF(AND(AU2=1,AN2="Y"),IF(COUNTIFS($A$2:$A$201,$A2,$AN$2:$AN$201,"Y",$AU$2:$AU$201,1,$G$2:$G$201,"<"&G2)+COUNTIFS($A$2:$A$201,$A2,$AN$2:$AN$201,"Y",$AU$2:$AU$201,1,$G$2:$G$201,G2,$AT$2:$AT$201,"<"&AT2)=0,1,0),0) | BW2: =IF(AND(BA2=1,N(V2)>=Config!$B$15),1,0) | BX2: =IF(AU2=1,IFERROR(MATCH($A2,INDEX(Clay_Offices!$A$2:$FZ$601,0,Sync!$C$5),0),""),"") | BY2: =IF(BX2="","",IFERROR(INDEX(Clay_Offices!$A$2:$FZ$601,BX2,Sync!$C$7)&"","")) | BZ2: =IF(BY2="","",IFERROR(INDEX(Lists!$J$2:$J$15,MATCH(BY2,Lists!$I$2:$I$15,0)),"")) | CA2: =IF(BX2="","",IFERROR(INDEX(Clay_Offices!$A$2:$FZ$601,BX2,Sync!$C$17)&"","")) | CB2: =IF(BX2="","",IFERROR(N(INDEX(Clay_Offices!$A$2:$FZ$601,BX2,Sync!$C$16)),0))
AS3: =IF(TRIM($A3)="","",IF(AND(LEFT($A3,6)="SAMPLE",Config!$B$19<>"Y"),"",IF(NOT(ISNUMBER(G3)),"call_date is blank or not a date",IF(Sync!$C$5="","Clay paste is empty or has no row_id column: paste the Clay export on Clay_Offices",IF(BX3="","row_id not found in the Clay paste: add the Clay row or fix the row_id",IF(AND(ISNUMBER(BZ3),BZ3>=1,BZ3<=5),"Clay status is "&BY3&": set call_done or later",IF(AND(AW3=1,CA3<>BS3),"Clay yes_in_principle should be "&BS3,IF(AND(AW3=1,CB3<>G3),"Clay call_date should be "&TEXT(G3,"yyyy-mm-dd"),"")))))))) | AT3: =ROW() | AU3: =IF(AND(TRIM($A3)<>"",ISNUMBER(G3)),IF(AND(LEFT($A3,6)="SAMPLE",Config!$B$19<>"Y"),0,1),0) | AV3: =IF(AU3=1,IF(COUNTIFS($A$2:$A$201,$A3,$AU$2:$AU$201,1,$G$2:$G$201,"<"&G3)+COUNTIFS($A$2:$A$201,$A3,$AU$2:$AU$201,1,$G$2:$G$201,G3,$AT$2:$AT$201,"<"&AT3)=0,1,0),0) | AW3: =IF(AU3=1,IF(COUNTIFS($A$2:$A$201,$A3,$AU$2:$AU$201,1,$G$2:$G$201,">"&G3)+COUNTIFS($A$2:$A$201,$A3,$AU$2:$AU$201,1,$G$2:$G$201,G3,$AT$2:$AT$201,">"&AT3)=0,1,0),0) | AX3: =IF(AND(AU3=1,AN3="Y",Z3="Y",TRIM(AD3)<>""),1,0) | AY3: =IF(AX3=1,IF(COUNTIFS($A$2:$A$201,$A3,$AX$2:$AX$201,1,$G$2:$G$201,"<"&G3)+COUNTIFS($A$2:$A$201,$A3,$AX$2:$AX$201,1,$G$2:$G$201,G3,$AT$2:$AT$201,"<"&AT3)=0,1,0),0) | AZ3: =IF(AND(AU3=1,AN3="Y",AX3=0),1,0) | BA3: =IF(AND(AU3=1,ISNUMBER(V3)),1,0) | BB3: =IF(BA3=1,IF(COUNTIFS($A$2:$A$201,$A3,$BA$2:$BA$201,1,$G$2:$G$201,"<"&G3)+COUNTIFS($A$2:$A$201,$A3,$BA$2:$BA$201,1,$G$2:$G$201,G3,$AT$2:$AT$201,"<"&AT3)=0,1,0),0) | BC3: =IF(AND(BB3=1,G3<=Config!$B$6),V3,"") | BD3: =IF(AND(BB3=1,G3<=Config!$B$7),V3,"") | BE3: =IF(AND(BB3=1,G3<=Config!$B$8),V3,"") | BF3: =IF(AND(BB3=1,G3<=Config!$B$5),V3,"") | BG3: =IF(BW3=1,IF(COUNTIFS($A$2:$A$201,$A3,$BW$2:$BW$201,1,$G$2:$G$201,"<"&G3)+COUNTIFS($A$2:$A$201,$A3,$BW$2:$BW$201,1,$G$2:$G$201,G3,$AT$2:$AT$201,"<"&AT3)=0,1,0),0) | BH3: =IF(AND(AU3=1,ISNUMBER(K3)),1,0) | BI3: =IF(BH3=1,IF(COUNTIFS($A$2:$A$201,$A3,$BH$2:$BH$201,1,$G$2:$G$201,"<"&G3)+COUNTIFS($A$2:$A$201,$A3,$BH$2:$BH$201,1,$G$2:$G$201,G3,$AT$2:$AT$201,"<"&AT3)=0,1,0),0) | BJ3: =IF(AND(BI3=1,G3<=Config!$B$5),K3,"") | BK3: =IF(AND(AU3=1,OR(TRIM(U3)<>"",ISNUMBER(V3))),1,0) | BL3: =IF(BK3=1,IF(COUNTIFS($A$2:$A$201,$A3,$BK$2:$BK$201,1,$G$2:$G$201,"<"&G3)+COUNTIFS($A$2:$A$201,$A3,$BK$2:$BK$201,1,$G$2:$G$201,G3,$AT$2:$AT$201,"<"&AT3)=0,1,0),0) | BM3: =IF(BL3=1,$A3,"") | BN3: =IF(AND(AU3=1,T3="Y",TRIM(U3)=""),1,0) | BO3: =IF(AU3=1,AJ3&"","") | BP3: =IF(AU3=1,AK3&"","") | BQ3: =IF(AU3=1,AL3&"","") | BR3: =IF(AND(AU3=1,ISNUMBER(AP3),G3<=Config!$B$5),AP3,"") | BS3: =IF(AU3=1,IF(COUNTIFS($A$2:$A$201,$A3,$AN$2:$AN$201,"Y",$AU$2:$AU$201,1)>0,"Y","N"),"") | BT3: =IF(AND(AU3=1,AN3="maybe"),1,0) | BU3: =IF(BT3=1,IF(COUNTIFS($A$2:$A$201,$A3,$BT$2:$BT$201,1,$G$2:$G$201,"<"&G3)+COUNTIFS($A$2:$A$201,$A3,$BT$2:$BT$201,1,$G$2:$G$201,G3,$AT$2:$AT$201,"<"&AT3)=0,1,0),0) | BV3: =IF(AND(AU3=1,AN3="Y"),IF(COUNTIFS($A$2:$A$201,$A3,$AN$2:$AN$201,"Y",$AU$2:$AU$201,1,$G$2:$G$201,"<"&G3)+COUNTIFS($A$2:$A$201,$A3,$AN$2:$AN$201,"Y",$AU$2:$AU$201,1,$G$2:$G$201,G3,$AT$2:$AT$201,"<"&AT3)=0,1,0),0) | BW3: =IF(AND(BA3=1,N(V3)>=Config!$B$15),1,0) | BX3: =IF(AU3=1,IFERROR(MATCH($A3,INDEX(Clay_Offices!$A$2:$FZ$601,0,Sync!$C$5),0),""),"") | BY3: =IF(BX3="","",IFERROR(INDEX(Clay_Offices!$A$2:$FZ$601,BX3,Sync!$C$7)&"","")) | BZ3: =IF(BY3="","",IFERROR(INDEX(Lists!$J$2:$J$15,MATCH(BY3,Lists!$I$2:$I$15,0)),"")) | CA3: =IF(BX3="","",IFERROR(INDEX(Clay_Offices!$A$2:$FZ$601,BX3,Sync!$C$17)&"","")) | CB3: =IF(BX3="","",IFERROR(N(INDEX(Clay_Offices!$A$2:$FZ$601,BX3,Sync!$C$16)),0))
AS4: =IF(TRIM($A4)="","",IF(AND(LEFT($A4,6)="SAMPLE",Config!$B$19<>"Y"),"",IF(NOT(ISNUMBER(G4)),"call_date is blank or not a date",IF(Sync!$C$5="","Clay paste is empty or has no row_id column: paste the Clay export on Clay_Offices",IF(BX4="","row_id not found in the Clay paste: add the Clay row or fix the row_id",IF(AND(ISNUMBER(BZ4),BZ4>=1,BZ4<=5),"Clay status is "&BY4&": set call_done or later",IF(AND(AW4=1,CA4<>BS4),"Clay yes_in_principle should be "&BS4,IF(AND(AW4=1,CB4<>G4),"Clay call_date should be "&TEXT(G4,"yyyy-mm-dd"),"")))))))) | AT4: =ROW() | AU4: =IF(AND(TRIM($A4)<>"",ISNUMBER(G4)),IF(AND(LEFT($A4,6)="SAMPLE",Config!$B$19<>"Y"),0,1),0) | AV4: =IF(AU4=1,IF(COUNTIFS($A$2:$A$201,$A4,$AU$2:$AU$201,1,$G$2:$G$201,"<"&G4)+COUNTIFS($A$2:$A$201,$A4,$AU$2:$AU$201,1,$G$2:$G$201,G4,$AT$2:$AT$201,"<"&AT4)=0,1,0),0) | AW4: =IF(AU4=1,IF(COUNTIFS($A$2:$A$201,$A4,$AU$2:$AU$201,1,$G$2:$G$201,">"&G4)+COUNTIFS($A$2:$A$201,$A4,$AU$2:$AU$201,1,$G$2:$G$201,G4,$AT$2:$AT$201,">"&AT4)=0,1,0),0) | AX4: =IF(AND(AU4=1,AN4="Y",Z4="Y",TRIM(AD4)<>""),1,0) | AY4: =IF(AX4=1,IF(COUNTIFS($A$2:$A$201,$A4,$AX$2:$AX$201,1,$G$2:$G$201,"<"&G4)+COUNTIFS($A$2:$A$201,$A4,$AX$2:$AX$201,1,$G$2:$G$201,G4,$AT$2:$AT$201,"<"&AT4)=0,1,0),0) | AZ4: =IF(AND(AU4=1,AN4="Y",AX4=0),1,0) | BA4: =IF(AND(AU4=1,ISNUMBER(V4)),1,0) | BB4: =IF(BA4=1,IF(COUNTIFS($A$2:$A$201,$A4,$BA$2:$BA$201,1,$G$2:$G$201,"<"&G4)+COUNTIFS($A$2:$A$201,$A4,$BA$2:$BA$201,1,$G$2:$G$201,G4,$AT$2:$AT$201,"<"&AT4)=0,1,0),0) | BC4: =IF(AND(BB4=1,G4<=Config!$B$6),V4,"") | BD4: =IF(AND(BB4=1,G4<=Config!$B$7),V4,"") | BE4: =IF(AND(BB4=1,G4<=Config!$B$8),V4,"") | BF4: =IF(AND(BB4=1,G4<=Config!$B$5),V4,"") | BG4: =IF(BW4=1,IF(COUNTIFS($A$2:$A$201,$A4,$BW$2:$BW$201,1,$G$2:$G$201,"<"&G4)+COUNTIFS($A$2:$A$201,$A4,$BW$2:$BW$201,1,$G$2:$G$201,G4,$AT$2:$AT$201,"<"&AT4)=0,1,0),0) | BH4: =IF(AND(AU4=1,ISNUMBER(K4)),1,0) | BI4: =IF(BH4=1,IF(COUNTIFS($A$2:$A$201,$A4,$BH$2:$BH$201,1,$G$2:$G$201,"<"&G4)+COUNTIFS($A$2:$A$201,$A4,$BH$2:$BH$201,1,$G$2:$G$201,G4,$AT$2:$AT$201,"<"&AT4)=0,1,0),0) | BJ4: =IF(AND(BI4=1,G4<=Config!$B$5),K4,"") | BK4: =IF(AND(AU4=1,OR(TRIM(U4)<>"",ISNUMBER(V4))),1,0) | BL4: =IF(BK4=1,IF(COUNTIFS($A$2:$A$201,$A4,$BK$2:$BK$201,1,$G$2:$G$201,"<"&G4)+COUNTIFS($A$2:$A$201,$A4,$BK$2:$BK$201,1,$G$2:$G$201,G4,$AT$2:$AT$201,"<"&AT4)=0,1,0),0) | BM4: =IF(BL4=1,$A4,"") | BN4: =IF(AND(AU4=1,T4="Y",TRIM(U4)=""),1,0) | BO4: =IF(AU4=1,AJ4&"","") | BP4: =IF(AU4=1,AK4&"","") | BQ4: =IF(AU4=1,AL4&"","") | BR4: =IF(AND(AU4=1,ISNUMBER(AP4),G4<=Config!$B$5),AP4,"") | BS4: =IF(AU4=1,IF(COUNTIFS($A$2:$A$201,$A4,$AN$2:$AN$201,"Y",$AU$2:$AU$201,1)>0,"Y","N"),"") | BT4: =IF(AND(AU4=1,AN4="maybe"),1,0) | BU4: =IF(BT4=1,IF(COUNTIFS($A$2:$A$201,$A4,$BT$2:$BT$201,1,$G$2:$G$201,"<"&G4)+COUNTIFS($A$2:$A$201,$A4,$BT$2:$BT$201,1,$G$2:$G$201,G4,$AT$2:$AT$201,"<"&AT4)=0,1,0),0) | BV4: =IF(AND(AU4=1,AN4="Y"),IF(COUNTIFS($A$2:$A$201,$A4,$AN$2:$AN$201,"Y",$AU$2:$AU$201,1,$G$2:$G$201,"<"&G4)+COUNTIFS($A$2:$A$201,$A4,$AN$2:$AN$201,"Y",$AU$2:$AU$201,1,$G$2:$G$201,G4,$AT$2:$AT$201,"<"&AT4)=0,1,0),0) | BW4: =IF(AND(BA4=1,N(V4)>=Config!$B$15),1,0) | BX4: =IF(AU4=1,IFERROR(MATCH($A4,INDEX(Clay_Offices!$A$2:$FZ$601,0,Sync!$C$5),0),""),"") | BY4: =IF(BX4="","",IFERROR(INDEX(Clay_Offices!$A$2:$FZ$601,BX4,Sync!$C$7)&"","")) | BZ4: =IF(BY4="","",IFERROR(INDEX(Lists!$J$2:$J$15,MATCH(BY4,Lists!$I$2:$I$15,0)),"")) | CA4: =IF(BX4="","",IFERROR(INDEX(Clay_Offices!$A$2:$FZ$601,BX4,Sync!$C$17)&"","")) | CB4: =IF(BX4="","",IFERROR(N(INDEX(Clay_Offices!$A$2:$FZ$601,BX4,Sync!$C$16)),0))
AS5: =IF(TRIM($A5)="","",IF(AND(LEFT($A5,6)="SAMPLE",Config!$B$19<>"Y"),"",IF(NOT(ISNUMBER(G5)),"call_date is blank or not a date",IF(Sync!$C$5="","Clay paste is empty or has no row_id column: paste the Clay export on Clay_Offices",IF(BX5="","row_id not found in the Clay paste: add the Clay row or fix the row_id",IF(AND(ISNUMBER(BZ5),BZ5>=1,BZ5<=5),"Clay status is "&BY5&": set call_done or later",IF(AND(AW5=1,CA5<>BS5),"Clay yes_in_principle should be "&BS5,IF(AND(AW5=1,CB5<>G5),"Clay call_date should be "&TEXT(G5,"yyyy-mm-dd"),"")))))))) | AT5: =ROW() | AU5: =IF(AND(TRIM($A5)<>"",ISNUMBER(G5)),IF(AND(LEFT($A5,6)="SAMPLE",Config!$B$19<>"Y"),0,1),0) | AV5: =IF(AU5=1,IF(COUNTIFS($A$2:$A$201,$A5,$AU$2:$AU$201,1,$G$2:$G$201,"<"&G5)+COUNTIFS($A$2:$A$201,$A5,$AU$2:$AU$201,1,$G$2:$G$201,G5,$AT$2:$AT$201,"<"&AT5)=0,1,0),0) | AW5: =IF(AU5=1,IF(COUNTIFS($A$2:$A$201,$A5,$AU$2:$AU$201,1,$G$2:$G$201,">"&G5)+COUNTIFS($A$2:$A$201,$A5,$AU$2:$AU$201,1,$G$2:$G$201,G5,$AT$2:$AT$201,">"&AT5)=0,1,0),0) | AX5: =IF(AND(AU5=1,AN5="Y",Z5="Y",TRIM(AD5)<>""),1,0) | AY5: =IF(AX5=1,IF(COUNTIFS($A$2:$A$201,$A5,$AX$2:$AX$201,1,$G$2:$G$201,"<"&G5)+COUNTIFS($A$2:$A$201,$A5,$AX$2:$AX$201,1,$G$2:$G$201,G5,$AT$2:$AT$201,"<"&AT5)=0,1,0),0) | AZ5: =IF(AND(AU5=1,AN5="Y",AX5=0),1,0) | BA5: =IF(AND(AU5=1,ISNUMBER(V5)),1,0) | BB5: =IF(BA5=1,IF(COUNTIFS($A$2:$A$201,$A5,$BA$2:$BA$201,1,$G$2:$G$201,"<"&G5)+COUNTIFS($A$2:$A$201,$A5,$BA$2:$BA$201,1,$G$2:$G$201,G5,$AT$2:$AT$201,"<"&AT5)=0,1,0),0) | BC5: =IF(AND(BB5=1,G5<=Config!$B$6),V5,"") | BD5: =IF(AND(BB5=1,G5<=Config!$B$7),V5,"") | BE5: =IF(AND(BB5=1,G5<=Config!$B$8),V5,"") | BF5: =IF(AND(BB5=1,G5<=Config!$B$5),V5,"") | BG5: =IF(BW5=1,IF(COUNTIFS($A$2:$A$201,$A5,$BW$2:$BW$201,1,$G$2:$G$201,"<"&G5)+COUNTIFS($A$2:$A$201,$A5,$BW$2:$BW$201,1,$G$2:$G$201,G5,$AT$2:$AT$201,"<"&AT5)=0,1,0),0) | BH5: =IF(AND(AU5=1,ISNUMBER(K5)),1,0) | BI5: =IF(BH5=1,IF(COUNTIFS($A$2:$A$201,$A5,$BH$2:$BH$201,1,$G$2:$G$201,"<"&G5)+COUNTIFS($A$2:$A$201,$A5,$BH$2:$BH$201,1,$G$2:$G$201,G5,$AT$2:$AT$201,"<"&AT5)=0,1,0),0) | BJ5: =IF(AND(BI5=1,G5<=Config!$B$5),K5,"") | BK5: =IF(AND(AU5=1,OR(TRIM(U5)<>"",ISNUMBER(V5))),1,0) | BL5: =IF(BK5=1,IF(COUNTIFS($A$2:$A$201,$A5,$BK$2:$BK$201,1,$G$2:$G$201,"<"&G5)+COUNTIFS($A$2:$A$201,$A5,$BK$2:$BK$201,1,$G$2:$G$201,G5,$AT$2:$AT$201,"<"&AT5)=0,1,0),0) | BM5: =IF(BL5=1,$A5,"") | BN5: =IF(AND(AU5=1,T5="Y",TRIM(U5)=""),1,0) | BO5: =IF(AU5=1,AJ5&"","") | BP5: =IF(AU5=1,AK5&"","") | BQ5: =IF(AU5=1,AL5&"","") | BR5: =IF(AND(AU5=1,ISNUMBER(AP5),G5<=Config!$B$5),AP5,"") | BS5: =IF(AU5=1,IF(COUNTIFS($A$2:$A$201,$A5,$AN$2:$AN$201,"Y",$AU$2:$AU$201,1)>0,"Y","N"),"") | BT5: =IF(AND(AU5=1,AN5="maybe"),1,0) | BU5: =IF(BT5=1,IF(COUNTIFS($A$2:$A$201,$A5,$BT$2:$BT$201,1,$G$2:$G$201,"<"&G5)+COUNTIFS($A$2:$A$201,$A5,$BT$2:$BT$201,1,$G$2:$G$201,G5,$AT$2:$AT$201,"<"&AT5)=0,1,0),0) | BV5: =IF(AND(AU5=1,AN5="Y"),IF(COUNTIFS($A$2:$A$201,$A5,$AN$2:$AN$201,"Y",$AU$2:$AU$201,1,$G$2:$G$201,"<"&G5)+COUNTIFS($A$2:$A$201,$A5,$AN$2:$AN$201,"Y",$AU$2:$AU$201,1,$G$2:$G$201,G5,$AT$2:$AT$201,"<"&AT5)=0,1,0),0) | BW5: =IF(AND(BA5=1,N(V5)>=Config!$B$15),1,0) | BX5: =IF(AU5=1,IFERROR(MATCH($A5,INDEX(Clay_Offices!$A$2:$FZ$601,0,Sync!$C$5),0),""),"") | BY5: =IF(BX5="","",IFERROR(INDEX(Clay_Offices!$A$2:$FZ$601,BX5,Sync!$C$7)&"","")) | BZ5: =IF(BY5="","",IFERROR(INDEX(Lists!$J$2:$J$15,MATCH(BY5,Lists!$I$2:$I$15,0)),"")) | CA5: =IF(BX5="","",IFERROR(INDEX(Clay_Offices!$A$2:$FZ$601,BX5,Sync!$C$17)&"","")) | CB5: =IF(BX5="","",IFERROR(N(INDEX(Clay_Offices!$A$2:$FZ$601,BX5,Sync!$C$16)),0))
AS6: =IF(TRIM($A6)="","",IF(AND(LEFT($A6,6)="SAMPLE",Config!$B$19<>"Y"),"",IF(NOT(ISNUMBER(G6)),"call_date is blank or not a date",IF(Sync!$C$5="","Clay paste is empty or has no row_id column: paste the Clay export on Clay_Offices",IF(BX6="","row_id not found in the Clay paste: add the Clay row or fix the row_id",IF(AND(ISNUMBER(BZ6),BZ6>=1,BZ6<=5),"Clay status is "&BY6&": set call_done or later",IF(AND(AW6=1,CA6<>BS6),"Clay yes_in_principle should be "&BS6,IF(AND(AW6=1,CB6<>G6),"Clay call_date should be "&TEXT(G6,"yyyy-mm-dd"),"")))))))) | AT6: =ROW() | AU6: =IF(AND(TRIM($A6)<>"",ISNUMBER(G6)),IF(AND(LEFT($A6,6)="SAMPLE",Config!$B$19<>"Y"),0,1),0) | AV6: =IF(AU6=1,IF(COUNTIFS($A$2:$A$201,$A6,$AU$2:$AU$201,1,$G$2:$G$201,"<"&G6)+COUNTIFS($A$2:$A$201,$A6,$AU$2:$AU$201,1,$G$2:$G$201,G6,$AT$2:$AT$201,"<"&AT6)=0,1,0),0) | AW6: =IF(AU6=1,IF(COUNTIFS($A$2:$A$201,$A6,$AU$2:$AU$201,1,$G$2:$G$201,">"&G6)+COUNTIFS($A$2:$A$201,$A6,$AU$2:$AU$201,1,$G$2:$G$201,G6,$AT$2:$AT$201,">"&AT6)=0,1,0),0) | AX6: =IF(AND(AU6=1,AN6="Y",Z6="Y",TRIM(AD6)<>""),1,0) | AY6: =IF(AX6=1,IF(COUNTIFS($A$2:$A$201,$A6,$AX$2:$AX$201,1,$G$2:$G$201,"<"&G6)+COUNTIFS($A$2:$A$201,$A6,$AX$2:$AX$201,1,$G$2:$G$201,G6,$AT$2:$AT$201,"<"&AT6)=0,1,0),0) | AZ6: =IF(AND(AU6=1,AN6="Y",AX6=0),1,0) | BA6: =IF(AND(AU6=1,ISNUMBER(V6)),1,0) | BB6: =IF(BA6=1,IF(COUNTIFS($A$2:$A$201,$A6,$BA$2:$BA$201,1,$G$2:$G$201,"<"&G6)+COUNTIFS($A$2:$A$201,$A6,$BA$2:$BA$201,1,$G$2:$G$201,G6,$AT$2:$AT$201,"<"&AT6)=0,1,0),0) | BC6: =IF(AND(BB6=1,G6<=Config!$B$6),V6,"") | BD6: =IF(AND(BB6=1,G6<=Config!$B$7),V6,"") | BE6: =IF(AND(BB6=1,G6<=Config!$B$8),V6,"") | BF6: =IF(AND(BB6=1,G6<=Config!$B$5),V6,"") | BG6: =IF(BW6=1,IF(COUNTIFS($A$2:$A$201,$A6,$BW$2:$BW$201,1,$G$2:$G$201,"<"&G6)+COUNTIFS($A$2:$A$201,$A6,$BW$2:$BW$201,1,$G$2:$G$201,G6,$AT$2:$AT$201,"<"&AT6)=0,1,0),0) | BH6: =IF(AND(AU6=1,ISNUMBER(K6)),1,0) | BI6: =IF(BH6=1,IF(COUNTIFS($A$2:$A$201,$A6,$BH$2:$BH$201,1,$G$2:$G$201,"<"&G6)+COUNTIFS($A$2:$A$201,$A6,$BH$2:$BH$201,1,$G$2:$G$201,G6,$AT$2:$AT$201,"<"&AT6)=0,1,0),0) | BJ6: =IF(AND(BI6=1,G6<=Config!$B$5),K6,"") | BK6: =IF(AND(AU6=1,OR(TRIM(U6)<>"",ISNUMBER(V6))),1,0) | BL6: =IF(BK6=1,IF(COUNTIFS($A$2:$A$201,$A6,$BK$2:$BK$201,1,$G$2:$G$201,"<"&G6)+COUNTIFS($A$2:$A$201,$A6,$BK$2:$BK$201,1,$G$2:$G$201,G6,$AT$2:$AT$201,"<"&AT6)=0,1,0),0) | BM6: =IF(BL6=1,$A6,"") | BN6: =IF(AND(AU6=1,T6="Y",TRIM(U6)=""),1,0) | BO6: =IF(AU6=1,AJ6&"","") | BP6: =IF(AU6=1,AK6&"","") | BQ6: =IF(AU6=1,AL6&"","") | BR6: =IF(AND(AU6=1,ISNUMBER(AP6),G6<=Config!$B$5),AP6,"") | BS6: =IF(AU6=1,IF(COUNTIFS($A$2:$A$201,$A6,$AN$2:$AN$201,"Y",$AU$2:$AU$201,1)>0,"Y","N"),"") | BT6: =IF(AND(AU6=1,AN6="maybe"),1,0) | BU6: =IF(BT6=1,IF(COUNTIFS($A$2:$A$201,$A6,$BT$2:$BT$201,1,$G$2:$G$201,"<"&G6)+COUNTIFS($A$2:$A$201,$A6,$BT$2:$BT$201,1,$G$2:$G$201,G6,$AT$2:$AT$201,"<"&AT6)=0,1,0),0) | BV6: =IF(AND(AU6=1,AN6="Y"),IF(COUNTIFS($A$2:$A$201,$A6,$AN$2:$AN$201,"Y",$AU$2:$AU$201,1,$G$2:$G$201,"<"&G6)+COUNTIFS($A$2:$A$201,$A6,$AN$2:$AN$201,"Y",$AU$2:$AU$201,1,$G$2:$G$201,G6,$AT$2:$AT$201,"<"&AT6)=0,1,0),0) | BW6: =IF(AND(BA6=1,N(V6)>=Config!$B$15),1,0) | BX6: =IF(AU6=1,IFERROR(MATCH($A6,INDEX(Clay_Offices!$A$2:$FZ$601,0,Sync!$C$5),0),""),"") | BY6: =IF(BX6="","",IFERROR(INDEX(Clay_Offices!$A$2:$FZ$601,BX6,Sync!$C$7)&"","")) | BZ6: =IF(BY6="","",IFERROR(INDEX(Lists!$J$2:$J$15,MATCH(BY6,Lists!$I$2:$I$15,0)),"")) | CA6: =IF(BX6="","",IFERROR(INDEX(Clay_Offices!$A$2:$FZ$601,BX6,Sync!$C$17)&"","")) | CB6: =IF(BX6="","",IFERROR(N(INDEX(Clay_Offices!$A$2:$FZ$601,BX6,Sync!$C$16)),0))
AS7: =IF(TRIM($A7)="","",IF(AND(LEFT($A7,6)="SAMPLE",Config!$B$19<>"Y"),"",IF(NOT(ISNUMBER(G7)),"call_date is blank or not a date",IF(Sync!$C$5="","Clay paste is empty or has no row_id column: paste the Clay export on Clay_Offices",IF(BX7="","row_id not found in the Clay paste: add the Clay row or fix the row_id",IF(AND(ISNUMBER(BZ7),BZ7>=1,BZ7<=5),"Clay status is "&BY7&": set call_done or later",IF(AND(AW7=1,CA7<>BS7),"Clay yes_in_principle should be "&BS7,IF(AND(AW7=1,CB7<>G7),"Clay call_date should be "&TEXT(G7,"yyyy-mm-dd"),"")))))))) | AT7: =ROW() | AU7: =IF(AND(TRIM($A7)<>"",ISNUMBER(G7)),IF(AND(LEFT($A7,6)="SAMPLE",Config!$B$19<>"Y"),0,1),0) | AV7: =IF(AU7=1,IF(COUNTIFS($A$2:$A$201,$A7,$AU$2:$AU$201,1,$G$2:$G$201,"<"&G7)+COUNTIFS($A$2:$A$201,$A7,$AU$2:$AU$201,1,$G$2:$G$201,G7,$AT$2:$AT$201,"<"&AT7)=0,1,0),0) | AW7: =IF(AU7=1,IF(COUNTIFS($A$2:$A$201,$A7,$AU$2:$AU$201,1,$G$2:$G$201,">"&G7)+COUNTIFS($A$2:$A$201,$A7,$AU$2:$AU$201,1,$G$2:$G$201,G7,$AT$2:$AT$201,">"&AT7)=0,1,0),0) | AX7: =IF(AND(AU7=1,AN7="Y",Z7="Y",TRIM(AD7)<>""),1,0) | AY7: =IF(AX7=1,IF(COUNTIFS($A$2:$A$201,$A7,$AX$2:$AX$201,1,$G$2:$G$201,"<"&G7)+COUNTIFS($A$2:$A$201,$A7,$AX$2:$AX$201,1,$G$2:$G$201,G7,$AT$2:$AT$201,"<"&AT7)=0,1,0),0) | AZ7: =IF(AND(AU7=1,AN7="Y",AX7=0),1,0) | BA7: =IF(AND(AU7=1,ISNUMBER(V7)),1,0) | BB7: =IF(BA7=1,IF(COUNTIFS($A$2:$A$201,$A7,$BA$2:$BA$201,1,$G$2:$G$201,"<"&G7)+COUNTIFS($A$2:$A$201,$A7,$BA$2:$BA$201,1,$G$2:$G$201,G7,$AT$2:$AT$201,"<"&AT7)=0,1,0),0) | BC7: =IF(AND(BB7=1,G7<=Config!$B$6),V7,"") | BD7: =IF(AND(BB7=1,G7<=Config!$B$7),V7,"") | BE7: =IF(AND(BB7=1,G7<=Config!$B$8),V7,"") | BF7: =IF(AND(BB7=1,G7<=Config!$B$5),V7,"") | BG7: =IF(BW7=1,IF(COUNTIFS($A$2:$A$201,$A7,$BW$2:$BW$201,1,$G$2:$G$201,"<"&G7)+COUNTIFS($A$2:$A$201,$A7,$BW$2:$BW$201,1,$G$2:$G$201,G7,$AT$2:$AT$201,"<"&AT7)=0,1,0),0) | BH7: =IF(AND(AU7=1,ISNUMBER(K7)),1,0) | BI7: =IF(BH7=1,IF(COUNTIFS($A$2:$A$201,$A7,$BH$2:$BH$201,1,$G$2:$G$201,"<"&G7)+COUNTIFS($A$2:$A$201,$A7,$BH$2:$BH$201,1,$G$2:$G$201,G7,$AT$2:$AT$201,"<"&AT7)=0,1,0),0) | BJ7: =IF(AND(BI7=1,G7<=Config!$B$5),K7,"") | BK7: =IF(AND(AU7=1,OR(TRIM(U7)<>"",ISNUMBER(V7))),1,0) | BL7: =IF(BK7=1,IF(COUNTIFS($A$2:$A$201,$A7,$BK$2:$BK$201,1,$G$2:$G$201,"<"&G7)+COUNTIFS($A$2:$A$201,$A7,$BK$2:$BK$201,1,$G$2:$G$201,G7,$AT$2:$AT$201,"<"&AT7)=0,1,0),0) | BM7: =IF(BL7=1,$A7,"") | BN7: =IF(AND(AU7=1,T7="Y",TRIM(U7)=""),1,0) | BO7: =IF(AU7=1,AJ7&"","") | BP7: =IF(AU7=1,AK7&"","") | BQ7: =IF(AU7=1,AL7&"","") | BR7: =IF(AND(AU7=1,ISNUMBER(AP7),G7<=Config!$B$5),AP7,"") | BS7: =IF(AU7=1,IF(COUNTIFS($A$2:$A$201,$A7,$AN$2:$AN$201,"Y",$AU$2:$AU$201,1)>0,"Y","N"),"") | BT7: =IF(AND(AU7=1,AN7="maybe"),1,0) | BU7: =IF(BT7=1,IF(COUNTIFS($A$2:$A$201,$A7,$BT$2:$BT$201,1,$G$2:$G$201,"<"&G7)+COUNTIFS($A$2:$A$201,$A7,$BT$2:$BT$201,1,$G$2:$G$201,G7,$AT$2:$AT$201,"<"&AT7)=0,1,0),0) | BV7: =IF(AND(AU7=1,AN7="Y"),IF(COUNTIFS($A$2:$A$201,$A7,$AN$2:$AN$201,"Y",$AU$2:$AU$201,1,$G$2:$G$201,"<"&G7)+COUNTIFS($A$2:$A$201,$A7,$AN$2:$AN$201,"Y",$AU$2:$AU$201,1,$G$2:$G$201,G7,$AT$2:$AT$201,"<"&AT7)=0,1,0),0) | BW7: =IF(AND(BA7=1,N(V7)>=Config!$B$15),1,0) | BX7: =IF(AU7=1,IFERROR(MATCH($A7,INDEX(Clay_Offices!$A$2:$FZ$601,0,Sync!$C$5),0),""),"") | BY7: =IF(BX7="","",IFERROR(INDEX(Clay_Offices!$A$2:$FZ$601,BX7,Sync!$C$7)&"","")) | BZ7: =IF(BY7="","",IFERROR(INDEX(Lists!$J$2:$J$15,MATCH(BY7,Lists!$I$2:$I$15,0)),"")) | CA7: =IF(BX7="","",IFERROR(INDEX(Clay_Offices!$A$2:$FZ$601,BX7,Sync!$C$17)&"","")) | CB7: =IF(BX7="","",IFERROR(N(INDEX(Clay_Offices!$A$2:$FZ$601,BX7,Sync!$C$16)),0))
AS8: =IF(TRIM($A8)="","",IF(AND(LEFT($A8,6)="SAMPLE",Config!$B$19<>"Y"),"",IF(NOT(ISNUMBER(G8)),"call_date is blank or not a date",IF(Sync!$C$5="","Clay paste is empty or has no row_id column: paste the Clay export on Clay_Offices",IF(BX8="","row_id not found in the Clay paste: add the Clay row or fix the row_id",IF(AND(ISNUMBER(BZ8),BZ8>=1,BZ8<=5),"Clay status is "&BY8&": set call_done or later",IF(AND(AW8=1,CA8<>BS8),"Clay yes_in_principle should be "&BS8,IF(AND(AW8=1,CB8<>G8),"Clay call_date should be "&TEXT(G8,"yyyy-mm-dd"),"")))))))) | AT8: =ROW() | AU8: =IF(AND(TRIM($A8)<>"",ISNUMBER(G8)),IF(AND(LEFT($A8,6)="SAMPLE",Config!$B$19<>"Y"),0,1),0) | AV8: =IF(AU8=1,IF(COUNTIFS($A$2:$A$201,$A8,$AU$2:$AU$201,1,$G$2:$G$201,"<"&G8)+COUNTIFS($A$2:$A$201,$A8,$AU$2:$AU$201,1,$G$2:$G$201,G8,$AT$2:$AT$201,"<"&AT8)=0,1,0),0) | AW8: =IF(AU8=1,IF(COUNTIFS($A$2:$A$201,$A8,$AU$2:$AU$201,1,$G$2:$G$201,">"&G8)+COUNTIFS($A$2:$A$201,$A8,$AU$2:$AU$201,1,$G$2:$G$201,G8,$AT$2:$AT$201,">"&AT8)=0,1,0),0) | AX8: =IF(AND(AU8=1,AN8="Y",Z8="Y",TRIM(AD8)<>""),1,0) | AY8: =IF(AX8=1,IF(COUNTIFS($A$2:$A$201,$A8,$AX$2:$AX$201,1,$G$2:$G$201,"<"&G8)+COUNTIFS($A$2:$A$201,$A8,$AX$2:$AX$201,1,$G$2:$G$201,G8,$AT$2:$AT$201,"<"&AT8)=0,1,0),0) | AZ8: =IF(AND(AU8=1,AN8="Y",AX8=0),1,0) | BA8: =IF(AND(AU8=1,ISNUMBER(V8)),1,0) | BB8: =IF(BA8=1,IF(COUNTIFS($A$2:$A$201,$A8,$BA$2:$BA$201,1,$G$2:$G$201,"<"&G8)+COUNTIFS($A$2:$A$201,$A8,$BA$2:$BA$201,1,$G$2:$G$201,G8,$AT$2:$AT$201,"<"&AT8)=0,1,0),0) | BC8: =IF(AND(BB8=1,G8<=Config!$B$6),V8,"") | BD8: =IF(AND(BB8=1,G8<=Config!$B$7),V8,"") | BE8: =IF(AND(BB8=1,G8<=Config!$B$8),V8,"") | BF8: =IF(AND(BB8=1,G8<=Config!$B$5),V8,"") | BG8: =IF(BW8=1,IF(COUNTIFS($A$2:$A$201,$A8,$BW$2:$BW$201,1,$G$2:$G$201,"<"&G8)+COUNTIFS($A$2:$A$201,$A8,$BW$2:$BW$201,1,$G$2:$G$201,G8,$AT$2:$AT$201,"<"&AT8)=0,1,0),0) | BH8: =IF(AND(AU8=1,ISNUMBER(K8)),1,0) | BI8: =IF(BH8=1,IF(COUNTIFS($A$2:$A$201,$A8,$BH$2:$BH$201,1,$G$2:$G$201,"<"&G8)+COUNTIFS($A$2:$A$201,$A8,$BH$2:$BH$201,1,$G$2:$G$201,G8,$AT$2:$AT$201,"<"&AT8)=0,1,0),0) | BJ8: =IF(AND(BI8=1,G8<=Config!$B$5),K8,"") | BK8: =IF(AND(AU8=1,OR(TRIM(U8)<>"",ISNUMBER(V8))),1,0) | BL8: =IF(BK8=1,IF(COUNTIFS($A$2:$A$201,$A8,$BK$2:$BK$201,1,$G$2:$G$201,"<"&G8)+COUNTIFS($A$2:$A$201,$A8,$BK$2:$BK$201,1,$G$2:$G$201,G8,$AT$2:$AT$201,"<"&AT8)=0,1,0),0) | BM8: =IF(BL8=1,$A8,"") | BN8: =IF(AND(AU8=1,T8="Y",TRIM(U8)=""),1,0) | BO8: =IF(AU8=1,AJ8&"","") | BP8: =IF(AU8=1,AK8&"","") | BQ8: =IF(AU8=1,AL8&"","") | BR8: =IF(AND(AU8=1,ISNUMBER(AP8),G8<=Config!$B$5),AP8,"") | BS8: =IF(AU8=1,IF(COUNTIFS($A$2:$A$201,$A8,$AN$2:$AN$201,"Y",$AU$2:$AU$201,1)>0,"Y","N"),"") | BT8: =IF(AND(AU8=1,AN8="maybe"),1,0) | BU8: =IF(BT8=1,IF(COUNTIFS($A$2:$A$201,$A8,$BT$2:$BT$201,1,$G$2:$G$201,"<"&G8)+COUNTIFS($A$2:$A$201,$A8,$BT$2:$BT$201,1,$G$2:$G$201,G8,$AT$2:$AT$201,"<"&AT8)=0,1,0),0) | BV8: =IF(AND(AU8=1,AN8="Y"),IF(COUNTIFS($A$2:$A$201,$A8,$AN$2:$AN$201,"Y",$AU$2:$AU$201,1,$G$2:$G$201,"<"&G8)+COUNTIFS($A$2:$A$201,$A8,$AN$2:$AN$201,"Y",$AU$2:$AU$201,1,$G$2:$G$201,G8,$AT$2:$AT$201,"<"&AT8)=0,1,0),0) | BW8: =IF(AND(BA8=1,N(V8)>=Config!$B$15),1,0) | BX8: =IF(AU8=1,IFERROR(MATCH($A8,INDEX(Clay_Offices!$A$2:$FZ$601,0,Sync!$C$5),0),""),"") | BY8: =IF(BX8="","",IFERROR(INDEX(Clay_Offices!$A$2:$FZ$601,BX8,Sync!$C$7)&"","")) | BZ8: =IF(BY8="","",IFERROR(INDEX(Lists!$J$2:$J$15,MATCH(BY8,Lists!$I$2:$I$15,0)),"")) | CA8: =IF(BX8="","",IFERROR(INDEX(Clay_Offices!$A$2:$FZ$601,BX8,Sync!$C$17)&"","")) | CB8: =IF(BX8="","",IFERROR(N(INDEX(Clay_Offices!$A$2:$FZ$601,BX8,Sync!$C$16)),0))
AS9: =IF(TRIM($A9)="","",IF(AND(LEFT($A9,6)="SAMPLE",Config!$B$19<>"Y"),"",IF(NOT(ISNUMBER(G9)),"call_date is blank or not a date",IF(Sync!$C$5="","Clay paste is empty or has no row_id column: paste the Clay export on Clay_Offices",IF(BX9="","row_id not found in the Clay paste: add the Clay row or fix the row_id",IF(AND(ISNUMBER(BZ9),BZ9>=1,BZ9<=5),"Clay status is "&BY9&": set call_done or later",IF(AND(AW9=1,CA9<>BS9),"Clay yes_in_principle should be "&BS9,IF(AND(AW9=1,CB9<>G9),"Clay call_date should be "&TEXT(G9,"yyyy-mm-dd"),"")))))))) | AT9: =ROW() | AU9: =IF(AND(TRIM($A9)<>"",ISNUMBER(G9)),IF(AND(LEFT($A9,6)="SAMPLE",Config!$B$19<>"Y"),0,1),0) | AV9: =IF(AU9=1,IF(COUNTIFS($A$2:$A$201,$A9,$AU$2:$AU$201,1,$G$2:$G$201,"<"&G9)+COUNTIFS($A$2:$A$201,$A9,$AU$2:$AU$201,1,$G$2:$G$201,G9,$AT$2:$AT$201,"<"&AT9)=0,1,0),0) | AW9: =IF(AU9=1,IF(COUNTIFS($A$2:$A$201,$A9,$AU$2:$AU$201,1,$G$2:$G$201,">"&G9)+COUNTIFS($A$2:$A$201,$A9,$AU$2:$AU$201,1,$G$2:$G$201,G9,$AT$2:$AT$201,">"&AT9)=0,1,0),0) | AX9: =IF(AND(AU9=1,AN9="Y",Z9="Y",TRIM(AD9)<>""),1,0) | AY9: =IF(AX9=1,IF(COUNTIFS($A$2:$A$201,$A9,$AX$2:$AX$201,1,$G$2:$G$201,"<"&G9)+COUNTIFS($A$2:$A$201,$A9,$AX$2:$AX$201,1,$G$2:$G$201,G9,$AT$2:$AT$201,"<"&AT9)=0,1,0),0) | AZ9: =IF(AND(AU9=1,AN9="Y",AX9=0),1,0) | BA9: =IF(AND(AU9=1,ISNUMBER(V9)),1,0) | BB9: =IF(BA9=1,IF(COUNTIFS($A$2:$A$201,$A9,$BA$2:$BA$201,1,$G$2:$G$201,"<"&G9)+COUNTIFS($A$2:$A$201,$A9,$BA$2:$BA$201,1,$G$2:$G$201,G9,$AT$2:$AT$201,"<"&AT9)=0,1,0),0) | BC9: =IF(AND(BB9=1,G9<=Config!$B$6),V9,"") | BD9: =IF(AND(BB9=1,G9<=Config!$B$7),V9,"") | BE9: =IF(AND(BB9=1,G9<=Config!$B$8),V9,"") | BF9: =IF(AND(BB9=1,G9<=Config!$B$5),V9,"") | BG9: =IF(BW9=1,IF(COUNTIFS($A$2:$A$201,$A9,$BW$2:$BW$201,1,$G$2:$G$201,"<"&G9)+COUNTIFS($A$2:$A$201,$A9,$BW$2:$BW$201,1,$G$2:$G$201,G9,$AT$2:$AT$201,"<"&AT9)=0,1,0),0) | BH9: =IF(AND(AU9=1,ISNUMBER(K9)),1,0) | BI9: =IF(BH9=1,IF(COUNTIFS($A$2:$A$201,$A9,$BH$2:$BH$201,1,$G$2:$G$201,"<"&G9)+COUNTIFS($A$2:$A$201,$A9,$BH$2:$BH$201,1,$G$2:$G$201,G9,$AT$2:$AT$201,"<"&AT9)=0,1,0),0) | BJ9: =IF(AND(BI9=1,G9<=Config!$B$5),K9,"") | BK9: =IF(AND(AU9=1,OR(TRIM(U9)<>"",ISNUMBER(V9))),1,0) | BL9: =IF(BK9=1,IF(COUNTIFS($A$2:$A$201,$A9,$BK$2:$BK$201,1,$G$2:$G$201,"<"&G9)+COUNTIFS($A$2:$A$201,$A9,$BK$2:$BK$201,1,$G$2:$G$201,G9,$AT$2:$AT$201,"<"&AT9)=0,1,0),0) | BM9: =IF(BL9=1,$A9,"") | BN9: =IF(AND(AU9=1,T9="Y",TRIM(U9)=""),1,0) | BO9: =IF(AU9=1,AJ9&"","") | BP9: =IF(AU9=1,AK9&"","") | BQ9: =IF(AU9=1,AL9&"","") | BR9: =IF(AND(AU9=1,ISNUMBER(AP9),G9<=Config!$B$5),AP9,"") | BS9: =IF(AU9=1,IF(COUNTIFS($A$2:$A$201,$A9,$AN$2:$AN$201,"Y",$AU$2:$AU$201,1)>0,"Y","N"),"") | BT9: =IF(AND(AU9=1,AN9="maybe"),1,0) | BU9: =IF(BT9=1,IF(COUNTIFS($A$2:$A$201,$A9,$BT$2:$BT$201,1,$G$2:$G$201,"<"&G9)+COUNTIFS($A$2:$A$201,$A9,$BT$2:$BT$201,1,$G$2:$G$201,G9,$AT$2:$AT$201,"<"&AT9)=0,1,0),0) | BV9: =IF(AND(AU9=1,AN9="Y"),IF(COUNTIFS($A$2:$A$201,$A9,$AN$2:$AN$201,"Y",$AU$2:$AU$201,1,$G$2:$G$201,"<"&G9)+COUNTIFS($A$2:$A$201,$A9,$AN$2:$AN$201,"Y",$AU$2:$AU$201,1,$G$2:$G$201,G9,$AT$2:$AT$201,"<"&AT9)=0,1,0),0) | BW9: =IF(AND(BA9=1,N(V9)>=Config!$B$15),1,0) | BX9: =IF(AU9=1,IFERROR(MATCH($A9,INDEX(Clay_Offices!$A$2:$FZ$601,0,Sync!$C$5),0),""),"") | BY9: =IF(BX9="","",IFERROR(INDEX(Clay_Offices!$A$2:$FZ$601,BX9,Sync!$C$7)&"","")) | BZ9: =IF(BY9="","",IFERROR(INDEX(Lists!$J$2:$J$15,MATCH(BY9,Lists!$I$2:$I$15,0)),"")) | CA9: =IF(BX9="","",IFERROR(INDEX(Clay_Offices!$A$2:$FZ$601,BX9,Sync!$C$17)&"","")) | CB9: =IF(BX9="","",IFERROR(N(INDEX(Clay_Offices!$A$2:$FZ$601,BX9,Sync!$C$16)),0))
AS10: =IF(TRIM($A10)="","",IF(AND(LEFT($A10,6)="SAMPLE",Config!$B$19<>"Y"),"",IF(NOT(ISNUMBER(G10)),"call_date is blank or not a date",IF(Sync!$C$5="","Clay paste is empty or has no row_id column: paste the Clay export on Clay_Offices",IF(BX10="","row_id not found in the Clay paste: add the Clay row or fix the row_id",IF(AND(ISNUMBER(BZ10),BZ10>=1,BZ10<=5),"Clay status is "&BY10&": set call_done or later",IF(AND(AW10=1,CA10<>BS10),"Clay yes_in_principle should be "&BS10,IF(AND(AW10=1,CB10<>G10),"Clay call_date should be "&TEXT(G10,"yyyy-mm-dd"),"")))))))) | AT10: =ROW() | AU10: =IF(AND(TRIM($A10)<>"",ISNUMBER(G10)),IF(AND(LEFT($A10,6)="SAMPLE",Config!$B$19<>"Y"),0,1),0) | AV10: =IF(AU10=1,IF(COUNTIFS($A$2:$A$201,$A10,$AU$2:$AU$201,1,$G$2:$G$201,"<"&G10)+COUNTIFS($A$2:$A$201,$A10,$AU$2:$AU$201,1,$G$2:$G$201,G10,$AT$2:$AT$201,"<"&AT10)=0,1,0),0) | AW10: =IF(AU10=1,IF(COUNTIFS($A$2:$A$201,$A10,$AU$2:$AU$201,1,$G$2:$G$201,">"&G10)+COUNTIFS($A$2:$A$201,$A10,$AU$2:$AU$201,1,$G$2:$G$201,G10,$AT$2:$AT$201,">"&AT10)=0,1,0),0) | AX10: =IF(AND(AU10=1,AN10="Y",Z10="Y",TRIM(AD10)<>""),1,0) | AY10: =IF(AX10=1,IF(COUNTIFS($A$2:$A$201,$A10,$AX$2:$AX$201,1,$G$2:$G$201,"<"&G10)+COUNTIFS($A$2:$A$201,$A10,$AX$2:$AX$201,1,$G$2:$G$201,G10,$AT$2:$AT$201,"<"&AT10)=0,1,0),0) | AZ10: =IF(AND(AU10=1,AN10="Y",AX10=0),1,0) | BA10: =IF(AND(AU10=1,ISNUMBER(V10)),1,0) | BB10: =IF(BA10=1,IF(COUNTIFS($A$2:$A$201,$A10,$BA$2:$BA$201,1,$G$2:$G$201,"<"&G10)+COUNTIFS($A$2:$A$201,$A10,$BA$2:$BA$201,1,$G$2:$G$201,G10,$AT$2:$AT$201,"<"&AT10)=0,1,0),0) | BC10: =IF(AND(BB10=1,G10<=Config!$B$6),V10,"") | BD10: =IF(AND(BB10=1,G10<=Config!$B$7),V10,"") | BE10: =IF(AND(BB10=1,G10<=Config!$B$8),V10,"") | BF10: =IF(AND(BB10=1,G10<=Config!$B$5),V10,"") | BG10: =IF(BW10=1,IF(COUNTIFS($A$2:$A$201,$A10,$BW$2:$BW$201,1,$G$2:$G$201,"<"&G10)+COUNTIFS($A$2:$A$201,$A10,$BW$2:$BW$201,1,$G$2:$G$201,G10,$AT$2:$AT$201,"<"&AT10)=0,1,0),0) | BH10: =IF(AND(AU10=1,ISNUMBER(K10)),1,0) | BI10: =IF(BH10=1,IF(COUNTIFS($A$2:$A$201,$A10,$BH$2:$BH$201,1,$G$2:$G$201,"<"&G10)+COUNTIFS($A$2:$A$201,$A10,$BH$2:$BH$201,1,$G$2:$G$201,G10,$AT$2:$AT$201,"<"&AT10)=0,1,0),0) | BJ10: =IF(AND(BI10=1,G10<=Config!$B$5),K10,"") | BK10: =IF(AND(AU10=1,OR(TRIM(U10)<>"",ISNUMBER(V10))),1,0) | BL10: =IF(BK10=1,IF(COUNTIFS($A$2:$A$201,$A10,$BK$2:$BK$201,1,$G$2:$G$201,"<"&G10)+COUNTIFS($A$2:$A$201,$A10,$BK$2:$BK$201,1,$G$2:$G$201,G10,$AT$2:$AT$201,"<"&AT10)=0,1,0),0) | BM10: =IF(BL10=1,$A10,"") | BN10: =IF(AND(AU10=1,T10="Y",TRIM(U10)=""),1,0) | BO10: =IF(AU10=1,AJ10&"","") | BP10: =IF(AU10=1,AK10&"","") | BQ10: =IF(AU10=1,AL10&"","") | BR10: =IF(AND(AU10=1,ISNUMBER(AP10),G10<=Config!$B$5),AP10,"") | BS10: =IF(AU10=1,IF(COUNTIFS($A$2:$A$201,$A10,$AN$2:$AN$201,"Y",$AU$2:$AU$201,1)>0,"Y","N"),"") | BT10: =IF(AND(AU10=1,AN10="maybe"),1,0) | BU10: =IF(BT10=1,IF(COUNTIFS($A$2:$A$201,$A10,$BT$2:$BT$201,1,$G$2:$G$201,"<"&G10)+COUNTIFS($A$2:$A$201,$A10,$BT$2:$BT$201,1,$G$2:$G$201,G10,$AT$2:$AT$201,"<"&AT10)=0,1,0),0) | BV10: =IF(AND(AU10=1,AN10="Y"),IF(COUNTIFS($A$2:$A$201,$A10,$AN$2:$AN$201,"Y",$AU$2:$AU$201,1,$G$2:$G$201,"<"&G10)+COUNTIFS($A$2:$A$201,$A10,$AN$2:$AN$201,"Y",$AU$2:$AU$201,1,$G$2:$G$201,G10,$AT$2:$AT$201,"<"&AT10)=0,1,0),0) | BW10: =IF(AND(BA10=1,N(V10)>=Config!$B$15),1,0) | BX10: =IF(AU10=1,IFERROR(MATCH($A10,INDEX(Clay_Offices!$A$2:$FZ$601,0,Sync!$C$5),0),""),"") | BY10: =IF(BX10="","",IFERROR(INDEX(Clay_Offices!$A$2:$FZ$601,BX10,Sync!$C$7)&"","")) | BZ10: =IF(BY10="","",IFERROR(INDEX(Lists!$J$2:$J$15,MATCH(BY10,Lists!$I$2:$I$15,0)),"")) | CA10: =IF(BX10="","",IFERROR(INDEX(Clay_Offices!$A$2:$FZ$601,BX10,Sync!$C$17)&"","")) | CB10: =IF(BX10="","",IFERROR(N(INDEX(Clay_Offices!$A$2:$FZ$601,BX10,Sync!$C$16)),0))
AS11: =IF(TRIM($A11)="","",IF(AND(LEFT($A11,6)="SAMPLE",Config!$B$19<>"Y"),"",IF(NOT(ISNUMBER(G11)),"call_date is blank or not a date",IF(Sync!$C$5="","Clay paste is empty or has no row_id column: paste the Clay export on Clay_Offices",IF(BX11="","row_id not found in the Clay paste: add the Clay row or fix the row_id",IF(AND(ISNUMBER(BZ11),BZ11>=1,BZ11<=5),"Clay status is "&BY11&": set call_done or later",IF(AND(AW11=1,CA11<>BS11),"Clay yes_in_principle should be "&BS11,IF(AND(AW11=1,CB11<>G11),"Clay call_date should be "&TEXT(G11,"yyyy-mm-dd"),"")))))))) | AT11: =ROW() | AU11: =IF(AND(TRIM($A11)<>"",ISNUMBER(G11)),IF(AND(LEFT($A11,6)="SAMPLE",Config!$B$19<>"Y"),0,1),0) | AV11: =IF(AU11=1,IF(COUNTIFS($A$2:$A$201,$A11,$AU$2:$AU$201,1,$G$2:$G$201,"<"&G11)+COUNTIFS($A$2:$A$201,$A11,$AU$2:$AU$201,1,$G$2:$G$201,G11,$AT$2:$AT$201,"<"&AT11)=0,1,0),0) | AW11: =IF(AU11=1,IF(COUNTIFS($A$2:$A$201,$A11,$AU$2:$AU$201,1,$G$2:$G$201,">"&G11)+COUNTIFS($A$2:$A$201,$A11,$AU$2:$AU$201,1,$G$2:$G$201,G11,$AT$2:$AT$201,">"&AT11)=0,1,0),0) | AX11: =IF(AND(AU11=1,AN11="Y",Z11="Y",TRIM(AD11)<>""),1,0) | AY11: =IF(AX11=1,IF(COUNTIFS($A$2:$A$201,$A11,$AX$2:$AX$201,1,$G$2:$G$201,"<"&G11)+COUNTIFS($A$2:$A$201,$A11,$AX$2:$AX$201,1,$G$2:$G$201,G11,$AT$2:$AT$201,"<"&AT11)=0,1,0),0) | AZ11: =IF(AND(AU11=1,AN11="Y",AX11=0),1,0) | BA11: =IF(AND(AU11=1,ISNUMBER(V11)),1,0) | BB11: =IF(BA11=1,IF(COUNTIFS($A$2:$A$201,$A11,$BA$2:$BA$201,1,$G$2:$G$201,"<"&G11)+COUNTIFS($A$2:$A$201,$A11,$BA$2:$BA$201,1,$G$2:$G$201,G11,$AT$2:$AT$201,"<"&AT11)=0,1,0),0) | BC11: =IF(AND(BB11=1,G11<=Config!$B$6),V11,"") | BD11: =IF(AND(BB11=1,G11<=Config!$B$7),V11,"") | BE11: =IF(AND(BB11=1,G11<=Config!$B$8),V11,"") | BF11: =IF(AND(BB11=1,G11<=Config!$B$5),V11,"") | BG11: =IF(BW11=1,IF(COUNTIFS($A$2:$A$201,$A11,$BW$2:$BW$201,1,$G$2:$G$201,"<"&G11)+COUNTIFS($A$2:$A$201,$A11,$BW$2:$BW$201,1,$G$2:$G$201,G11,$AT$2:$AT$201,"<"&AT11)=0,1,0),0) | BH11: =IF(AND(AU11=1,ISNUMBER(K11)),1,0) | BI11: =IF(BH11=1,IF(COUNTIFS($A$2:$A$201,$A11,$BH$2:$BH$201,1,$G$2:$G$201,"<"&G11)+COUNTIFS($A$2:$A$201,$A11,$BH$2:$BH$201,1,$G$2:$G$201,G11,$AT$2:$AT$201,"<"&AT11)=0,1,0),0) | BJ11: =IF(AND(BI11=1,G11<=Config!$B$5),K11,"") | BK11: =IF(AND(AU11=1,OR(TRIM(U11)<>"",ISNUMBER(V11))),1,0) | BL11: =IF(BK11=1,IF(COUNTIFS($A$2:$A$201,$A11,$BK$2:$BK$201,1,$G$2:$G$201,"<"&G11)+COUNTIFS($A$2:$A$201,$A11,$BK$2:$BK$201,1,$G$2:$G$201,G11,$AT$2:$AT$201,"<"&AT11)=0,1,0),0) | BM11: =IF(BL11=1,$A11,"") | BN11: =IF(AND(AU11=1,T11="Y",TRIM(U11)=""),1,0) | BO11: =IF(AU11=1,AJ11&"","") | BP11: =IF(AU11=1,AK11&"","") | BQ11: =IF(AU11=1,AL11&"","") | BR11: =IF(AND(AU11=1,ISNUMBER(AP11),G11<=Config!$B$5),AP11,"") | BS11: =IF(AU11=1,IF(COUNTIFS($A$2:$A$201,$A11,$AN$2:$AN$201,"Y",$AU$2:$AU$201,1)>0,"Y","N"),"") | BT11: =IF(AND(AU11=1,AN11="maybe"),1,0) | BU11: =IF(BT11=1,IF(COUNTIFS($A$2:$A$201,$A11,$BT$2:$BT$201,1,$G$2:$G$201,"<"&G11)+COUNTIFS($A$2:$A$201,$A11,$BT$2:$BT$201,1,$G$2:$G$201,G11,$AT$2:$AT$201,"<"&AT11)=0,1,0),0) | BV11: =IF(AND(AU11=1,AN11="Y"),IF(COUNTIFS($A$2:$A$201,$A11,$AN$2:$AN$201,"Y",$AU$2:$AU$201,1,$G$2:$G$201,"<"&G11)+COUNTIFS($A$2:$A$201,$A11,$AN$2:$AN$201,"Y",$AU$2:$AU$201,1,$G$2:$G$201,G11,$AT$2:$AT$201,"<"&AT11)=0,1,0),0) | BW11: =IF(AND(BA11=1,N(V11)>=Config!$B$15),1,0) | BX11: =IF(AU11=1,IFERROR(MATCH($A11,INDEX(Clay_Offices!$A$2:$FZ$601,0,Sync!$C$5),0),""),"") | BY11: =IF(BX11="","",IFERROR(INDEX(Clay_Offices!$A$2:$FZ$601,BX11,Sync!$C$7)&"","")) | BZ11: =IF(BY11="","",IFERROR(INDEX(Lists!$J$2:$J$15,MATCH(BY11,Lists!$I$2:$I$15,0)),"")) | CA11: =IF(BX11="","",IFERROR(INDEX(Clay_Offices!$A$2:$FZ$601,BX11,Sync!$C$17)&"","")) | CB11: =IF(BX11="","",IFERROR(N(INDEX(Clay_Offices!$A$2:$FZ$601,BX11,Sync!$C$16)),0))
AS12: =IF(TRIM($A12)="","",IF(AND(LEFT($A12,6)="SAMPLE",Config!$B$19<>"Y"),"",IF(NOT(ISNUMBER(G12)),"call_date is blank or not a date",IF(Sync!$C$5="","Clay paste is empty or has no row_id column: paste the Clay export on Clay_Offices",IF(BX12="","row_id not found in the Clay paste: add the Clay row or fix the row_id",IF(AND(ISNUMBER(BZ12),BZ12>=1,BZ12<=5),"Clay status is "&BY12&": set call_done or later",IF(AND(AW12=1,CA12<>BS12),"Clay yes_in_principle should be "&BS12,IF(AND(AW12=1,CB12<>G12),"Clay call_date should be "&TEXT(G12,"yyyy-mm-dd"),"")))))))) | AT12: =ROW() | AU12: =IF(AND(TRIM($A12)<>"",ISNUMBER(G12)),IF(AND(LEFT($A12,6)="SAMPLE",Config!$B$19<>"Y"),0,1),0) | AV12: =IF(AU12=1,IF(COUNTIFS($A$2:$A$201,$A12,$AU$2:$AU$201,1,$G$2:$G$201,"<"&G12)+COUNTIFS($A$2:$A$201,$A12,$AU$2:$AU$201,1,$G$2:$G$201,G12,$AT$2:$AT$201,"<"&AT12)=0,1,0),0) | AW12: =IF(AU12=1,IF(COUNTIFS($A$2:$A$201,$A12,$AU$2:$AU$201,1,$G$2:$G$201,">"&G12)+COUNTIFS($A$2:$A$201,$A12,$AU$2:$AU$201,1,$G$2:$G$201,G12,$AT$2:$AT$201,">"&AT12)=0,1,0),0) | AX12: =IF(AND(AU12=1,AN12="Y",Z12="Y",TRIM(AD12)<>""),1,0) | AY12: =IF(AX12=1,IF(COUNTIFS($A$2:$A$201,$A12,$AX$2:$AX$201,1,$G$2:$G$201,"<"&G12)+COUNTIFS($A$2:$A$201,$A12,$AX$2:$AX$201,1,$G$2:$G$201,G12,$AT$2:$AT$201,"<"&AT12)=0,1,0),0) | AZ12: =IF(AND(AU12=1,AN12="Y",AX12=0),1,0) | BA12: =IF(AND(AU12=1,ISNUMBER(V12)),1,0) | BB12: =IF(BA12=1,IF(COUNTIFS($A$2:$A$201,$A12,$BA$2:$BA$201,1,$G$2:$G$201,"<"&G12)+COUNTIFS($A$2:$A$201,$A12,$BA$2:$BA$201,1,$G$2:$G$201,G12,$AT$2:$AT$201,"<"&AT12)=0,1,0),0) | BC12: =IF(AND(BB12=1,G12<=Config!$B$6),V12,"") | BD12: =IF(AND(BB12=1,G12<=Config!$B$7),V12,"") | BE12: =IF(AND(BB12=1,G12<=Config!$B$8),V12,"") | BF12: =IF(AND(BB12=1,G12<=Config!$B$5),V12,"") | BG12: =IF(BW12=1,IF(COUNTIFS($A$2:$A$201,$A12,$BW$2:$BW$201,1,$G$2:$G$201,"<"&G12)+COUNTIFS($A$2:$A$201,$A12,$BW$2:$BW$201,1,$G$2:$G$201,G12,$AT$2:$AT$201,"<"&AT12)=0,1,0),0) | BH12: =IF(AND(AU12=1,ISNUMBER(K12)),1,0) | BI12: =IF(BH12=1,IF(COUNTIFS($A$2:$A$201,$A12,$BH$2:$BH$201,1,$G$2:$G$201,"<"&G12)+COUNTIFS($A$2:$A$201,$A12,$BH$2:$BH$201,1,$G$2:$G$201,G12,$AT$2:$AT$201,"<"&AT12)=0,1,0),0) | BJ12: =IF(AND(BI12=1,G12<=Config!$B$5),K12,"") | BK12: =IF(AND(AU12=1,OR(TRIM(U12)<>"",ISNUMBER(V12))),1,0) | BL12: =IF(BK12=1,IF(COUNTIFS($A$2:$A$201,$A12,$BK$2:$BK$201,1,$G$2:$G$201,"<"&G12)+COUNTIFS($A$2:$A$201,$A12,$BK$2:$BK$201,1,$G$2:$G$201,G12,$AT$2:$AT$201,"<"&AT12)=0,1,0),0) | BM12: =IF(BL12=1,$A12,"") | BN12: =IF(AND(AU12=1,T12="Y",TRIM(U12)=""),1,0) | BO12: =IF(AU12=1,AJ12&"","") | BP12: =IF(AU12=1,AK12&"","") | BQ12: =IF(AU12=1,AL12&"","") | BR12: =IF(AND(AU12=1,ISNUMBER(AP12),G12<=Config!$B$5),AP12,"") | BS12: =IF(AU12=1,IF(COUNTIFS($A$2:$A$201,$A12,$AN$2:$AN$201,"Y",$AU$2:$AU$201,1)>0,"Y","N"),"") | BT12: =IF(AND(AU12=1,AN12="maybe"),1,0) | BU12: =IF(BT12=1,IF(COUNTIFS($A$2:$A$201,$A12,$BT$2:$BT$201,1,$G$2:$G$201,"<"&G12)+COUNTIFS($A$2:$A$201,$A12,$BT$2:$BT$201,1,$G$2:$G$201,G12,$AT$2:$AT$201,"<"&AT12)=0,1,0),0) | BV12: =IF(AND(AU12=1,AN12="Y"),IF(COUNTIFS($A$2:$A$201,$A12,$AN$2:$AN$201,"Y",$AU$2:$AU$201,1,$G$2:$G$201,"<"&G12)+COUNTIFS($A$2:$A$201,$A12,$AN$2:$AN$201,"Y",$AU$2:$AU$201,1,$G$2:$G$201,G12,$AT$2:$AT$201,"<"&AT12)=0,1,0),0) | BW12: =IF(AND(BA12=1,N(V12)>=Config!$B$15),1,0) | BX12: =IF(AU12=1,IFERROR(MATCH($A12,INDEX(Clay_Offices!$A$2:$FZ$601,0,Sync!$C$5),0),""),"") | BY12: =IF(BX12="","",IFERROR(INDEX(Clay_Offices!$A$2:$FZ$601,BX12,Sync!$C$7)&"","")) | BZ12: =IF(BY12="","",IFERROR(INDEX(Lists!$J$2:$J$15,MATCH(BY12,Lists!$I$2:$I$15,0)),"")) | CA12: =IF(BX12="","",IFERROR(INDEX(Clay_Offices!$A$2:$FZ$601,BX12,Sync!$C$17)&"","")) | CB12: =IF(BX12="","",IFERROR(N(INDEX(Clay_Offices!$A$2:$FZ$601,BX12,Sync!$C$16)),0))
