Workbook

Sheet README
A1: =Inputs!$C$8&" financial model v1: README"
A2: Version 1, built 2026-10-23. The company name lives in one cell (Inputs, section 1, 'Company name'); rename it there only.
A5: What this workbook is
A6: The workbook you open every week for six months to see whether the business is working. It answers three questions: what each drop earns per founder hour, how low cumulative cash goes and when, and which gate or decision scenario the real numbers point to.
A7: Every number is a planning estimate from plan.md, never a forecast. Every assumption sits in one labeled cell on Inputs with its unit and source. Every other number is a formula. Change one input and every output moves.
A9: Your weekly routine (about ten minutes)
A10: 1. Log hours | B10: Add the week's hours on Hours_Log (one row per entry: date, drop_id or blank, activity key, hours). If you use a paid Toggl plan, paste its export on Toggl_Import instead.
A11: 2. Log the pipeline | B11: Paste or type outreach events on Pipeline: conversations, yeses, signed offices with Tuesday headcount, paid brands, budget-probe answers, renewal answers.
A12: 3. After each drop | B12: Paste the campaign actuals and drop costs from the operations exports into Actuals_Campaigns and Actuals_DropCosts, then set 'Actuals in' to Y for that drop on Schedule.
A13: 4. Read the Dashboard | B13: Gates show pass, miss or not yet against real numbers only. The headline shows the next drop's contribution per hour, the lowest point of cash and the gap to the plan's $6,510.
A14: 5. Keep the plan current | B14: Edit Schedule when a date, delivery model or brand count changes. Edit Inputs when a quote comes in. The 'Changed?' column records every edit against the plan default.
A16: Change the price and read the result in under a minute
A17: Whole model | B17: Inputs, section 3, 'Standard price per office' (now $150). Type a new number. Read Dashboard: 'Its contribution per founder hour' and the drop table at the bottom.
A18: One drop only | B18: Calculator: type a price in 'Standard price per office'. The result column shows revenue, costs, hours and contribution per founder hour. Nothing else changes.
A19: Many prices at once | B19: Sensitivity, Table 1: contribution per founder hour for eight prices and one to five brands. Green cells clear the $50 Gate 3 target.
A21: Tabs, in the order you use them
A22: Dashboard | B22: Headline numbers, every gate threshold beside its live value with pass, miss or not yet, the decision rule, the scenario the numbers point to, six-month goals, and contribution per hour on each drop.
A23: Inputs | B23: Every assumption: prices, payment terms and lags, the processing toggle, units, every hard-cost line, monthly overhead, hours by activity, the delivery-model table, renewal, gates, startup outlays with timing, the start date. Yellow cells are inputs.
A24: Scenarios | B24: The plan's decision situations A to D as assumption sets, beside the plan base. Pick one on Inputs. It drives the two decision-window drops and the steady state.
A25: Schedule | B25: The editable drop schedule: date, delivery model, tier, offices, new offices, brands, renewals, and the switch to actuals. Checks Tuesday or Wednesday and every blackout.
A26: Calculator | B26: A single drop of any tier, brand count, office count and delivery model, run through the same engine.
A27: Drop_PnL | B27: Per-drop P&L on the plan basis for every scheduled drop, with hours by activity, contribution per founder hour, cash timing on the plan's terms, and live values (actual where in).
A28: Cash_Flow | B28: Weekly cash flow for 26 weeks with a monthly cross-check: brand receipts, direct costs, overhead paid once, startup outlays at their timing, cumulative cash and its lowest point.
A29: Steady_State | B29: The plan's monthly picture reproduced, the scenario in force at steady state, and break-even: campaigns to recover startup cash, campaigns a month to cover overhead, the brand count and price where contribution per hour crosses $50.
A30: Sensitivity | B30: Four plain-formula tables: price x brands, renewal x brands, renewal against the monthly steady state, price against the monthly steady state. Direction checks at the bottom.
A31: Plan_Check | B31: The plan's five scenario rows, the $1,000 reading, edge cases, the founder-hour table cell by cell, and a reconciliation of every plan figure: plan, model, difference, reason.
A32: Capital | B32: The plan's capital table line by line, where the model pays each line, and the cash the plan's table leaves out.
A33: Hours_Log | B33: The hand-filled hours log by the seven activity keys, with totals per drop and per week.
... A40: Lists | B40: Fixed keys (delivery model, tier, activities, events), federal holidays and blackouts. Add holidays or blackouts in the blank yellow rows.
A42: Colours and conventions
A43: Yellow cell, blue text | B43: An input. Type here.
A44: Grey cell | B44: Calculated on the Inputs tab. Do not type over it.
A45: Green cell | B45: A key output.
A46: Formulas | B46: No numeric literal other than 0 or 1 appears in any formula; conversions such as days per week sit in input cells. _work/audit_formulas.py checks this.
A47: Signs | B47: Cash outflows are negative on Cash_Flow. Costs are positive on the P&L tabs.
A48: Dates | B48: YYYY-MM-DD. Week 1 starts Monday 2026-10-26 (CONTRACTS section 3).
A50: Plan readings (each verified by Plan_Check; none is a fudge)
A51: (a) Display kit | B51: $8 per office per drop, not per brand. Only this reproduces the scenario hard costs: a three-brand courier drop is $80 + $300 + $75 + $30 + $50 + $135 = $670. Per brand it would be $830.
A52: (b) Campaign zero | B52: Reproduces with storage at $0 (sealed cases at home), transport $120 and processing at 3%: $40 + $120 + $0 + $30 + $50 + $36 = $276, which the plan rounds to $280. Contribution is $924 against the plan's $920, and $16.2 per hour.
A53: (c) Direct-ship row | B53: The three-brand direct-ship row ($370) keeps the $75 storage allocation and $0 transport.
...

Sheet Dashboard
A1: =Inputs!$C$8&" financial model v1"
A2: =Inputs!$C$9
A3: Planning estimates, not a forecast. Gates count real numbers only (pipeline log and actuals). Change assumptions on Inputs; type real numbers into the logs.
B5: As of | C5: =Inputs!$C$17 | D5: Scenario in force | E5: =Inputs!$C$29 | F5: Model checks | G5: =IF(Checks!$D$34=0,"all integrity checks pass",Checks!$D$34&" integrity check(s) failing")
A7: Headline
B8: Measure | C8: Value | D8: Detail
B9: Next scheduled drop | C9: =IFERROR(INDEX(Drop_PnL!$A$7:$A$18,MATCH(1,Drop_PnL!$BG$7:$BG$18,0)),"none scheduled") | D9: =IFERROR(TEXT(INDEX(Drop_PnL!$B$7:$B$18,MATCH(1,Drop_PnL!$BG$7:$BG$18,0)),"ddd yyyy-mm-dd")&", "&INDEX(Drop_PnL!$C$7:$C$18,MATCH(1,Drop_PnL!$BG$7:$BG$18,0))&", "&INDEX(Drop_PnL!$G$7:$G$18,MATCH(1,Drop_PnL!$BG$7:$BG$18,0))&" brand(s), "&INDEX(Drop_PnL!$E$7:$E$18,MATCH(1,Drop_PnL!$BG$7:$BG$18,0))&" offices","")
B10: Its contribution per founder hour (plan) | C10: =IFERROR(INDEX(Drop_PnL!$AK$7:$AK$18,MATCH(1,Drop_PnL!$BG$7:$BG$18,0)),"n/a") | D10: =IFERROR("revenue "&TEXT(INDEX(Drop_PnL!$S$7:$S$18,MATCH(1,Drop_PnL!$BG$7:$BG$18,0)),"$#,##0")&", "&TEXT(INDEX(Drop_PnL!$AI$7:$AI$18,MATCH(1,Drop_PnL!$BG$7:$BG$18,0)),"0")&" founder hours","")
B11: Standard runs to Gate 3: contribution per founder hour, plan | C11: =E38 | D11: ="actual: "&IF(F38="","not yet",TEXT(F38,"$#,##0.0"))&"; target "&TEXT(Inputs!$C$126,"$#,##0")
B12: Lowest point of cumulative cash (before founder cash) | C12: =Cash_Flow!$C$32 | D12: ="in week "&Cash_Flow!$C$33&", starting "&TEXT(Cash_Flow!$C$34,"ddd yyyy-mm-dd")
B13: Capital to commit: lowest point plus the reserve | C13: =Cash_Flow!$C$37 | D13: ="reserve "&TEXT(Inputs!$C$107,"$#,##0")&" (plan)"
B14: Plan capital figure (high end of the plan's table) | C14: =Capital!$D$14 | D14: ="low end "&TEXT(Capital!$C$14,"$#,##0")
B15: Gap to the plan capital figure (positive = headroom) | C15: =Cash_Flow!$C$39 | D15: =IF(C15>=0,"the plan figure covers the model need","the model needs more than the plan figure")
B16: Founder cash committed | C16: =Cash_Flow!$C$40 | D16: =IF(Inputs!$C$105="","set it on Inputs (plan question 7)",IF(Inputs!$C$105>=Cash_Flow!$C$37,"covers capital to commit","short of capital to commit by "&TEXT(Cash_Flow!$C$37-Inputs!$C$105,"$#,##0")))
B17: Overhead paid but not absorbed by drops, six months | C17: =Cash_Flow!$C$69 | D17: ="paid "&TEXT(Cash_Flow!$C$68,"$#,##0")&", allocated to drops "&TEXT(Cash_Flow!$C$67,"$#,##0")&": the ramp-up months carry overhead with few drops"
B18: Six months all-in: contribution after all overhead per founder hour | C18: =IF(SUMIFS(Drop_PnL!$BC$7:$BC$18,Drop_PnL!$B$7:$B$18,"<="&Cash_Flow!$AB$6)+Inputs!$C$90*Inputs!$C$91>0,(SUMIFS(Drop_PnL!$BD$7:$BD$18,Drop_PnL!$B$7:$B$18,"<="&Cash_Flow!$AB$6)-Cash_Flow!$C$69)/(SUMIFS(Drop_PnL!$BC$7:$BC$18,Drop_PnL!$B$7:$B$18,"<="&Cash_Flow!$AB$6)+Inputs!$C$90*Inputs!$C$91),"n/a") | D18: ="includes "&TEXT(Inputs!$C$90*Inputs!$C$91,"0")&" discovery hours; after one-time startup outlays: "&IF(SUMIFS(Drop_PnL!$BC$7:$BC$18,Drop_PnL!$B$7:$B$18,"<="&Cash_Flow!$AB$6)+Inputs!$C$90*Inputs!$C$91>0,TEXT((SUMIFS(Drop_PnL!$BD$7:$BD$18,Drop_PnL!$B$7:$B$18,"<="&Cash_Flow!$AB$6)-Cash_Flow!$C$69-Inputs!$Q$160)/(SUMIFS(Drop_PnL!$BC$7:$BC$18,Drop_PnL!$B$7:$B$18,"<="&Cash_Flow!$AB$6)+Inputs!$C$90*Inputs!$C$91),"$#,##0.0"),"n/a")&" per hour"
B19: Steady state, scenario in force: contribution per month | C19: =Steady_State!$D$26 | D19: ="per founder hour "&IF(ISNUMBER(Steady_State!$D$27),TEXT(Steady_State!$D$27,"$#,##0.0"),"n/a")&"; net of all overhead "&TEXT(Steady_State!$D$37,"$#,##0")&" a month"
B20: Office-fatigue warnings on Schedule | C20: =COUNTIF(Schedule!$W$7:$W$18,"some*") | D20: =IF(C20=0,"no office gets two drops within four weeks","drops where some offices get a second drop within four weeks (plan: one drop a month)")
B21: Schedule rows changed or added since the derived default | C21: =COUNTIF(Schedule!$X$7:$X$18,"changed") | D21: =IF(C21=0,"schedule is the derived default","edited by you")
B22: Inputs changed from plan defaults | C22: =Inputs!$C$162 | D22: =IF(Checks!$D$36=0,"plan figures reproduce","plan reproduction differs in "&Checks!$D$36&" check(s); expected after edits")
A24: Gate dashboard (live values are actuals only)
A25: Gate | B25: Test | C25: Review date | D25: Threshold | E25: Model assumes | F25: Live value | G25: Status | H25: If it fails (plan)
A26: Gate 0 | B26: Office conversations held (context) | C26: =Inputs!$C$11 | D26: =Inputs!$C$112 | F26: =Pipeline!$U$5 | G26: info
A27: Gate 0 | B27: Offices yes in principle, with owner and receiving window | C27: =Inputs!$C$11 | D27: =Inputs!$C$111 | F27: =Pipeline!$U$6 | G27: =IF(F27="",IF(Inputs!$C$17>C27,"miss","not yet"),IF(F27>=D27,"pass",IF(Inputs!$C$17>C27,"miss","not yet"))) | H27: Fewer than 5 offices: change the cluster or office size band, not the model.
A28: Gate 0 | B28: Brand conversations held (context) | C28: =Inputs!$C$11 | D28: =Inputs!$C$115 | F28: =Pipeline!$U$7 | G28: info
A29: Gate 0 | B29: Brands that would pay $500 or more and control the budget | C29: =Inputs!$C$11 | D29: =Inputs!$C$113 | F29: =Pipeline!$U$8 | G29: =IF(F29="",IF(Inputs!$C$17>C29,"miss","not yet"),IF(F29>=D29,"pass",IF(Inputs!$C$17>C29,"miss","not yet"))) | H29: Fewer than 3: test the office-paid version for three more weeks before deciding.
A30: Gate 1 | B30: Offices signed | C30: =Inputs!$C$12 | D30: =Inputs!$C$116 | E30: =Drop_PnL!E7 | F30: =Pipeline!$U$9 | G30: =IF(F30="",IF(Inputs!$C$17>C30,"miss","not yet"),IF(F30>=D30,"pass",IF(Inputs!$C$17>C30,"miss","not yet"))) | H30: Offices sign but no brand pays even $600: pivot to office-paid or stop. No free campaign.
A31: Gate 1 | B31: Combined Tuesday headcount of signed offices | C31: =Inputs!$C$12 | D31: =Inputs!$C$117 | F31: =Pipeline!$U$10 | G31: =IF(F31="",IF(Inputs!$C$17>C31,"miss","not yet"),IF(F31>=D31,"pass",IF(Inputs!$C$17>C31,"miss","not yet")))
A32: Gate 1 | B32: Brands paid in full | C32: =Inputs!$C$12 | D32: =Inputs!$C$118 | E32: =Drop_PnL!G7 | F32: =Pipeline!$U$11 | G32: =IF(F32="",IF(Inputs!$C$17>C32,"miss","not yet"),IF(F32>=D32,"pass",IF(Inputs!$C$17>C32,"miss","not yet"))) | H32: One paid brand is a soft pass: run it, make the second sale first.
A33: Gate 2 | B33: Units placed within one business day (share of delivered) | C33: =Inputs!$C$13 | D33: =Inputs!$C$120 | F33: =IFERROR(INDEX(Drop_Actuals!$AG$7:$AG$18,MATCH(Inputs!$C$119,Drop_Actuals!$A$7:$A$18,0)),"") | G33: =IF(F33="",IF(Inputs!$C$17>C33,"miss","not yet"),IF(F33>=D33,"pass",IF(Inputs!$C$17>C33,"miss","not yet"))) | H33: Fix the procedure once (card, handoff, Slack post). A second miss is a stop signal.
A34: Gate 2 | B34: Brand campaigns under 5 survey responses per office (must be 0) | C34: =Inputs!$C$13 | D34: 0 | F34: =IF(N(IFERROR(INDEX(Drop_Actuals!$AF$7:$AF$18,MATCH(Inputs!$C$119,Drop_Actuals!$A$7:$A$18,0)),""))=0,"",IFERROR(INDEX(Drop_Actuals!$AH$7:$AH$18,MATCH(Inputs!$C$119,Drop_Actuals!$A$7:$A$18,0)),"")) | G34: =IF(F34="",IF(Inputs!$C$17>C34,"miss","not yet"),IF(F34<=D34,"pass",IF(Inputs!$C$17>C34,"miss","not yet")))
A35: Gate 2 | B35: Reports late (after T+7) or missing (must be 0) | C35: =Inputs!$C$13 | D35: 0 | F35: =IF(N(IFERROR(INDEX(Drop_Actuals!$AF$7:$AF$18,MATCH(Inputs!$C$119,Drop_Actuals!$A$7:$A$18,0)),""))=0,"",IFERROR(INDEX(Drop_Actuals!$AI$7:$AI$18,MATCH(Inputs!$C$119,Drop_Actuals!$A$7:$A$18,0)),"")) | G35: =IF(F35="",IF(Inputs!$C$17>C35,"miss","not yet"),IF(F35<=D35,"pass",IF(Inputs!$C$17>C35,"miss","not yet")))
A36: Gate 2 | B36: Brands that would buy again | C36: =Inputs!$C$13 | D36: =Inputs!$C$123 | F36: =IF(N(IFERROR(INDEX(Drop_Actuals!$AF$7:$AF$18,MATCH(Inputs!$C$119,Drop_Actuals!$A$7:$A$18,0)),""))=0,"",IFERROR(INDEX(Drop_Actuals!$AJ$7:$AJ$18,MATCH(Inputs!$C$119,Drop_Actuals!$A$7:$A$18,0)),"")) | G36: =IF(F36="",IF(Inputs!$C$17>C36,"miss","not yet"),IF(F36>=D36,"pass",IF(Inputs!$C$17>C36,"miss","not yet")))
A37: Gate 3 | B37: Renewals at $1,500 or more, signed by the review date | C37: =Inputs!$C$14 | D37: =Inputs!$C$124 | E37: =SUMIFS(Drop_PnL!$H$7:$H$18,Drop_PnL!$AQ$7:$AQ$18,"<="&Inputs!$C$14)-SUMIFS(Drop_PnL!$I$7:$I$18,Drop_PnL!$AQ$7:$AQ$18,"<="&Inputs!$C$14) | F37: =Pipeline!$U$12 | G37: =IF(F37="",IF(Inputs!$C$17>C37,"miss","not yet"),IF(F37>=D37,"pass",IF(Inputs!$C$17>C37,"miss","not yet"))) | H37: No renewal: redesign the evidence (velocity, redemptions), run one more drop. A second miss is a stop.
A38: Gate 3 | B38: Contribution per founder hour, standard runs | C38: =Inputs!$C$14 | D38: =Inputs!$C$126 | E38: =IF(SUMIFS(Drop_PnL!$AI$7:$AI$18,Drop_PnL!$D$7:$D$18,"standard",Drop_PnL!$B$7:$B$18,"<="&Inputs!$C$14)>0,SUMIFS(Drop_PnL!$AJ$7:$AJ$18,Drop_PnL!$D$7:$D$18,"standard",Drop_PnL!$B$7:$B$18,"<="&Inputs!$C$14)/SUMIFS(Drop_PnL!$AI$7:$AI$18,Drop_PnL!$D$7:$D$18,"standard",Drop_PnL!$B$7:$B$18,"<="&Inputs!$C$14),"") | F38: =IF(SUMIFS(Drop_Actuals!$R$7:$R$18,Drop_PnL!$D$7:$D$18,"standard",Drop_PnL!$B$7:$B$18,"<="&Inputs!$C$14,Drop_PnL!$AZ$7:$AZ$18,"Y")>0,SUMIFS(Drop_Actuals!$S$7:$S$18,Drop_PnL!$D$7:$D$18,"standard",Drop_PnL!$B$7:$B$18,"<="&Inputs!$C$14,Drop_PnL!$AZ$7:$AZ$18,"Y")/SUMIFS(Drop_Actuals!$R$7:$R$18,Drop_PnL!$D$7:$D$18,"standard",Drop_PnL!$B$7:$B$18,"<="&Inputs!$C$14,Drop_PnL!$AZ$7:$AZ$18,"Y"),"") | G38: =IF(F38="",IF(Inputs!$C$17>C38,"miss","not yet"),IF(F38>=D38,"pass",IF(Inputs!$C$17>C38,"miss","not yet")))
A40: Gate | B40: Review date | C40: Overall
A41: Gate 0 | B41: =C26 | C41: =IF(IF(G27="miss",1,0)+IF(G29="miss",1,0)>0,"miss",IF(IF(G27="not yet",1,0)+IF(G29="not yet",1,0)>0,"not yet","pass"))
A42: Gate 1 | B42: =C30 | C42: =IF(IF(G30="miss",1,0)+IF(G31="miss",1,0)+IF(G32="miss",1,0)>0,"miss",IF(IF(G30="not yet",1,0)+IF(G31="not yet",1,0)+IF(G32="not yet",1,0)>0,"not yet","pass"))
A43: Gate 2 | B43: =C33 | C43: =IF(IF(G33="miss",1,0)+IF(G34="miss",1,0)+IF(G35="miss",1,0)+IF(G36="miss",1,0)>0,"miss",IF(IF(G33="not yet",1,0)+IF(G34="not yet",1,0)+IF(G35="not yet",1,0)+IF(G36="not yet",1,0)>0,"not yet","pass"))
A44: Gate 3 | B44: =C37 | C44: =IF(IF(G37="miss",1,0)+IF(G38="miss",1,0)>0,"miss",IF(IF(G37="not yet",1,0)+IF(G38="not yet",1,0)>0,"not yet","pass"))
...

Sheet Inputs
A1: Inputs
A2: Every assumption in one labeled cell. Yellow cells are inputs. Grey cells are calculated; do not type over them.
A3: All defaults are planning estimates from plan.md, never forecasts. 'Plan default' keeps the original figure; 'Changed' flags any cell you edit.
A6: 1. Company and calendar
A7: key | B7: Assumption | C7: Value | D7: Unit | E7: Low | F7: High | G7: Status | H7: Source | I7: Notes | J7: Plan default | K7: Changed?
A8: company_name | B8: Company name (working name, not yet cleared) | C8: Desk Drop | D8: text | G8: working name | H8: Prompt; CONTRACTS s2 rename-ability | I8: The only cell that holds the company name. Rename here and every tab follows. | J8: Desk Drop | K8: =IF(C8&""=J8&"","","changed")
A9: tagline | B9: Tagline (working, may change) | C9: Emerging brands. Delivered to your workday. | D9: text | G9: working | H9: Prompt; CONTRACTS s2 | J9: Emerging brands. Delivered to your workday. | K9: =IF(C9&""=J9&"","","changed")
A10: week1_start | B10: Week 1 starts (Monday) | C10: 46321 | D10: date | G10: derived, founder to confirm | H10: CONTRACTS.md section 3 (canonical calendar) | I10: Week n starts on this date plus 7 x (n - 1) days. | J10: 46321 | K10: =IF(C10&""=J10&"","","changed")
A11: gate0_date | B11: Gate 0 review (end of week 3) | C11: 46339 | D11: date | G11: derived, founder to confirm | H11: CONTRACTS.md section 3 (canonical calendar) | J11: 46339 | K11: =IF(C11&""=J11&"","","changed")
A12: gate1_date | B12: Gate 1 review (end of week 7) | C12: 46367 | D12: date | G12: derived, founder to confirm | H12: CONTRACTS.md section 3 (canonical calendar) | J12: 46367 | K12: =IF(C12&""=J12&"","","changed")
A13: gate2_date | B13: Gate 2 review (campaign zero report, T+7) | C13: 46409 | D13: date | G13: derived, founder to confirm | H13: CONTRACTS.md section 3 (canonical calendar) | I13: Moved from the plan's week 9 because campaign zero moved to 2027-01-12 (December blackout collision). | J13: 46409 | K13: =IF(C13&""=J13&"","","changed")
A14: gate3_date | B14: Gate 3 review | C14: 46458 | D14: date | G14: derived, founder to confirm | H14: CONTRACTS.md section 3 (canonical calendar) | I14: Week 20; replaces the plan's week 16. | J14: 46458 | K14: =IF(C14&""=J14&"","","changed")
A15: decision_date | B15: Six-month decision (end of week 24) | C15: 46486 | D15: date | G15: derived, founder to confirm | H15: CONTRACTS.md section 3 (canonical calendar) | J15: 46486 | K15: =IF(C15&""=J15&"","","changed")
A16: as_of_override | B16: As-of date override (blank = today) | D16: date | G16: setting | H16: Model setting | I16: Leave blank to use today's date. Type a date to see gates and the next drop as of that day. | K16: =IF(C16&""=J16&"","","changed")
A17: as_of | B17: As-of date in use | C17: =IF(C16="",TODAY(),C16) | D17: date | G17: calculated | H17: Model
A18: days_per_week | B18: Days per week | C18: 7 | D18: days | G18: conversion | H18: Calendar | J18: 7 | K18: =IF(C18&""=J18&"","","changed")
A19: weeks_per_year | B19: Weeks per year | C19: 52 | D19: weeks | G19: conversion | H19: Calendar | J19: 52 | K19: =IF(C19&""=J19&"","","changed")
A20: months_per_year | B20: Months per year | C20: 12 | D20: months | G20: conversion | H20: Calendar | J20: 12 | K20: =IF(C20&""=J20&"","","changed")
A21: weeks_per_month | B21: Weeks per month | C21: =Inputs!$C$19/Inputs!$C$20 | D21: weeks | G21: calculated | H21: Weeks per year / months per year
A22: hours_per_day | B22: Hours per day (converts Toggl durations) | C22: 24 | D22: hours | G22: conversion | H22: Calendar | J22: 24 | K22: =IF(C22&""=J22&"","","changed")
A23: window_bd | B23: Campaign window | C23: 5 | D23: business days | G23: planning estimate | H23: plan.md, What brands buy: 'Five business days' | I23: T is day 1; the window closes at T+4. | J23: 5 | K23: =IF(C23&""=J23&"","","changed")
A24: drop_prefix | B24: Drop ID prefix | C24: DRP- | D24: text | G24: convention | H24: CONTRACTS s6.5 (DRP-###) | I24: Toggl projects named DRP-001 etc. map to drops. | J24: DRP- | K24: =IF(C24&""=J24&"","","changed")
A25: office_window_days | B25: An office should get at most one drop in this many days | C25: 28 | D25: days | G25: derived, founder to confirm | H25: plan.md, What has to be true #4: 'Offices accept one drop a month' | I25: Four weeks counts as monthly, so drops 28 days apart do not flag. Used for the office-fatigue warning on Schedule. | J25: 28 | K25: =IF(C25&""=J25&"","","changed")
A27: 2. Scenario in force
A28: key | B28: Assumption | C28: Value | D28: Unit | E28: Low | F28: High | G28: Status | H28: Source | I28: Notes | J28: Plan default | K28: Changed?
A29: active_scenario | B29: Scenario applied to drops after Gate 3 and to the steady state | C29: Plan base | D29: list | G29: setting | H29: plan.md, After the first standard runs: decision scenarios | I29: Plan base = the plan's 'What has to be true'. A to D = the plan's four decision situations. See the Scenarios tab. | J29: Plan base | K29: =IF(C29&""=J29&"","","changed")
A31: 3. Prices and payment terms
A32: key | B32: Assumption | C32: Value | D32: Unit | E32: Low | F32: High | G32: Status | H32: Source | I32: Notes | J32: Plan default | K32: Changed?
A33: price_std_office | B33: Standard price per office | C33: 150 | D33: USD per office | G33: planning estimate | H33: plan.md, Revised model: Price table | I33: $1,500 for 10 offices. Change this cell to test a price. | J33: 150 | K33: =IF(C33&""=J33&"","","changed")
A34: std_pkg_offices | B34: Standard package size | C34: 10 | D34: offices | G34: planning estimate | H34: plan.md, Revised model: Price table | J34: 10 | K34: =IF(C34&""=J34&"","","changed")
A35: std_pkg_price | B35: Standard package price | C35: =Inputs!$C$33*Inputs!$C$34 | D35: USD per brand | G35: calculated | H35: Price per office x package offices
A36: price_fnd_office | B36: Founding price per office | C36: 120 | D36: USD per office | E36: 120 | F36: 180 | G36: planning estimate | H36: plan.md, Revised model: Price table | I36: $600 for 5 offices. The plan's summary table once said $600 to $900; the decided price is $600 (low end shown as default). | J36: 120 | K36: =IF(C36&""=J36&"","","changed")
A37: fnd_pkg_offices | B37: Founding package size | C37: 5 | D37: offices | G37: planning estimate | H37: plan.md, Revised model: Price table | J37: 5 | K37: =IF(C37&""=J37&"","","changed")
A38: fnd_pkg_price | B38: Founding package price | C38: =Inputs!$C$36*Inputs!$C$37 | D38: USD per brand | G38: calculated | H38: Price per office x package offices
A39: extra_office_price | B39: Extra office beyond the package | C39: 150 | D39: USD per office | G39: planning estimate | H39: plan.md, Revised model: Price table | I39: Applies to offices beyond 5 (founding) or 10 (standard). Founding renewals stay at the founding rate per office for any office count. | J39: 150 | K39: =IF(C39&""=J39&"","","changed")
A40: founding_cap | B40: Founding tier closes after | C40: 3 | D40: brands | G40: planning estimate | H40: plan.md, Revised model: Price table | I40: 'First three brands only'. | J40: 3 | K40: =IF(C40&""=J40&"","","changed")
A41: founding_lock | B41: Founding price locked for | C41: 2 | D41: further campaigns | G41: planning estimate | H41: plan.md, Revised model: Price table | J41: 2 | K41: =IF(C41&""=J41&"","","changed")
A42: fnd_upfront_share | B42: Founding: share paid before product ships | C42: 1 | D42: share | G42: planning estimate | H42: plan.md, Revised model: Price table | I42: 'Paid in full before product ships'. | J42: 1 | K42: =IF(C42&""=J42&"","","changed")
A43: fnd_pay_lead_bd | B43: Founding: payment lands this many business days before the drop | C43: 20 | D43: business days | G43: derived, founder to confirm | H43: CONTRACTS.md section 3 (canonical calendar) | I43: Campaign zero's payment at Gate 1 (Fri 2026-12-11) is 20 business days before the Tue 2027-01-12 drop. | J43: 20 | K43: =IF(C43&""=J43&"","","changed")
A44: std_deposit_share | B44: Standard: share invoiced at signature | C44: 0.5 | D44: share | G44: planning estimate | H44: plan.md, Revised model: Price table | I44: 50% at signature, 50% at placement confirmation. | J44: 0.5 | K44: =IF(C44&""=J44&"","","changed")
...

Sheet Scenarios
A1: Scenarios A to D
A2: The plan's four decision situations as assumption sets. Pick one on Inputs ('Scenario in force'). The Active column feeds drops after Gate 3 and the steady state.
A3: Planning estimates. Where a scenario does not name a figure, it uses the plan base and says so. Nothing here is a forecast of which scenario will happen.
B5: Lever | C5: Plan base | D5: A | E5: B | F5: C | G5: D | H5: Active (in force) | I5: Unit | J5: Source and reading | L5: default: Plan base | M5: default: A | N5: default: B | O5: default: C | P5: default: D | Q5: Changed?
B6: Situation | C6: What has to be true | D6: Both sides work | E6: Brands pay once, offices love it | F6: Brands willing, offices unreliable | G6: Neither converts
B7: What the numbers show | C7: Three brands per drop, six hours or less per win, 40% renew, $1,500 holds | D7: 40% or more of brands renew; placement above 80%; contribution above $50 an hour | E7: Renewal under 30%; offices asking when the next drop is | F7: Placement under 80% twice; photos missing; responses under five | G7: No renewal, weak placement
B8: What to do next (plan) | C8: Run the plan | D8: Scale: second cluster, roster 20 to 30, price to $1,800 to $2,000, part-time delivery at about $25 an hour above two drops a month, launch-partner tier | E8: Fix the evidence, run two more drops; if renewal is still under 30%, switch to office-paid for offices that named $100 a month or more | F8: Replace the weakest offices, raise the commitment bar; if a third drop misses, stop | G8: Stop; write the post-mortem; keep office relationships warm
B10: Post-Gate-3 drops that run in the six months (of the two scheduled) | C10: 2 | D10: 2 | E10: 2 | F10: 1 | G10: 0 | H10: =INDEX(C10:G10,MATCH(Inputs!$C$29,$C$5:$G$5,0)) | I10: drops | J10: Base and A: two drops a month. B: 'run two more drops'. C: 'if a third drop misses, stop', so one more. D: 'Stop'. | L10: 2 | M10: 2 | N10: 2 | O10: 1 | P10: 0 | Q10: =IF(AND(C10&""=L10&"",D10&""=M10&"",E10&""=N10&"",F10&""=O10&"",G10&""=P10&""),"","changed")
B11: Brands per drop after Gate 3 | C11: 3 | D11: 3 | E11: 3 | F11: 3 | G11: 0 | H11: =INDEX(C11:G11,MATCH(Inputs!$C$29,$C$5:$G$5,0)) | I11: brands | J11: Plan: three brands per drop. D stops. | L11: 3 | M11: 3 | N11: 3 | O11: 3 | P11: 0 | Q11: =IF(AND(C11&""=L11&"",D11&""=M11&"",E11&""=N11&"",F11&""=O11&"",G11&""=P11&""),"","changed")
B12: Renewal rate (share of brand slots that are renewals) | C12: =Inputs!$C$101 | D12: 0.4 | E12: 0 | F12: =C12 | G12: 0 | H12: =INDEX(C12:G12,MATCH(Inputs!$C$29,$C$5:$G$5,0)) | I12: share | J12: A: '40% or more', low end. B: 'under 30%' and 'brands pay once': 0%, the low end of 0% to 29%. C: not named, plan base. D: 'No renewal'. | L12: =Inputs!$C$101 | M12: 0.4 | N12: 0 | O12: =C12 | P12: 0 | Q12: =IF(AND(C12&""=L12&"",D12&""=M12&"",E12&""=N12&"",F12&""=O12&"",G12&""=P12&""),"","changed")
B13: New offices recruited per post-Gate-3 drop | C13: 0 | D13: 0 | E13: 0 | G13: 0 | H13: =INDEX(C13:G13,MATCH(Inputs!$C$29,$C$5:$G$5,0)) | I13: offices | J13: C: 'replace the weakest offices'; the plan gives no count. Blank = 0; founder to set. | L13: 0 | M13: 0 | N13: 0 | P13: 0 | Q13: =IF(AND(C13&""=L13&"",D13&""=M13&"",E13&""=N13&"",F13&""=O13&"",G13&""=P13&""),"","changed")
B14: Standard price per office for drops after the decision date | C14: =Inputs!$C$33 | D14: 180 | E14: =Inputs!$C$33 | F14: =Inputs!$C$33 | G14: =Inputs!$C$33 | H14: =INDEX(C14:G14,MATCH(Inputs!$C$29,$C$5:$G$5,0)) | I14: USD per office | J14: A: 'raise the standard price to $1,800 to $2,000' = $180 to $200 per office; low end. | L14: =Inputs!$C$33 | M14: 180 | N14: =Inputs!$C$33 | O14: =Inputs!$C$33 | P14: =Inputs!$C$33 | Q14: =IF(AND(C14&""=L14&"",D14&""=M14&"",E14&""=N14&"",F14&""=O14&"",G14&""=P14&""),"","changed")
B15: Steady-state drops per month | C15: =Inputs!$C$102 | D15: 2 | E15: 2 | F15: 2 | G15: 0 | H15: =INDEX(C15:G15,MATCH(Inputs!$C$29,$C$5:$G$5,0)) | I15: drops per month | J15: Plan monthly picture: two drops a month. | L15: =Inputs!$C$102 | M15: 2 | N15: 2 | O15: 2 | P15: 0 | Q15: =IF(AND(C15&""=L15&"",D15&""=M15&"",E15&""=N15&"",F15&""=O15&"",G15&""=P15&""),"","changed")
B16: Steady-state brands per drop | C16: 3 | D16: 3 | E16: 3 | F16: 3 | G16: 0 | H16: =INDEX(C16:G16,MATCH(Inputs!$C$29,$C$5:$G$5,0)) | I16: brands | J16: Plan monthly picture: three-brand drops. | L16: 3 | M16: 3 | N16: 3 | O16: 3 | P16: 0 | Q16: =IF(AND(C16&""=L16&"",D16&""=M16&"",E16&""=N16&"",F16&""=O16&"",G16&""=P16&""),"","changed")
B17: Offices on an office-paid tier (steady state) | C17: 0 | D17: 0 | E17: 5 | F17: 0 | G17: 0 | H17: =INDEX(C17:G17,MATCH(Inputs!$C$29,$C$5:$G$5,0)) | I17: offices | J17: B: offices that named $100 a month or more; at least five. | L17: 0 | M17: 0 | N17: 5 | O17: 0 | P17: 0 | Q17: =IF(AND(C17&""=L17&"",D17&""=M17&"",E17&""=N17&"",F17&""=O17&"",G17&""=P17&""),"","changed")
B18: Office-paid fee per office per month | E18: 100 | H18: =INDEX(C18:G18,MATCH(Inputs!$C$29,$C$5:$G$5,0)) | I18: USD per month | J18: B: $100 to $200 a month; low end. | N18: 100 | Q18: =IF(AND(C18&""=L18&"",D18&""=M18&"",E18&""=N18&"",F18&""=O18&"",G18&""=P18&""),"","changed")
B19: Cost to serve one office-paid office per month | H19: =INDEX(C19:G19,MATCH(Inputs!$C$29,$C$5:$G$5,0)) | I19: USD per month | J19: Needs quote. The plan prices no cost for guaranteed twice-monthly curated drops. | Q19: =IF(AND(C19&""=L19&"",D19&""=M19&"",E19&""=N19&"",F19&""=O19&"",G19&""=P19&""),"","changed")
B20: Part-time delivery hire | C20: 25 | D20: 25 | H20: =INDEX(C20:G20,MATCH(Inputs!$C$29,$C$5:$G$5,0)) | I20: USD per hour | J20: A: 'about $25 an hour once you run more than two drops a month'. It replaces drop-day hours (model reading). | L20: 25 | M20: 25 | Q20: =IF(AND(C20&""=L20&"",D20&""=M20&"",E20&""=N20&"",F20&""=O20&"",G20&""=P20&""),"","changed")
B21: Hire once steady-state drops per month exceed | C21: 2 | D21: 2 | E21: 2 | F21: 2 | G21: 2 | H21: =INDEX(C21:G21,MATCH(Inputs!$C$29,$C$5:$G$5,0)) | I21: drops per month | J21: Plan: 'more than two drops a month'. | L21: 2 | M21: 2 | N21: 2 | O21: 2 | P21: 2 | Q21: =IF(AND(C21&""=L21&"",D21&""=M21&"",E21&""=N21&"",F21&""=O21&"",G21&""=P21&""),"","changed")
B23: How it works
B24: The two decision-window drops on Schedule (DRP-004, DRP-005) take brands, renewals and new offices from the Active column. Type over those Schedule cells to replace the scenario with real plans. The steady-state view and the sensitivity tables use the Active column too. Drops before Gate 3 do not change with the scenario.

Sheet Schedule
A1: Drop schedule
A2: One row per drop. Edit dates, delivery model, offices, brands and renewals. Rows marked derived are the simplest schedule that meets the plan; founder to confirm.
A3: Drop days are Tuesday or Wednesday only; no window may overlap a blackout (Lists). Set 'Actuals in' to Y once a drop's actuals are pasted, and the model switches that drop from plan to actual.
A4: Yellow = your input. Blue = follows the scenario in force (Scenarios tab); type over it to replace. Red 'changed' = the row no longer matches the derived default.
AA5: Derived defaults (for the 'Changed' flag; do not edit)
A6: drop_id | B6: Label | C6: Basis | D6: Post-Gate-3 sequence | E6: Drop date | F6: Day | G6: Delivery model | H6: Tier | I6: Offices | J6: New offices | K6: Brands | L6: of which renewals | M6: of which founding-rate renewals | N6: Actuals in (Y/N) | O6: Notes | P6: Tue or Wed? | Q6: Window closes (T+4) | R6: Blackout clash? | S6: Units brands ship (incl. reserve) | T6: Row check | U6: Office slots on drops in the last four weeks | V6: Roster to date (new offices so far) | W6: Office fatigue | X6: Changed from the derived default? | AA6: default date | AB6: default model | AC6: default tier | AD6: default offices | AE6: default new offices | AF6: default brands | AG6: default renewals | AH6: default founding renewals
A7: DRP-001 | B7: Campaign zero (founding) | C7: derived: CONTRACTS s3 | E7: 46399 | F7: =IF(E7="","",TEXT(E7,"ddd")) | G7: founder | H7: founding | I7: 5 | J7: 5 | K7: 2 | L7: 0 | M7: 0 | N7: N | O7: Stretch option Tue 2026-12-08 only if both brands pay by 2026-11-20. Brands asked to ship by 2026-12-22. | P7: =IF(E7="","",IF(OR(WEEKDAY(E7)=Lists!$V$4,WEEKDAY(E7)=Lists!$V$5),"ok","not Tue/Wed")) | Q7: =IF(E7="","",WORKDAY(E7,Inputs!$C$23-1,Lists!$N$4:$N$30)) | R7: =IF(E7="","",IF(COUNTIFS(Lists!$Q$4:$Q$12,"<="&Q7,Lists!$R$4:$R$12,">="&E7)>0,"clash","ok")) | S7: =IF(E7="","",N(K7)*N(I7)*Inputs!$C$53*(1+Inputs!$C$54)) | T7: =IF(E7="",IF(N(K7)>0,"date missing",""),IF(AND(P7="ok",R7="ok",N(J7)<=N(I7),N(L7)<=N(K7),N(M7)<=N(L7),OR(N(K7)=0,N(I7)>0),G7<>"",H7<>""),"ok","check")) | U7: =IF(OR(E7="",N(K7)=0),"",SUMIFS($I$7:$I$18,$E$7:$E$18,">"&E7-Inputs!$C$25,$E$7:$E$18,"<="&E7,$K$7:$K$18,">0")) | V7: =IF(E7="","",SUMIFS($J$7:$J$18,$E$7:$E$18,"<="&E7)) | W7: =IF(U7="","",IF(U7>V7,"some offices get a second drop within four weeks","ok")) | X7: =IF(AND(E7&""=AA7&"",G7&""=AB7&"",H7&""=AC7&"",I7&""=AD7&"",J7&""=AE7&"",K7&""=AF7&"",L7&""=AG7&"",M7&""=AH7&""),"","changed") | AA7: 46399 | AB7: founder | AC7: founding | AD7: 5 | AE7: 5 | AF7: 2 | AG7: 0 | AH7: 0
A8: DRP-002 | B8: Standard run 1 | C8: derived: CONTRACTS s3 | E8: 46427 | F8: =IF(E8="","",TEXT(E8,"ddd")) | G8: courier | H8: standard | I8: 10 | J8: 5 | K8: 3 | L8: 0 | M8: 0 | N8: N | O8: Campaigns one and two: founder plus courier (plan). Five new offices take the roster from 5 to 10. | P8: =IF(E8="","",IF(OR(WEEKDAY(E8)=Lists!$V$4,WEEKDAY(E8)=Lists!$V$5),"ok","not Tue/Wed")) | Q8: =IF(E8="","",WORKDAY(E8,Inputs!$C$23-1,Lists!$N$4:$N$30)) | R8: =IF(E8="","",IF(COUNTIFS(Lists!$Q$4:$Q$12,"<="&Q8,Lists!$R$4:$R$12,">="&E8)>0,"clash","ok")) | S8: =IF(E8="","",N(K8)*N(I8)*Inputs!$C$53*(1+Inputs!$C$54)) | T8: =IF(E8="",IF(N(K8)>0,"date missing",""),IF(AND(P8="ok",R8="ok",N(J8)<=N(I8),N(L8)<=N(K8),N(M8)<=N(L8),OR(N(K8)=0,N(I8)>0),G8<>"",H8<>""),"ok","check")) | U8: =IF(OR(E8="",N(K8)=0),"",SUMIFS($I$7:$I$18,$E$7:$E$18,">"&E8-Inputs!$C$25,$E$7:$E$18,"<="&E8,$K$7:$K$18,">0")) | V8: =IF(E8="","",SUMIFS($J$7:$J$18,$E$7:$E$18,"<="&E8)) | W8: =IF(U8="","",IF(U8>V8,"some offices get a second drop within four weeks","ok")) | X8: =IF(AND(E8&""=AA8&"",G8&""=AB8&"",H8&""=AC8&"",I8&""=AD8&"",J8&""=AE8&"",K8&""=AF8&"",L8&""=AG8&"",M8&""=AH8&""),"","changed") | AA8: 46427 | AB8: courier | AC8: standard | AD8: 10 | AE8: 5 | AF8: 3 | AG8: 0 | AH8: 0
A9: DRP-003 | B9: Standard run 2 | C9: derived: CONTRACTS s3 | E9: 46441 | F9: =IF(E9="","",TEXT(E9,"ddd")) | G9: courier | H9: standard | I9: 10 | J9: 2 | K9: 3 | L9: 0 | M9: 0 | N9: N | O9: Two new offices reach the six-month goal of 12 active offices. Two weeks after run 1, so most offices get two drops in February. | P9: =IF(E9="","",IF(OR(WEEKDAY(E9)=Lists!$V$4,WEEKDAY(E9)=Lists!$V$5),"ok","not Tue/Wed")) | Q9: =IF(E9="","",WORKDAY(E9,Inputs!$C$23-1,Lists!$N$4:$N$30)) | R9: =IF(E9="","",IF(COUNTIFS(Lists!$Q$4:$Q$12,"<="&Q9,Lists!$R$4:$R$12,">="&E9)>0,"clash","ok")) | S9: =IF(E9="","",N(K9)*N(I9)*Inputs!$C$53*(1+Inputs!$C$54)) | T9: =IF(E9="",IF(N(K9)>0,"date missing",""),IF(AND(P9="ok",R9="ok",N(J9)<=N(I9),N(L9)<=N(K9),N(M9)<=N(L9),OR(N(K9)=0,N(I9)>0),G9<>"",H9<>""),"ok","check")) | U9: =IF(OR(E9="",N(K9)=0),"",SUMIFS($I$7:$I$18,$E$7:$E$18,">"&E9-Inputs!$C$25,$E$7:$E$18,"<="&E9,$K$7:$K$18,">0")) | V9: =IF(E9="","",SUMIFS($J$7:$J$18,$E$7:$E$18,"<="&E9)) | W9: =IF(U9="","",IF(U9>V9,"some offices get a second drop within four weeks","ok")) | X9: =IF(AND(E9&""=AA9&"",G9&""=AB9&"",H9&""=AC9&"",I9&""=AD9&"",J9&""=AE9&"",K9&""=AF9&"",L9&""=AG9&"",M9&""=AH9&""),"","changed") | AA9: 46441 | AB9: courier | AC9: standard | AD9: 10 | AE9: 2 | AF9: 3 | AG9: 0 | AH9: 0
A10: DRP-004 | B10: Decision window drop 1 | C10: derived: scenario | D10: 1 | E10: 46469 | F10: =IF(E10="","",TEXT(E10,"ddd")) | G10: direct-ship | H10: standard | I10: 10 | J10: =IF(K10>0,N(Scenarios!$H$13),0) | K10: =IF(D10<=Scenarios!$H$10,Scenarios!$H$11,0) | L10: =ROUND(Scenarios!$H$12*K10,0) | M10: 0 | N10: N | O10: Campaign three onward: brands ship direct (plan). Brands, renewals and new offices follow the scenario in force. | P10: =IF(E10="","",IF(OR(WEEKDAY(E10)=Lists!$V$4,WEEKDAY(E10)=Lists!$V$5),"ok","not Tue/Wed")) | Q10: =IF(E10="","",WORKDAY(E10,Inputs!$C$23-1,Lists!$N$4:$N$30)) | R10: =IF(E10="","",IF(COUNTIFS(Lists!$Q$4:$Q$12,"<="&Q10,Lists!$R$4:$R$12,">="&E10)>0,"clash","ok")) | S10: =IF(E10="","",N(K10)*N(I10)*Inputs!$C$53*(1+Inputs!$C$54)) | T10: =IF(E10="",IF(N(K10)>0,"date missing",""),IF(AND(P10="ok",R10="ok",N(J10)<=N(I10),N(L10)<=N(K10),N(M10)<=N(L10),OR(N(K10)=0,N(I10)>0),G10<>"",H10<>""),"ok","check")) | U10: =IF(OR(E10="",N(K10)=0),"",SUMIFS($I$7:$I$18,$E$7:$E$18,">"&E10-Inputs!$C$25,$E$7:$E$18,"<="&E10,$K$7:$K$18,">0")) | V10: =IF(E10="","",SUMIFS($J$7:$J$18,$E$7:$E$18,"<="&E10)) | W10: =IF(U10="","",IF(U10>V10,"some offices get a second drop within four weeks","ok")) | X10: =IF(AND(E10&""=AA10&"",G10&""=AB10&"",H10&""=AC10&"",I10&""=AD10&"",J10&""=AE10&"",K10&""=AF10&"",L10&""=AG10&"",M10&""=AH10&""),"","changed") | AA10: 46469 | AB10: direct-ship | AC10: standard | AD10: 10 | AE10: =IF(K10>0,N(Scenarios!$H$13),0) | AF10: =IF(D10<=Scenarios!$H$10,Scenarios!$H$11,0) | AG10: =ROUND(Scenarios!$H$12*K10,0) | AH10: 0
A11: DRP-005 | B11: Decision window drop 2 | C11: derived: scenario | D11: 2 | E11: 46483 | F11: =IF(E11="","",TEXT(E11,"ddd")) | G11: direct-ship | H11: standard | I11: 10 | J11: =IF(K11>0,N(Scenarios!$H$13),0) | K11: =IF(D11<=Scenarios!$H$10,Scenarios!$H$11,0) | L11: =ROUND(Scenarios!$H$12*K11,0) | M11: 0 | N11: N | O11: Second extra drop before the decision (scenario B's 'two more drops'; two drops a month in the base). | P11: =IF(E11="","",IF(OR(WEEKDAY(E11)=Lists!$V$4,WEEKDAY(E11)=Lists!$V$5),"ok","not Tue/Wed")) | Q11: =IF(E11="","",WORKDAY(E11,Inputs!$C$23-1,Lists!$N$4:$N$30)) | R11: =IF(E11="","",IF(COUNTIFS(Lists!$Q$4:$Q$12,"<="&Q11,Lists!$R$4:$R$12,">="&E11)>0,"clash","ok")) | S11: =IF(E11="","",N(K11)*N(I11)*Inputs!$C$53*(1+Inputs!$C$54)) | T11: =IF(E11="",IF(N(K11)>0,"date missing",""),IF(AND(P11="ok",R11="ok",N(J11)<=N(I11),N(L11)<=N(K11),N(M11)<=N(L11),OR(N(K11)=0,N(I11)>0),G11<>"",H11<>""),"ok","check")) | U11: =IF(OR(E11="",N(K11)=0),"",SUMIFS($I$7:$I$18,$E$7:$E$18,">"&E11-Inputs!$C$25,$E$7:$E$18,"<="&E11,$K$7:$K$18,">0")) | V11: =IF(E11="","",SUMIFS($J$7:$J$18,$E$7:$E$18,"<="&E11)) | W11: =IF(U11="","",IF(U11>V11,"some offices get a second drop within four weeks","ok")) | X11: =IF(AND(E11&""=AA11&"",G11&""=AB11&"",H11&""=AC11&"",I11&""=AD11&"",J11&""=AE11&"",K11&""=AF11&"",L11&""=AG11&"",M11&""=AH11&""),"","changed") | AA11: 46483 | AB11: direct-ship | AC11: standard | AD11: 10 | AE11: =IF(K11>0,N(Scenarios!$H$13),0) | AF11: =IF(D11<=Scenarios!$H$10,Scenarios!$H$11,0) | AG11: =ROUND(Scenarios!$H$12*K11,0) | AH11: 0
A12: DRP-006 | C12: founder entry | F12: =IF(E12="","",TEXT(E12,"ddd")) | N12: N | P12: =IF(E12="","",IF(OR(WEEKDAY(E12)=Lists!$V$4,WEEKDAY(E12)=Lists!$V$5),"ok","not Tue/Wed")) | Q12: =IF(E12="","",WORKDAY(E12,Inputs!$C$23-1,Lists!$N$4:$N$30)) | R12: =IF(E12="","",IF(COUNTIFS(Lists!$Q$4:$Q$12,"<="&Q12,Lists!$R$4:$R$12,">="&E12)>0,"clash","ok")) | S12: =IF(E12="","",N(K12)*N(I12)*Inputs!$C$53*(1+Inputs!$C$54)) | T12: =IF(E12="",IF(N(K12)>0,"date missing",""),IF(AND(P12="ok",R12="ok",N(J12)<=N(I12),N(L12)<=N(K12),N(M12)<=N(L12),OR(N(K12)=0,N(I12)>0),G12<>"",H12<>""),"ok","check")) | U12: =IF(OR(E12="",N(K12)=0),"",SUMIFS($I$7:$I$18,$E$7:$E$18,">"&E12-Inputs!$C$25,$E$7:$E$18,"<="&E12,$K$7:$K$18,">0")) | V12: =IF(E12="","",SUMIFS($J$7:$J$18,$E$7:$E$18,"<="&E12)) | W12: =IF(U12="","",IF(U12>V12,"some offices get a second drop within four weeks","ok")) | X12: =IF(AND(E12&""=AA12&"",G12&""=AB12&"",H12&""=AC12&"",I12&""=AD12&"",J12&""=AE12&"",K12&""=AF12&"",L12&""=AG12&"",M12&""=AH12&""),"","changed")
A13: DRP-007 | C13: founder entry | F13: =IF(E13="","",TEXT(E13,"ddd")) | N13: N | P13: =IF(E13="","",IF(OR(WEEKDAY(E13)=Lists!$V$4,WEEKDAY(E13)=Lists!$V$5),"ok","not Tue/Wed")) | Q13: =IF(E13="","",WORKDAY(E13,Inputs!$C$23-1,Lists!$N$4:$N$30)) | R13: =IF(E13="","",IF(COUNTIFS(Lists!$Q$4:$Q$12,"<="&Q13,Lists!$R$4:$R$12,">="&E13)>0,"clash","ok")) | S13: =IF(E13="","",N(K13)*N(I13)*Inputs!$C$53*(1+Inputs!$C$54)) | T13: =IF(E13="",IF(N(K13)>0,"date missing",""),IF(AND(P13="ok",R13="ok",N(J13)<=N(I13),N(L13)<=N(K13),N(M13)<=N(L13),OR(N(K13)=0,N(I13)>0),G13<>"",H13<>""),"ok","check")) | U13: =IF(OR(E13="",N(K13)=0),"",SUMIFS($I$7:$I$18,$E$7:$E$18,">"&E13-Inputs!$C$25,$E$7:$E$18,"<="&E13,$K$7:$K$18,">0")) | V13: =IF(E13="","",SUMIFS($J$7:$J$18,$E$7:$E$18,"<="&E13)) | W13: =IF(U13="","",IF(U13>V13,"some offices get a second drop within four weeks","ok")) | X13: =IF(AND(E13&""=AA13&"",G13&""=AB13&"",H13&""=AC13&"",I13&""=AD13&"",J13&""=AE13&"",K13&""=AF13&"",L13&""=AG13&"",M13&""=AH13&""),"","changed")
A14: DRP-008 | C14: founder entry | F14: =IF(E14="","",TEXT(E14,"ddd")) | N14: N | P14: =IF(E14="","",IF(OR(WEEKDAY(E14)=Lists!$V$4,WEEKDAY(E14)=Lists!$V$5),"ok","not Tue/Wed")) | Q14: =IF(E14="","",WORKDAY(E14,Inputs!$C$23-1,Lists!$N$4:$N$30)) | R14: =IF(E14="","",IF(COUNTIFS(Lists!$Q$4:$Q$12,"<="&Q14,Lists!$R$4:$R$12,">="&E14)>0,"clash","ok")) | S14: =IF(E14="","",N(K14)*N(I14)*Inputs!$C$53*(1+Inputs!$C$54)) | T14: =IF(E14="",IF(N(K14)>0,"date missing",""),IF(AND(P14="ok",R14="ok",N(J14)<=N(I14),N(L14)<=N(K14),N(M14)<=N(L14),OR(N(K14)=0,N(I14)>0),G14<>"",H14<>""),"ok","check")) | U14: =IF(OR(E14="",N(K14)=0),"",SUMIFS($I$7:$I$18,$E$7:$E$18,">"&E14-Inputs!$C$25,$E$7:$E$18,"<="&E14,$K$7:$K$18,">0")) | V14: =IF(E14="","",SUMIFS($J$7:$J$18,$E$7:$E$18,"<="&E14)) | W14: =IF(U14="","",IF(U14>V14,"some offices get a second drop within four weeks","ok")) | X14: =IF(AND(E14&""=AA14&"",G14&""=AB14&"",H14&""=AC14&"",I14&""=AD14&"",J14&""=AE14&"",K14&""=AF14&"",L14&""=AG14&"",M14&""=AH14&""),"","changed")
A15: DRP-009 | C15: founder entry | F15: =IF(E15="","",TEXT(E15,"ddd")) | N15: N | P15: =IF(E15="","",IF(OR(WEEKDAY(E15)=Lists!$V$4,WEEKDAY(E15)=Lists!$V$5),"ok","not Tue/Wed")) | Q15: =IF(E15="","",WORKDAY(E15,Inputs!$C$23-1,Lists!$N$4:$N$30)) | R15: =IF(E15="","",IF(COUNTIFS(Lists!$Q$4:$Q$12,"<="&Q15,Lists!$R$4:$R$12,">="&E15)>0,"clash","ok")) | S15: =IF(E15="","",N(K15)*N(I15)*Inputs!$C$53*(1+Inputs!$C$54)) | T15: =IF(E15="",IF(N(K15)>0,"date missing",""),IF(AND(P15="ok",R15="ok",N(J15)<=N(I15),N(L15)<=N(K15),N(M15)<=N(L15),OR(N(K15)=0,N(I15)>0),G15<>"",H15<>""),"ok","check")) | U15: =IF(OR(E15="",N(K15)=0),"",SUMIFS($I$7:$I$18,$E$7:$E$18,">"&E15-Inputs!$C$25,$E$7:$E$18,"<="&E15,$K$7:$K$18,">0")) | V15: =IF(E15="","",SUMIFS($J$7:$J$18,$E$7:$E$18,"<="&E15)) | W15: =IF(U15="","",IF(U15>V15,"some offices get a second drop within four weeks","ok")) | X15: =IF(AND(E15&""=AA15&"",G15&""=AB15&"",H15&""=AC15&"",I15&""=AD15&"",J15&""=AE15&"",K15&""=AF15&"",L15&""=AG15&"",M15&""=AH15&""),"","changed")
A16: DRP-010 | C16: founder entry | F16: =IF(E16="","",TEXT(E16,"ddd")) | N16: N | P16: =IF(E16="","",IF(OR(WEEKDAY(E16)=Lists!$V$4,WEEKDAY(E16)=Lists!$V$5),"ok","not Tue/Wed")) | Q16: =IF(E16="","",WORKDAY(E16,Inputs!$C$23-1,Lists!$N$4:$N$30)) | R16: =IF(E16="","",IF(COUNTIFS(Lists!$Q$4:$Q$12,"<="&Q16,Lists!$R$4:$R$12,">="&E16)>0,"clash","ok")) | S16: =IF(E16="","",N(K16)*N(I16)*Inputs!$C$53*(1+Inputs!$C$54)) | T16: =IF(E16="",IF(N(K16)>0,"date missing",""),IF(AND(P16="ok",R16="ok",N(J16)<=N(I16),N(L16)<=N(K16),N(M16)<=N(L16),OR(N(K16)=0,N(I16)>0),G16<>"",H16<>""),"ok","check")) | U16: =IF(OR(E16="",N(K16)=0),"",SUMIFS($I$7:$I$18,$E$7:$E$18,">"&E16-Inputs!$C$25,$E$7:$E$18,"<="&E16,$K$7:$K$18,">0")) | V16: =IF(E16="","",SUMIFS($J$7:$J$18,$E$7:$E$18,"<="&E16)) | W16: =IF(U16="","",IF(U16>V16,"some offices get a second drop within four weeks","ok")) | X16: =IF(AND(E16&""=AA16&"",G16&""=AB16&"",H16&""=AC16&"",I16&""=AD16&"",J16&""=AE16&"",K16&""=AF16&"",L16&""=AG16&"",M16&""=AH16&""),"","changed")
A17: DRP-011 | C17: founder entry | F17: =IF(E17="","",TEXT(E17,"ddd")) | N17: N | P17: =IF(E17="","",IF(OR(WEEKDAY(E17)=Lists!$V$4,WEEKDAY(E17)=Lists!$V$5),"ok","not Tue/Wed")) | Q17: =IF(E17="","",WORKDAY(E17,Inputs!$C$23-1,Lists!$N$4:$N$30)) | R17: =IF(E17="","",IF(COUNTIFS(Lists!$Q$4:$Q$12,"<="&Q17,Lists!$R$4:$R$12,">="&E17)>0,"clash","ok")) | S17: =IF(E17="","",N(K17)*N(I17)*Inputs!$C$53*(1+Inputs!$C$54)) | T17: =IF(E17="",IF(N(K17)>0,"date missing",""),IF(AND(P17="ok",R17="ok",N(J17)<=N(I17),N(L17)<=N(K17),N(M17)<=N(L17),OR(N(K17)=0,N(I17)>0),G17<>"",H17<>""),"ok","check")) | U17: =IF(OR(E17="",N(K17)=0),"",SUMIFS($I$7:$I$18,$E$7:$E$18,">"&E17-Inputs!$C$25,$E$7:$E$18,"<="&E17,$K$7:$K$18,">0")) | V17: =IF(E17="","",SUMIFS($J$7:$J$18,$E$7:$E$18,"<="&E17)) | W17: =IF(U17="","",IF(U17>V17,"some offices get a second drop within four weeks","ok")) | X17: =IF(AND(E17&""=AA17&"",G17&""=AB17&"",H17&""=AC17&"",I17&""=AD17&"",J17&""=AE17&"",K17&""=AF17&"",L17&""=AG17&"",M17&""=AH17&""),"","changed")
A18: DRP-012 | C18: founder entry | F18: =IF(E18="","",TEXT(E18,"ddd")) | N18: N | P18: =IF(E18="","",IF(OR(WEEKDAY(E18)=Lists!$V$4,WEEKDAY(E18)=Lists!$V$5),"ok","not Tue/Wed")) | Q18: =IF(E18="","",WORKDAY(E18,Inputs!$C$23-1,Lists!$N$4:$N$30)) | R18: =IF(E18="","",IF(COUNTIFS(Lists!$Q$4:$Q$12,"<="&Q18,Lists!$R$4:$R$12,">="&E18)>0,"clash","ok")) | S18: =IF(E18="","",N(K18)*N(I18)*Inputs!$C$53*(1+Inputs!$C$54)) | T18: =IF(E18="",IF(N(K18)>0,"date missing",""),IF(AND(P18="ok",R18="ok",N(J18)<=N(I18),N(L18)<=N(K18),N(M18)<=N(L18),OR(N(K18)=0,N(I18)>0),G18<>"",H18<>""),"ok","check")) | U18: =IF(OR(E18="",N(K18)=0),"",SUMIFS($I$7:$I$18,$E$7:$E$18,">"&E18-Inputs!$C$25,$E$7:$E$18,"<="&E18,$K$7:$K$18,">0")) | V18: =IF(E18="","",SUMIFS($J$7:$J$18,$E$7:$E$18,"<="&E18)) | W18: =IF(U18="","",IF(U18>V18,"some offices get a second drop within four weeks","ok")) | X18: =IF(AND(E18&""=AA18&"",G18&""=AB18&"",H18&""=AC18&"",I18&""=AD18&"",J18&""=AE18&"",K18&""=AF18&"",L18&""=AG18&"",M18&""=AH18&""),"","changed")
B19: Totals | I19: =SUM(I7:I18) | J19: =SUM(J7:J18) | K19: =SUM(K7:K18) | L19: =SUM(L7:L18) | M19: =SUM(M7:M18) | S19: =SUM(S7:S18)
B21: Offices column counts every office on the drop; New offices counts the ones visiting for the first time (4 hours each instead of 1). Brands counts brand campaigns on the drop; renewals are part of that count (2 hours each instead of 6 or 10). Tier sets the price of the new brands; founding-rate renewals pay the founding rate per office.

Sheet Calculator
A1: Drop calculator
A2: Pick any tier, delivery model, office count and brand count. It runs the same engine as the drops and does not change the model.
A3: To test a price: type it in 'Standard price per office' below (or on Inputs to move the whole model). Read 'Contribution per founder hour'.
B5: Your drop | E5: Result
B6: Tier | C6: standard | E6: Line | F6: Whole drop | G6: Per brand (equal split of shared costs)
B7: Delivery model | C7: courier | E7: Revenue | F7: =S40 | G7: =IF(G40>0,F7/G40,"")
B8: Offices | C8: 10 | E8: Display kits | F8: =T40 | G8: =IF(G40>0,F8/G40,"")
B9: of which new offices | C9: 0 | E9: Transport | F9: =U40 | G9: =IF(G40>0,F9/G40,"")
B10: Brands | C10: 3 | E10: Kit mailing | F10: =V40 | G10: =IF(G40>0,F10/G40,"")
B11: of which renewals | C11: 0 | E11: Card processing | F11: =W40 | G11: =IF(G40>0,F11/G40,"")
B12: of which founding-rate renewals | C12: 0 | E12: Storage allocation | F12: =X40 | G12: =IF(G40>0,F12/G40,"")
B13: Standard price per office (blank = Inputs) | E13: Software allocation | F13: =Y40 | G13: =IF(G40>0,F13/G40,"")
B14: Founding price per office (blank = Inputs) | E14: Insurance allocation | F14: =Z40 | G14: =IF(G40>0,F14/G40,"")
B15: Storage allocated? Y/N (blank = Inputs choice) | E15: Hard costs | F15: =AA40 | G15: =IF(G40>0,F15/G40,"")
B16: Card processing? Y/N (blank = Inputs toggle) | E16: Contribution | F16: =AJ40 | G16: =IF(G40>0,F16/G40,"")
E17: brand_sales (h) | F17: =AB40 | G17: =IF(G40>0,F17/G40,"")
E18: office_coordination (h) | F18: =AC40 | G18: =IF(G40>0,F18/G40,"")
E19: receiving_kitting (h) | F19: =AD40 | G19: =IF(G40>0,F19/G40,"")
E20: drop_day (h) | F20: =AE40 | G20: =IF(G40>0,F20/G40,"")
E21: checks_pickup (h) | F21: =AF40 | G21: =IF(G40>0,F21/G40,"")
E22: reporting_debriefs (h) | F22: =AG40 | G22: =IF(G40>0,F22/G40,"")
E23: admin_invoicing (h) | F23: =AH40 | G23: =IF(G40>0,F23/G40,"")
E24: Founder hours | F24: =AI40 | G24: =IF(G40>0,F24/G40,"")
E25: Contribution per founder hour | F25: =AK40 | G25: =F25
E26: Against the Gate 3 target | F26: =IF(ISNUMBER(F25),IF(F25>=Inputs!$C$126,"at or above target","below target"),"n/a")
E27: Units each brand ships (incl. reserve) | F27: =E40*Inputs!$C$53*(1+Inputs!$C$54)
E29: Per-brand column: revenue and processing are averaged across brands, and shared costs and hours (kits, transport, allocations, office and drop-day time) are split equally. Brand sales and reporting hours are per brand already.
A37: Engine row: the same formulas as every row on Drop_PnL. Read-only; the result table above reads it.
A39: Drop or case | B39: Drop date | C39: Delivery model | D39: Tier | E39: Offices | F39: New offices | G39: Brands | H39: of which renewals | I39: of which founding-rate renewals | J39: Standard price per office | K39: Founding price per office | L39: Storage allocated (1/0) | M39: Card processing (1/0) | N39: Drop runs (1/0) | O39: New founding brands | P39: New standard brands | Q39: Revenue at founding rate | R39: Revenue at standard rate | S39: Revenue | T39: Display kits | U39: Transport | V39: Kit mailing | W39: Card processing | X39: Storage allocation | Y39: Software allocation | Z39: Insurance allocation | AA39: Hard costs | AB39: brand_sales (h) | AC39: office_coordination (h) | AD39: receiving_kitting (h) | AE39: drop_day (h) | AF39: checks_pickup (h) | AG39: reporting_debriefs (h) | AH39: admin_invoicing (h) | AI39: Founder hours | AJ39: Contribution | AK39: Contribution per founder hour | AL39: Direct costs (kits, transport, mailing, processing) | AM39: Overhead allocations (views of monthly costs)
A40: Calculator drop | C40: =$C$7 | D40: =$C$6 | E40: =N($C$8) | F40: =N($C$9) | G40: =N($C$10) | H40: =N($C$11) | I40: =N($C$12) | J40: =IF($C$13="",Inputs!$C$33,$C$13) | K40: =IF($C$14="",Inputs!$C$36,$C$14) | L40: =IF($C$15="",IF(Inputs!$C$65="unit",1,0),IF($C$15="Y",1,0)) | M40: =IF($C$16="",Inputs!$C$49,IF($C$16="Y",1,0)) | N40: =IF(G40>0,1,0) | O40: =IF(D40="founding",G40-H40,0) | P40: =IF(D40="standard",G40-H40,0) | Q40: =O40*(K40*MIN(E40,Inputs!$C$37)+Inputs!$C$39*MAX(E40-Inputs!$C$37,0))+I40*K40*E40 | R40: =(P40+H40-I40)*(J40*MIN(E40,Inputs!$C$34)+Inputs!$C$39*MAX(E40-Inputs!$C$34,0)) | S40: =Q40+R40 | T40: =N40*E40*(Inputs!$C$58+Inputs!$C$59*MAX(G40-1,0)) | U40: =IF(N40=0,0,INDEX(Inputs!$C$95:$C$97,MATCH(C40,Inputs!$B$95:$B$97,0))+INDEX(Inputs!$D$95:$D$97,MATCH(C40,Inputs!$B$95:$B$97,0))*E40) | V40: =IF(N40=0,0,INDEX(Inputs!$E$95:$E$97,MATCH(C40,Inputs!$B$95:$B$97,0))*E40) | W40: =S40*Inputs!$C$48*M40 | X40: =N40*L40*Inputs!$C$66/Inputs!$C$75 | Y40: =N40*Inputs!$C$69/Inputs!$C$75 | Z40: =N40*Inputs!$C$71/Inputs!$C$75 | AA40: =SUM(T40:Z40) | AB40: =O40*Inputs!$C$79+P40*Inputs!$C$83+H40*Inputs!$C$84 | AC40: =N40*(F40*Inputs!$C$85+(E40-F40)*Inputs!$C$86) | AD40: =IF(N40=0,0,INDEX(Inputs!$F$95:$F$97,MATCH(C40,Inputs!$B$95:$B$97,0))+Inputs!$C$87*G40) | AE40: =IF(N40=0,0,INDEX(Inputs!$G$95:$G$97,MATCH(C40,Inputs!$B$95:$B$97,0))*E40) | AF40: =IF(N40=0,0,INDEX(Inputs!$H$95:$H$97,MATCH(C40,Inputs!$B$95:$B$97,0))*E40) | AG40: =Inputs!$C$88*G40 | AH40: =N40*Inputs!$C$89 | AI40: =SUM(AB40:AH40) | AJ40: =S40-AA40 | AK40: =IF(AI40>0,AJ40/AI40,"n/a") | AL40: =T40+U40+V40+W40 | AM40: =X40+Y40+Z40

Sheet Drop_PnL
A1: Per-drop P&L (plan basis) with cash timing
A2: One row per Schedule row. Contribution = revenue minus hard costs, as the plan defines it. Overhead allocations are views; the cash flow pays overhead once.
A3: Planning estimates. The 'Live' columns switch to actuals when Schedule says 'Actuals in = Y'. Shared drop costs are split equally across the drop's brands where a per-brand figure is shown.
A5: Case | E5: Inputs to the engine | N5: Revenue | T5: Hard costs | AB5: Founder hours by activity | AJ5: Result | AL5: Split | AO5: Cash timing on the plan's terms (feeds Cash_Flow) | AZ5: Live: actual where Actuals in = Y, otherwise plan
A6: Drop or case | B6: Drop date | C6: Delivery model | D6: Tier | E6: Offices | F6: New offices | G6: Brands | H6: of which renewals | I6: of which founding-rate renewals | J6: Standard price per office | K6: Founding price per office | L6: Storage allocated (1/0) | M6: Card processing (1/0) | N6: Drop runs (1/0) | O6: New founding brands | P6: New standard brands | Q6: Revenue at founding rate | R6: Revenue at standard rate | S6: Revenue | T6: Display kits | U6: Transport | V6: Kit mailing | W6: Card processing | X6: Storage allocation | Y6: Software allocation | Z6: Insurance allocation | AA6: Hard costs | AB6: brand_sales (h) | AC6: office_coordination (h) | AD6: receiving_kitting (h) | AE6: drop_day (h) | AF6: checks_pickup (h) | AG6: reporting_debriefs (h) | AH6: admin_invoicing (h) | AI6: Founder hours | AJ6: Contribution | AK6: Contribution per founder hour | AL6: Direct costs (kits, transport, mailing, processing) | AM6: Overhead allocations (views of monthly costs) | AO6: Founding payment date | AP6: Founding payment | AQ6: Standard deposit date | AR6: Standard deposit | AS6: Balance date | AT6: Balance | AU6: Processing on founding payment | AV6: Processing on deposit | AW6: Processing on balance | AX6: Kits printed (and mailed) | AY6: Transport paid | AZ6: Actuals in | BA6: Live revenue | BB6: Live hard costs | BC6: Live founder hours | BD6: Live contribution | BE6: Live contribution per founder hour | BF6: Basis | BG6: Upcoming drop (1/0)
A7: =Schedule!A7 | B7: =IF(Schedule!E7="","",Schedule!E7) | C7: =IF(Schedule!G7="","",Schedule!G7) | D7: =IF(Schedule!H7="","",Schedule!H7) | E7: =N(Schedule!I7) | F7: =N(Schedule!J7) | G7: =N(Schedule!K7) | H7: =N(Schedule!L7) | I7: =N(Schedule!M7) | J7: =IF(AND(B7<>"",B7>Inputs!$C$15),Scenarios!$H$14,Inputs!$C$33) | K7: =Inputs!$C$36 | L7: =IF(AND(Inputs!$C$65="unit",B7<>"",B7>=Inputs!$C$67,OR(Inputs!$C$68="",B7<=Inputs!$C$68)),1,0) | M7: =Inputs!$C$49 | N7: =IF(G7>0,1,0) | O7: =IF(D7="founding",G7-H7,0) | P7: =IF(D7="standard",G7-H7,0) | Q7: =O7*(K7*MIN(E7,Inputs!$C$37)+Inputs!$C$39*MAX(E7-Inputs!$C$37,0))+I7*K7*E7 | R7: =(P7+H7-I7)*(J7*MIN(E7,Inputs!$C$34)+Inputs!$C$39*MAX(E7-Inputs!$C$34,0)) | S7: =Q7+R7 | T7: =N7*E7*(Inputs!$C$58+Inputs!$C$59*MAX(G7-1,0)) | U7: =IF(N7=0,0,INDEX(Inputs!$C$95:$C$97,MATCH(C7,Inputs!$B$95:$B$97,0))+INDEX(Inputs!$D$95:$D$97,MATCH(C7,Inputs!$B$95:$B$97,0))*E7) | V7: =IF(N7=0,0,INDEX(Inputs!$E$95:$E$97,MATCH(C7,Inputs!$B$95:$B$97,0))*E7) | W7: =S7*Inputs!$C$48*M7 | X7: =N7*L7*Inputs!$C$66/Inputs!$C$75 | Y7: =N7*Inputs!$C$69/Inputs!$C$75 | Z7: =N7*Inputs!$C$71/Inputs!$C$75 | AA7: =SUM(T7:Z7) | AB7: =O7*Inputs!$C$79+P7*Inputs!$C$83+H7*Inputs!$C$84 | AC7: =N7*(F7*Inputs!$C$85+(E7-F7)*Inputs!$C$86) | AD7: =IF(N7=0,0,INDEX(Inputs!$F$95:$F$97,MATCH(C7,Inputs!$B$95:$B$97,0))+Inputs!$C$87*G7) | AE7: =IF(N7=0,0,INDEX(Inputs!$G$95:$G$97,MATCH(C7,Inputs!$B$95:$B$97,0))*E7) | AF7: =IF(N7=0,0,INDEX(Inputs!$H$95:$H$97,MATCH(C7,Inputs!$B$95:$B$97,0))*E7) | AG7: =Inputs!$C$88*G7 | AH7: =N7*Inputs!$C$89 | AI7: =SUM(AB7:AH7) | AJ7: =S7-AA7 | AK7: =IF(AI7>0,AJ7/AI7,"n/a") | AL7: =T7+U7+V7+W7 | AM7: =X7+Y7+Z7 | AO7: =IF(OR(N7=0,AP7=0),"",WORKDAY(B7,-Inputs!$C$43,Lists!$N$4:$N$30)+N(Inputs!$C$47)) | AP7: =Q7*Inputs!$C$42 | AQ7: =IF(OR(N7=0,AR7=0),"",WORKDAY(B7,-Inputs!$C$45,Lists!$N$4:$N$30)+N(Inputs!$C$47)) | AR7: =R7*Inputs!$C$44 | AS7: =IF(OR(N7=0,AT7=0),"",WORKDAY(B7,Inputs!$C$46,Lists!$N$4:$N$30)+N(Inputs!$C$47)) | AT7: =Q7*(1-Inputs!$C$42)+R7*(1-Inputs!$C$44) | AU7: =AP7*Inputs!$C$48*M7 | AV7: =AR7*Inputs!$C$48*M7 | AW7: =AT7*Inputs!$C$48*M7 | AX7: =IF(N7=0,"",WORKDAY(B7,-Inputs!$C$64,Lists!$N$4:$N$30)) | AY7: =IF(N7=0,"",B7) | AZ7: =IF(Schedule!N7="Y","Y","N") | BA7: =IF(AZ7="Y",Drop_Actuals!D7,S7) | BB7: =IF(AZ7="Y",Drop_Actuals!J7,AA7) | BC7: =IF(AZ7="Y",Drop_Actuals!R7,AI7) | BD7: =BA7-BB7 | BE7: =IF(BC7>0,BD7/BC7,"n/a") | BF7: =IF(AND(N7=0,AZ7="N"),"",IF(AZ7="Y","actual","plan")) | BG7: =IF(AND(N7=1,B7>=Inputs!$C$17),1,0)
A8: =Schedule!A8 | B8: =IF(Schedule!E8="","",Schedule!E8) | C8: =IF(Schedule!G8="","",Schedule!G8) | D8: =IF(Schedule!H8="","",Schedule!H8) | E8: =N(Schedule!I8) | F8: =N(Schedule!J8) | G8: =N(Schedule!K8) | H8: =N(Schedule!L8) | I8: =N(Schedule!M8) | J8: =IF(AND(B8<>"",B8>Inputs!$C$15),Scenarios!$H$14,Inputs!$C$33) | K8: =Inputs!$C$36 | L8: =IF(AND(Inputs!$C$65="unit",B8<>"",B8>=Inputs!$C$67,OR(Inputs!$C$68="",B8<=Inputs!$C$68)),1,0) | M8: =Inputs!$C$49 | N8: =IF(G8>0,1,0) | O8: =IF(D8="founding",G8-H8,0) | P8: =IF(D8="standard",G8-H8,0) | Q8: =O8*(K8*MIN(E8,Inputs!$C$37)+Inputs!$C$39*MAX(E8-Inputs!$C$37,0))+I8*K8*E8 | R8: =(P8+H8-I8)*(J8*MIN(E8,Inputs!$C$34)+Inputs!$C$39*MAX(E8-Inputs!$C$34,0)) | S8: =Q8+R8 | T8: =N8*E8*(Inputs!$C$58+Inputs!$C$59*MAX(G8-1,0)) | U8: =IF(N8=0,0,INDEX(Inputs!$C$95:$C$97,MATCH(C8,Inputs!$B$95:$B$97,0))+INDEX(Inputs!$D$95:$D$97,MATCH(C8,Inputs!$B$95:$B$97,0))*E8) | V8: =IF(N8=0,0,INDEX(Inputs!$E$95:$E$97,MATCH(C8,Inputs!$B$95:$B$97,0))*E8) | W8: =S8*Inputs!$C$48*M8 | X8: =N8*L8*Inputs!$C$66/Inputs!$C$75 | Y8: =N8*Inputs!$C$69/Inputs!$C$75 | Z8: =N8*Inputs!$C$71/Inputs!$C$75 | AA8: =SUM(T8:Z8) | AB8: =O8*Inputs!$C$79+P8*Inputs!$C$83+H8*Inputs!$C$84 | AC8: =N8*(F8*Inputs!$C$85+(E8-F8)*Inputs!$C$86) | AD8: =IF(N8=0,0,INDEX(Inputs!$F$95:$F$97,MATCH(C8,Inputs!$B$95:$B$97,0))+Inputs!$C$87*G8) | AE8: =IF(N8=0,0,INDEX(Inputs!$G$95:$G$97,MATCH(C8,Inputs!$B$95:$B$97,0))*E8) | AF8: =IF(N8=0,0,INDEX(Inputs!$H$95:$H$97,MATCH(C8,Inputs!$B$95:$B$97,0))*E8) | AG8: =Inputs!$C$88*G8 | AH8: =N8*Inputs!$C$89 | AI8: =SUM(AB8:AH8) | AJ8: =S8-AA8 | AK8: =IF(AI8>0,AJ8/AI8,"n/a") | AL8: =T8+U8+V8+W8 | AM8: =X8+Y8+Z8 | AO8: =IF(OR(N8=0,AP8=0),"",WORKDAY(B8,-Inputs!$C$43,Lists!$N$4:$N$30)+N(Inputs!$C$47)) | AP8: =Q8*Inputs!$C$42 | AQ8: =IF(OR(N8=0,AR8=0),"",WORKDAY(B8,-Inputs!$C$45,Lists!$N$4:$N$30)+N(Inputs!$C$47)) | AR8: =R8*Inputs!$C$44 | AS8: =IF(OR(N8=0,AT8=0),"",WORKDAY(B8,Inputs!$C$46,Lists!$N$4:$N$30)+N(Inputs!$C$47)) | AT8: =Q8*(1-Inputs!$C$42)+R8*(1-Inputs!$C$44) | AU8: =AP8*Inputs!$C$48*M8 | AV8: =AR8*Inputs!$C$48*M8 | AW8: =AT8*Inputs!$C$48*M8 | AX8: =IF(N8=0,"",WORKDAY(B8,-Inputs!$C$64,Lists!$N$4:$N$30)) | AY8: =IF(N8=0,"",B8) | AZ8: =IF(Schedule!N8="Y","Y","N") | BA8: =IF(AZ8="Y",Drop_Actuals!D8,S8) | BB8: =IF(AZ8="Y",Drop_Actuals!J8,AA8) | BC8: =IF(AZ8="Y",Drop_Actuals!R8,AI8) | BD8: =BA8-BB8 | BE8: =IF(BC8>0,BD8/BC8,"n/a") | BF8: =IF(AND(N8=0,AZ8="N"),"",IF(AZ8="Y","actual","plan")) | BG8: =IF(AND(N8=1,B8>=Inputs!$C$17),1,0)
