Workbook

Sheet Offices
A1: row_id | B1: company | C1: website | D1: domain | E1: rank | F1: score_at_build | G1: ready_at_build | H1: primary_first_name | I1: primary_last_name | J1: primary_title | K1: primary_linkedin_url | L1: primary_contact_role | M1: primary_contact_status | N1: primary_contact_evidence | O1: primary_contact_source_url | P1: primary_contact_source_date | Q1: backup_first_name | R1: backup_last_name | S1: backup_title | T1: backup_linkedin_url | U1: backup_contact_role | V1: backup_contact_status | W1: backup_contact_evidence | X1: backup_contact_source_url | Y1: backup_contact_source_date | Z1: backup_contact_name_as_found | AA1: backup_contact_record_date | AB1: backup_contact_note | AC1: backup_contact_ny_base | AD1: backup_linkedin_status | AE1: street_address | AF1: floor | AG1: industry | AH1: employee_count | AI1: linkedin_company_url | AJ1: top50 | AK1: onsite_band | AL1: contacts_researched | AM1: onsite_high | AN1: onsite_confidence | AO1: attendance_signal | AP1: company_group | AQ1: hold_before_outreach | AR1: hold_reason | AS1: opt_out_date | AT1: ready_for_outreach | AU1: ready_reason | AV1: founder_ok_to_queue | AW1: promote_backup | AX1: onsite_founder_call | AY1: primary_first_name | AZ1: primary_last_name | BA1: primary_title | BB1: primary_linkedin_url | BC1: primary_work_email | BD1: primary_email_status | BE1: primary_contact_role | BF1: primary_contact_status | BG1: primary_contact_evidence | BH1: primary_contact_source_url | BI1: primary_contact_source_date | BJ1: primary_title_match | BK1: primary_check_before_send | BL1: primary_reason_who | BM1: backup_first_name | BN1: backup_last_name | BO1: backup_title | BP1: backup_linkedin_url | BQ1: backup_work_email | BR1: backup_email_status | BS1: backup_contact_role | BT1: backup_contact_status | BU1: backup_contact_evidence | BV1: backup_contact_source_url | BW1: backup_contact_source_date | BX1: backup_title_match | BY1: backup_check_before_send | BZ1: backup_reason_who | CA1: score_reason_core | CB1: channel_base | CC1: contact_name_as_found | CD1: contact_record_date | CE1: contact_note | CF1: contact_ny_base | CG1: linkedin_status | CH1: backup_contact_name_as_found | CI1: backup_contact_record_date | CJ1: backup_contact_note | CK1: backup_contact_ny_base | CL1: backup_linkedin_status | CM1: contacts_researched | CN1: gate_result | CO1: gate_reason | CP1: org_type | CQ1: b_id | CR1: website | CS1: industry | CT1: employee_count | CU1: employee_count_second | CV1: headcount_band | CW1: headcount_scope | CX1: headcount_check | CY1: headcount_source_url | CZ1: headcount_second_source_url | DA1: size_class | DB1: hq_city | DC1: hq_in_nyc | DD1: parent_company | DE1: linkedin_company_url | DF1: zip | DG1: lat | DH1: lon | DI1: in_boundary | DJ1: blocks_outside | DK1: building_id | DL1: building_name | DM1: address_source_url | DN1: address_source_date | DO1: address_source_type | DP1: second_source_url | DQ1: second_source_date | DR1: source_note | DS1: confidence | DT1: move_in_date | DU1: in_coworking | DV1: coworking_id | DW1: pantry_control | DX1: lobby_type | DY1: lobby_source_url | DZ1: lobby_note | EA1: coi_required | EB1: tuesday_named_in_policy | EC1: attendance_evidence | ED1: attendance_source_url | EE1: attendance_source_date | EF1: onsite_central | EG1: onsite_flags | EH1: onsite_space_check | EI1: onsite_basis | EJ1: onsite_label | EK1: onsite_fit_share | EL1: score_raw | EM1: score_onsite | EN1: score_size | EO1: score_attendance | EP1: score_address | EQ1: score_title | ER1: score_known | ES1: b_candidate_status | ET1: near_miss_class | EU1: nyc_office_may_fit | EV1: leased_sf_mentioned | EW1: leased_sf_source | EX1: b_notes | EY1: a_corrections | EZ1: linkedin_company_source | FA1: company_group_reason | FB1: sequence | FC1: touch_1_date | FD1: touch_2_date | FE1: touch_3_date | FF1: last_reply_date | FG1: reply_type | FH1: call_date | FI1: call_notes | FJ1: yes_in_principle | FK1: next_action | FL1: next_action_date | FM1: referral_from | FN1: street_short | FO1: why_now_hook | FP1: call_note_hook | FQ1: how_we_know | FR1: referrer_ok_to_name | FS1: in_flight | FT1: dnc_any | FU1: group_key | FV1: group_blocked | FW1: eligible | FX1: view_pick | FY1: in_daily_view | FZ1: view_slot | GA1: walk_ok | GB1: walk_slot | GC1: intact | GD1: row_order
A2: AO-C-009 | B2: Alpine Investors | C2: https://www.alpineinvestors.com | D2: alpineinvestors.com | E2: 1 | F2: 80.0 | G2: Y | H2: Jake | I2: Jones | J2: Office Coordinator, New York office | L2: pantry or office lead (primary) | M2: verified-page | N2: employer's own site | O2: https://alpineinvestors.com/group/alpine-management/page/4/ | P2: 2026-10-24 | Q2: Katira | R2: Getzen | S2: Office Coordinator, New York City office | U2: pantry or office lead (backup) | V2: verified-page | W2: employer's own site | X2: https://alpineinvestors.com/group/alpine-management/page/4/ | Y2: 2026-10-24 | Z2: Katira Getzen | AA2: 2025-03-11 | AB2: title_match=target; Alpine team page bio: "Katira is an Office Coordinator at Alpine's New York City office"; bio posted 2025-03-11. Darween Edouard (Executive Assistant, New York office, alpine-management/page/6, 2024-02-05) is a third option. A search snippet named a Harry Garcia as NYC Office Manager and EA (2023) but he is not on the current team page, so not recorded. | AC2: confirmed | AE2: 124 East 14th Street | AF2: 12 | AG2: private equity | AH2: 203 | AI2: https://www.linkedin.com/company/alpine-investors | AJ2: Y | AK2: 76-150 | AL2: Y | AM2: 136 | AN2: low | AO2: in-office-5 | AP2: AO-C-009 | AQ2: N | AT2: =IF($A2="","",IF(AND(CN2="pass",AQ2<>"Y",C2<>"",OR(AX2<>"Y",AV2="Y")),"Y","N")) -> Y | AU2: =IF($A2="","",_xlfn.TEXTJOIN("; ",TRUE(),IF(CN2<>"pass","gated out",""),IF(AQ2="Y","on hold: "&AR2,""),IF(C2="","no contact named on an opened page",""),IF(AND(AX2="Y",AV2<>"Y"),"Tuesday estimate band "&L2&": founder's call",""))) | AX2: N | AY2: Jake | AZ2: Jones | BA2: Office Coordinator, New York office | BC2: =IF($A2="","",IFERROR(INDEX(Enrichment!$A$2:$GZ$2000,MATCH($A2,INDEX(Enrichment!$A$2:$GZ$2000,0,MATCH("row_id",Enrichment!$A$1:$GZ$1,0)),0),MATCH("work_email",Enrichment!$A$1:$GZ$1,0))&"","")) | BD2: =IF($A2="","",IF(BC2="","none",IF(OR(IFERROR(INDEX(Enrichment!$A$2:$GZ$2000,MATCH($A2,INDEX(Enrichment!$A$2:$GZ$2000,0,MATCH("row_id",Enrichment!$A$1:$GZ$1,0)),0),MATCH("email_status",Enrichment!$A$1:$GZ$1,0))&"","")="verified",IFERROR(INDEX(Enrichment!$A$2:$GZ$2000,MATCH($A2,INDEX(Enrichment!$A$2:$GZ$2000,0,MATCH("row_id",Enrichment!$A$1:$GZ$1,0)),0),MATCH("email_status",Enrichment!$A$1:$GZ$1,0))&"","")="unverified"),IFERROR(INDEX(Enrichment!$A$2:$GZ$2000,MATCH($A2,INDEX(Enrichment!$A$2:$GZ$2000,0,MATCH("row_id",Enrichment!$A$1:$GZ$1,0)),0),MATCH("email_status",Enrichment!$A$1:$GZ$1,0))&"",""),"unverified"))) -> none | BE2: pantry or office lead (primary) | BF2: verified-page | BG2: employer's own site | BH2: https://alpineinvestors.com/group/alpine-management/page/4/ | BI2: 2026-10-24 | BJ2: exact | BK2: find Jake Jones at Alpine Investors on LinkedIn and paste the profile URL into primary_linkedin_url; the source is dated 2025-09-15: check Jake still holds the role | BL2: contact in the target titles named (Office Coordinator, New York office) | BM2: Katira | BN2: Getzen | BO2: Office Coordinator, New York City office | BQ2: =IF($A2="","",IFERROR(INDEX(Enrichment!$A$2:$GZ$2000,MATCH($A2,INDEX(Enrichment!$A$2:$GZ$2000,0,MATCH("row_id",Enrichment!$A$1:$GZ$1,0)),0),MATCH("backup_work_email",Enrichment!$A$1:$GZ$1,0))&"","")) | BR2: =IF($A2="","",IF(BQ2="","none",IF(OR(IFERROR(INDEX(Enrichment!$A$2:$GZ$2000,MATCH($A2,INDEX(Enrichment!$A$2:$GZ$2000,0,MATCH("row_id",Enrichment!$A$1:$GZ$1,0)),0),MATCH("backup_email_status",Enrichment!$A$1:$GZ$1,0))&"","")="verified",IFERROR(INDEX(Enrichment!$A$2:$GZ$2000,MATCH($A2,INDEX(Enrichment!$A$2:$GZ$2000,0,MATCH("row_id",Enrichment!$A$1:$GZ$1,0)),0),MATCH("backup_email_status",Enrichment!$A$1:$GZ$1,0))&"","")="unverified"),IFERROR(INDEX(Enrichment!$A$2:$GZ$2000,MATCH($A2,INDEX(Enrichment!$A$2:$GZ$2000,0,MATCH("row_id",Enrichment!$A$1:$GZ$1,0)),0),MATCH("backup_email_status",Enrichment!$A$1:$GZ$1,0))&"",""),"unverified"))) -> none | BS2: pantry or office lead (backup) | BT2: verified-page | BU2: employer's own site | BV2: https://alpineinvestors.com/group/alpine-management/page/4/ | BW2: 2026-10-24 | BX2: exact | BY2: find Katira Getzen at Alpine Investors on LinkedIn and paste the profile URL into backup_linkedin_url; the source is dated 2025-03-11: check Katira still holds the role | BZ2: contact in the target titles named (Office Coordinator, New York City office) | CA2: Tuesday estimate 88 to 136 (low confidence), under 500 staff company-wide, on-site 5 days a week per its profile, occupied at a high-confidence address | CB2: linkedin | CC2: Jake Jones | CD2: 2025-09-15 | CE2: title_match=target; Alpine team page bio: "Jake is an Office Coordinator at Alpine’s New York office"; bio posted 2025-09-15; also listed under Finance & Operations on alpineinvestors.com/team/. LinkedIn profile not searched. | CF2: confirmed | CH2: Katira Getzen | CI2: 2025-03-11 | CJ2: title_match=target; Alpine team page bio: "Katira is an Office Coordinator at Alpine's New York City office"; bio posted 2025-03-11. Darween Edouard (Executive Assistant, New York office, alpine-management/page/6, 2024-02-05) is a third option. A search snippet named a Harry Garcia as NYC Office Manager and EA (2023) but he is not on the current team page, so not recorded. | CK2: confirmed | CM2: Y | CN2: pass | CO2: passes all hard gates | CP2: company | CQ2: B-C-009 | CR2: https://www.alpineinvestors.com | CS2: private equity | CT2: 203 | CV2: 151-250 | CW2: whole-company | CX2: single-source | CY2: https://www.builtinnyc.com/company/alpine-investors | DA2: le500 | DB2: San Francisco | DC2: N | DD2: unknown | DE2: https://www.linkedin.com/company/alpine-investors | DF2: 10003 | DG2: 40.733674 | DH2: -73.988766 | DI2: Y | DJ2: 0 | DK2: B-B-002 | DL2: Zero Irving | DM2: https://www.alpineinvestors.com/contact/ | DN2: 2026-10-24 | DO2: company-site | DP2: https://commercialobserver.com/2022/11/alpine-investors-lease-zero-irving/ | DQ2: 2022-11-17 | DS2: high | DU2: N | DX2: unknown | EA2: unknown | EB2: N | EC2: Built In workplace type: OnSite Workplace; typical time on-site: 5 days a week | ED2: https://www.builtinnyc.com/company/alpine-investors/offices | EE2: 2026-10-24 | EF2: 109 | EH2: Y | EI2: 203 (Built In) staff (whole-company count) x 5% to 100% of them in the New York office (HQ outside New York; share assumed) x 67% (Partnership for NYC, firms under 500) in on a weekday; space-based for a company headquartered outside New York: 22,000 sf seats 88 to 176 at 250 to 125 sf per person, kept within the headcount math (7 to 136) (largest square footage the sources mention at this address; if the company holds more space here, intake corrects it) = 88 to 136, central 109; low confidence; estimate until intake replaces it. | EJ2: estimate until intake replaces it | EK2: 1 | EL2: 80 | EM2: 25 | EN2: 15 | EO2: 15 | EP2: 15 | EQ2: =IF($A2="","",IF(AH2="exact",10,IF(AH2="adjacent",5,0))) -> 0 | ER2: =IF($A2="","",IF(R2="Y",15,0)) -> 0 | ES2: candidate | EV2: 22,000 sf | EW2: B's sources | EX2: Site: 'NEW YORK Zero Irving, 124 East 14th St., 12th Floor New York, NY 10003'. CO 2022-11-17: five-year lease, 22,000 sf on the entire 12th floor and part of the 14th. Zero Irving is on the south side of 14th between Irving Pl and Third Ave (same tax block as Trader Joe's 142 E 14th), so margin. Built In NYC: 203 total employees, HQ San Francisco; NYC share unknown. | EZ2: linked from the company's own site (https://alpineinvestors.com/, opened 2026-10-24); LinkedIn not opened | FS2: =IF($A2="","",IF(ISNUMBER(MATCH(U2,{"queued","contacted","replied","call_booked","call_done","yes_in_principle","materials_sent"},0)),"Y","N")) -> N | FT2: =IF($A2="","",IF(OR(T2="Y",U2="do_not_contact",AS2&""<>""),"Y","N")) -> N | FU2: =IF($A2="","",IF(AP2&""<>"",AP2&"",$A2)) -> AO-C-009 | FV2: =IF($A2="","",IF(COUNTIFS($FU$2:$FU$1000,FU2,$FS$2:$FS$1000,"Y")+COUNTIFS($FU$2:$FU$1000,FU2,$FT$2:$FT$1000,"Y")>0,"Y","N")) -> N | FW2: =IF($A2="","",IF(AND(U2="new",T2="N",FT2="N",AT2="Y",FV2="N"),"Y","N")) -> N | FX2: =IF($A2="","",IF(FW2<>"Y","N",IF(COUNTIFS($FU$2:$FU$1000,FU2,$FW$2:$FW$1000,"Y",$J$2:$J$1000,">"&J2)+COUNTIFS($FU$2:$FU$1000,FU2,$FW$2:$FW$1000,"Y",$J$2:$J$1000,J2,$GD$2:$GD$1000,"<"&GD2)=0,"Y","N"))) -> N | FY2: =IF($A2="","",IF(AND(FW2="Y",FX2="Y",Y2&""<>""),IF(Y2<=10,"Y","N"),"N")) -> N | FZ2: =IF(FY2="Y",Y2,"") | GA2: =IF($A2="","",IF(AND(I2="walk-in",CN2="pass",U2="new",FT2="N",FV2="N",AQ2<>"Y"),"Y","N")) -> N | GB2: =IF(GA2<>"Y","",IF(COUNTIFS($GA$2:$GA$1000,"Y",$J$2:$J$1000,">"&J2)+COUNTIFS($GA$2:$GA$1000,"Y",$J$2:$J$1000,J2,$GD$2:$GD$1000,"<"&GD2)+1<=25,COUNTIFS($GA$2:$GA$1000,"Y",$J$2:$J$1000,">"&J2)+COUNTIFS($GA$2:$GA$1000,"Y",$J$2:$J$1000,J2,$GD$2:$GD$1000,"<"&GD2)+1,"")) | GC2: =IF(AND(_xlfn.ISFORMULA(C2),_xlfn.ISFORMULA(J2)),"Y","N") -> N | GD2: =ROW()-1 -> 1
A3: AO-C-035 | B3: Global Strategy Group | C3: https://www.globalstrategygroup.com | D3: globalstrategygroup.com | E3: 2 | F3: 80.0 | G3: Y | H3: Joan | I3: McHugh-Ward | J3: Manager, HQ-Office Services | L3: pantry or office lead (primary) | M3: verified-page | N3: employer's own site | O3: https://globalstrategygroup.com/team/ | P3: 2026-10-24 | Q3: Liana | R3: Kane | S3: Senior Executive Assistant to the CEO | T3: https://www.linkedin.com/in/liana-kane-ba771b29/ | U3: pantry or office lead (backup) | V3: verified-page | W3: employer's own site | X3: https://globalstrategygroup.com/team/liana-kane/ | Y3: 2026-10-24 | Z3: Liana Kane | AA3: 2026-09-07 | AB3: ny_base=confirmed; title_fit=family (EA to CEO). Company profile page gives the title and links this LinkedIn profile (LinkedIn not opened). The Org (https://theorg.com/org/global-strategy-group/person/liana-kane, updated 2026-09-07) attaches her to the New York HQ office. Bio lists office organization among her duties. | AC3: confirmed | AD3: listed on an opened page or in search results; LinkedIn itself not opened | AE3: 215 Park Avenue South | AF3: 15 | AG3: public affairs, research and communications consulting | AH3: 187 | AI3: https://www.linkedin.com/company/global-strategy-group | AJ3: Y | AK3: 76-150 | AL3: Y | AM3: 125 | AN3: low | AO3: in-office-5 | AP3: AO-C-035 | AQ3: N | AT3: =IF($A3="","",IF(AND(CN3="pass",AQ3<>"Y",C3<>"",OR(AX3<>"Y",AV3="Y")),"Y","N")) -> Y | AU3: =IF($A3="","",_xlfn.TEXTJOIN("; ",TRUE(),IF(CN3<>"pass","gated out",""),IF(AQ3="Y","on hold: "&AR3,""),IF(C3="","no contact named on an opened page",""),IF(AND(AX3="Y",AV3<>"Y"),"Tuesday estimate band "&L3&": founder's call",""))) | AX3: N | AY3: Joan | AZ3: McHugh-Ward | BA3: Manager, HQ-Office Services | BC3: =IF($A3="","",IFERROR(INDEX(Enrichment!$A$2:$GZ$2000,MATCH($A3,INDEX(Enrichment!$A$2:$GZ$2000,0,MATCH("row_id",Enrichment!$A$1:$GZ$1,0)),0),MATCH("work_email",Enrichment!$A$1:$GZ$1,0))&"","")) | BD3: =IF($A3="","",IF(BC3="","none",IF(OR(IFERROR(INDEX(Enrichment!$A$2:$GZ$2000,MATCH($A3,INDEX(Enrichment!$A$2:$GZ$2000,0,MATCH("row_id",Enrichment!$A$1:$GZ$1,0)),0),MATCH("email_status",Enrichment!$A$1:$GZ$1,0))&"","")="verified",IFERROR(INDEX(Enrichment!$A$2:$GZ$2000,MATCH($A3,INDEX(Enrichment!$A$2:$GZ$2000,0,MATCH("row_id",Enrichment!$A$1:$GZ$1,0)),0),MATCH("email_status",Enrichment!$A$1:$GZ$1,0))&"","")="unverified"),IFERROR(INDEX(Enrichment!$A$2:$GZ$2000,MATCH($A3,INDEX(Enrichment!$A$2:$GZ$2000,0,MATCH("row_id",Enrichment!$A$1:$GZ$1,0)),0),MATCH("email_status",Enrichment!$A$1:$GZ$1,0))&"",""),"unverified"))) -> none | BE3: pantry or office lead (primary) | BF3: verified-page | BG3: employer's own site | BH3: https://globalstrategygroup.com/team/ | BI3: 2026-10-24 | BJ3: exact | BK3: find Joan McHugh-Ward at Global Strategy Group on LinkedIn and paste the profile URL into primary_linkedin_url | BL3: contact in the target titles named (Manager, HQ-Office Services) | BM3: Liana | BN3: Kane | BO3: Senior Executive Assistant to the CEO | BP3: https://www.linkedin.com/in/liana-kane-ba771b29/ | BQ3: =IF($A3="","",IFERROR(INDEX(Enrichment!$A$2:$GZ$2000,MATCH($A3,INDEX(Enrichment!$A$2:$GZ$2000,0,MATCH("row_id",Enrichment!$A$1:$GZ$1,0)),0),MATCH("backup_work_email",Enrichment!$A$1:$GZ$1,0))&"","")) | BR3: =IF($A3="","",IF(BQ3="","none",IF(OR(IFERROR(INDEX(Enrichment!$A$2:$GZ$2000,MATCH($A3,INDEX(Enrichment!$A$2:$GZ$2000,0,MATCH("row_id",Enrichment!$A$1:$GZ$1,0)),0),MATCH("backup_email_status",Enrichment!$A$1:$GZ$1,0))&"","")="verified",IFERROR(INDEX(Enrichment!$A$2:$GZ$2000,MATCH($A3,INDEX(Enrichment!$A$2:$GZ$2000,0,MATCH("row_id",Enrichment!$A$1:$GZ$1,0)),0),MATCH("backup_email_status",Enrichment!$A$1:$GZ$1,0))&"","")="unverified"),IFERROR(INDEX(Enrichment!$A$2:$GZ$2000,MATCH($A3,INDEX(Enrichment!$A$2:$GZ$2000,0,MATCH("row_id",Enrichment!$A$1:$GZ$1,0)),0),MATCH("backup_email_status",Enrichment!$A$1:$GZ$1,0))&"",""),"unverified"))) -> none | BS3: pantry or office lead (backup) | BT3: verified-page | BU3: employer's own site | BV3: https://globalstrategygroup.com/team/liana-kane/ | BW3: 2026-10-24 | BX3: exact | BY3: open the LinkedIn URL and confirm it is Liana Kane, Senior Executive Assistant to the CEO at Global Strategy Group (found on another page, never opened) | BZ3: contact in the target titles named (Senior Executive Assistant to the CEO) | CA3: Tuesday estimate 63 to 125 (low confidence), under 500 staff company-wide, on-site 5 days a week per its profile, occupied at a high-confidence address | CB3: linkedin | CC3: Joan McHugh-Ward | CE3: ny_base=confirmed; title_fit=family (office services manager). Company team page lists 'Manager, HQ-Office Services'; her profile page https://globalstrategygroup.com/team/joan-mchugh/ is titled 'HQ Office Services'. GSG HQ is New York (215 Park Avenue South). No LinkedIn URL on the company page. | CF3: confirmed | CH3: Liana Kane | CI3: 2026-09-07 | CJ3: ny_base=confirmed; title_fit=family (EA to CEO). Company profile page gives the title and links this LinkedIn profile (LinkedIn not opened). The Org (https://theorg.com/org/global-strategy-group/person/liana-kane, updated 2026-09-07) attaches her to the New York HQ office. Bio lists office organization among her duties. | CK3: confirmed | CL3: listed on an opened page or in search results; LinkedIn itself not opened | CM3: Y | CN3: pass | CO3: passes all hard gates | CP3: company | CQ3: B-C-035 | CR3: https://www.globalstrategygroup.com | CS3: public affairs, research and communications consulting | CT3: 187 | CV3: 151-250 | CW3: whole-company | CX3: single-source | CY3: https://www.builtinnyc.com/company/global-strategy-group | DA3: le500 | DB3: New York | DC3: Y | DD3: unknown | DE3: https://www.linkedin.com/company/global-strategy-group | DF3: 10003 | DG3: 40.73686 | DH3: -73.988546 | DI3: Y | DJ3: 0 | DK3: B-B-016 | DL3: 215 Park Avenue South (SL Green managed) | DM3: https://www.globalstrategygroup.com/locations/ | DN3: 2026-10-23 | DO3: company-site | DP3: https://www.sec.gov/Archives/edgar/data/1013454/000153949726000704/n5676_x5-424h.htm | DQ3: 2026-02 | DR3: cites a sec.gov filing: agents do not open it (EDGAR demands a contact email); the founder may open it in a browser | DS3: high | DU3: N | DX3: security desk | DY3: https://www.metro-manhattan.com/buildings/215-park-avenue-south/ | EA3: unknown | EB3: N | EC3: Built In workplace type: OnSite Workplace; typical time on-site: 5 days a week; recent job tags: 1 Hybrid | ED3: https://www.builtinnyc.com/company/global-strategy-group/offices | EE3: 2026-10-24 | EF3: 89 | EH3: N | EI3: 187 (Built In) staff (whole-company count) x 50% to 100% of them in the New York office (HQ New York; share assumed) x 67% (Partnership for NYC, firms under 500) in on a weekday = 63 to 125, central 89; low confidence; estimate until intake replaces it. | EJ3: estimate until intake replaces it | EK3: 1 | EL3: 80 | EM3: 25 | EN3: 15 | EO3: 15 | EP3: 15 | EQ3: =IF($A3="","",IF(AH3="exact",10,IF(AH3="adjacent",5,0))) -> 0 | ER3: =IF($A3="","",IF(R3="Y",15,0)) -> 0 | ES3: candidate | EV3: 21,974 sf | EW3: B's sources | EX3: Locations page: '215 Park Avenue South, 15th Floor'. SEC rent roll 2026-02-05: 21,974 sf, lease to 2032-08-31. Built In NYC: 187 total employees across 8 offices, HQ New York. | Assembly 2026-10-24: SEC EDGAR source (sec.gov): this agent will not re-open it, because EDGAR serves only requests that carry a contact email and the project rule forbids sending one; the founder may open it in a browser. Review round 2: corner lot: the lot-centroid pin sat 20 m from E 18 ST but 39 m from PARK AVE S, so it was moved to the PARK AVE S frontage near the corner (14 m from the PARK AVE S centreline, 26 m from E 18 ST; 26 m from the old pin). Tax lot unchanged. | EZ3: linked from the company's own site (https://globalstrategygroup.com/, opened 2026-10-24); LinkedIn not opened | FS3: =IF($A3="","",IF(ISNUMBER(MATCH(U3,{"queued","contacted","replied","call_booked","call_done","yes_in_principle","materials_sent"},0)),"Y","N")) -> N | FT3: =IF($A3="","",IF(OR(T3="Y",U3="do_not_contact",AS3&""<>""),"Y","N")) -> N | FU3: =IF($A3="","",IF(AP3&""<>"",AP3&"",$A3)) -> AO-C-035 | FV3: =IF($A3="","",IF(COUNTIFS($FU$2:$FU$1000,FU3,$FS$2:$FS$1000,"Y")+COUNTIFS($FU$2:$FU$1000,FU3,$FT$2:$FT$1000,"Y")>0,"Y","N")) -> N | FW3: =IF($A3="","",IF(AND(U3="new",T3="N",FT3="N",AT3="Y",FV3="N"),"Y","N")) -> N | FX3: =IF($A3="","",IF(FW3<>"Y","N",IF(COUNTIFS($FU$2:$FU$1000,FU3,$FW$2:$FW$1000,"Y",$J$2:$J$1000,">"&J3)+COUNTIFS($FU$2:$FU$1000,FU3,$FW$2:$FW$1000,"Y",$J$2:$J$1000,J3,$GD$2:$GD$1000,"<"&GD3)=0,"Y","N"))) -> N | FY3: =IF($A3="","",IF(AND(FW3="Y",FX3="Y",Y3&""<>""),IF(Y3<=10,"Y","N"),"N")) -> N | FZ3: =IF(FY3="Y",Y3,"") | GA3: =IF($A3="","",IF(AND(I3="walk-in",CN3="pass",U3="new",FT3="N",FV3="N",AQ3<>"Y"),"Y","N")) -> N | GB3: =IF(GA3<>"Y","",IF(COUNTIFS($GA$2:$GA$1000,"Y",$J$2:$J$1000,">"&J3)+COUNTIFS($GA$2:$GA$1000,"Y",$J$2:$J$1000,J3,$GD$2:$GD$1000,"<"&GD3)+1<=25,COUNTIFS($GA$2:$GA$1000,"Y",$J$2:$J$1000,">"&J3)+COUNTIFS($GA$2:$GA$1000,"Y",$J$2:$J$1000,J3,$GD$2:$GD$1000,"<"&GD3)+1,"")) | GC3: =IF(AND(_xlfn.ISFORMULA(C3),_xlfn.ISFORMULA(J3)),"Y","N") -> N | GD3: =ROW()-1 -> 2
A4: AO-C-171 | B4: Signal AI | C4: https://www.signal-ai.com | D4: signal-ai.com | E4: 3 | F4: 80.0 | G4: Y | H4: Hannah | I4: Grow | J4: Senior People Operations Coordinator | L4: pantry or office lead (primary) | M4: crowd-listed | N4: The Org (crowd-edited org chart) | O4: https://theorg.com/org/signal-ai/person/hannah-grow | P4: 2026-10-24 | Q4: Lauren | R4: Stone | S4: Head Of People | U4: pantry or office lead (backup) | V4: crowd-listed | W4: The Org (crowd-edited org chart) | X4: https://theorg.com/org/signal-ai/person/lauren-stone | Y4: 2026-10-24 | Z4: Lauren Stone | AA4: 2025-05-01 | AB4: ny_base=confirmed (same New York office record); title_fit=variant (people lead). The Org updated 2025-05-01. | AC4: confirmed | AE4: 440 Park Avenue South | AF4: 14 | AG4: software (AI risk and reputation intelligence) | AH4: 226 | AI4: https://www.linkedin.com/company/signal-artificial-intelligence | AJ4: Y | AK4: 40-75 | AL4: Y | AM4: 89 | AN4: low | AO4: in-office-5 | AP4: AO-C-171 | AQ4: N | AT4: =IF($A4="","",IF(AND(CN4="pass",AQ4<>"Y",C4<>"",OR(AX4<>"Y",AV4="Y")),"Y","N")) -> Y | AU4: =IF($A4="","",_xlfn.TEXTJOIN("; ",TRUE(),IF(CN4<>"pass","gated out",""),IF(AQ4="Y","on hold: "&AR4,""),IF(C4="","no contact named on an opened page",""),IF(AND(AX4="Y",AV4<>"Y"),"Tuesday estimate band "&L4&": founder's call",""))) | AX4: N | AY4: Hannah | AZ4: Grow | BA4: Senior People Operations Coordinator | BC4: =IF($A4="","",IFERROR(INDEX(Enrichment!$A$2:$GZ$2000,MATCH($A4,INDEX(Enrichment!$A$2:$GZ$2000,0,MATCH("row_id",Enrichment!$A$1:$GZ$1,0)),0),MATCH("work_email",Enrichment!$A$1:$GZ$1,0))&"","")) | BD4: =IF($A4="","",IF(BC4="","none",IF(OR(IFERROR(INDEX(Enrichment!$A$2:$GZ$2000,MATCH($A4,INDEX(Enrichment!$A$2:$GZ$2000,0,MATCH("row_id",Enrichment!$A$1:$GZ$1,0)),0),MATCH("email_status",Enrichment!$A$1:$GZ$1,0))&"","")="verified",IFERROR(INDEX(Enrichment!$A$2:$GZ$2000,MATCH($A4,INDEX(Enrichment!$A$2:$GZ$2000,0,MATCH("row_id",Enrichment!$A$1:$GZ$1,0)),0),MATCH("email_status",Enrichment!$A$1:$GZ$1,0))&"","")="unverified"),IFERROR(INDEX(Enrichment!$A$2:$GZ$2000,MATCH($A4,INDEX(Enrichment!$A$2:$GZ$2000,0,MATCH("row_id",Enrichment!$A$1:$GZ$1,0)),0),MATCH("email_status",Enrichment!$A$1:$GZ$1,0))&"",""),"unverified"))) -> none | BE4: pantry or office lead (primary) | BF4: crowd-listed | BG4: The Org (crowd-edited org chart) | BH4: https://theorg.com/org/signal-ai/person/hannah-grow | BI4: 2026-10-24 | BJ4: exact | BK4: find Hannah Grow at Signal AI on LinkedIn and paste the profile URL into primary_linkedin_url (this also confirms the name: The Org is crowd-edited and marks it Unverified) | BL4: contact in the target titles named (Senior People Operations Coordinator) (crowd-listed on The Org) | BM4: Lauren | BN4: Stone | BO4: Head Of People | BQ4: =IF($A4="","",IFERROR(INDEX(Enrichment!$A$2:$GZ$2000,MATCH($A4,INDEX(Enrichment!$A$2:$GZ$2000,0,MATCH("row_id",Enrichment!$A$1:$GZ$1,0)),0),MATCH("backup_work_email",Enrichment!$A$1:$GZ$1,0))&"","")) | BR4: =IF($A4="","",IF(BQ4="","none",IF(OR(IFERROR(INDEX(Enrichment!$A$2:$GZ$2000,MATCH($A4,INDEX(Enrichment!$A$2:$GZ$2000,0,MATCH("row_id",Enrichment!$A$1:$GZ$1,0)),0),MATCH("backup_email_status",Enrichment!$A$1:$GZ$1,0))&"","")="verified",IFERROR(INDEX(Enrichment!$A$2:$GZ$2000,MATCH($A4,INDEX(Enrichment!$A$2:$GZ$2000,0,MATCH("row_id",Enrichment!$A$1:$GZ$1,0)),0),MATCH("backup_email_status",Enrichment!$A$1:$GZ$1,0))&"","")="unverified"),IFERROR(INDEX(Enrichment!$A$2:$GZ$2000,MATCH($A4,INDEX(Enrichment!$A$2:$GZ$2000,0,MATCH("row_id",Enrichment!$A$1:$GZ$1,0)),0),MATCH("backup_email_status",Enrichment!$A$1:$GZ$1,0))&"",""),"unverified"))) -> none | BS4: pantry or office lead (backup) | BT4: crowd-listed | BU4: The Org (crowd-edited org chart) | BV4: https://theorg.com/org/signal-ai/person/lauren-stone | BW4: 2026-10-24 | BX4: adjacent | BY4: find Lauren Stone at Signal AI on LinkedIn and paste the profile URL into backup_linkedin_url (this also confirms the name: The Org is crowd-edited and marks it Unverified); the source is dated 2025-05-01: check Lauren still holds the role; adjacent title: ask who runs the pantry | BZ4: adjacent contact named (Head Of People) (crowd-listed on The Org) | CA4: Tuesday estimate 45 to 89 (low confidence), under 500 staff company-wide, on-site 5 days a week per its profile, occupied at a high-confidence address | CB4: linkedin | CC4: Hannah Grow | CD4: 2026-02-09 | CE4: ny_base=confirmed (The Org attaches the role to Signal AI's New York office; that record shows 154 W 14th St while B's company-site address is 440 Park Avenue South); title_fit=family (people operations). The Org updated 2026-02-09. | CF4: confirmed | CH4: Lauren Stone | CI4: 2025-05-01 | CJ4: ny_base=confirmed (same New York office record); title_fit=variant (people lead). The Org updated 2025-05-01. | CK4: confirmed | CM4: Y | CN4: pass | CO4: passes all hard gates | CP4: company | CQ4: B-C-171 | CR4: https://www.signal-ai.com | CS4: software (AI risk and reputation intelligence) | CT4: 226 | CV4: 151-250 | CW4: whole-company | CX4: single-source | CY4: https://www.builtinnyc.com/company/signal-ai/offices | DA4: le500 | DB4: London | DC4: N | DD4: unknown | DE4: https://www.linkedin.com/company/signal-artificial-intelligence | DF4: 10016 | DG4: 40.744442 | DH4: -73.983525 | DI4: Y | DJ4: 0 | DK4: B-B-080 | DL4: 440 Park Avenue South (Samco Properties) | DM4: https://www.signal-ai.com/ | DN4: 2026-10-24 | DO4: company-site | DP4: https://commercialobserver.com/2022/12/signal-ai-doubles-offices-in-move-to-440-park-avenue-south/ | DQ4: 2022-12-19 | DS4: high | DU4: N | DX4: unknown | EA4: unknown | EB4: N | EC4: Built In workplace type: OnSite Workplace; typical time on-site: 5 days a week | ED4: https://www.builtinnyc.com/company/signal-ai/offices | EE4: 2026-10-24 | EF4: 63 | EH4: Y | EI4: 226 (Built In) staff (whole-company count) x 5% to 100% of them in the New York office (HQ outside New York; share assumed) x 67% (Partnership for NYC, firms under 500) in on a weekday; space-based for a company headquartered outside New York: 11,140 sf seats 45 to 89 at 250 to 125 sf per person, kept within the headcount math (8 to 151) (largest square footage the sources mention at this address; if the company holds more space here, intake corrects it) = 45 to 89, central 63; low confidence; estimate until intake replaces it. | EJ4: estimate until intake replaces it | EK4: 1 | EL4: 80 | EM4: 25 | EN4: 15 | EO4: 15 | EP4: 15 | EQ4: =IF($A4="","",IF(AH4="exact",10,IF(AH4="adjacent",5,0))) -> 0 | ER4: =IF($A4="","",IF(R4="Y",15,0)) -> 0 | ES4: candidate | EV4: 11,140 sf | EW4: B's sources | EX4: Built In lists New York office at 440 Park Avenue South, 14th Floor; 226 total employees (HQ London). CO 2022: 11,140 SF US HQ. | Assembly 2026-10-24: Review round 1: Signal AI's own site footer (opened 2026-10-24) lists 'United States 440 Park Avenue South, 14th floor, New York NY 10016' beside its London office, so the row stays high on its own page plus Built In. Review round 3: Built In is an employer-editable profile, so it no longer counts as the independent confirmation of the company's own page. The independent source is now CO 2022-12-19 (opened 2026-10-24): 'signed a lease for space at Samco Properties at 440 Park Avenue South' (11,140 sf; lease length not disclosed). The row stays high. Review round 2: corner lot: the lot-centroid pin sat 23 m from E 30 ST but 24 m from PARK AVE S, so it was moved to the PARK AVE S frontage near the corner (13 m from the PARK AVE S centreline, 27 m from E 30 ST; 12 m from the old pin). Tax lot unchanged. | EZ4: linked from the company's own site (https://signal-ai.com/, opened 2026-10-24); LinkedIn not opened | FS4: =IF($A4="","",IF(ISNUMBER(MATCH(U4,{"queued","contacted","replied","call_booked","call_done","yes_in_principle","materials_sent"},0)),"Y","N")) -> N | FT4: =IF($A4="","",IF(OR(T4="Y",U4="do_not_contact",AS4&""<>""),"Y","N")) -> N | FU4: =IF($A4="","",IF(AP4&""<>"",AP4&"",$A4)) -> AO-C-171 | FV4: =IF($A4="","",IF(COUNTIFS($FU$2:$FU$1000,FU4,$FS$2:$FS$1000,"Y")+COUNTIFS($FU$2:$FU$1000,FU4,$FT$2:$FT$1000,"Y")>0,"Y","N")) -> N | FW4: =IF($A4="","",IF(AND(U4="new",T4="N",FT4="N",AT4="Y",FV4="N"),"Y","N")) -> N | FX4: =IF($A4="","",IF(FW4<>"Y","N",IF(COUNTIFS($FU$2:$FU$1000,FU4,$FW$2:$FW$1000,"Y",$J$2:$J$1000,">"&J4)+COUNTIFS($FU$2:$FU$1000,FU4,$FW$2:$FW$1000,"Y",$J$2:$J$1000,J4,$GD$2:$GD$1000,"<"&GD4)=0,"Y","N"))) -> N | FY4: =IF($A4="","",IF(AND(FW4="Y",FX4="Y",Y4&""<>""),IF(Y4<=10,"Y","N"),"N")) -> N | FZ4: =IF(FY4="Y",Y4,"") | GA4: =IF($A4="","",IF(AND(I4="walk-in",CN4="pass",U4="new",FT4="N",FV4="N",AQ4<>"Y"),"Y","N")) -> N | GB4: =IF(GA4<>"Y","",IF(COUNTIFS($GA$2:$GA$1000,"Y",$J$2:$J$1000,">"&J4)+COUNTIFS($GA$2:$GA$1000,"Y",$J$2:$J$1000,J4,$GD$2:$GD$1000,"<"&GD4)+1<=25,COUNTIFS($GA$2:$GA$1000,"Y",$J$2:$J$1000,">"&J4)+COUNTIFS($GA$2:$GA$1000,"Y",$J$2:$J$1000,J4,$GD$2:$GD$1000,"<"&GD4)+1,"")) | GC4: =IF(AND(_xlfn.ISFORMULA(C4),_xlfn.ISFORMULA(J4)),"Y","N") -> N | GD4: =ROW()-1 -> 3
A5: AO-C-160 | B5: K Health | C5: https://khealth.com | D5: khealth.com | E5: 4 | F5: 76.5 | G5: Y | H5: Naomy | I5: Ambroise | J5: People Operations Generalist | L5: pantry or office lead (primary) | M5: crowd-listed | N5: The Org (crowd-edited org chart) | O5: https://theorg.com/org/k-health/person/naomy-ambroise | P5: 2026-10-24 | Q5: Ana | R5: Ramos | S5: VP of Operations | U5: pantry or office lead (backup) | V5: crowd-listed | W5: The Org (crowd-edited org chart) | X5: https://theorg.com/org/k-health/person/ana-ramos | Y5: 2026-10-24 | Z5: Ana Ramos | AA5: 2026-01-19 | AB5: ny_base=confirmed (The Org attaches the role to K Health's New York HQ office); title_fit=adjacent (operations lead, team 'Finance and Operations'). The Org updated 2026-01-19. | AC5: confirmed | AE5: 387 Park Avenue South | AF5: 9 | AG5: healthtech (AI primary care) | AH5: 363 | AI5: https://www.linkedin.com/company/khealthinc | AJ5: Y | AK5: 151-250 | AL5: Y | AM5: 281 | AN5: low | AO5: in-office-5 | AP5: AO-C-160 | AQ5: N | AS5: 2026-10-30 | AT5: =IF($A5="","",IF(AND(CN5="pass",AQ5<>"Y",C5<>"",OR(AX5<>"Y",AV5="Y")),"Y","N")) -> Y | AU5: =IF($A5="","",_xlfn.TEXTJOIN("; ",TRUE(),IF(CN5<>"pass","gated out",""),IF(AQ5="Y","on hold: "&AR5,""),IF(C5="","no contact named on an opened page",""),IF(AND(AX5="Y",AV5<>"Y"),"Tuesday estimate band "&L5&": founder's call",""))) | AX5: N | AY5: Naomy | AZ5: Ambroise | BA5: People Operations Generalist | BC5: =IF($A5="","",IFERROR(INDEX(Enrichment!$A$2:$GZ$2000,MATCH($A5,INDEX(Enrichment!$A$2:$GZ$2000,0,MATCH("row_id",Enrichment!$A$1:$GZ$1,0)),0),MATCH("work_email",Enrichment!$A$1:$GZ$1,0))&"","")) | BD5: =IF($A5="","",IF(BC5="","none",IF(OR(IFERROR(INDEX(Enrichment!$A$2:$GZ$2000,MATCH($A5,INDEX(Enrichment!$A$2:$GZ$2000,0,MATCH("row_id",Enrichment!$A$1:$GZ$1,0)),0),MATCH("email_status",Enrichment!$A$1:$GZ$1,0))&"","")="verified",IFERROR(INDEX(Enrichment!$A$2:$GZ$2000,MATCH($A5,INDEX(Enrichment!$A$2:$GZ$2000,0,MATCH("row_id",Enrichment!$A$1:$GZ$1,0)),0),MATCH("email_status",Enrichment!$A$1:$GZ$1,0))&"","")="unverified"),IFERROR(INDEX(Enrichment!$A$2:$GZ$2000,MATCH($A5,INDEX(Enrichment!$A$2:$GZ$2000,0,MATCH("row_id",Enrichment!$A$1:$GZ$1,0)),0),MATCH("email_status",Enrichment!$A$1:$GZ$1,0))&"",""),"unverified"))) -> none | BE5: pantry or office lead (primary) | BF5: crowd-listed | BG5: The Org (crowd-edited org chart) | BH5: https://theorg.com/org/k-health/person/naomy-ambroise | BI5: 2026-10-24 | BJ5: exact | BK5: find Naomy Ambroise at K Health on LinkedIn and paste the profile URL into primary_linkedin_url (this also confirms the name: The Org is crowd-edited and marks it Unverified) | BL5: contact in the target titles named (People Operations Generalist) (crowd-listed on The Org) | BM5: Ana | BN5: Ramos | BO5: VP of Operations | BQ5: =IF($A5="","",IFERROR(INDEX(Enrichment!$A$2:$GZ$2000,MATCH($A5,INDEX(Enrichment!$A$2:$GZ$2000,0,MATCH("row_id",Enrichment!$A$1:$GZ$1,0)),0),MATCH("backup_work_email",Enrichment!$A$1:$GZ$1,0))&"","")) | BR5: =IF($A5="","",IF(BQ5="","none",IF(OR(IFERROR(INDEX(Enrichment!$A$2:$GZ$2000,MATCH($A5,INDEX(Enrichment!$A$2:$GZ$2000,0,MATCH("row_id",Enrichment!$A$1:$GZ$1,0)),0),MATCH("backup_email_status",Enrichment!$A$1:$GZ$1,0))&"","")="verified",IFERROR(INDEX(Enrichment!$A$2:$GZ$2000,MATCH($A5,INDEX(Enrichment!$A$2:$GZ$2000,0,MATCH("row_id",Enrichment!$A$1:$GZ$1,0)),0),MATCH("backup_email_status",Enrichment!$A$1:$GZ$1,0))&"","")="unverified"),IFERROR(INDEX(Enrichment!$A$2:$GZ$2000,MATCH($A5,INDEX(Enrichment!$A$2:$GZ$2000,0,MATCH("row_id",Enrichment!$A$1:$GZ$1,0)),0),MATCH("backup_email_status",Enrichment!$A$1:$GZ$1,0))&"",""),"unverified"))) -> none | BS5: pantry or office lead (backup) | BT5: crowd-listed | BU5: The Org (crowd-edited org chart) | BV5: https://theorg.com/org/k-health/person/ana-ramos | BW5: 2026-10-24 | BX5: adjacent | BY5: find Ana Ramos at K Health on LinkedIn and paste the profile URL into backup_linkedin_url (this also confirms the name: The Org is crowd-edited and marks it Unverified); adjacent title: ask who runs the pantry | BZ5: adjacent contact named (VP of Operations) (crowd-listed on The Org) | CA5: Tuesday estimate 122 to 281 (low confidence), under 500 staff company-wide, on-site 5 days a week per its profile, occupied at a high-confidence address | CB5: linkedin | CC5: Naomy Ambroise | CD5: 2026-02-14 | CE5: ny_base=likely (The Org gives a New York location, no office attached); title_fit=family (people operations). The Org updated 2026-02-14. Search results showed a temporary 'Executive Assistant and Office Manager' New York posting (2026-09-04, job boards, not opened); it no longer appears on K Health's Greenhouse board (opened 2026-10-24), so an office manager may have just joined: ask for them by name. | CF5: likely | CH5: Ana Ramos | CI5: 2026-01-19 | CJ5: ny_base=confirmed (The Org attaches the role to K Health's New York HQ office); title_fit=adjacent (operations lead, team 'Finance and Operations'). The Org updated 2026-01-19. | CK5: confirmed | CM5: Y | CN5: pass | CO5: passes all hard gates | CP5: company | CQ5: B-C-160 | CR5: https://khealth.com | CS5: healthtech (AI primary care) | CT5: 363 | CU5: 419 | CV5: 251-500 | CW5: whole-company | CX5: agree | CY5: https://www.builtinnyc.com/company/k-health/offices | CZ5: https://www.reveliolabs.com/companies/k-health/employees | DA5: le500 | DB5: New York | DC5: Y | DD5: unknown | DE5: https://www.linkedin.com/company/khealthinc | DF5: 10016 | DG5: 40.742833 | DH5: -73.984174 | DI5: Y | DJ5: 0 | DK5: B-B-073 | DL5: 387 Park Avenue South (TF Cornerstone) | DM5: https://www.connectcre.com/stories/ai-native-hanover-park-leases-full-floor-at-387-park-ave-south/ | DN5: 2026-08-14 | DO5: leasing-press | DP5: https://khealth.com/terms-of-use/ | DQ5: 2026-10-24 | DS5: high | DU5: N | DX5: unknown | EA5: unknown | EB5: N | EC5: completed a long-term renewal at 387 PAS in late 2025. CONFLICT: Built In (363 employees, on-site 5 days) lists HQ at 298 5th Ave, 7th | ED5: https://www.builtinnyc.com/company/k-health/offices | EE5: 2026-10-23 | EF5: 185 | EG5: may exceed 250 | EH5: N | EI5: 363 (Built In) and 419 (Revelio Labs) staff (whole-company count) x 50% to 100% of them in the New York office (HQ New York; share assumed) x 67% (Partnership for NYC, firms under 500) in on a weekday = 122 to 281, central 185; low confidence; estimate until intake replaces it. | EJ5: estimate until intake replaces it | EK5: 0.86 | EL5: 76.5 | EM5: 21.5 | EN5: 15 | EO5: 15 | EP5: 15 | EQ5: =IF($A5="","",IF(AH5="exact",10,IF(AH5="adjacent",5,0))) -> 0 | ER5: =IF($A5="","",IF(R5="Y",15,0)) -> 0 | ES5: candidate | EX5: Connect CRE says K Health completed a long-term renewal at 387 PAS in late 2025. CONFLICT: Built In (363 employees, on-site 5 days) lists HQ at 298 5th Ave, 7th Floor (30th-31st St, margin). Founder to confirm which office is current. | Assembly 2026-10-24: Conflict resolved at assembly: K Health's own terms of use (opened 2026-10-24) give 'Company's Legal Department, 387 Park Ave South, 9th Floor, NY, NY 10016', which agrees with the Connect CRE renewal at 387 PAS (late 2025). Built In's 298 Fifth Ave, 7th floor is stale. Upgraded to high. Review round 2: a second count agrees with the band: Revelio Labs (K Health, Inc., HQ New York City): about 419 employees worldwide as of March 2026. Review round 2: corner lot: the lot-centroid pin sat 24 m from E 27 ST but 34 m from PARK AVE S, so it was moved to the PARK AVE S frontage near the corner (13 m from the PARK AVE S centreline, 26 m from E 27 ST; 21 m from the old pin). Tax lot unchanged. | EZ5: linked from the company's own site (https://khealth.com/, opened 2026-10-24); LinkedIn not opened | FS5: =IF($A5="","",IF(ISNUMBER(MATCH(U5,{"queued","contacted","replied","call_booked","call_done","yes_in_principle","materials_sent"},0)),"Y","N")) -> N | FT5: =IF($A5="","",IF(OR(T5="Y",U5="do_not_contact",AS5&""<>""),"Y","N")) -> Y | FU5: =IF($A5="","",IF(AP5&""<>"",AP5&"",$A5)) -> AO-C-160 | FV5: =IF($A5="","",IF(COUNTIFS($FU$2:$FU$1000,FU5,$FS$2:$FS$1000,"Y")+COUNTIFS($FU$2:$FU$1000,FU5,$FT$2:$FT$1000,"Y")>0,"Y","N")) -> Y | FW5: =IF($A5="","",IF(AND(U5="new",T5="N",FT5="N",AT5="Y",FV5="N"),"Y","N")) -> N | FX5: =IF($A5="","",IF(FW5<>"Y","N",IF(COUNTIFS($FU$2:$FU$1000,FU5,$FW$2:$FW$1000,"Y",$J$2:$J$1000,">"&J5)+COUNTIFS($FU$2:$FU$1000,FU5,$FW$2:$FW$1000,"Y",$J$2:$J$1000,J5,$GD$2:$GD$1000,"<"&GD5)=0,"Y","N"))) -> N | FY5: =IF($A5="","",IF(AND(FW5="Y",FX5="Y",Y5&""<>""),IF(Y5<=10,"Y","N"),"N")) -> N | FZ5: =IF(FY5="Y",Y5,"") | GA5: =IF($A5="","",IF(AND(I5="walk-in",CN5="pass",U5="new",FT5="N",FV5="N",AQ5<>"Y"),"Y","N")) -> N | GB5: =IF(GA5<>"Y","",IF(COUNTIFS($GA$2:$GA$1000,"Y",$J$2:$J$1000,">"&J5)+COUNTIFS($GA$2:$GA$1000,"Y",$J$2:$J$1000,J5,$GD$2:$GD$1000,"<"&GD5)+1<=25,COUNTIFS($GA$2:$GA$1000,"Y",$J$2:$J$1000,">"&J5)+COUNTIFS($GA$2:$GA$1000,"Y",$J$2:$J$1000,J5,$GD$2:$GD$1000,"<"&GD5)+1,"")) | GC5: =IF(AND(_xlfn.ISFORMULA(C5),_xlfn.ISFORMULA(J5)),"Y","N") -> N | GD5: =ROW()-1 -> 4
A6: AO-C-050 | B6: Global Trading Systems (GTS) | C6: https://gtsx.com | D6: gtsx.com | E6: 5 | F6: 75.9 | G6: Y | H6: Katherine | I6: Hickey | J6: Executive Assistant to CEO | L6: pantry or office lead (primary) | M6: crowd-listed | N6: The Org (crowd-edited org chart) | O6: https://theorg.com/org/global-trading-systems-1/person/katherine-hickey | P6: 2026-10-24 | V6: none | AE6: 625 Avenue of the Americas | AF6: 3 | AG6: electronic trading / market making | AH6: 420 | AI6: https://www.linkedin.com/company/global-trading-systems | AJ6: Y | AK6: 151-250 | AL6: Y | AM6: 281 | AN6: low | AO6: in-office-5 | AP6: AO-C-050 | AQ6: N | AT6: =IF($A6="","",IF(AND(CN6="pass",AQ6<>"Y",C6<>"",OR(AX6<>"Y",AV6="Y")),"Y","N")) -> Y | AU6: =IF($A6="","",_xlfn.TEXTJOIN("; ",TRUE(),IF(CN6<>"pass","gated out",""),IF(AQ6="Y","on hold: "&AR6,""),IF(C6="","no contact named on an opened page",""),IF(AND(AX6="Y",AV6<>"Y"),"Tuesday estimate band "&L6&": founder's call",""))) | AX6: N | AY6: Katherine | AZ6: Hickey | BA6: Executive Assistant to CEO | BC6: =IF($A6="","",IFERROR(INDEX(Enrichment!$A$2:$GZ$2000,MATCH($A6,INDEX(Enrichment!$A$2:$GZ$2000,0,MATCH("row_id",Enrichment!$A$1:$GZ$1,0)),0),MATCH("work_email",Enrichment!$A$1:$GZ$1,0))&"","")) | BD6: =IF($A6="","",IF(BC6="","none",IF(OR(IFERROR(INDEX(Enrichment!$A$2:$GZ$2000,MATCH($A6,INDEX(Enrichment!$A$2:$GZ$2000,0,MATCH("row_id",Enrichment!$A$1:$GZ$1,0)),0),MATCH("email_status",Enrichment!$A$1:$GZ$1,0))&"","")="verified",IFERROR(INDEX(Enrichment!$A$2:$GZ$2000,MATCH($A6,INDEX(Enrichment!$A$2:$GZ$2000,0,MATCH("row_id",Enrichment!$A$1:$GZ$1,0)),0),MATCH("email_status",Enrichment!$A$1:$GZ$1,0))&"","")="unverified"),IFERROR(INDEX(Enrichment!$A$2:$GZ$2000,MATCH($A6,INDEX(Enrichment!$A$2:$GZ$2000,0,MATCH("row_id",Enrichment!$A$1:$GZ$1,0)),0),MATCH("email_status",Enrichment!$A$1:$GZ$1,0))&"",""),"unverified"))) -> none | BE6: pantry or office lead (primary) | BF6: crowd-listed | BG6: The Org (crowd-edited org chart) | BH6: https://theorg.com/org/global-trading-systems-1/person/katherine-hickey | BI6: 2026-10-24 | BJ6: exact | BK6: find Katherine Hickey at Global Trading Systems (GTS) on LinkedIn and paste the profile URL into primary_linkedin_url (this also confirms the name: The Org is crowd-edited and marks it Unverified) | BL6: contact in the target titles named (Executive Assistant to CEO) (crowd-listed on The Org) | BQ6: =IF($A6="","",IFERROR(INDEX(Enrichment!$A$2:$GZ$2000,MATCH($A6,INDEX(Enrichment!$A$2:$GZ$2000,0,MATCH("row_id",Enrichment!$A$1:$GZ$1,0)),0),MATCH("backup_work_email",Enrichment!$A$1:$GZ$1,0))&"","")) | BR6: =IF($A6="","",IF(BQ6="","none",IF(OR(IFERROR(INDEX(Enrichment!$A$2:$GZ$2000,MATCH($A6,INDEX(Enrichment!$A$2:$GZ$2000,0,MATCH("row_id",Enrichment!$A$1:$GZ$1,0)),0),MATCH("backup_email_status",Enrichment!$A$1:$GZ$1,0))&"","")="verified",IFERROR(INDEX(Enrichment!$A$2:$GZ$2000,MATCH($A6,INDEX(Enrichment!$A$2:$GZ$2000,0,MATCH("row_id",Enrichment!$A$1:$GZ$1,0)),0),MATCH("backup_email_status",Enrichment!$A$1:$GZ$1,0))&"","")="unverified"),IFERROR(INDEX(Enrichment!$A$2:$GZ$2000,MATCH($A6,INDEX(Enrichment!$A$2:$GZ$2000,0,MATCH("row_id",Enrichment!$A$1:$GZ$1,0)),0),MATCH("backup_email_status",Enrichment!$A$1:$GZ$1,0))&"",""),"unverified"))) -> none | BT6: none | BX6: none | BY6: no backup named: back to research | BZ6: no backup contact named | CA6: Tuesday estimate 137 to 281 (low confidence), under 500 staff company-wide, on-site 5 days a week per its profile, occupied at a high-confidence address | CB6: linkedin | CC6: Katherine Hickey | CD6: 2026-01-28 | CE6: ny_base=confirmed; title_fit=family (EA to the CEO). The Org position page (opened 2026-10-24, updated 2026-01-28) lists her as Executive Assistant to CEO, located in the New York area; GTS is a New York firm. The Org is crowd-edited and marks crowd-added people Unverified. | CF6: confirmed | CM6: Y | CN6: pass | CO6: passes all hard gates | CP6: company | CQ6: B-C-050 | CR6: https://gtsx.com | CS6: electronic trading / market making | CT6: 420 | CU6: 410 | CV6: 251-500 | CW6: whole-company | CX6: agree | CY6: https://www.builtinnyc.com/company/gts | CZ6: https://www.reveliolabs.com/companies/global-trading-systems/employees | DA6: le500 | DB6: New York | DC6: Y | DD6: unknown | DE6: https://www.linkedin.com/company/global-trading-systems | DF6: 10011 | DG6: 40.74024 | DH6: -73.994996 | DI6: Y | DJ6: 0 | DK6: B-B-020 | DL6: 625 Avenue of the Americas (Taub family) | DM6: https://commercialobserver.com/2024/11/trading-firm-gts-lease-625-avenue-of-the-americas/ | DN6: 2024-11-21 | DO6: leasing-press | DP6: https://gtsx.com/locations/ | DQ6: 2026-10-24 | DS6: high | DU6: N | DX6: unknown | EA6: unknown | EB6: N | EC6: Built In workplace type: OnSite Workplace; typical time on-site: 5 days a week | ED6: https://www.builtinnyc.com/company/gts/offices | EE6: 2026-10-24 | EF6: 196 | EG6: may exceed 250 | EH6: N | EI6: 420 (Built In) and 410 (Revelio Labs) staff (whole-company count) x 50% to 100% of them in the New York office (HQ New York; share assumed) x 67% (Partnership for NYC, firms under 500) in on a weekday = 137 to 281, central 196; low confidence; estimate until intake replaces it. | EJ6: estimate until intake replaces it | EK6: 0.84 | EL6: 75.9 | EM6: 20.9 | EN6: 15 | EO6: 15 | EP6: 15 | EQ6: =IF($A6="","",IF(AH6="exact",10,IF(AH6="adjacent",5,0))) -> 0 | ER6: =IF($A6="","",IF(R6="Y",15,0)) -> 0 | ES6: candidate | EV6: 35,156 sf | EW6: B's sources | EX6: 15-year, 35,156 sf lease of the 3rd floor (CO Nov 2024), relocating from 545 Madison Ave; keeps 40 Wall St. Company locations page (opened 2026-10-24) lists New York at 625 Sixth Avenue, NY 10011. Built In shows 420 total employees and still lists 545 Madison Ave. | Assembly 2026-10-24: Review round 2: a second count agrees with the band: Revelio Labs (Global Trading Systems LLC, HQ New York City): about 410 employees worldwide as of March 2026. Review round 2: corner lot: the lot-centroid pin sat 37 m from W 19 ST but 38 m from AVE OF THE AMERICAS, so it was moved to the AVE OF THE AMERICAS frontage near the corner (18 m from the AVE OF THE AMERICAS centreline, 37 m from W 19 ST; 20 m from the old pin). Tax lot unchanged. | EZ6: linked from the company's own site (https://gtsx.com/, opened 2026-10-24); LinkedIn not opened | FS6: =IF($A6="","",IF(ISNUMBER(MATCH(U6,{"queued","contacted","replied","call_booked","call_done","yes_in_principle","materials_sent"},0)),"Y","N")) -> N | FT6: =IF($A6="","",IF(OR(T6="Y",U6="do_not_contact",AS6&""<>""),"Y","N")) -> N | FU6: =IF($A6="","",IF(AP6&""<>"",AP6&"",$A6)) -> AO-C-050 | FV6: =IF($A6="","",IF(COUNTIFS($FU$2:$FU$1000,FU6,$FS$2:$FS$1000,"Y")+COUNTIFS($FU$2:$FU$1000,FU6,$FT$2:$FT$1000,"Y")>0,"Y","N")) -> N | FW6: =IF($A6="","",IF(AND(U6="new",T6="N",FT6="N",AT6="Y",FV6="N"),"Y","N")) -> N | FX6: =IF($A6="","",IF(FW6<>"Y","N",IF(COUNTIFS($FU$2:$FU$1000,FU6,$FW$2:$FW$1000,"Y",$J$2:$J$1000,">"&J6)+COUNTIFS($FU$2:$FU$1000,FU6,$FW$2:$FW$1000,"Y",$J$2:$J$1000,J6,$GD$2:$GD$1000,"<"&GD6)=0,"Y","N"))) -> N | FY6: =IF($A6="","",IF(AND(FW6="Y",FX6="Y",Y6&""<>""),IF(Y6<=10,"Y","N"),"N")) -> N | FZ6: =IF(FY6="Y",Y6,"") | GA6: =IF($A6="","",IF(AND(I6="walk-in",CN6="pass",U6="new",FT6="N",FV6="N",AQ6<>"Y"),"Y","N")) -> N | GB6: =IF(GA6<>"Y","",IF(COUNTIFS($GA$2:$GA$1000,"Y",$J$2:$J$1000,">"&J6)+COUNTIFS($GA$2:$GA$1000,"Y",$J$2:$J$1000,J6,$GD$2:$GD$1000,"<"&GD6)+1<=25,COUNTIFS($GA$2:$GA$1000,"Y",$J$2:$J$1000,">"&J6)+COUNTIFS($GA$2:$GA$1000,"Y",$J$2:$J$1000,J6,$GD$2:$GD$1000,"<"&GD6)+1,"")) | GC6: =IF(AND(_xlfn.ISFORMULA(C6),_xlfn.ISFORMULA(J6)),"Y","N") -> N | GD6: =ROW()-1 -> 5
A7: AO-C-037 | B7: Nayya | C7: https://www.nayya.com | D7: nayya.com | E7: 6 | F7: 75.0 | G7: Y | H7: Phoebe | I7: Waxman | J7: Senior People Operations Analyst | L7: pantry or office lead (primary) | M7: crowd-listed | N7: The Org (crowd-edited org chart) | O7: https://theorg.com/org/nayya/person/phoebe-waxman | P7: 2026-10-24 | Q7: Amber | R7: Hewko | S7: Executive Assistant | U7: pantry or office lead (backup) | V7: crowd-listed | W7: The Org (crowd-edited org chart) | X7: https://theorg.com/org/nayya/person/amber-hewko | Y7: 2026-10-24 | Z7: Amber Hewko | AA7: 2025-05-30 | AB7: ny_base=unconfirmed (no location or office on The Org); title_fit=variant (The Org shows her reporting to the CEO, Sarah Liebel). The Org updated 2025-05-30. | AC7: unconfirmed | AE7: 215 Park Avenue South | AF7: 4 | AG7: benefits software (health tech) | AH7: 150 | AI7: https://www.linkedin.com/company/64515483 | AJ7: Y | AK7: 76-150 | AL7: Y | AM7: 134 | AN7: low | AO7: hybrid-3 | AP7: AO-C-037 | AQ7: N | AT7: =IF($A7="","",IF(AND(CN7="pass",AQ7<>"Y",C7<>"",OR(AX7<>"Y",AV7="Y")),"Y","N")) -> Y | AU7: =IF($A7="","",_xlfn.TEXTJOIN("; ",TRUE(),IF(CN7<>"pass","gated out",""),IF(AQ7="Y","on hold: "&AR7,""),IF(C7="","no contact named on an opened page",""),IF(AND(AX7="Y",AV7<>"Y"),"Tuesday estimate band "&L7&": founder's call",""))) | AX7: N | AY7: Phoebe | AZ7: Waxman | BA7: Senior People Operations Analyst | BC7: =IF($A7="","",IFERROR(INDEX(Enrichment!$A$2:$GZ$2000,MATCH($A7,INDEX(Enrichment!$A$2:$GZ$2000,0,MATCH("row_id",Enrichment!$A$1:$GZ$1,0)),0),MATCH("work_email",Enrichment!$A$1:$GZ$1,0))&"","")) | BD7: =IF($A7="","",IF(BC7="","none",IF(OR(IFERROR(INDEX(Enrichment!$A$2:$GZ$2000,MATCH($A7,INDEX(Enrichment!$A$2:$GZ$2000,0,MATCH("row_id",Enrichment!$A$1:$GZ$1,0)),0),MATCH("email_status",Enrichment!$A$1:$GZ$1,0))&"","")="verified",IFERROR(INDEX(Enrichment!$A$2:$GZ$2000,MATCH($A7,INDEX(Enrichment!$A$2:$GZ$2000,0,MATCH("row_id",Enrichment!$A$1:$GZ$1,0)),0),MATCH("email_status",Enrichment!$A$1:$GZ$1,0))&"","")="unverified"),IFERROR(INDEX(Enrichment!$A$2:$GZ$2000,MATCH($A7,INDEX(Enrichment!$A$2:$GZ$2000,0,MATCH("row_id",Enrichment!$A$1:$GZ$1,0)),0),MATCH("email_status",Enrichment!$A$1:$GZ$1,0))&"",""),"unverified"))) -> none | BE7: pantry or office lead (primary) | BF7: crowd-listed | BG7: The Org (crowd-edited org chart) | BH7: https://theorg.com/org/nayya/person/phoebe-waxman | BI7: 2026-10-24 | BJ7: exact | BK7: find Phoebe Waxman at Nayya on LinkedIn and paste the profile URL into primary_linkedin_url (this also confirms the name: The Org is crowd-edited and marks it Unverified) | BL7: contact in the target titles named (Senior People Operations Analyst) (crowd-listed on The Org) | BM7: Amber | BN7: Hewko | BO7: Executive Assistant | BQ7: =IF($A7="","",IFERROR(INDEX(Enrichment!$A$2:$GZ$2000,MATCH($A7,INDEX(Enrichment!$A$2:$GZ$2000,0,MATCH("row_id",Enrichment!$A$1:$GZ$1,0)),0),MATCH("backup_work_email",Enrichment!$A$1:$GZ$1,0))&"","")) | BR7: =IF($A7="","",IF(BQ7="","none",IF(OR(IFERROR(INDEX(Enrichment!$A$2:$GZ$2000,MATCH($A7,INDEX(Enrichment!$A$2:$GZ$2000,0,MATCH("row_id",Enrichment!$A$1:$GZ$1,0)),0),MATCH("backup_email_status",Enrichment!$A$1:$GZ$1,0))&"","")="verified",IFERROR(INDEX(Enrichment!$A$2:$GZ$2000,MATCH($A7,INDEX(Enrichment!$A$2:$GZ$2000,0,MATCH("row_id",Enrichment!$A$1:$GZ$1,0)),0),MATCH("backup_email_status",Enrichment!$A$1:$GZ$1,0))&"","")="unverified"),IFERROR(INDEX(Enrichment!$A$2:$GZ$2000,MATCH($A7,INDEX(Enrichment!$A$2:$GZ$2000,0,MATCH("row_id",Enrichment!$A$1:$GZ$1,0)),0),MATCH("backup_email_status",Enrichment!$A$1:$GZ$1,0))&"",""),"unverified"))) -> none | BS7: pantry or office lead (backup) | BT7: crowd-listed | BU7: The Org (crowd-edited org chart) | BV7: https://theorg.com/org/nayya/person/amber-hewko | BW7: 2026-10-24 | BX7: adjacent | BY7: find Amber Hewko at Nayya on LinkedIn and paste the profile URL into backup_linkedin_url (this also confirms the name: The Org is crowd-edited and marks it Unverified); the source is dated 2025-05-30: check Amber still holds the role; check Amber works from the New York office; adjacent title: ask who runs the pantry | BZ7: adjacent contact named (Executive Assistant) (crowd-listed on The Org) | CA7: Tuesday estimate 50 to 134 (low confidence), under 500 staff company-wide, hybrid 3 days, occupied at a high-confidence address | CB7: linkedin | CC7: Phoebe Waxman | CD7: 2026-01-24 | CE7: ny_base=likely (The Org gives a New York location, no office attached); title_fit=family (people operations). The Org updated 2026-01-24. Nayya has advertised a 5-days-in-office NYC Office Manager role (search results: builtinnyc.com/job/office-manager/297301, venturefizz, not opened); no name found for that seat. | CF7: likely | CH7: Amber Hewko | CI7: 2025-05-30 | CJ7: ny_base=unconfirmed (no location or office on The Org); title_fit=variant (The Org shows her reporting to the CEO, Sarah Liebel). The Org updated 2025-05-30. | CK7: unconfirmed | CM7: Y | CN7: pass | CO7: passes all hard gates | CP7: company | CQ7: B-C-037 | CR7: https://www.nayya.com | CS7: benefits software (health tech) | CT7: 150 | CU7: 200 | CV7: unknown | CW7: unknown | CX7: disagree | CY7: https://www.builtinnyc.com/company/nayya | CZ7: https://www.reveliolabs.com/companies/nayya-health/employees | DA7: le500 | DB7: New York | DC7: Y | DD7: unknown | DE7: https://www.linkedin.com/company/64515483 | DF7: 10003 | DG7: 40.73686 | DH7: -73.988546 | DI7: Y | DJ7: 0 | DK7: B-B-016 | DL7: 215 Park Avenue South (SL Green managed) | DM7: https://www.sec.gov/Archives/edgar/data/1013454/000153949726000704/n5676_x5-424h.htm | DN7: 2026-02 | DO7: other | DP7: https://www.nyrej.com/sl-green-signs-29-915-s-f-lease-with-nayya-health-at-215-park-ave-south | DQ7: 2024-12-10 | DR7: cites a sec.gov filing: agents do not open it (EDGAR demands a contact email); the founder may open it in a browser | DS7: high | DU7: N | DX7: security desk | DY7: https://www.metro-manhattan.com/buildings/215-park-avenue-south/ | EA7: unknown | EB7: N | EC7: Built In workplace type: Hybrid Workplace; typical time on-site: 3 days a week; recent job tags: 3 Hybrid | ED7: https://www.builtinnyc.com/company/nayya/offices | EE7: 2026-10-24 | EF7: 82 | EH7: N | EI7: 150 (Built In) and 200 (Revelio Labs) staff (whole-company count) x 50% to 100% of them in the New York office (HQ New York; share assumed) x 67% (Partnership for NYC, firms under 500) in on a weekday = 50 to 134, central 82; low confidence; estimate until intake replaces it. | EJ7: estimate until intake replaces it | EK7: 1 | EL7: 75 | EM7: 25 | EN7: 15 | EO7: 10 | EP7: 15 | EQ7: =IF($A7="","",IF(AH7="exact",10,IF(AH7="adjacent",5,0))) -> 0 | ER7: =IF($A7="","",IF(R7="Y",15,0)) -> 0 | ES7: candidate | EV7: 29,915 sf;12,660 sf | EW7: B's sources | EX7: SEC CMBS prospectus (Benchmark 2026-B42), rent roll dated 2026-02-05: Nayya Health Inc. 29,915 sf, lease to 2029-12-31, subleases its 18th-floor part (12,660 sf) to BaseTen Labs. NYREJ 2024-12-10: entire 4th floor plus part of 18th. Built In NYC: 150 total employees, HQ New York. | Assembly 2026-10-24: SEC EDGAR source (sec.gov): this agent will not re-open it, because EDGAR serves only requests that carry a contact email and the project rule forbids sending one; the founder may open it in a browser. Review round 2: band changed from 76-150 to unknown. Sources disagree: Built In shows 150 (76-150) and Revelio Labs (Nayya Health, Inc., HQ New York City): about 200 employees worldwide as of March 2026 (151-250). Band left unknown; founder to confirm at intake. Review round 2: corner lot: the lot-centroid pin sat 20 m from E 18 ST but 39 m from PARK AVE S, so it was moved to the PARK AVE S frontage near the corner (14 m from the PARK AVE S centreline, 26 m from E 18 ST; 26 m from the old pin). Tax lot unchanged. | EZ7: linked from the company's own site (https://www.nayya.com/, opened 2026-10-24); LinkedIn not opened | FS7: =IF($A7="","",IF(ISNUMBER(MATCH(U7,{"queued","contacted","replied","call_booked","call_done","yes_in_principle","materials_sent"},0)),"Y","N")) -> N | FT7: =IF($A7="","",IF(OR(T7="Y",U7="do_not_contact",AS7&""<>""),"Y","N")) -> N | FU7: =IF($A7="","",IF(AP7&""<>"",AP7&"",$A7)) -> AO-C-037 | FV7: =IF($A7="","",IF(COUNTIFS($FU$2:$FU$1000,FU7,$FS$2:$FS$1000,"Y")+COUNTIFS($FU$2:$FU$1000,FU7,$FT$2:$FT$1000,"Y")>0,"Y","N")) -> N | FW7: =IF($A7="","",IF(AND(U7="new",T7="N",FT7="N",AT7="Y",FV7="N"),"Y","N")) -> N | FX7: =IF($A7="","",IF(FW7<>"Y","N",IF(COUNTIFS($FU$2:$FU$1000,FU7,$FW$2:$FW$1000,"Y",$J$2:$J$1000,">"&J7)+COUNTIFS($FU$2:$FU$1000,FU7,$FW$2:$FW$1000,"Y",$J$2:$J$1000,J7,$GD$2:$GD$1000,"<"&GD7)=0,"Y","N"))) -> N | FY7: =IF($A7="","",IF(AND(FW7="Y",FX7="Y",Y7&""<>""),IF(Y7<=10,"Y","N"),"N")) -> N | FZ7: =IF(FY7="Y",Y7,"") | GA7: =IF($A7="","",IF(AND(I7="walk-in",CN7="pass",U7="new",FT7="N",FV7="N",AQ7<>"Y"),"Y","N")) -> N | GB7: =IF(GA7<>"Y","",IF(COUNTIFS($GA$2:$GA$1000,"Y",$J$2:$J$1000,">"&J7)+COUNTIFS($GA$2:$GA$1000,"Y",$J$2:$J$1000,J7,$GD$2:$GD$1000,"<"&GD7)+1<=25,COUNTIFS($GA$2:$GA$1000,"Y",$J$2:$J$1000,">"&J7)+COUNTIFS($GA$2:$GA$1000,"Y",$J$2:$J$1000,J7,$GD$2:$GD$1000,"<"&GD7)+1,"")) | GC7: =IF(AND(_xlfn.ISFORMULA(C7),_xlfn.ISFORMULA(J7)),"Y","N") -> N | GD7: =ROW()-1 -> 6
