Workbook

Sheet README
A1: =Inputs!$C$8&" financial model v1: README" -> Desk Drop financial model v1: README
A2: Version 1, built 2026-10-23 to 2026-10-24. The company name lives in one cell (Inputs, section 1, 'Company name'); rename it there only.
A5: What this workbook is
A6: The workbook you open every week for six months to see whether the business is working. It answers three questions: what each drop earns per founder hour, how low cumulative cash goes and when, and which gate or decision scenario the real numbers point to.
A7: Every number is a planning estimate from plan.md or the legal pack, never a forecast; fees the legal pack verified say 'verified' and the date on Inputs. Every assumption sits in one labeled cell on Inputs with its unit and source. Every other number is a formula. Change one input and every output moves. The only typed figures outside Inputs are the plan's own numbers, kept for comparison on purpose: the Plan_Check cases, the plan columns on Capital, and the 'Plan reading (e), fixed for comparison' row on Steady_State.
A9: Your weekly routine (about ten minutes)
A10: 1. Log hours | B10: Add the week's hours on Hours_Log (one row per entry: date, drop_id or blank, activity key, hours). If you use a paid Toggl plan, paste its export on Toggl_Import instead.
A11: 2. Log the pipeline | B11: Paste or type outreach events on Pipeline: conversations, yeses, signed offices with Tuesday headcount, paid brands, budget-probe answers, renewal answers.
A12: 3. After each drop | B12: Paste the campaign actuals and drop costs from the operations exports into Actuals_Campaigns and Actuals_DropCosts. Set 'Actuals in' to Y for that drop on Schedule once revenue, payments, direct costs and hours are final (by T+10, the debrief). code_redemptions_day30 (T+30) and renewal answers can be filled in later: they move no money or hours. The Gate 3 rate stays 'not yet' until every standard run dated by the review has actuals in. Dates must arrive as real dates and amounts as numbers: if Checks says 'stored as text', see 'Dates and amounts' below.
A13: 4. Read the Dashboard | B13: Next to 'Checks' it should say 'all integrity and data checks pass'; if not, open Checks first, because a failing data check means pasted rows are being ignored. Gates show pass, miss or not yet against real numbers only. The headline shows the next drop's contribution per hour, the price in force, the lowest point of cash and the gap to the plan's $6,510.
A14: 5. Check against the bank (optional) | B14: Type your actual bank balance at the end of the week on Cash_Flow, row 30. Row 31 shows the variance against the model; the summary shows the latest week.
A15: 6. Keep the plan current | B15: Edit Schedule when a date, delivery model or brand count changes. Edit Inputs when a quote comes in. The 'Changed?' column records every edit against the plan default.
A17: Change the price and read the result in under a minute
A18: Whole model | B18: ="Inputs, section 3, 'Standard price per office' (now "&TEXT(Inputs!$C$39,"$#,##0")&"). Type a new number. On the Dashboard read 'Price in force' (it shows your number), then "&"'A standard drop at that price: contribution per founder hour' (the next row), 'Standard runs to Gate 3' and the drop table at the bottom. "&"'Its contribution per founder hour' does not move: the next drop is campaign zero, at the founding rate." -> Inputs, section 3, 'Standard price per office' (now $150). Type a new number. On the Dashboard read 'Price in force' (it shows your number), then 'A standard drop at that price: contribution per founder hour' (the next row), 'Standard runs to Gate 3' and the drop table at the bottom. 'Its contribution per founder hour' does not move: the next drop is campaign zero, at the founding rate.
A19: One drop only | B19: Calculator: type a price in 'Standard price per office'. The result column shows revenue, costs, hours and contribution per founder hour. Nothing else changes.
A20: Many prices at once | B20: Sensitivity, Table 1: contribution per founder hour for eight prices and one to five brands. Green cells clear the $50 Gate 3 target.
A22: Tabs, in the order you use them
A23: Dashboard | B23: Headline numbers; cash at each stop point (paid out, brand cash received, refunds owed on campaigns not yet run, and the net if you stop at each gate); every gate threshold beside its live value with pass, miss or not yet; the decision rule, the scenario the numbers point to, six-month goals, and contribution per hour on each drop.
A24: Inputs | B24: Every assumption: prices, payment terms and lags, the processing toggle, units, every hard-cost line, monthly overhead, hours by activity, the delivery-model table, renewal, gates, startup outlays with timing, the start date. Yellow cells are inputs.
A25: Scenarios | B25: The plan's decision situations A to D as assumption sets, beside the plan base. Pick one on Inputs. It drives the two decision-window drops and the steady state.
A26: Schedule | B26: The editable drop schedule: date, delivery model, tier, offices, new offices, brands, renewals, and the switch to actuals. Checks Tuesday or Wednesday and every blackout. Columns Y to AE show the brand wins and qualified conversations each drop needs, cumulated to its sign-by date, beside the Pipeline's actual counts; AF to AH flag a decision-window drop whose debrief lands after the decision date; AI shows the offices to add so no office gets two drops within four weeks. A drop you add takes the next spare drop_id (DRP-006 onward) and may sit out of date order: that is fine, because every total, the cash flow and the Dashboard's next drop read dates, not row order. Never re-sort the rows: the drop_id is the key every actuals file uses.
A27: Calculator | B27: A single drop of any tier, brand count, office count and delivery model, run through the same engine.
A28: Drop_PnL | B28: Per-drop P&L on the plan basis for every scheduled drop, with hours by activity, contribution per founder hour, cash timing on the plan's terms, and live values (actual where in).
A29: Cash_Flow | B29: Weekly cash flow for 26 weeks with a monthly cross-check: brand receipts, direct costs, overhead paid once, startup outlays at their timing, cumulative cash and its lowest point. Row 30 takes your actual bank balance; row 31 shows the variance. Below the monthly view: overhead not absorbed, and insurance prepaid beyond the six months.
A30: Steady_State | B30: The plan's monthly picture reproduced (row 7, fixed for comparison), a standard drop on today's Inputs (row 8), the scenario in force at steady state, and break-even: campaigns to recover startup cash, campaigns a month to cover overhead, the brand count and price where contribution per hour crosses $50. Every break-even line follows Inputs.
A31: Sensitivity | B31: Four plain-formula tables: price x brands, renewal x brands, renewal against the monthly steady state, price against the monthly steady state. Direction checks at the bottom.
A32: Plan_Check | B32: The plan's five scenario rows, the $1,000 reading, edge cases, the founder-hour table cell by cell, and a reconciliation of every plan figure: plan, model, difference, reason.
A33: Capital | B33: The plan's capital table line by line, where the model pays each line, and the cash the plan's table leaves out.
A34: Hours_Log | B34: The hand-filled hours log by the seven activity keys, with totals per drop and per week.
... A41: Lists | B41: Fixed keys (delivery model, tier, activities, events), federal holidays and blackouts. Add holidays or blackouts in the blank yellow rows.
A43: Colours and conventions
A44: Yellow cell, blue text | B44: An input. Type here.
A45: Blue cell | B45: An input whose default follows another cell (a gate date, Inputs or the scenario in force). Type over it to replace; the 'Changed' flag records it.
A46: Grey cell | B46: Calculated on the Inputs tab. Do not type over it.
A47: Green cell | B47: A key output.
A48: Formulas | B48: No numeric literal other than 0 or 1 appears in any formula; conversions such as days per week sit in input cells. _work/audit_formulas.py checks this.
A49: Signs | B49: Cash outflows are negative on Cash_Flow. Costs are positive on the P&L tabs.
A50: Dates | B50: YYYY-MM-DD. Week 1 starts Monday 2026-10-26 (CONTRACTS section 3). Moving week 1 does not move the gate or drop dates, which are typed CONTRACTS dates: move them too (Checks flags week 1 moved on its own).
A51: Dates and amounts must be real dates and numbers | B51: Every date window and every amount is a SUMIFS, so a date or amount stored as text drops out of the cash flow and the gates with no error. Checks has one 'stored as text' line per paste tab, and the Dashboard banner turns red. To avoid it: bring the CSV in with File, Import, 'Replace data starting at selected cell', with cell A4 of the tab selected (support.google.com/docs/answer/40608, opened 2026-10-24); if the dialog offers to convert text to numbers and dates, leave it on (unverified, founder to confirm). To fix a column that is already text: put =DATEVALUE(cell) for a date or =VALUE(cell) for an amount in a spare column, copy it, paste it back over the original column as values only, and clear the spare column. A format change alone may leave stored text as text, so read the Checks line again after the fix.
A53: Plan readings (each verified by Plan_Check; none is a fudge)
...

Sheet Dashboard
A1: =Inputs!$C$8&" financial model v1" -> Desk Drop financial model v1
A2: =Inputs!$C$9 -> Emerging brands. Delivered to your workday.
A3: Planning estimates, not a forecast. Gates count real numbers only (pipeline log and actuals). Change assumptions on Inputs; type real numbers into the logs.
A4: SAMPLE DATA. A scratch copy loaded with SAMPLE exports from campaign-ops. Illustrative placeholders, not results.
B5: As of | C5: =Inputs!$C$17 -> 46430 | D5: Scenario | E5: =Inputs!$C$35 -> Plan base | F5: Checks | G5: =IF(Checks!$D$45>0,Checks!$D$45&" integrity check(s) failing: see Checks",IF(Checks!$D$46>0,Checks!$D$46&" data check(s) failing: pasted rows are ignored or misread (see Checks)","all integrity and data checks pass")) -> all integrity and data checks pass
A7: Headline
B8: Measure | C8: Value | D8: Detail
B9: Next scheduled drop | C9: =IFERROR(INDEX(Drop_PnL!$A$7:$A$18,MATCH(MIN(Drop_PnL!$BJ$7:$BJ$18),Drop_PnL!$BJ$7:$BJ$18,0)),"none scheduled") -> DRP-003 | D9: =IFERROR(TEXT(INDEX(Drop_PnL!$B$7:$B$18,MATCH(MIN(Drop_PnL!$BJ$7:$BJ$18),Drop_PnL!$BJ$7:$BJ$18,0)),"ddd yyyy-mm-dd")&", "&INDEX(Drop_PnL!$C$7:$C$18,MATCH(MIN(Drop_PnL!$BJ$7:$BJ$18),Drop_PnL!$BJ$7:$BJ$18,0))&", "&INDEX(Drop_PnL!$G$7:$G$18,MATCH(MIN(Drop_PnL!$BJ$7:$BJ$18),Drop_PnL!$BJ$7:$BJ$18,0))&" brand(s), "&INDEX(Drop_PnL!$E$7:$E$18,MATCH(MIN(Drop_PnL!$BJ$7:$BJ$18),Drop_PnL!$BJ$7:$BJ$18,0))&" offices, "&INDEX(Drop_PnL!$D$7:$D$18,MATCH(MIN(Drop_PnL!$BJ$7:$BJ$18),Drop_PnL!$BJ$7:$BJ$18,0))&" tier","") -> Tue 2027-02-23, courier, 3 brand(s), 10 offices, standard tier
B10: Its contribution per founder hour (plan) | C10: =IFERROR(INDEX(Drop_PnL!$AK$7:$AK$18,MATCH(MIN(Drop_PnL!$BJ$7:$BJ$18),Drop_PnL!$BJ$7:$BJ$18,0)),"n/a") -> 66.034483 | D10: =IFERROR("revenue "&TEXT(INDEX(Drop_PnL!$S$7:$S$18,MATCH(MIN(Drop_PnL!$BJ$7:$BJ$18),Drop_PnL!$BJ$7:$BJ$18,0)),"$#,##0")&", "&TEXT(INDEX(Drop_PnL!$AI$7:$AI$18,MATCH(MIN(Drop_PnL!$BJ$7:$BJ$18),Drop_PnL!$BJ$7:$BJ$18,0)),"0")&" founder hours; campaign zero is at the founding rate, so the standard price does not move it","") -> revenue $4,500, 58 founder hours; campaign zero is at the founding rate, so the standard price does not move it
B11: Price in force: standard price per office (Inputs, section 3) | C11: =Inputs!$C$39 -> 150 | D11: ="standard package "&TEXT(Inputs!$C$41,"$#,##0")&" for "&Inputs!$C$40&" offices; founding "&TEXT(Inputs!$C$42,"$#,##0")&" per office. Change the price on Inputs and read the next row." -> standard package $1,500 for 10 offices; founding $120 per office. Change the price on Inputs and read the next row.
B12: A standard drop at that price: contribution per founder hour | C12: =Steady_State!$AK$8 -> 73.653846 | D12: =Steady_State!$G$8&" new brands, "&Steady_State!$E$8&" offices, "&Steady_State!$C$8&": revenue "&TEXT(Steady_State!$S$8,"$#,##0")&", contribution "&TEXT(Steady_State!$AJ$8,"$#,##0")&", "&TEXT(Steady_State!$AI$8,"0")&" founder hours" -> 3 new brands, 10 offices, courier: revenue $4,500, contribution $3,830, 52 founder hours
B13: Standard runs to Gate 3: contribution per founder hour, plan | C13: =IF(E54="","n/a",E54) -> 61.28 | D13: ="actual: "&IF(F54="","not yet",TEXT(F54,"$#,##0.0"))&" ("&F55&" of "&D55&" standard runs with actuals in); target "&TEXT(Inputs!$C$136,"$#,##0") -> actual: not yet (0 of 2 standard runs with actuals in); target $50
B14: Same, if the roster grows so no office gets two drops within four weeks | C14: =IF(SUMIFS(Drop_PnL!$AI$7:$AI$18,Drop_PnL!$D$7:$D$18,"standard",Drop_PnL!$B$7:$B$18,"<="&Inputs!$C$14)+(SUMIFS(Schedule!$AI$7:$AI$18,Schedule!$H$7:$H$18,"standard",Schedule!$E$7:$E$18,"<="&Inputs!$C$14))*(Inputs!$C$95-Inputs!$C$96)>0,SUMIFS(Drop_PnL!$AJ$7:$AJ$18,Drop_PnL!$D$7:$D$18,"standard",Drop_PnL!$B$7:$B$18,"<="&Inputs!$C$14)/(SUMIFS(Drop_PnL!$AI$7:$AI$18,Drop_PnL!$D$7:$D$18,"standard",Drop_PnL!$B$7:$B$18,"<="&Inputs!$C$14)+(SUMIFS(Schedule!$AI$7:$AI$18,Schedule!$H$7:$H$18,"standard",Schedule!$E$7:$E$18,"<="&Inputs!$C$14))*(Inputs!$C$95-Inputs!$C$96)),"n/a") -> 51.409396 | D14: ="adds "&TEXT(SUMIFS(Schedule!$AI$7:$AI$18,Schedule!$H$7:$H$18,"standard",Schedule!$E$7:$E$18,"<="&Inputs!$C$14),"0")&" new offices and "&TEXT((SUMIFS(Schedule!$AI$7:$AI$18,Schedule!$H$7:$H$18,"standard",Schedule!$E$7:$E$18,"<="&Inputs!$C$14))*(Inputs!$C$95-Inputs!$C$96),"0")&" founder hours to the standard runs; the plan wants one drop per office a month (a roster of about 20)" -> adds 8 new offices and 24 founder hours to the standard runs; the plan wants one drop per office a month (a roster of about 20)
B15: Lowest point of cumulative cash (before founder cash) | C15: =Cash_Flow!$C$34 -> -4552 | D15: ="in week "&Cash_Flow!$C$35&", starting "&TEXT(Cash_Flow!$C$36,"ddd yyyy-mm-dd") -> in week 13, starting Mon 2027-01-18
B16: Capital to commit: lowest point plus the reserve | C16: =Cash_Flow!$C$39 -> 5552 | D16: ="reserve "&TEXT(Inputs!$C$117,"$#,##0")&" (plan)"&IF(Inputs!$C$175>0,"; counts "&Inputs!$C$175&" unpriced cost line(s) as $0 until quoted (Inputs, status needs quote or needs founder decision)","") -> reserve $1,000 (plan); counts 5 unpriced cost line(s) as $0 until quoted (Inputs, status needs quote or needs founder decision)
B17: Plan capital figure (high end of the plan's table) | C17: =Capital!$D$14 -> 6510 | D17: ="low end "&TEXT(Capital!$C$14,"$#,##0") -> low end $3,360
B18: Gap to the plan capital figure (positive = headroom) | C18: =Cash_Flow!$C$41 -> 958 | D18: =IF(C18>=0,"the plan figure covers the model need","the model needs more than the plan figure") -> the plan figure covers the model need
B19: Founder cash committed | C19: =Cash_Flow!$C$42 -> not set | D19: =IF(Inputs!$C$115="","set it on Inputs (plan question 7)",IF(Inputs!$C$115>=Cash_Flow!$C$39,"covers capital to commit","short of capital to commit by "&TEXT(Cash_Flow!$C$39-Inputs!$C$115,"$#,##0"))) -> set it on Inputs (plan question 7)
B20: Overhead paid but not absorbed by drops, six months (cash) | C20: =Cash_Flow!$C$72 -> 1310 | D20: ="paid "&TEXT(Cash_Flow!$C$71,"$#,##0")&", allocated to drops "&TEXT(Cash_Flow!$C$70,"$#,##0")&"; of that gap, "&TEXT(Cash_Flow!$C$75,"$#,##0")&" is insurance prepaid beyond the six months and the rest is ramp-up months with few drops" -> paid $2,010, allocated to drops $700; of that gap, $700 is insurance prepaid beyond the six months and the rest is ramp-up months with few drops
B21: Six months all-in per founder hour: roadmap drops only (to Gate 3) | C21: =IF((SUMIFS(Drop_PnL!$BC$7:$BC$18,Drop_PnL!$B$7:$B$18,"<="&Inputs!$C$14)+MAX(Inputs!$C$100*Inputs!$C$101,Hours_Log!$Z$53))>0,(SUMIFS(Drop_PnL!$BD$7:$BD$18,Drop_PnL!$B$7:$B$18,"<="&Inputs!$C$14)+SUMIFS(Drop_PnL!$AM$7:$AM$18,Drop_PnL!$B$7:$B$18,">="&Inputs!$C$10,Drop_PnL!$B$7:$B$18,"<="&Inputs!$C$14)-Cash_Flow!$C$76)/(SUMIFS(Drop_PnL!$BC$7:$BC$18,Drop_PnL!$B$7:$B$18,"<="&Inputs!$C$14)+MAX(Inputs!$C$100*Inputs!$C$101,Hours_Log!$Z$53)),"n/a") -> 33.427313 | D21: ="campaign zero and the standard runs, with all six months of overhead (expensed basis) and "&IF(Hours_Log!$Z$53>Inputs!$C$100*Inputs!$C$101,TEXT(Hours_Log!$Z$53,"0")&" logged hours not tied to a drop",TEXT(Inputs!$C$100*Inputs!$C$101,"0")&" planned discovery hours")&"; after one-time startup outlays: "&IF((SUMIFS(Drop_PnL!$BC$7:$BC$18,Drop_PnL!$B$7:$B$18,"<="&Inputs!$C$14)+MAX(Inputs!$C$100*Inputs!$C$101,Hours_Log!$Z$53))>0,TEXT(((SUMIFS(Drop_PnL!$BD$7:$BD$18,Drop_PnL!$B$7:$B$18,"<="&Inputs!$C$14)+SUMIFS(Drop_PnL!$AM$7:$AM$18,Drop_PnL!$B$7:$B$18,">="&Inputs!$C$10,Drop_PnL!$B$7:$B$18,"<="&Inputs!$C$14)-Cash_Flow!$C$76)-Inputs!$Q$172)/(SUMIFS(Drop_PnL!$BC$7:$BC$18,Drop_PnL!$B$7:$B$18,"<="&Inputs!$C$14)+MAX(Inputs!$C$100*Inputs!$C$101,Hours_Log!$Z$53)),"$#,##0.0"),"n/a")&" per hour" -> campaign zero and the standard runs, with all six months of overhead (expensed basis) and 45 planned discovery hours; after one-time startup outlays: $15.3 per hour
B22: Six months all-in per founder hour: with the decision-window drops (derived, not in the plan's roadmap) | C22: =IF((SUMIFS(Drop_PnL!$BC$7:$BC$18,Drop_PnL!$B$7:$B$18,"<="&Cash_Flow!$AB$6)+MAX(Inputs!$C$100*Inputs!$C$101,Hours_Log!$Z$53))>0,(SUMIFS(Drop_PnL!$BD$7:$BD$18,Drop_PnL!$B$7:$B$18,"<="&Cash_Flow!$AB$6)+SUMIFS(Drop_PnL!$AM$7:$AM$18,Drop_PnL!$B$7:$B$18,">="&Inputs!$C$10,Drop_PnL!$B$7:$B$18,"<="&Cash_Flow!$AB$6)-Cash_Flow!$C$76)/(SUMIFS(Drop_PnL!$BC$7:$BC$18,Drop_PnL!$B$7:$B$18,"<="&Cash_Flow!$AB$6)+MAX(Inputs!$C$100*Inputs!$C$101,Hours_Log!$Z$53)),"n/a") -> 52.291262 | D22: ="adds "&COUNTIFS(Drop_PnL!$B$7:$B$18,">"&Inputs!$C$14,Drop_PnL!$B$7:$B$18,"<="&Cash_Flow!$AB$6,Drop_PnL!$N$7:$N$18,1)&" drop(s) after Gate 3, with "&IF(Hours_Log!$Z$53>Inputs!$C$100*Inputs!$C$101,TEXT(Hours_Log!$Z$53,"0")&" logged hours not tied to a drop",TEXT(Inputs!$C$100*Inputs!$C$101,"0")&" planned discovery hours")&"; insurance prepaid beyond the window ("&TEXT(Cash_Flow!$C$75,"$#,##0")&") is left out; after one-time startup outlays: "&IF((SUMIFS(Drop_PnL!$BC$7:$BC$18,Drop_PnL!$B$7:$B$18,"<="&Cash_Flow!$AB$6)+MAX(Inputs!$C$100*Inputs!$C$101,Hours_Log!$Z$53))>0,TEXT(((SUMIFS(Drop_PnL!$BD$7:$BD$18,Drop_PnL!$B$7:$B$18,"<="&Cash_Flow!$AB$6)+SUMIFS(Drop_PnL!$AM$7:$AM$18,Drop_PnL!$B$7:$B$18,">="&Inputs!$C$10,Drop_PnL!$B$7:$B$18,"<="&Cash_Flow!$AB$6)-Cash_Flow!$C$76)-Inputs!$Q$172)/(SUMIFS(Drop_PnL!$BC$7:$BC$18,Drop_PnL!$B$7:$B$18,"<="&Cash_Flow!$AB$6)+MAX(Inputs!$C$100*Inputs!$C$101,Hours_Log!$Z$53)),"$#,##0.0"),"n/a")&" per hour" -> adds 2 drop(s) after Gate 3, with 45 planned discovery hours; insurance prepaid beyond the window ($700) is left out; after one-time startup outlays: $38.9 per hour
B23: Cumulative cash at week 26: roadmap drops only | C23: =Cash_Flow!$C$44-SUMIFS(Drop_PnL!$BI$7:$BI$18,Drop_PnL!$B$7:$B$18,">"&Inputs!$C$14) -> 2763 | D23: ="the decision-window drops add "&TEXT(C24-C23,"$#,##0")&" by week 26" -> the decision-window drops add $8,570 by week 26
B24: Cumulative cash at week 26: with the decision-window drops (derived) | C24: =Cash_Flow!$C$44 -> 11333 | D24: ="before founder cash; lowest balance with founder cash "&IF(Inputs!$C$115="","(founder cash not set)",TEXT(Cash_Flow!$C$43,"$#,##0")) -> before founder cash; lowest balance with founder cash (founder cash not set)
B25: Steady state, scenario in force: contribution per month | C25: =Steady_State!$D$27 -> 7660 | D25: ="per founder hour "&IF(ISNUMBER(Steady_State!$D$28),TEXT(Steady_State!$D$28,"$#,##0.0"),"n/a")&"; net of all overhead "&TEXT(Steady_State!$D$39,"$#,##0")&" a month"&IF(AND(N(Scenarios!$H$17)>0,Scenarios!$R$19=1),"; office-paid revenue left out of the net until its cost to serve is quoted","") -> per founder hour $81.1; net of all overhead $7,660 a month
B26: Office-fatigue warnings on Schedule | C26: =COUNTIF(Schedule!$W$7:$W$18,"some*") -> 2 | D26: =IF(C26=0,"no office gets two drops within four weeks","drops where some offices get a second drop within four weeks (plan: one drop a month); see the Gate 3 rate with a bigger roster above") -> drops where some offices get a second drop within four weeks (plan: one drop a month); see the Gate 3 rate with a bigger roster above
B27: Decision-window drops whose debrief (T+10) lands after the decision date | C27: =COUNTIF(Schedule!$AG$7:$AG$18,"after the decision") -> 1 | D27: =IF(C27=0,"every decision-window drop reports by the decision date","last debrief "&TEXT(MAX(Schedule!$AH$7:$AH$18),"ddd yyyy-mm-dd")&", after the "&TEXT(Inputs!$C$15,"ddd yyyy-mm-dd")&" decision: the switch test cannot finish in time (REPORT.md, question 1)") -> last debrief Tue 2027-04-20, after the Fri 2027-04-09 decision: the switch test cannot finish in time (REPORT.md, question 1)
B28: Schedule rows changed or added since the derived default | C28: =COUNTIF(Schedule!$X$7:$X$18,"changed") -> 0 | D28: =IF(C28=0,"schedule is the derived default","edited by you") -> schedule is the derived default
B29: Inputs changed from plan defaults | C29: =Inputs!$C$174 -> 1 | D29: =IF(Checks!$D$47=0,"plan figures reproduce","plan reproduction differs in "&Checks!$D$47&" check(s); expected after edits") -> plan figures reproduce
A31: Cash at each stop point (before founder cash)
B32: Review | C32: Date | D32: Paid out before the review day (gross; no brand money) | E32: Brand cash received by the review day | F32: Refunds owed if you stop: payments received for drops not yet run | G32: Net if you stop here: paid out + received - refunds | H32: Cumulative net cash at the end of that week, if every gate passes
B33: Gate 0 | C33: =Inputs!$C$11 -> 46339 | D33: =-SUMIFS(Drop_PnL!$T$7:$T$18,Drop_PnL!$AX$7:$AX$18,">="&Inputs!$C$10,Drop_PnL!$AX$7:$AX$18,"<="&(Inputs!$C$11-1),Drop_PnL!$AZ$7:$AZ$18,"N")-SUMIFS(Drop_PnL!$U$7:$U$18,Drop_PnL!$AY$7:$AY$18,">="&Inputs!$C$10,Drop_PnL!$AY$7:$AY$18,"<="&(Inputs!$C$11-1),Drop_PnL!$AZ$7:$AZ$18,"N")-SUMIFS(Drop_PnL!$V$7:$V$18,Drop_PnL!$AX$7:$AX$18,">="&Inputs!$C$10,Drop_PnL!$AX$7:$AX$18,"<="&(Inputs!$C$11-1),Drop_PnL!$AZ$7:$AZ$18,"N")-(SUMIFS(Drop_PnL!$AU$7:$AU$18,Drop_PnL!$AO$7:$AO$18,">="&Inputs!$C$10,Drop_PnL!$AO$7:$AO$18,"<="&(Inputs!$C$11-1),Drop_PnL!$AZ$7:$AZ$18,"N")+SUMIFS(Drop_PnL!$AV$7:$AV$18,Drop_PnL!$AQ$7:$AQ$18,">="&Inputs!$C$10,Drop_PnL!$AQ$7:$AQ$18,"<="&(Inputs!$C$11-1),Drop_PnL!$AZ$7:$AZ$18,"N")+SUMIFS(Drop_PnL!$AW$7:$AW$18,Drop_PnL!$AS$7:$AS$18,">="&Inputs!$C$10,Drop_PnL!$AS$7:$AS$18,"<="&(Inputs!$C$11-1),Drop_PnL!$AZ$7:$AZ$18,"N"))-(SUMIFS(Actuals_DropCosts!$F$5:$F$104,Actuals_DropCosts!$B$5:$B$104,">="&Inputs!$C$10,Actuals_DropCosts!$B$5:$B$104,"<="&(Inputs!$C$11-1),Actuals_DropCosts!$U$5:$U$104,"Y")+SUMIFS(Actuals_DropCosts!$G$5:$G$104,Actuals_DropCosts!$B$5:$B$104,">="&Inputs!$C$10,Actuals_DropCosts!$B$5:$B$104,"<="&(Inputs!$C$11-1),Actuals_DropCosts!$U$5:$U$104,"Y")+SUMIFS(Actuals_DropCosts!$H$5:$H$104,Actuals_DropCosts!$B$5:$B$104,">="&Inputs!$C$10,Actuals_DropCosts!$B$5:$B$104,"<="&(Inputs!$C$11-1),Actuals_DropCosts!$U$5:$U$104,"Y")+SUMIFS(Actuals_Campaigns!$T$5:$T$204,Actuals_Campaigns!$S$5:$S$204,">="&Inputs!$C$10,Actuals_Campaigns!$S$5:$S$204,"<="&(Inputs!$C$11-1),Actuals_Campaigns!$AL$5:$AL$204,"Y"))-SUMIFS(Cash_Ledger!$D$5:$D$53,Cash_Ledger!$C$5:$C$53,">="&Inputs!$C$10,Cash_Ledger!$C$5:$C$53,"<="&(Inputs!$C$11-1),Cash_Ledger!$A$5:$A$53,"software")-SUMIFS(Cash_Ledger!$D$5:$D$53,Cash_Ledger!$C$5:$C$53,">="&Inputs!$C$10,Cash_Ledger!$C$5:$C$53,"<="&(Inputs!$C$11-1),Cash_Ledger!$A$5:$A$53,"insurance")-SUMIFS(Cash_Ledger!$D$5:$D$53,Cash_Ledger!$C$5:$C$53,">="&Inputs!$C$10,Cash_Ledger!$C$5:$C$53,"<="&(Inputs!$C$11-1),Cash_Ledger!$A$5:$A$53,"storage")-SUMIFS(Cash_Ledger!$D$5:$D$53,Cash_Ledger!$C$5:$C$53,">="&Inputs!$C$10,Cash_Ledger!$C$5:$C$53,"<="&(Inputs!$C$11-1),Cash_Ledger!$A$5:$A$53,"phone")-SUMIFS(Inputs!$Q$158:$Q$171,Inputs!$R$158:$R$171,">="&Inputs!$C$10,Inputs!$R$158:$R$171,"<="&(Inputs!$C$11-1)) -> -160 | E33: =SUMIFS(Drop_PnL!$AP$7:$AP$18,Drop_PnL!$AO$7:$AO$18,">="&Inputs!$C$10,Drop_PnL!$AO$7:$AO$18,"<="&Inputs!$C$11,Drop_PnL!$AZ$7:$AZ$18,"N")+SUMIFS(Drop_PnL!$AR$7:$AR$18,Drop_PnL!$AQ$7:$AQ$18,">="&Inputs!$C$10,Drop_PnL!$AQ$7:$AQ$18,"<="&Inputs!$C$11,Drop_PnL!$AZ$7:$AZ$18,"N")+SUMIFS(Drop_PnL!$AT$7:$AT$18,Drop_PnL!$AS$7:$AS$18,">="&Inputs!$C$10,Drop_PnL!$AS$7:$AS$18,"<="&Inputs!$C$11,Drop_PnL!$AZ$7:$AZ$18,"N")+SUMIFS(Actuals_Campaigns!$X$5:$X$204,Actuals_Campaigns!$Y$5:$Y$204,">="&Inputs!$C$10,Actuals_Campaigns!$Y$5:$Y$204,"<="&Inputs!$C$11,Actuals_Campaigns!$AL$5:$AL$204,"Y")+SUMIFS(Actuals_Campaigns!$AM$5:$AM$204,Actuals_Campaigns!$S$5:$S$204,">="&Inputs!$C$10,Actuals_Campaigns!$S$5:$S$204,"<="&Inputs!$C$11,Actuals_Campaigns!$AL$5:$AL$204,"Y") -> 0 | F33: =SUMIFS(Drop_PnL!$AP$7:$AP$18,Drop_PnL!$AO$7:$AO$18,"<="&Inputs!$C$11,Drop_PnL!$B$7:$B$18,">"&Inputs!$C$11,Drop_PnL!$AZ$7:$AZ$18,"N")+SUMIFS(Drop_PnL!$AR$7:$AR$18,Drop_PnL!$AQ$7:$AQ$18,"<="&Inputs!$C$11,Drop_PnL!$B$7:$B$18,">"&Inputs!$C$11,Drop_PnL!$AZ$7:$AZ$18,"N")+SUMIFS(Drop_PnL!$AT$7:$AT$18,Drop_PnL!$AS$7:$AS$18,"<="&Inputs!$C$11,Drop_PnL!$B$7:$B$18,">"&Inputs!$C$11,Drop_PnL!$AZ$7:$AZ$18,"N")+SUMIFS(Actuals_Campaigns!$X$5:$X$204,Actuals_Campaigns!$Y$5:$Y$204,"<="&Inputs!$C$11,Actuals_Campaigns!$C$5:$C$204,">"&Inputs!$C$11,Actuals_Campaigns!$AL$5:$AL$204,"Y")+SUMIFS(Actuals_Campaigns!$AM$5:$AM$204,Actuals_Campaigns!$S$5:$S$204,"<="&Inputs!$C$11,Actuals_Campaigns!$C$5:$C$204,">"&Inputs!$C$11,Actuals_Campaigns!$AL$5:$AL$204,"Y") -> 0 | G33: =D33+E33-F33 -> -160 | H33: =SUMIFS(Cash_Flow!$C$26:$AB$26,Cash_Flow!$C$5:$AB$5,"<="&Inputs!$C$11) -> -160
B34: Gate 1 | C34: =Inputs!$C$12 -> 46367 | D34: =-SUMIFS(Drop_PnL!$T$7:$T$18,Drop_PnL!$AX$7:$AX$18,">="&Inputs!$C$10,Drop_PnL!$AX$7:$AX$18,"<="&(Inputs!$C$12-1),Drop_PnL!$AZ$7:$AZ$18,"N")-SUMIFS(Drop_PnL!$U$7:$U$18,Drop_PnL!$AY$7:$AY$18,">="&Inputs!$C$10,Drop_PnL!$AY$7:$AY$18,"<="&(Inputs!$C$12-1),Drop_PnL!$AZ$7:$AZ$18,"N")-SUMIFS(Drop_PnL!$V$7:$V$18,Drop_PnL!$AX$7:$AX$18,">="&Inputs!$C$10,Drop_PnL!$AX$7:$AX$18,"<="&(Inputs!$C$12-1),Drop_PnL!$AZ$7:$AZ$18,"N")-(SUMIFS(Drop_PnL!$AU$7:$AU$18,Drop_PnL!$AO$7:$AO$18,">="&Inputs!$C$10,Drop_PnL!$AO$7:$AO$18,"<="&(Inputs!$C$12-1),Drop_PnL!$AZ$7:$AZ$18,"N")+SUMIFS(Drop_PnL!$AV$7:$AV$18,Drop_PnL!$AQ$7:$AQ$18,">="&Inputs!$C$10,Drop_PnL!$AQ$7:$AQ$18,"<="&(Inputs!$C$12-1),Drop_PnL!$AZ$7:$AZ$18,"N")+SUMIFS(Drop_PnL!$AW$7:$AW$18,Drop_PnL!$AS$7:$AS$18,">="&Inputs!$C$10,Drop_PnL!$AS$7:$AS$18,"<="&(Inputs!$C$12-1),Drop_PnL!$AZ$7:$AZ$18,"N"))-(SUMIFS(Actuals_DropCosts!$F$5:$F$104,Actuals_DropCosts!$B$5:$B$104,">="&Inputs!$C$10,Actuals_DropCosts!$B$5:$B$104,"<="&(Inputs!$C$12-1),Actuals_DropCosts!$U$5:$U$104,"Y")+SUMIFS(Actuals_DropCosts!$G$5:$G$104,Actuals_DropCosts!$B$5:$B$104,">="&Inputs!$C$10,Actuals_DropCosts!$B$5:$B$104,"<="&(Inputs!$C$12-1),Actuals_DropCosts!$U$5:$U$104,"Y")+SUMIFS(Actuals_DropCosts!$H$5:$H$104,Actuals_DropCosts!$B$5:$B$104,">="&Inputs!$C$10,Actuals_DropCosts!$B$5:$B$104,"<="&(Inputs!$C$12-1),Actuals_DropCosts!$U$5:$U$104,"Y")+SUMIFS(Actuals_Campaigns!$T$5:$T$204,Actuals_Campaigns!$S$5:$S$204,">="&Inputs!$C$10,Actuals_Campaigns!$S$5:$S$204,"<="&(Inputs!$C$12-1),Actuals_Campaigns!$AL$5:$AL$204,"Y"))-SUMIFS(Cash_Ledger!$D$5:$D$53,Cash_Ledger!$C$5:$C$53,">="&Inputs!$C$10,Cash_Ledger!$C$5:$C$53,"<="&(Inputs!$C$12-1),Cash_Ledger!$A$5:$A$53,"software")-SUMIFS(Cash_Ledger!$D$5:$D$53,Cash_Ledger!$C$5:$C$53,">="&Inputs!$C$10,Cash_Ledger!$C$5:$C$53,"<="&(Inputs!$C$12-1),Cash_Ledger!$A$5:$A$53,"insurance")-SUMIFS(Cash_Ledger!$D$5:$D$53,Cash_Ledger!$C$5:$C$53,">="&Inputs!$C$10,Cash_Ledger!$C$5:$C$53,"<="&(Inputs!$C$12-1),Cash_Ledger!$A$5:$A$53,"storage")-SUMIFS(Cash_Ledger!$D$5:$D$53,Cash_Ledger!$C$5:$C$53,">="&Inputs!$C$10,Cash_Ledger!$C$5:$C$53,"<="&(Inputs!$C$12-1),Cash_Ledger!$A$5:$A$53,"phone")-SUMIFS(Inputs!$Q$158:$Q$171,Inputs!$R$158:$R$171,">="&Inputs!$C$10,Inputs!$R$158:$R$171,"<="&(Inputs!$C$12-1)) -> -3120 | E34: =SUMIFS(Drop_PnL!$AP$7:$AP$18,Drop_PnL!$AO$7:$AO$18,">="&Inputs!$C$10,Drop_PnL!$AO$7:$AO$18,"<="&Inputs!$C$12,Drop_PnL!$AZ$7:$AZ$18,"N")+SUMIFS(Drop_PnL!$AR$7:$AR$18,Drop_PnL!$AQ$7:$AQ$18,">="&Inputs!$C$10,Drop_PnL!$AQ$7:$AQ$18,"<="&Inputs!$C$12,Drop_PnL!$AZ$7:$AZ$18,"N")+SUMIFS(Drop_PnL!$AT$7:$AT$18,Drop_PnL!$AS$7:$AS$18,">="&Inputs!$C$10,Drop_PnL!$AS$7:$AS$18,"<="&Inputs!$C$12,Drop_PnL!$AZ$7:$AZ$18,"N")+SUMIFS(Actuals_Campaigns!$X$5:$X$204,Actuals_Campaigns!$Y$5:$Y$204,">="&Inputs!$C$10,Actuals_Campaigns!$Y$5:$Y$204,"<="&Inputs!$C$12,Actuals_Campaigns!$AL$5:$AL$204,"Y")+SUMIFS(Actuals_Campaigns!$AM$5:$AM$204,Actuals_Campaigns!$S$5:$S$204,">="&Inputs!$C$10,Actuals_Campaigns!$S$5:$S$204,"<="&Inputs!$C$12,Actuals_Campaigns!$AL$5:$AL$204,"Y") -> 1080 | F34: =SUMIFS(Drop_PnL!$AP$7:$AP$18,Drop_PnL!$AO$7:$AO$18,"<="&Inputs!$C$12,Drop_PnL!$B$7:$B$18,">"&Inputs!$C$12,Drop_PnL!$AZ$7:$AZ$18,"N")+SUMIFS(Drop_PnL!$AR$7:$AR$18,Drop_PnL!$AQ$7:$AQ$18,"<="&Inputs!$C$12,Drop_PnL!$B$7:$B$18,">"&Inputs!$C$12,Drop_PnL!$AZ$7:$AZ$18,"N")+SUMIFS(Drop_PnL!$AT$7:$AT$18,Drop_PnL!$AS$7:$AS$18,"<="&Inputs!$C$12,Drop_PnL!$B$7:$B$18,">"&Inputs!$C$12,Drop_PnL!$AZ$7:$AZ$18,"N")+SUMIFS(Actuals_Campaigns!$X$5:$X$204,Actuals_Campaigns!$Y$5:$Y$204,"<="&Inputs!$C$12,Actuals_Campaigns!$C$5:$C$204,">"&Inputs!$C$12,Actuals_Campaigns!$AL$5:$AL$204,"Y")+SUMIFS(Actuals_Campaigns!$AM$5:$AM$204,Actuals_Campaigns!$S$5:$S$204,"<="&Inputs!$C$12,Actuals_Campaigns!$C$5:$C$204,">"&Inputs!$C$12,Actuals_Campaigns!$AL$5:$AL$204,"Y") -> 1080 | G34: =D34+E34-F34 -> -3120 | H34: =SUMIFS(Cash_Flow!$C$26:$AB$26,Cash_Flow!$C$5:$AB$5,"<="&Inputs!$C$12) -> -3940
B35: Gate 2 | C35: =Inputs!$C$13 -> 46409 | D35: =-SUMIFS(Drop_PnL!$T$7:$T$18,Drop_PnL!$AX$7:$AX$18,">="&Inputs!$C$10,Drop_PnL!$AX$7:$AX$18,"<="&(Inputs!$C$13-1),Drop_PnL!$AZ$7:$AZ$18,"N")-SUMIFS(Drop_PnL!$U$7:$U$18,Drop_PnL!$AY$7:$AY$18,">="&Inputs!$C$10,Drop_PnL!$AY$7:$AY$18,"<="&(Inputs!$C$13-1),Drop_PnL!$AZ$7:$AZ$18,"N")-SUMIFS(Drop_PnL!$V$7:$V$18,Drop_PnL!$AX$7:$AX$18,">="&Inputs!$C$10,Drop_PnL!$AX$7:$AX$18,"<="&(Inputs!$C$13-1),Drop_PnL!$AZ$7:$AZ$18,"N")-(SUMIFS(Drop_PnL!$AU$7:$AU$18,Drop_PnL!$AO$7:$AO$18,">="&Inputs!$C$10,Drop_PnL!$AO$7:$AO$18,"<="&(Inputs!$C$13-1),Drop_PnL!$AZ$7:$AZ$18,"N")+SUMIFS(Drop_PnL!$AV$7:$AV$18,Drop_PnL!$AQ$7:$AQ$18,">="&Inputs!$C$10,Drop_PnL!$AQ$7:$AQ$18,"<="&(Inputs!$C$13-1),Drop_PnL!$AZ$7:$AZ$18,"N")+SUMIFS(Drop_PnL!$AW$7:$AW$18,Drop_PnL!$AS$7:$AS$18,">="&Inputs!$C$10,Drop_PnL!$AS$7:$AS$18,"<="&(Inputs!$C$13-1),Drop_PnL!$AZ$7:$AZ$18,"N"))-(SUMIFS(Actuals_DropCosts!$F$5:$F$104,Actuals_DropCosts!$B$5:$B$104,">="&Inputs!$C$10,Actuals_DropCosts!$B$5:$B$104,"<="&(Inputs!$C$13-1),Actuals_DropCosts!$U$5:$U$104,"Y")+SUMIFS(Actuals_DropCosts!$G$5:$G$104,Actuals_DropCosts!$B$5:$B$104,">="&Inputs!$C$10,Actuals_DropCosts!$B$5:$B$104,"<="&(Inputs!$C$13-1),Actuals_DropCosts!$U$5:$U$104,"Y")+SUMIFS(Actuals_DropCosts!$H$5:$H$104,Actuals_DropCosts!$B$5:$B$104,">="&Inputs!$C$10,Actuals_DropCosts!$B$5:$B$104,"<="&(Inputs!$C$13-1),Actuals_DropCosts!$U$5:$U$104,"Y")+SUMIFS(Actuals_Campaigns!$T$5:$T$204,Actuals_Campaigns!$S$5:$S$204,">="&Inputs!$C$10,Actuals_Campaigns!$S$5:$S$204,"<="&(Inputs!$C$13-1),Actuals_Campaigns!$AL$5:$AL$204,"Y"))-SUMIFS(Cash_Ledger!$D$5:$D$53,Cash_Ledger!$C$5:$C$53,">="&Inputs!$C$10,Cash_Ledger!$C$5:$C$53,"<="&(Inputs!$C$13-1),Cash_Ledger!$A$5:$A$53,"software")-SUMIFS(Cash_Ledger!$D$5:$D$53,Cash_Ledger!$C$5:$C$53,">="&Inputs!$C$10,Cash_Ledger!$C$5:$C$53,"<="&(Inputs!$C$13-1),Cash_Ledger!$A$5:$A$53,"insurance")-SUMIFS(Cash_Ledger!$D$5:$D$53,Cash_Ledger!$C$5:$C$53,">="&Inputs!$C$10,Cash_Ledger!$C$5:$C$53,"<="&(Inputs!$C$13-1),Cash_Ledger!$A$5:$A$53,"storage")-SUMIFS(Cash_Ledger!$D$5:$D$53,Cash_Ledger!$C$5:$C$53,">="&Inputs!$C$10,Cash_Ledger!$C$5:$C$53,"<="&(Inputs!$C$13-1),Cash_Ledger!$A$5:$A$53,"phone")-SUMIFS(Inputs!$Q$158:$Q$171,Inputs!$R$158:$R$171,">="&Inputs!$C$10,Inputs!$R$158:$R$171,"<="&(Inputs!$C$13-1)) -> -5282 | E35: =SUMIFS(Drop_PnL!$AP$7:$AP$18,Drop_PnL!$AO$7:$AO$18,">="&Inputs!$C$10,Drop_PnL!$AO$7:$AO$18,"<="&Inputs!$C$13,Drop_PnL!$AZ$7:$AZ$18,"N")+SUMIFS(Drop_PnL!$AR$7:$AR$18,Drop_PnL!$AQ$7:$AQ$18,">="&Inputs!$C$10,Drop_PnL!$AQ$7:$AQ$18,"<="&Inputs!$C$13,Drop_PnL!$AZ$7:$AZ$18,"N")+SUMIFS(Drop_PnL!$AT$7:$AT$18,Drop_PnL!$AS$7:$AS$18,">="&Inputs!$C$10,Drop_PnL!$AS$7:$AS$18,"<="&Inputs!$C$13,Drop_PnL!$AZ$7:$AZ$18,"N")+SUMIFS(Actuals_Campaigns!$X$5:$X$204,Actuals_Campaigns!$Y$5:$Y$204,">="&Inputs!$C$10,Actuals_Campaigns!$Y$5:$Y$204,"<="&Inputs!$C$13,Actuals_Campaigns!$AL$5:$AL$204,"Y")+SUMIFS(Actuals_Campaigns!$AM$5:$AM$204,Actuals_Campaigns!$S$5:$S$204,">="&Inputs!$C$10,Actuals_Campaigns!$S$5:$S$204,"<="&Inputs!$C$13,Actuals_Campaigns!$AL$5:$AL$204,"Y") -> 1080 | F35: =SUMIFS(Drop_PnL!$AP$7:$AP$18,Drop_PnL!$AO$7:$AO$18,"<="&Inputs!$C$13,Drop_PnL!$B$7:$B$18,">"&Inputs!$C$13,Drop_PnL!$AZ$7:$AZ$18,"N")+SUMIFS(Drop_PnL!$AR$7:$AR$18,Drop_PnL!$AQ$7:$AQ$18,"<="&Inputs!$C$13,Drop_PnL!$B$7:$B$18,">"&Inputs!$C$13,Drop_PnL!$AZ$7:$AZ$18,"N")+SUMIFS(Drop_PnL!$AT$7:$AT$18,Drop_PnL!$AS$7:$AS$18,"<="&Inputs!$C$13,Drop_PnL!$B$7:$B$18,">"&Inputs!$C$13,Drop_PnL!$AZ$7:$AZ$18,"N")+SUMIFS(Actuals_Campaigns!$X$5:$X$204,Actuals_Campaigns!$Y$5:$Y$204,"<="&Inputs!$C$13,Actuals_Campaigns!$C$5:$C$204,">"&Inputs!$C$13,Actuals_Campaigns!$AL$5:$AL$204,"Y")+SUMIFS(Actuals_Campaigns!$AM$5:$AM$204,Actuals_Campaigns!$S$5:$S$204,"<="&Inputs!$C$13,Actuals_Campaigns!$C$5:$C$204,">"&Inputs!$C$13,Actuals_Campaigns!$AL$5:$AL$204,"Y") -> 0 | G35: =D35+E35-F35 -> -4202 | H35: =SUMIFS(Cash_Flow!$C$26:$AB$26,Cash_Flow!$C$5:$AB$5,"<="&Inputs!$C$13) -> -4552
B36: Gate 3 | C36: =Inputs!$C$14 -> 46458 | D36: =-SUMIFS(Drop_PnL!$T$7:$T$18,Drop_PnL!$AX$7:$AX$18,">="&Inputs!$C$10,Drop_PnL!$AX$7:$AX$18,"<="&(Inputs!$C$14-1),Drop_PnL!$AZ$7:$AZ$18,"N")-SUMIFS(Drop_PnL!$U$7:$U$18,Drop_PnL!$AY$7:$AY$18,">="&Inputs!$C$10,Drop_PnL!$AY$7:$AY$18,"<="&(Inputs!$C$14-1),Drop_PnL!$AZ$7:$AZ$18,"N")-SUMIFS(Drop_PnL!$V$7:$V$18,Drop_PnL!$AX$7:$AX$18,">="&Inputs!$C$10,Drop_PnL!$AX$7:$AX$18,"<="&(Inputs!$C$14-1),Drop_PnL!$AZ$7:$AZ$18,"N")-(SUMIFS(Drop_PnL!$AU$7:$AU$18,Drop_PnL!$AO$7:$AO$18,">="&Inputs!$C$10,Drop_PnL!$AO$7:$AO$18,"<="&(Inputs!$C$14-1),Drop_PnL!$AZ$7:$AZ$18,"N")+SUMIFS(Drop_PnL!$AV$7:$AV$18,Drop_PnL!$AQ$7:$AQ$18,">="&Inputs!$C$10,Drop_PnL!$AQ$7:$AQ$18,"<="&(Inputs!$C$14-1),Drop_PnL!$AZ$7:$AZ$18,"N")+SUMIFS(Drop_PnL!$AW$7:$AW$18,Drop_PnL!$AS$7:$AS$18,">="&Inputs!$C$10,Drop_PnL!$AS$7:$AS$18,"<="&(Inputs!$C$14-1),Drop_PnL!$AZ$7:$AZ$18,"N"))-(SUMIFS(Actuals_DropCosts!$F$5:$F$104,Actuals_DropCosts!$B$5:$B$104,">="&Inputs!$C$10,Actuals_DropCosts!$B$5:$B$104,"<="&(Inputs!$C$14-1),Actuals_DropCosts!$U$5:$U$104,"Y")+SUMIFS(Actuals_DropCosts!$G$5:$G$104,Actuals_DropCosts!$B$5:$B$104,">="&Inputs!$C$10,Actuals_DropCosts!$B$5:$B$104,"<="&(Inputs!$C$14-1),Actuals_DropCosts!$U$5:$U$104,"Y")+SUMIFS(Actuals_DropCosts!$H$5:$H$104,Actuals_DropCosts!$B$5:$B$104,">="&Inputs!$C$10,Actuals_DropCosts!$B$5:$B$104,"<="&(Inputs!$C$14-1),Actuals_DropCosts!$U$5:$U$104,"Y")+SUMIFS(Actuals_Campaigns!$T$5:$T$204,Actuals_Campaigns!$S$5:$S$204,">="&Inputs!$C$10,Actuals_Campaigns!$S$5:$S$204,"<="&(Inputs!$C$14-1),Actuals_Campaigns!$AL$5:$AL$204,"Y"))-SUMIFS(Cash_Ledger!$D$5:$D$53,Cash_Ledger!$C$5:$C$53,">="&Inputs!$C$10,Cash_Ledger!$C$5:$C$53,"<="&(Inputs!$C$14-1),Cash_Ledger!$A$5:$A$53,"software")-SUMIFS(Cash_Ledger!$D$5:$D$53,Cash_Ledger!$C$5:$C$53,">="&Inputs!$C$10,Cash_Ledger!$C$5:$C$53,"<="&(Inputs!$C$14-1),Cash_Ledger!$A$5:$A$53,"insurance")-SUMIFS(Cash_Ledger!$D$5:$D$53,Cash_Ledger!$C$5:$C$53,">="&Inputs!$C$10,Cash_Ledger!$C$5:$C$53,"<="&(Inputs!$C$14-1),Cash_Ledger!$A$5:$A$53,"storage")-SUMIFS(Cash_Ledger!$D$5:$D$53,Cash_Ledger!$C$5:$C$53,">="&Inputs!$C$10,Cash_Ledger!$C$5:$C$53,"<="&(Inputs!$C$14-1),Cash_Ledger!$A$5:$A$53,"phone")-SUMIFS(Inputs!$Q$158:$Q$171,Inputs!$R$158:$R$171,">="&Inputs!$C$10,Inputs!$R$158:$R$171,"<="&(Inputs!$C$14-1)) -> -7149.5 | E36: =SUMIFS(Drop_PnL!$AP$7:$AP$18,Drop_PnL!$AO$7:$AO$18,">="&Inputs!$C$10,Drop_PnL!$AO$7:$AO$18,"<="&Inputs!$C$14,Drop_PnL!$AZ$7:$AZ$18,"N")+SUMIFS(Drop_PnL!$AR$7:$AR$18,Drop_PnL!$AQ$7:$AQ$18,">="&Inputs!$C$10,Drop_PnL!$AQ$7:$AQ$18,"<="&Inputs!$C$14,Drop_PnL!$AZ$7:$AZ$18,"N")+SUMIFS(Drop_PnL!$AT$7:$AT$18,Drop_PnL!$AS$7:$AS$18,">="&Inputs!$C$10,Drop_PnL!$AS$7:$AS$18,"<="&Inputs!$C$14,Drop_PnL!$AZ$7:$AZ$18,"N")+SUMIFS(Actuals_Campaigns!$X$5:$X$204,Actuals_Campaigns!$Y$5:$Y$204,">="&Inputs!$C$10,Actuals_Campaigns!$Y$5:$Y$204,"<="&Inputs!$C$14,Actuals_Campaigns!$AL$5:$AL$204,"Y")+SUMIFS(Actuals_Campaigns!$AM$5:$AM$204,Actuals_Campaigns!$S$5:$S$204,">="&Inputs!$C$10,Actuals_Campaigns!$S$5:$S$204,"<="&Inputs!$C$14,Actuals_Campaigns!$AL$5:$AL$204,"Y") -> 12330 | F36: =SUMIFS(Drop_PnL!$AP$7:$AP$18,Drop_PnL!$AO$7:$AO$18,"<="&Inputs!$C$14,Drop_PnL!$B$7:$B$18,">"&Inputs!$C$14,Drop_PnL!$AZ$7:$AZ$18,"N")+SUMIFS(Drop_PnL!$AR$7:$AR$18,Drop_PnL!$AQ$7:$AQ$18,"<="&Inputs!$C$14,Drop_PnL!$B$7:$B$18,">"&Inputs!$C$14,Drop_PnL!$AZ$7:$AZ$18,"N")+SUMIFS(Drop_PnL!$AT$7:$AT$18,Drop_PnL!$AS$7:$AS$18,"<="&Inputs!$C$14,Drop_PnL!$B$7:$B$18,">"&Inputs!$C$14,Drop_PnL!$AZ$7:$AZ$18,"N")+SUMIFS(Actuals_Campaigns!$X$5:$X$204,Actuals_Campaigns!$Y$5:$Y$204,"<="&Inputs!$C$14,Actuals_Campaigns!$C$5:$C$204,">"&Inputs!$C$14,Actuals_Campaigns!$AL$5:$AL$204,"Y")+SUMIFS(Actuals_Campaigns!$AM$5:$AM$204,Actuals_Campaigns!$S$5:$S$204,"<="&Inputs!$C$14,Actuals_Campaigns!$C$5:$C$204,">"&Inputs!$C$14,Actuals_Campaigns!$AL$5:$AL$204,"Y") -> 2250 | G36: =D36+E36-F36 -> 2930.5 | H36: =SUMIFS(Cash_Flow!$C$26:$AB$26,Cash_Flow!$C$5:$AB$5,"<="&Inputs!$C$14) -> 5180.5
B37: Six-month decision | C37: =Inputs!$C$15 -> 46486 | D37: =-SUMIFS(Drop_PnL!$T$7:$T$18,Drop_PnL!$AX$7:$AX$18,">="&Inputs!$C$10,Drop_PnL!$AX$7:$AX$18,"<="&(Inputs!$C$15-1),Drop_PnL!$AZ$7:$AZ$18,"N")-SUMIFS(Drop_PnL!$U$7:$U$18,Drop_PnL!$AY$7:$AY$18,">="&Inputs!$C$10,Drop_PnL!$AY$7:$AY$18,"<="&(Inputs!$C$15-1),Drop_PnL!$AZ$7:$AZ$18,"N")-SUMIFS(Drop_PnL!$V$7:$V$18,Drop_PnL!$AX$7:$AX$18,">="&Inputs!$C$10,Drop_PnL!$AX$7:$AX$18,"<="&(Inputs!$C$15-1),Drop_PnL!$AZ$7:$AZ$18,"N")-(SUMIFS(Drop_PnL!$AU$7:$AU$18,Drop_PnL!$AO$7:$AO$18,">="&Inputs!$C$10,Drop_PnL!$AO$7:$AO$18,"<="&(Inputs!$C$15-1),Drop_PnL!$AZ$7:$AZ$18,"N")+SUMIFS(Drop_PnL!$AV$7:$AV$18,Drop_PnL!$AQ$7:$AQ$18,">="&Inputs!$C$10,Drop_PnL!$AQ$7:$AQ$18,"<="&(Inputs!$C$15-1),Drop_PnL!$AZ$7:$AZ$18,"N")+SUMIFS(Drop_PnL!$AW$7:$AW$18,Drop_PnL!$AS$7:$AS$18,">="&Inputs!$C$10,Drop_PnL!$AS$7:$AS$18,"<="&(Inputs!$C$15-1),Drop_PnL!$AZ$7:$AZ$18,"N"))-(SUMIFS(Actuals_DropCosts!$F$5:$F$104,Actuals_DropCosts!$B$5:$B$104,">="&Inputs!$C$10,Actuals_DropCosts!$B$5:$B$104,"<="&(Inputs!$C$15-1),Actuals_DropCosts!$U$5:$U$104,"Y")+SUMIFS(Actuals_DropCosts!$G$5:$G$104,Actuals_DropCosts!$B$5:$B$104,">="&Inputs!$C$10,Actuals_DropCosts!$B$5:$B$104,"<="&(Inputs!$C$15-1),Actuals_DropCosts!$U$5:$U$104,"Y")+SUMIFS(Actuals_DropCosts!$H$5:$H$104,Actuals_DropCosts!$B$5:$B$104,">="&Inputs!$C$10,Actuals_DropCosts!$B$5:$B$104,"<="&(Inputs!$C$15-1),Actuals_DropCosts!$U$5:$U$104,"Y")+SUMIFS(Actuals_Campaigns!$T$5:$T$204,Actuals_Campaigns!$S$5:$S$204,">="&Inputs!$C$10,Actuals_Campaigns!$S$5:$S$204,"<="&(Inputs!$C$15-1),Actuals_Campaigns!$AL$5:$AL$204,"Y"))-SUMIFS(Cash_Ledger!$D$5:$D$53,Cash_Ledger!$C$5:$C$53,">="&Inputs!$C$10,Cash_Ledger!$C$5:$C$53,"<="&(Inputs!$C$15-1),Cash_Ledger!$A$5:$A$53,"software")-SUMIFS(Cash_Ledger!$D$5:$D$53,Cash_Ledger!$C$5:$C$53,">="&Inputs!$C$10,Cash_Ledger!$C$5:$C$53,"<="&(Inputs!$C$15-1),Cash_Ledger!$A$5:$A$53,"insurance")-SUMIFS(Cash_Ledger!$D$5:$D$53,Cash_Ledger!$C$5:$C$53,">="&Inputs!$C$10,Cash_Ledger!$C$5:$C$53,"<="&(Inputs!$C$15-1),Cash_Ledger!$A$5:$A$53,"storage")-SUMIFS(Cash_Ledger!$D$5:$D$53,Cash_Ledger!$C$5:$C$53,">="&Inputs!$C$10,Cash_Ledger!$C$5:$C$53,"<="&(Inputs!$C$15-1),Cash_Ledger!$A$5:$A$53,"phone")-SUMIFS(Inputs!$Q$158:$Q$171,Inputs!$R$158:$R$171,">="&Inputs!$C$10,Inputs!$R$158:$R$171,"<="&(Inputs!$C$15-1)) -> -7747 | E37: =SUMIFS(Drop_PnL!$AP$7:$AP$18,Drop_PnL!$AO$7:$AO$18,">="&Inputs!$C$10,Drop_PnL!$AO$7:$AO$18,"<="&Inputs!$C$15,Drop_PnL!$AZ$7:$AZ$18,"N")+SUMIFS(Drop_PnL!$AR$7:$AR$18,Drop_PnL!$AQ$7:$AQ$18,">="&Inputs!$C$10,Drop_PnL!$AQ$7:$AQ$18,"<="&Inputs!$C$15,Drop_PnL!$AZ$7:$AZ$18,"N")+SUMIFS(Drop_PnL!$AT$7:$AT$18,Drop_PnL!$AS$7:$AS$18,">="&Inputs!$C$10,Drop_PnL!$AS$7:$AS$18,"<="&Inputs!$C$15,Drop_PnL!$AZ$7:$AZ$18,"N")+SUMIFS(Actuals_Campaigns!$X$5:$X$204,Actuals_Campaigns!$Y$5:$Y$204,">="&Inputs!$C$10,Actuals_Campaigns!$Y$5:$Y$204,"<="&Inputs!$C$15,Actuals_Campaigns!$AL$5:$AL$204,"Y")+SUMIFS(Actuals_Campaigns!$AM$5:$AM$204,Actuals_Campaigns!$S$5:$S$204,">="&Inputs!$C$10,Actuals_Campaigns!$S$5:$S$204,"<="&Inputs!$C$15,Actuals_Campaigns!$AL$5:$AL$204,"Y") -> 19080 | F37: =SUMIFS(Drop_PnL!$AP$7:$AP$18,Drop_PnL!$AO$7:$AO$18,"<="&Inputs!$C$15,Drop_PnL!$B$7:$B$18,">"&Inputs!$C$15,Drop_PnL!$AZ$7:$AZ$18,"N")+SUMIFS(Drop_PnL!$AR$7:$AR$18,Drop_PnL!$AQ$7:$AQ$18,"<="&Inputs!$C$15,Drop_PnL!$B$7:$B$18,">"&Inputs!$C$15,Drop_PnL!$AZ$7:$AZ$18,"N")+SUMIFS(Drop_PnL!$AT$7:$AT$18,Drop_PnL!$AS$7:$AS$18,"<="&Inputs!$C$15,Drop_PnL!$B$7:$B$18,">"&Inputs!$C$15,Drop_PnL!$AZ$7:$AZ$18,"N")+SUMIFS(Actuals_Campaigns!$X$5:$X$204,Actuals_Campaigns!$Y$5:$Y$204,"<="&Inputs!$C$15,Actuals_Campaigns!$C$5:$C$204,">"&Inputs!$C$15,Actuals_Campaigns!$AL$5:$AL$204,"Y")+SUMIFS(Actuals_Campaigns!$AM$5:$AM$204,Actuals_Campaigns!$S$5:$S$204,"<="&Inputs!$C$15,Actuals_Campaigns!$C$5:$C$204,">"&Inputs!$C$15,Actuals_Campaigns!$AL$5:$AL$204,"Y") -> 0 | G37: =D37+E37-F37 -> 11333 | H37: =SUMIFS(Cash_Flow!$C$26:$AB$26,Cash_Flow!$C$5:$AB$5,"<="&Inputs!$C$15) -> 11333
B38: Paid out counts every outflow dated before the review day (startup outlays, overhead, drop costs, card fees) and no brand money: at Gate 1 it is what you are out if no brand pays. Spending the plan makes on the review day itself is left out, because you make it only if the gate passes (at Gate 1: insurance, the licence and printing; at Gate 2: the trademark). Net if you stop here adds the brand cash received by that day and takes off what you would refund: payments for campaigns whose drop has not run yet (founding payments, deposits). Card fees on refunded payments are not recovered. Founding brands pay on Gate 1 day by default.
A40: Gate dashboard (live values are actuals only)
A41: Gate | B41: Test | C41: Review date | D41: Threshold | E41: Model assumes | F41: Live value | G41: Status | H41: If it fails (plan)
A42: Gate 0 | B42: Office conversations held (context) | C42: =Inputs!$C$11 -> 46339 | D42: =Inputs!$C$122 -> 15 | F42: =Pipeline!$AH$5 -> 0 | G42: info
A43: Gate 0 | B43: Offices yes in principle, with owner and receiving window | C43: =Inputs!$C$11 -> 46339 | D43: =Inputs!$C$121 -> 5 | F43: =Pipeline!$AH$6 -> 0 | G43: =IF(F43="",IF(Inputs!$C$17>C43,"miss","not yet"),IF(F43>=D43,"pass",IF(Inputs!$C$17>C43,"miss","not yet"))) -> miss | H43: Fewer than 5 offices: change the cluster or office size band, not the model.
...

Sheet Inputs
A1: Inputs
A2: Every assumption in one labeled cell. Yellow cells are inputs. Blue cells are inputs that follow another cell by default; type over them to replace. Grey cells are calculated; do not type over them.
A3: All defaults are planning estimates from plan.md, never forecasts. 'Plan default' keeps the original figure; 'Changed' flags any cell you edit.
A6: 1. Company and calendar
A7: key | B7: Assumption | C7: Value | D7: Unit | E7: Low | F7: High | G7: Status | H7: Source | I7: Notes | J7: Plan default | K7: Changed?
A8: company_name | B8: Company name (working name, not yet cleared) | C8: Desk Drop | D8: text | G8: working name | H8: Prompt; CONTRACTS s2 rename-ability | I8: The only cell that holds the company name. Rename here and every tab follows. Not counted as a change. | J8: not tracked | K8: =IF(C8="","missing","")
A9: tagline | B9: Tagline (working, may change) | C9: Emerging brands. Delivered to your workday. | D9: text | G9: working | H9: Prompt; CONTRACTS s2 | I9: The only cell that holds the tagline. | J9: not tracked | K9: =IF(C9="","missing","")
A10: week1_start | B10: Week 1 starts (Monday) | C10: 46321 | D10: date | G10: derived, founder to confirm | H10: CONTRACTS.md section 3 (canonical calendar) | I10: Week n starts on this date plus 7 x (n - 1) days. Moving it moves the cash-flow weeks, software, the domain and any mailbox only. The gate dates below and the drop dates on Schedule are typed CONTRACTS dates: move them too. Checks flags week 1 moved on its own (review R3-09). | J10: 46321 | K10: =IF(C10&""=J10&"","","changed")
A11: gate0_date | B11: Gate 0 review (end of week 3) | C11: 46339 | D11: date | G11: derived, founder to confirm | H11: CONTRACTS.md section 3 (canonical calendar) | J11: 46339 | K11: =IF(C11&""=J11&"","","changed")
A12: gate1_date | B12: Gate 1 review (end of week 7) | C12: 46367 | D12: date | G12: derived, founder to confirm | H12: CONTRACTS.md section 3 (canonical calendar) | J12: 46367 | K12: =IF(C12&""=J12&"","","changed")
A13: gate2_date | B13: Gate 2 review (campaign zero report, T+7) | C13: =IFERROR(WORKDAY(INDEX(Schedule!$E$7:$E$18,MATCH(Inputs!$C$129,Schedule!$A$7:$A$18,0)),Inputs!$C$132,Lists!$N$4:$N$30),"") -> 46409 | D13: date | G13: derived, founder to confirm | H13: CONTRACTS.md section 3 (canonical calendar) | I13: Follows the Gate 2 drop on Schedule: its date plus the report deadline (T+7, 2027-01-22 by default). Moved from the plan's week 9 because campaign zero moved to 2027-01-12 (December blackout collision). | J13: =IFERROR(WORKDAY(INDEX(Schedule!$E$7:$E$18,MATCH(Inputs!$C$129,Schedule!$A$7:$A$18,0)),Inputs!$C$132,Lists!$N$4:$N$30),"") -> 46409 | K13: =IF(C13&""=J13&"","","changed")
A14: gate3_date | B14: Gate 3 review | C14: 46458 | D14: date | G14: derived, founder to confirm | H14: CONTRACTS.md section 3 (canonical calendar) | I14: Week 20; replaces the plan's week 16. | J14: 46458 | K14: =IF(C14&""=J14&"","","changed")
A15: decision_date | B15: Six-month decision (end of week 24) | C15: 46486 | D15: date | G15: derived, founder to confirm | H15: CONTRACTS.md section 3 (canonical calendar) | J15: 46486 | K15: =IF(C15&""=J15&"","","changed")
A16: as_of_override | B16: As-of date override (blank = today) | C16: 46430 | D16: date | G16: setting | H16: Model setting | I16: Leave blank to use today's date. Type a date to see gates and the next drop as of that day. | K16: =IF(C16&""=J16&"","","changed") -> changed
A17: as_of | B17: As-of date in use | C17: =IF(C16="",TODAY(),C16) -> 46430 | D17: date | G17: calculated | H17: Model
A18: days_per_week | B18: Days per week | C18: 7 | D18: days | G18: conversion | H18: Calendar | J18: 7 | K18: =IF(C18&""=J18&"","","changed")
A19: weeks_per_year | B19: Weeks per year | C19: 52 | D19: weeks | G19: conversion | H19: Calendar | J19: 52 | K19: =IF(C19&""=J19&"","","changed")
A20: months_per_year | B20: Months per year | C20: 12 | D20: months | G20: conversion | H20: Calendar | J20: 12 | K20: =IF(C20&""=J20&"","","changed")
A21: weeks_per_month | B21: Weeks per month | C21: =Inputs!$C$19/Inputs!$C$20 -> 4.3333333 | D21: weeks | G21: calculated | H21: Weeks per year / months per year
A22: hours_per_day | B22: Hours per day (converts Toggl durations) | C22: 24 | D22: hours | G22: conversion | H22: Calendar | J22: 24 | K22: =IF(C22&""=J22&"","","changed")
A23: window_bd | B23: Campaign window | C23: 5 | D23: business days | G23: planning estimate | H23: plan.md, What brands buy: 'Five business days' | I23: T is day 1; the window closes at T+4. | J23: 5 | K23: =IF(C23&""=J23&"","","changed")
A24: debrief_bd | B24: Debrief this many business days after the drop (T+10) | C24: 10 | D24: business days | G24: planning estimate | H24: CONTRACTS.md section 3 (canonical calendar) (debrief at T+10) | I24: Used to flag a decision-window drop whose results land after the decision date (Schedule, Dashboard). | J24: 10 | K24: =IF(C24&""=J24&"","","changed")
A25: llc_filing_bd | B25: LLC Articles filed this many business days after Gate 0 | C25: 4 | D25: business days | G25: derived, founder to confirm | H25: desk-drop-legal-pack/figures.csv (re-read 2026-10-24, after its 02:33 update), Articles timing: 'never before the attorney hour; earliest Thu 2026-11-19' | I25: Sets the filing date in section 11: Fri 2026-11-13 plus 4 business days is Thu 2026-11-19, the day after the attorney hour. | J25: 4 | K25: =IF(C25&""=J25&"","","changed")
A26: attorney_bd | B26: Attorney hour held this many business days after Gate 0 | C26: 3 | D26: business days | G26: derived, founder to confirm | H26: desk-drop-legal-pack/figures.csv (re-read 2026-10-24, after its 02:33 update), attorney_hour timing: 'booked at Gate 0 ... held early in week 4, by Wed 2026-11-18' | I26: Sets the attorney payment date in section 11 (Wed 2026-11-18). | J26: 3 | K26: =IF(C26&""=J26&"","","changed")
A27: accountant_bd | B27: Accountant hour held this many business days after Gate 0 | C27: 5 | D27: business days | G27: derived, founder to confirm | H27: desk-drop-legal-pack/figures.csv (re-read 2026-10-24, after its 02:33 update), accountant_hour timing: 'held in week 4, by Fri 2026-11-20' | I27: Sets the accountant payment date in section 11 (Fri 2026-11-20). | J27: 5 | K27: =IF(C27&""=J27&"","","changed")
A28: pub_order_bd | B28: Newspaper publication ordered this many business days after the LLC filing | C28: 10 | D28: business days | G28: derived, founder to confirm | H28: desk-drop-legal-pack/figures.csv (re-read 2026-10-24, after its 02:33 update), publication timing: 'Order within 10 business days of filing' | I28: Sets the publication payment date in section 11 (Fri 2026-12-04, skipping Thanksgiving). | J28: 10 | K28: =IF(C28&""=J28&"","","changed")
A29: pub_weeks | B29: Weekly newspaper runs before the Certificate of Publication is filed | C29: 6 | D29: weeks | G29: planning estimate | H29: plan.md, Legal table: 'publish in two newspapers for six weeks' | I29: Sets the certificate's payment date in section 11. | J29: 6 | K29: =IF(C29&""=J29&"","","changed")
A30: drop_prefix | B30: Drop ID prefix | C30: DRP- | D30: text | G30: convention | H30: CONTRACTS s6.5 (DRP-###) | I30: Toggl projects named DRP-001 etc. map to drops. | J30: DRP- | K30: =IF(C30&""=J30&"","","changed")
A31: office_window_days | B31: An office should get at most one drop in this many days | C31: 28 | D31: days | G31: derived, founder to confirm | H31: plan.md, What has to be true #4: 'Offices accept one drop a month' | I31: Four weeks counts as monthly, so drops 28 days apart do not flag. Used for the office-fatigue warning on Schedule. | J31: 28 | K31: =IF(C31&""=J31&"","","changed")
A33: 2. Scenario in force
A34: key | B34: Assumption | C34: Value | D34: Unit | E34: Low | F34: High | G34: Status | H34: Source | I34: Notes | J34: Plan default | K34: Changed?
A35: active_scenario | B35: Scenario applied to drops after Gate 3 and to the steady state | C35: Plan base | D35: list | G35: setting | H35: plan.md, After the first standard runs: decision scenarios | I35: Plan base = the plan's 'What has to be true'. A to D = the plan's four decision situations. See the Scenarios tab. | J35: Plan base | K35: =IF(C35&""=J35&"","","changed")
A37: 3. Prices and payment terms
A38: key | B38: Assumption | C38: Value | D38: Unit | E38: Low | F38: High | G38: Status | H38: Source | I38: Notes | J38: Plan default | K38: Changed?
A39: price_std_office | B39: Standard price per office | C39: 150 | D39: USD per office | G39: planning estimate | H39: plan.md, Revised model: Price table | I39: $1,500 for 10 offices. Change this cell to test a price. | J39: 150 | K39: =IF(C39&""=J39&"","","changed")
A40: std_pkg_offices | B40: Standard package size | C40: 10 | D40: offices | G40: planning estimate | H40: plan.md, Revised model: Price table | J40: 10 | K40: =IF(C40&""=J40&"","","changed")
A41: std_pkg_price | B41: Standard package price | C41: =Inputs!$C$39*Inputs!$C$40 -> 1500 | D41: USD per brand | G41: calculated | H41: Price per office x package offices
A42: price_fnd_office | B42: Founding price per office | C42: 120 | D42: USD per office | E42: 120 | F42: 180 | G42: planning estimate | H42: plan.md, Revised model: Price table | I42: $600 for 5 offices. The plan's summary table once said $600 to $900; the decided price is $600 (low end shown as default). | J42: 120 | K42: =IF(C42&""=J42&"","","changed")
A43: fnd_pkg_offices | B43: Founding package size | C43: 5 | D43: offices | G43: planning estimate | H43: plan.md, Revised model: Price table | J43: 5 | K43: =IF(C43&""=J43&"","","changed")
A44: fnd_pkg_price | B44: Founding package price | C44: =Inputs!$C$42*Inputs!$C$43 -> 600 | D44: USD per brand | G44: calculated | H44: Price per office x package offices
...

Sheet Scenarios
A1: Scenarios A to D
A2: The plan's four decision situations as assumption sets. Pick one on Inputs ('Scenario in force'). The Active column feeds drops after Gate 3 and the steady state.
A3: Planning estimates. Where a scenario does not name a figure, it follows the plan base (blue cells) and says so. Nothing here is a forecast of which scenario will happen.
B5: Lever | C5: Plan base | D5: A | E5: B | F5: C | G5: D | H5: Active (in force) | I5: Unit | J5: Source and reading | L5: default: Plan base | M5: default: A | N5: default: B | O5: default: C | P5: default: D | Q5: Changed? | R5: Blank in force? (1 = needs a figure)
B6: Situation | C6: What has to be true | D6: Both sides work | E6: Brands pay once, offices love it | F6: Brands willing, offices unreliable | G6: Neither converts
B7: What the numbers show | C7: Three brands per drop, six hours or less per win, 40% renew, $1,500 holds | D7: 40% or more of brands renew; placement above 80%; contribution above $50 an hour | E7: Renewal under 30%; offices asking when the next drop is | F7: Placement under 80% twice; photos missing; responses under five | G7: No renewal, weak placement
B8: What to do next (plan) | C8: Run the plan | D8: Scale: second cluster, roster 20 to 30, price to $1,800 to $2,000, part-time delivery at about $25 an hour above two drops a month, launch-partner tier | E8: Fix the evidence, run two more drops; if renewal is still under 30%, switch to office-paid for offices that named $100 a month or more | F8: Replace the weakest offices, raise the commitment bar; if a third drop misses, stop | G8: Stop; write the post-mortem; keep office relationships warm
B10: Post-Gate-3 drops that run in the six months (of the two scheduled) | C10: 2 | D10: 2 | E10: 2 | F10: 1 | G10: 0 | H10: =INDEX(C10:G10,1,MATCH(Inputs!$C$35,$C$5:$G$5,0)) -> 2 | I10: drops | J10: Base and A: two drops a month. B: 'run two more drops'. C: 'if a third drop misses, stop', so one more. D: 'Stop'. | L10: 2 | M10: 2 | N10: 2 | O10: 1 | P10: 0 | Q10: =IF(AND(C10&""=L10&"",D10&""=M10&"",E10&""=N10&"",F10&""=O10&"",G10&""=P10&""),"","changed") | R10: =IF(INDEX(C10:G10,1,MATCH(Inputs!$C$35,$C$5:$G$5,0))="",1,0) -> 0
B11: Brands per drop after Gate 3 | C11: =Inputs!$C$62 -> 3 | D11: =$C11 -> 3 | E11: =$C11 -> 3 | F11: =$C11 -> 3 | G11: 0 | H11: =INDEX(C11:G11,1,MATCH(Inputs!$C$35,$C$5:$G$5,0)) -> 3 | I11: brands | J11: Plan: three brands per drop (Inputs, 'Brands per standard drop'). A, B and C do not name a figure, so they follow the plan base. D stops. | L11: =Inputs!$C$62 -> 3 | M11: =$C11 -> 3 | N11: =$C11 -> 3 | O11: =$C11 -> 3 | P11: 0 | Q11: =IF(AND(C11&""=L11&"",D11&""=M11&"",E11&""=N11&"",F11&""=O11&"",G11&""=P11&""),"","changed") | R11: =IF(INDEX(C11:G11,1,MATCH(Inputs!$C$35,$C$5:$G$5,0))="",1,0) -> 0
B12: Renewal rate (share of brand slots that are renewals) | C12: =Inputs!$C$111 -> 0.4 | D12: 0.4 | E12: 0 | F12: =C12 -> 0.4 | G12: 0 | H12: =INDEX(C12:G12,1,MATCH(Inputs!$C$35,$C$5:$G$5,0)) -> 0.4 | I12: share | J12: A: '40% or more', low end. B: 'under 30%' and 'brands pay once': 0%, the low end of 0% to 29%. C: not named, plan base. D: 'No renewal'. | L12: =Inputs!$C$111 -> 0.4 | M12: 0.4 | N12: 0 | O12: =C12 -> 0.4 | P12: 0 | Q12: =IF(AND(C12&""=L12&"",D12&""=M12&"",E12&""=N12&"",F12&""=O12&"",G12&""=P12&""),"","changed") | R12: =IF(INDEX(C12:G12,1,MATCH(Inputs!$C$35,$C$5:$G$5,0))="",1,0) -> 0
B13: New offices recruited per post-Gate-3 drop | C13: 0 | D13: 4 | E13: 0 | G13: 0 | H13: =INDEX(C13:G13,1,MATCH(Inputs!$C$35,$C$5:$G$5,0)) -> 0 | I13: offices | J13: A: 'Grow the roster to 20 to 30 offices': 4 new offices on each of the two decision-window drops take the 12-office roster to 20, the low end (derived, founder to confirm; review R3-08). C: 'replace the weakest offices'; the plan gives no count. Blank = 0; founder to set. | L13: 0 | M13: 4 | N13: 0 | P13: 0 | Q13: =IF(AND(C13&""=L13&"",D13&""=M13&"",E13&""=N13&"",F13&""=O13&"",G13&""=P13&""),"","changed") | R13: =IF(INDEX(C13:G13,1,MATCH(Inputs!$C$35,$C$5:$G$5,0))="",1,0) -> 0
B14: Standard price per office for drops after the decision date | C14: =Inputs!$C$39 -> 150 | D14: 180 | E14: =Inputs!$C$39 -> 150 | F14: =Inputs!$C$39 -> 150 | G14: =Inputs!$C$39 -> 150 | H14: =INDEX(C14:G14,1,MATCH(Inputs!$C$35,$C$5:$G$5,0)) -> 150 | I14: USD per office | J14: A: 'raise the standard price to $1,800 to $2,000' = $180 to $200 per office; low end. | L14: =Inputs!$C$39 -> 150 | M14: 180 | N14: =Inputs!$C$39 -> 150 | O14: =Inputs!$C$39 -> 150 | P14: =Inputs!$C$39 -> 150 | Q14: =IF(AND(C14&""=L14&"",D14&""=M14&"",E14&""=N14&"",F14&""=O14&"",G14&""=P14&""),"","changed") | R14: =IF(INDEX(C14:G14,1,MATCH(Inputs!$C$35,$C$5:$G$5,0))="",1,0) -> 0
B15: Steady-state drops per month | C15: =Inputs!$C$112 -> 2 | D15: =$C15 -> 2 | E15: =$C15 -> 2 | F15: =$C15 -> 2 | G15: 0 | H15: =INDEX(C15:G15,1,MATCH(Inputs!$C$35,$C$5:$G$5,0)) -> 2 | I15: drops per month | J15: Plan monthly picture: two drops a month (Inputs section 8). A, B and C follow the plan base. D stops. | L15: =Inputs!$C$112 -> 2 | M15: =$C15 -> 2 | N15: =$C15 -> 2 | O15: =$C15 -> 2 | P15: 0 | Q15: =IF(AND(C15&""=L15&"",D15&""=M15&"",E15&""=N15&"",F15&""=O15&"",G15&""=P15&""),"","changed") | R15: =IF(INDEX(C15:G15,1,MATCH(Inputs!$C$35,$C$5:$G$5,0))="",1,0) -> 0
B16: Steady-state brands per drop | C16: =Inputs!$C$62 -> 3 | D16: =$C16 -> 3 | E16: =$C16 -> 3 | F16: =$C16 -> 3 | G16: 0 | H16: =INDEX(C16:G16,1,MATCH(Inputs!$C$35,$C$5:$G$5,0)) -> 3 | I16: brands | J16: Plan monthly picture: three-brand drops (Inputs, 'Brands per standard drop'). A, B and C follow the plan base. D stops. | L16: =Inputs!$C$62 -> 3 | M16: =$C16 -> 3 | N16: =$C16 -> 3 | O16: =$C16 -> 3 | P16: 0 | Q16: =IF(AND(C16&""=L16&"",D16&""=M16&"",E16&""=N16&"",F16&""=O16&"",G16&""=P16&""),"","changed") | R16: =IF(INDEX(C16:G16,1,MATCH(Inputs!$C$35,$C$5:$G$5,0))="",1,0) -> 0
B17: Offices on an office-paid tier (steady state) | C17: 0 | D17: 0 | E17: 5 | F17: 0 | G17: 0 | H17: =INDEX(C17:G17,1,MATCH(Inputs!$C$35,$C$5:$G$5,0)) -> 0 | I17: offices | J17: B: offices that named $100 a month or more; at least five. | L17: 0 | M17: 0 | N17: 5 | O17: 0 | P17: 0 | Q17: =IF(AND(C17&""=L17&"",D17&""=M17&"",E17&""=N17&"",F17&""=O17&"",G17&""=P17&""),"","changed") | R17: =IF(INDEX(C17:G17,1,MATCH(Inputs!$C$35,$C$5:$G$5,0))="",1,0) -> 0
B18: Office-paid fee per office per month | E18: 100 | H18: =INDEX(C18:G18,1,MATCH(Inputs!$C$35,$C$5:$G$5,0)) -> 0 | I18: USD per month | J18: B: $100 to $200 a month; low end. | N18: 100 | Q18: =IF(AND(C18&""=L18&"",D18&""=M18&"",E18&""=N18&"",F18&""=O18&"",G18&""=P18&""),"","changed") | R18: =IF(INDEX(C18:G18,1,MATCH(Inputs!$C$35,$C$5:$G$5,0))="",1,0) -> 1
B19: Cost to serve one office-paid office per month | H19: =INDEX(C19:G19,1,MATCH(Inputs!$C$35,$C$5:$G$5,0)) -> 0 | I19: USD per month | J19: Needs quote. The plan prices no cost for guaranteed twice-monthly curated drops. | Q19: =IF(AND(C19&""=L19&"",D19&""=M19&"",E19&""=N19&"",F19&""=O19&"",G19&""=P19&""),"","changed") | R19: =IF(INDEX(C19:G19,1,MATCH(Inputs!$C$35,$C$5:$G$5,0))="",1,0) -> 1
