Workbook

Sheet README
A1: ="Campaign tracker · "&config!$B$2 -> Campaign tracker · Desk Drop
A2: Every number in a brand report comes from a row in this file or a photo. Type only in white cells. Grey cells are formulas: never type over them. Cream tabs are written by forms, scripts or a pasted file.
A3: Rename: change config!B2 (company_name). Nothing else in this file holds the name. The printed pieces take it from desk-drop-identity/brand.json: change both the same day; every tool refuses while they differ (README, Rename).
A5: Tabs in the order a campaign touches them
A6: office_intake, brand_intake: website form rows (CONTRACTS 6.3), written by the website's script when it is bound to this file.
A7: office_form, brand_form: the founder-side Google Forms' response tabs; office_intake_founder, brand_intake_founder turn them into the same 6.3 columns.
A8: in_signed_offices: paste E's signed_offices.csv. offices: type the office_id; the rest fills by header name.
A9: brands: type brand_id and intake_key (the brand's submitted_at); the seven checks fill in. in_paid_brands: paste E's paid_brands.csv to check it.
A10: drops: one row per route. The date is refused unless it is a Tuesday or Wednesday business day with a window clear of blackouts.
A11: campaigns: one row per brand per drop: terms, card text, survey links, report inputs, and every ladder number.
A12: invoices: issue, then log paid_date. The ship date is released only when the pre-ship payment is in, the agreement is signed, the certificate checked and the offices approved.
A13: approvals: one row per office per campaign: the office's yes, its units, and its whole ladder (formulas).
A14: stops: one row per office per drop: the route.
... A29: Google Sheets: File > Settings > Locale United States, Time zone America/New_York.

Sheet dashboard
A1: ="Campaign tracker · "&config!$B$2 -> Campaign tracker · Desk Drop
A2: =IF(COUNTIF(campaigns!$A$2:$A$51,"SAMPLE*")+COUNTIF(drops!$A$2:$A$21,"SAMPLE*")>0,"SAMPLE DATA. Illustrative placeholders, not results.","") -> SAMPLE DATA. Illustrative placeholders, not results.
A3: Today | B3: =IF(config!$B$37<>"",config!$B$37,TODAY()) -> 46468
A5: Checks to fix (0 everywhere = nothing to fix; lines starting info: are facts, not counted)
A6: check | B6: count | C6: where to look
A7: Drops with a refused date | B7: =IFERROR(COUNTIF(drops!$I$2:$I$21,"REFUSED*"),0) -> 0 | C7: drops, date_check
A8: Campaigns with checks to read | B8: =IFERROR(COUNTIF(campaigns!$DV$2:$DV$51,"?*")-COUNTIF(campaigns!$DV$2:$DV$51,"info:*"),0) -> 0 | C8: campaigns, checks
A9: Campaigns on ship HOLD | B9: =IFERROR(COUNTIF(campaigns!$BW$2:$BW$51,"HOLD*"),0) -> 0 | C9: campaigns, ship_release
A10: Office rows with checks | B10: =IFERROR(COUNTIF(approvals!$AP$2:$AP$251,"?*")-COUNTIF(approvals!$AP$2:$AP$251,"info:*"),0) -> 0 | C10: approvals, checks
A11: Stops with checks | B11: =IFERROR(COUNTIF(stops!$AD$2:$AD$151,"?*")-COUNTIF(stops!$AD$2:$AD$151,"info:*"),0) -> 0 | C11: stops, checks
A12: Inventory rows with checks | B12: =IFERROR(COUNTIF(inventory!$Q$2:$Q$801,"?*")-COUNTIF(inventory!$Q$2:$Q$801,"info:*"),0) -> 0 | C12: inventory, checks
A13: Count rows with checks | B13: =IFERROR(COUNTIF(counts!$K$2:$K$701,"?*")-COUNTIF(counts!$K$2:$K$701,"info:*"),0) -> 0 | C13: counts, checks
A14: Photo rows with checks | B14: =IFERROR(COUNTIF(photos!$Q$2:$Q$701,"?*")-COUNTIF(photos!$Q$2:$Q$701,"info:*"),0) -> 0 | C14: photos, checks
A15: Link rows with checks | B15: =IFERROR(COUNTIF(links!$I$2:$I$501,"?*")-COUNTIF(links!$I$2:$I$501,"info:*"),0) -> 0 | C15: links, checks
A16: Scan readings with checks | B16: =IFERROR(COUNTIF(scans!$J$2:$J$1601,"?*")-COUNTIF(scans!$J$2:$J$1601,"info:*"),0) -> 0 | C16: scans, checks
A17: Issues open | B17: =IFERROR(SUMPRODUCT((LEN(issues!$A$2:$A$121)>0)*(LEN(issues!$L$2:$L$121)=0)),0) -> 0 | C17: issues
A18: Issue rows with checks | B18: =IFERROR(COUNTIF(issues!$O$2:$O$121,"?*")-COUNTIF(issues!$O$2:$O$121,"info:*"),0) -> 0 | C18: issues, checks
A19: Hours rows with checks | B19: =IFERROR(COUNTIF(hours!$G$2:$G$1501,"?*")-COUNTIF(hours!$G$2:$G$1501,"info:*"),0) -> 0 | C19: hours, checks
A20: Cost rows with checks | B20: =IFERROR(COUNTIF(costs!$I$2:$I$301,"?*")-COUNTIF(costs!$I$2:$I$301,"info:*"),0) -> 0 | C20: costs, checks
A21: Invoices overdue | B21: =IFERROR(COUNTIF(invoices!$Q$2:$Q$151,"overdue"),0) -> 0 | C21: invoices, status
A22: Invoice rows with checks | B22: =IFERROR(COUNTIF(invoices!$S$2:$S$151,"?*")-COUNTIF(invoices!$S$2:$S$151,"info:*"),0) -> 0 | C22: invoices, checks
A23: Brands in E's paid_brands.csv not on brands | B23: =IFERROR(SUMPRODUCT((in_paid_brands!$A$2:$A$81<>"")*(COUNTIF(brands!$A$2:$A$41,INDEX(in_paid_brands!$A$2:$BZ$81,0,MATCH("brand_id",in_paid_brands!$A$1:$BZ$1,0)))=0)),0) -> 0 | C23: in_paid_brands
A24: Offices in E's signed_offices.csv not on offices | B24: =IFERROR(SUMPRODUCT((in_signed_offices!$A$2:$A$81<>"")*(COUNTIF(offices!$A$2:$A$61,INDEX(in_signed_offices!$A$2:$BZ$81,0,MATCH("office_id",in_signed_offices!$A$1:$BZ$1,0)))=0)),0) -> 0 | C24: in_signed_offices
A25: Offices that left: contact details past their keep date | B25: =IFERROR(SUMPRODUCT((offices!$K$2:$K$61="left")*ISNUMBER(offices!$L$2:$L$61)*((IF(config!$B$37<>"",config!$B$37,TODAY())-offices!$L$2:$L$61)>config!$B$42)*((LEN(offices!$S$2:$S$61)+LEN(offices!$U$2:$U$61)+LEN(offices!$V$2:$V$61)+LEN(offices!$AJ$2:$AJ$61))>0)),0) -> 0 | C25: offices: clear names, emails, phones in in_signed_offices, office_intake, office_form
A26: Brands whose payments in E's paid_brands.csv differ from the invoices tab | B26: =IFERROR(COUNTIF(brands!$AJ$2:$AJ$41,"?*"),0) -> 0 | C26: brands, e_payment_check (E's file feeds the financial model's Pipeline; the invoices tab releases the ship date)
A27: Tabs over 90% full (rows below the last formula row are not counted) | B27: =IFERROR((COUNTA(drops!$A:$A)-1>0.9*20)+(COUNTA(brands!$A:$A)-1>0.9*40)+(COUNTA(offices!$A:$A)-1>0.9*60)+(COUNTA(campaigns!$A:$A)-1>0.9*50)+(COUNTA(approvals!$A:$A)-1>0.9*250)+(COUNTA(stops!$A:$A)-1>0.9*150)+(COUNTA(inventory!$A:$A)-1>0.9*800)+(COUNTA(counts!$A:$A)-1>0.9*700)+(COUNTA(photos!$A:$A)-1>0.9*700)+(COUNTA(scans!$A:$A)-1>0.9*1600)+(COUNTA(redemptions!$A:$A)-1>0.9*120)+(COUNTA(issues!$A:$A)-1>0.9*120)+(COUNTA(hours!$A:$A)-1>0.9*1500)+(COUNTA(costs!$A:$A)-1>0.9*300)+(COUNTA(invoices!$A:$A)-1>0.9*150)+(COUNTA(INDIRECT("office_form!A:A"))-1>0.9*80)+(COUNTA(INDIRECT("brand_form!A:A"))-1>0.9*80)+(COUNTA(in_signed_offices!$A:$A)-1>0.9*80)+(COUNTA(in_paid_brands!$A:$A)-1>0.9*80)+(COUNTA(office_intake!$A:$A)-1>0.9*400)+(COUNTA(brand_intake!$A:$A)-1>0.9*400)+(COUNTA(survey_frozen!$A:$A)-1>0.9*250),0) -> 0 | C27: runbook, 'Speed and size': rebuild with tools/build_tracker.py --size full before a tab runs out
A28: Offices with roster checks (declined twice, coworking, outside the boundary) | B28: =IFERROR(COUNTIF(offices!$AR$2:$AR$61,"?*")-COUNTIF(offices!$AR$2:$AR$61,"info:*"),0) -> 0 | C28: offices, checks (review round 2)
A30: Drops
A31: drop | B31: date | C31: model | D31: status | E31: date check | F31: next step | G31: on | H31: stops | I31: brands | J31: units | K31: revenue | L31: direct cost | M31: cost per stop | N31: founder hours | O31: contribution before overhead | P31: per founder hour, before overhead | Q31: G2 placed in 1 bd | R31: G2 fewest responses | S31: G2 reports late | T31: G2 buy again
A32: =IF(INDEX(drops!$A$2:$A$21,1)="","",INDEX(drops!$A$2:$A$21,1)) -> SAMPLE-DRP-001 | B32: =IF(INDEX(drops!$A$2:$A$21,1)="","",INDEX(drops!$B$2:$B$21,1)) -> 46399 | C32: =IF(INDEX(drops!$A$2:$A$21,1)="","",INDEX(drops!$C$2:$C$21,1)) -> founder | D32: =IF(INDEX(drops!$A$2:$A$21,1)="","",INDEX(drops!$D$2:$D$21,1)) -> confirmed | E32: =IF(INDEX(drops!$A$2:$A$21,1)="","",INDEX(drops!$I$2:$I$21,1)) -> OK | F32: =IF(INDEX(drops!$A$2:$A$21,1)="","",INDEX(drops!$X$2:$X$21,1)) -> done | G32: =IF(INDEX(drops!$A$2:$A$21,1)="","",INDEX(drops!$Y$2:$Y$21,1)) | H32: =IF(INDEX(drops!$A$2:$A$21,1)="","",INDEX(drops!$AA$2:$AA$21,1)) -> 5 | I32: =IF(INDEX(drops!$A$2:$A$21,1)="","",INDEX(drops!$Z$2:$Z$21,1)) -> 2 | J32: =IF(INDEX(drops!$A$2:$A$21,1)="","",INDEX(drops!$AB$2:$AB$21,1)) -> 500 | K32: =IF(INDEX(drops!$A$2:$A$21,1)="","",INDEX(drops!$AC$2:$AC$21,1)) -> 1080 | L32: =IF(INDEX(drops!$A$2:$A$21,1)="","",INDEX(drops!$AG$2:$AG$21,1)) -> 152 | M32: =IF(INDEX(drops!$A$2:$A$21,1)="","",INDEX(drops!$AH$2:$AH$21,1)) -> 30.4 | N32: =IF(INDEX(drops!$A$2:$A$21,1)="","",INDEX(drops!$AI$2:$AI$21,1)) -> 57 | O32: =IF(INDEX(drops!$A$2:$A$21,1)="","",INDEX(drops!$AJ$2:$AJ$21,1)) -> 928 | P32: =IF(INDEX(drops!$A$2:$A$21,1)="","",INDEX(drops!$AK$2:$AK$21,1)) -> 16.28 | Q32: =IF(INDEX(drops!$A$2:$A$21,1)="","",INDEX(drops!$AL$2:$AL$21,1)) -> 0.896 | R32: =IF(INDEX(drops!$A$2:$A$21,1)="","",INDEX(drops!$AM$2:$AM$21,1)) -> 4 | S32: =IF(INDEX(drops!$A$2:$A$21,1)="","",INDEX(drops!$AN$2:$AN$21,1)) -> 0 | T32: =IF(INDEX(drops!$A$2:$A$21,1)="","",INDEX(drops!$AO$2:$AO$21,1)) -> 1
A33: =IF(INDEX(drops!$A$2:$A$21,2)="","",INDEX(drops!$A$2:$A$21,2)) -> SAMPLE-DRP-002 | B33: =IF(INDEX(drops!$A$2:$A$21,2)="","",INDEX(drops!$B$2:$B$21,2)) -> 46427 | C33: =IF(INDEX(drops!$A$2:$A$21,2)="","",INDEX(drops!$C$2:$C$21,2)) -> courier | D33: =IF(INDEX(drops!$A$2:$A$21,2)="","",INDEX(drops!$D$2:$D$21,2)) -> confirmed | E33: =IF(INDEX(drops!$A$2:$A$21,2)="","",INDEX(drops!$I$2:$I$21,2)) -> OK | F33: =IF(INDEX(drops!$A$2:$A$21,2)="","",INDEX(drops!$X$2:$X$21,2)) -> done | G33: =IF(INDEX(drops!$A$2:$A$21,2)="","",INDEX(drops!$Y$2:$Y$21,2)) | H33: =IF(INDEX(drops!$A$2:$A$21,2)="","",INDEX(drops!$AA$2:$AA$21,2)) -> 10 | I33: =IF(INDEX(drops!$A$2:$A$21,2)="","",INDEX(drops!$Z$2:$Z$21,2)) -> 3 | J33: =IF(INDEX(drops!$A$2:$A$21,2)="","",INDEX(drops!$AB$2:$AB$21,2)) -> 1455 | K33: =IF(INDEX(drops!$A$2:$A$21,2)="","",INDEX(drops!$AC$2:$AC$21,2)) -> 4350 | L33: =IF(INDEX(drops!$A$2:$A$21,2)="","",INDEX(drops!$AG$2:$AG$21,2)) -> 590 | M33: =IF(INDEX(drops!$A$2:$A$21,2)="","",INDEX(drops!$AH$2:$AH$21,2)) -> 59 | N33: =IF(INDEX(drops!$A$2:$A$21,2)="","",INDEX(drops!$AI$2:$AI$21,2)) -> 52 | O33: =IF(INDEX(drops!$A$2:$A$21,2)="","",INDEX(drops!$AJ$2:$AJ$21,2)) -> 3760 | P33: =IF(INDEX(drops!$A$2:$A$21,2)="","",INDEX(drops!$AK$2:$AK$21,2)) -> 72.31 | Q33: =IF(INDEX(drops!$A$2:$A$21,2)="","",INDEX(drops!$AL$2:$AL$21,2)) -> 1 | R33: =IF(INDEX(drops!$A$2:$A$21,2)="","",INDEX(drops!$AM$2:$AM$21,2)) -> 4 | S33: =IF(INDEX(drops!$A$2:$A$21,2)="","",INDEX(drops!$AN$2:$AN$21,2)) -> 0 | T33: =IF(INDEX(drops!$A$2:$A$21,2)="","",INDEX(drops!$AO$2:$AO$21,2)) -> 2
A34: =IF(INDEX(drops!$A$2:$A$21,3)="","",INDEX(drops!$A$2:$A$21,3)) -> SAMPLE-DRP-003 | B34: =IF(INDEX(drops!$A$2:$A$21,3)="","",INDEX(drops!$B$2:$B$21,3)) -> 46441 | C34: =IF(INDEX(drops!$A$2:$A$21,3)="","",INDEX(drops!$C$2:$C$21,3)) -> courier | D34: =IF(INDEX(drops!$A$2:$A$21,3)="","",INDEX(drops!$D$2:$D$21,3)) -> confirmed | E34: =IF(INDEX(drops!$A$2:$A$21,3)="","",INDEX(drops!$I$2:$I$21,3)) -> OK | F34: =IF(INDEX(drops!$A$2:$A$21,3)="","",INDEX(drops!$X$2:$X$21,3)) -> T+30 redemption check | G34: =IF(INDEX(drops!$A$2:$A$21,3)="","",INDEX(drops!$Y$2:$Y$21,3)) -> 46471 | H34: =IF(INDEX(drops!$A$2:$A$21,3)="","",INDEX(drops!$AA$2:$AA$21,3)) -> 10 | I34: =IF(INDEX(drops!$A$2:$A$21,3)="","",INDEX(drops!$Z$2:$Z$21,3)) -> 1 | J34: =IF(INDEX(drops!$A$2:$A$21,3)="","",INDEX(drops!$AB$2:$AB$21,3)) -> 465 | K34: =IF(INDEX(drops!$A$2:$A$21,3)="","",INDEX(drops!$AC$2:$AC$21,3)) -> 1350 | L34: =IF(INDEX(drops!$A$2:$A$21,3)="","",INDEX(drops!$AG$2:$AG$21,3)) -> 380 | M34: =IF(INDEX(drops!$A$2:$A$21,3)="","",INDEX(drops!$AH$2:$AH$21,3)) -> 38 | N34: =IF(INDEX(drops!$A$2:$A$21,3)="","",INDEX(drops!$AI$2:$AI$21,3)) -> 20.5 | O34: =IF(INDEX(drops!$A$2:$A$21,3)="","",INDEX(drops!$AJ$2:$AJ$21,3)) -> 970 | P34: =IF(INDEX(drops!$A$2:$A$21,3)="","",INDEX(drops!$AK$2:$AK$21,3)) -> 47.32 | Q34: =IF(INDEX(drops!$A$2:$A$21,3)="","",INDEX(drops!$AL$2:$AL$21,3)) -> 1 | R34: =IF(INDEX(drops!$A$2:$A$21,3)="","",INDEX(drops!$AM$2:$AM$21,3)) -> 5 | S34: =IF(INDEX(drops!$A$2:$A$21,3)="","",INDEX(drops!$AN$2:$AN$21,3)) -> 0 | T34: =IF(INDEX(drops!$A$2:$A$21,3)="","",INDEX(drops!$AO$2:$AO$21,3)) -> 1
A35: =IF(INDEX(drops!$A$2:$A$21,4)="","",INDEX(drops!$A$2:$A$21,4)) -> SAMPLE-DRP-004 | B35: =IF(INDEX(drops!$A$2:$A$21,4)="","",INDEX(drops!$B$2:$B$21,4)) -> 46469 | C35: =IF(INDEX(drops!$A$2:$A$21,4)="","",INDEX(drops!$C$2:$C$21,4)) -> direct-ship | D35: =IF(INDEX(drops!$A$2:$A$21,4)="","",INDEX(drops!$D$2:$D$21,4)) -> confirmed | E35: =IF(INDEX(drops!$A$2:$A$21,4)="","",INDEX(drops!$I$2:$I$21,4)) -> OK | F35: =IF(INDEX(drops!$A$2:$A$21,4)="","",INDEX(drops!$X$2:$X$21,4)) -> T-1 confirm owners, pack | G35: =IF(INDEX(drops!$A$2:$A$21,4)="","",INDEX(drops!$Y$2:$Y$21,4)) -> 46468 | H35: =IF(INDEX(drops!$A$2:$A$21,4)="","",INDEX(drops!$AA$2:$AA$21,4)) -> 10 | I35: =IF(INDEX(drops!$A$2:$A$21,4)="","",INDEX(drops!$Z$2:$Z$21,4)) -> 2 | J35: =IF(INDEX(drops!$A$2:$A$21,4)="","",INDEX(drops!$AB$2:$AB$21,4)) -> 1030 | K35: =IF(INDEX(drops!$A$2:$A$21,4)="","",INDEX(drops!$AC$2:$AC$21,4)) -> 1950 | L35: =IF(INDEX(drops!$A$2:$A$21,4)="","",INDEX(drops!$AG$2:$AG$21,4)) -> 205 | M35: =IF(INDEX(drops!$A$2:$A$21,4)="","",INDEX(drops!$AH$2:$AH$21,4)) -> 20.5 | N35: =IF(INDEX(drops!$A$2:$A$21,4)="","",INDEX(drops!$AI$2:$AI$21,4)) -> 8 | O35: =IF(INDEX(drops!$A$2:$A$21,4)="","",INDEX(drops!$AJ$2:$AJ$21,4)) -> 1745 | P35: =IF(INDEX(drops!$A$2:$A$21,4)="","",INDEX(drops!$AK$2:$AK$21,4)) -> 218.13 | Q35: =IF(INDEX(drops!$A$2:$A$21,4)="","",INDEX(drops!$AL$2:$AL$21,4)) | R35: =IF(INDEX(drops!$A$2:$A$21,4)="","",INDEX(drops!$AM$2:$AM$21,4)) -> 0 | S35: =IF(INDEX(drops!$A$2:$A$21,4)="","",INDEX(drops!$AN$2:$AN$21,4)) -> 0 | T35: =IF(INDEX(drops!$A$2:$A$21,4)="","",INDEX(drops!$AO$2:$AO$21,4)) -> 0
A36: =IF(INDEX(drops!$A$2:$A$21,5)="","",INDEX(drops!$A$2:$A$21,5)) | B36: =IF(INDEX(drops!$A$2:$A$21,5)="","",INDEX(drops!$B$2:$B$21,5)) | C36: =IF(INDEX(drops!$A$2:$A$21,5)="","",INDEX(drops!$C$2:$C$21,5)) | D36: =IF(INDEX(drops!$A$2:$A$21,5)="","",INDEX(drops!$D$2:$D$21,5)) | E36: =IF(INDEX(drops!$A$2:$A$21,5)="","",INDEX(drops!$I$2:$I$21,5)) | F36: =IF(INDEX(drops!$A$2:$A$21,5)="","",INDEX(drops!$X$2:$X$21,5)) | G36: =IF(INDEX(drops!$A$2:$A$21,5)="","",INDEX(drops!$Y$2:$Y$21,5)) | H36: =IF(INDEX(drops!$A$2:$A$21,5)="","",INDEX(drops!$AA$2:$AA$21,5)) | I36: =IF(INDEX(drops!$A$2:$A$21,5)="","",INDEX(drops!$Z$2:$Z$21,5)) | J36: =IF(INDEX(drops!$A$2:$A$21,5)="","",INDEX(drops!$AB$2:$AB$21,5)) | K36: =IF(INDEX(drops!$A$2:$A$21,5)="","",INDEX(drops!$AC$2:$AC$21,5)) | L36: =IF(INDEX(drops!$A$2:$A$21,5)="","",INDEX(drops!$AG$2:$AG$21,5)) | M36: =IF(INDEX(drops!$A$2:$A$21,5)="","",INDEX(drops!$AH$2:$AH$21,5)) | N36: =IF(INDEX(drops!$A$2:$A$21,5)="","",INDEX(drops!$AI$2:$AI$21,5)) | O36: =IF(INDEX(drops!$A$2:$A$21,5)="","",INDEX(drops!$AJ$2:$AJ$21,5)) | P36: =IF(INDEX(drops!$A$2:$A$21,5)="","",INDEX(drops!$AK$2:$AK$21,5)) | Q36: =IF(INDEX(drops!$A$2:$A$21,5)="","",INDEX(drops!$AL$2:$AL$21,5)) | R36: =IF(INDEX(drops!$A$2:$A$21,5)="","",INDEX(drops!$AM$2:$AM$21,5)) | S36: =IF(INDEX(drops!$A$2:$A$21,5)="","",INDEX(drops!$AN$2:$AN$21,5)) | T36: =IF(INDEX(drops!$A$2:$A$21,5)="","",INDEX(drops!$AO$2:$AO$21,5))
A37: =IF(INDEX(drops!$A$2:$A$21,6)="","",INDEX(drops!$A$2:$A$21,6)) | B37: =IF(INDEX(drops!$A$2:$A$21,6)="","",INDEX(drops!$B$2:$B$21,6)) | C37: =IF(INDEX(drops!$A$2:$A$21,6)="","",INDEX(drops!$C$2:$C$21,6)) | D37: =IF(INDEX(drops!$A$2:$A$21,6)="","",INDEX(drops!$D$2:$D$21,6)) | E37: =IF(INDEX(drops!$A$2:$A$21,6)="","",INDEX(drops!$I$2:$I$21,6)) | F37: =IF(INDEX(drops!$A$2:$A$21,6)="","",INDEX(drops!$X$2:$X$21,6)) | G37: =IF(INDEX(drops!$A$2:$A$21,6)="","",INDEX(drops!$Y$2:$Y$21,6)) | H37: =IF(INDEX(drops!$A$2:$A$21,6)="","",INDEX(drops!$AA$2:$AA$21,6)) | I37: =IF(INDEX(drops!$A$2:$A$21,6)="","",INDEX(drops!$Z$2:$Z$21,6)) | J37: =IF(INDEX(drops!$A$2:$A$21,6)="","",INDEX(drops!$AB$2:$AB$21,6)) | K37: =IF(INDEX(drops!$A$2:$A$21,6)="","",INDEX(drops!$AC$2:$AC$21,6)) | L37: =IF(INDEX(drops!$A$2:$A$21,6)="","",INDEX(drops!$AG$2:$AG$21,6)) | M37: =IF(INDEX(drops!$A$2:$A$21,6)="","",INDEX(drops!$AH$2:$AH$21,6)) | N37: =IF(INDEX(drops!$A$2:$A$21,6)="","",INDEX(drops!$AI$2:$AI$21,6)) | O37: =IF(INDEX(drops!$A$2:$A$21,6)="","",INDEX(drops!$AJ$2:$AJ$21,6)) | P37: =IF(INDEX(drops!$A$2:$A$21,6)="","",INDEX(drops!$AK$2:$AK$21,6)) | Q37: =IF(INDEX(drops!$A$2:$A$21,6)="","",INDEX(drops!$AL$2:$AL$21,6)) | R37: =IF(INDEX(drops!$A$2:$A$21,6)="","",INDEX(drops!$AM$2:$AM$21,6)) | S37: =IF(INDEX(drops!$A$2:$A$21,6)="","",INDEX(drops!$AN$2:$AN$21,6)) | T37: =IF(INDEX(drops!$A$2:$A$21,6)="","",INDEX(drops!$AO$2:$AO$21,6))
A38: =IF(INDEX(drops!$A$2:$A$21,7)="","",INDEX(drops!$A$2:$A$21,7)) | B38: =IF(INDEX(drops!$A$2:$A$21,7)="","",INDEX(drops!$B$2:$B$21,7)) | C38: =IF(INDEX(drops!$A$2:$A$21,7)="","",INDEX(drops!$C$2:$C$21,7)) | D38: =IF(INDEX(drops!$A$2:$A$21,7)="","",INDEX(drops!$D$2:$D$21,7)) | E38: =IF(INDEX(drops!$A$2:$A$21,7)="","",INDEX(drops!$I$2:$I$21,7)) | F38: =IF(INDEX(drops!$A$2:$A$21,7)="","",INDEX(drops!$X$2:$X$21,7)) | G38: =IF(INDEX(drops!$A$2:$A$21,7)="","",INDEX(drops!$Y$2:$Y$21,7)) | H38: =IF(INDEX(drops!$A$2:$A$21,7)="","",INDEX(drops!$AA$2:$AA$21,7)) | I38: =IF(INDEX(drops!$A$2:$A$21,7)="","",INDEX(drops!$Z$2:$Z$21,7)) | J38: =IF(INDEX(drops!$A$2:$A$21,7)="","",INDEX(drops!$AB$2:$AB$21,7)) | K38: =IF(INDEX(drops!$A$2:$A$21,7)="","",INDEX(drops!$AC$2:$AC$21,7)) | L38: =IF(INDEX(drops!$A$2:$A$21,7)="","",INDEX(drops!$AG$2:$AG$21,7)) | M38: =IF(INDEX(drops!$A$2:$A$21,7)="","",INDEX(drops!$AH$2:$AH$21,7)) | N38: =IF(INDEX(drops!$A$2:$A$21,7)="","",INDEX(drops!$AI$2:$AI$21,7)) | O38: =IF(INDEX(drops!$A$2:$A$21,7)="","",INDEX(drops!$AJ$2:$AJ$21,7)) | P38: =IF(INDEX(drops!$A$2:$A$21,7)="","",INDEX(drops!$AK$2:$AK$21,7)) | Q38: =IF(INDEX(drops!$A$2:$A$21,7)="","",INDEX(drops!$AL$2:$AL$21,7)) | R38: =IF(INDEX(drops!$A$2:$A$21,7)="","",INDEX(drops!$AM$2:$AM$21,7)) | S38: =IF(INDEX(drops!$A$2:$A$21,7)="","",INDEX(drops!$AN$2:$AN$21,7)) | T38: =IF(INDEX(drops!$A$2:$A$21,7)="","",INDEX(drops!$AO$2:$AO$21,7))
A39: =IF(INDEX(drops!$A$2:$A$21,8)="","",INDEX(drops!$A$2:$A$21,8)) | B39: =IF(INDEX(drops!$A$2:$A$21,8)="","",INDEX(drops!$B$2:$B$21,8)) | C39: =IF(INDEX(drops!$A$2:$A$21,8)="","",INDEX(drops!$C$2:$C$21,8)) | D39: =IF(INDEX(drops!$A$2:$A$21,8)="","",INDEX(drops!$D$2:$D$21,8)) | E39: =IF(INDEX(drops!$A$2:$A$21,8)="","",INDEX(drops!$I$2:$I$21,8)) | F39: =IF(INDEX(drops!$A$2:$A$21,8)="","",INDEX(drops!$X$2:$X$21,8)) | G39: =IF(INDEX(drops!$A$2:$A$21,8)="","",INDEX(drops!$Y$2:$Y$21,8)) | H39: =IF(INDEX(drops!$A$2:$A$21,8)="","",INDEX(drops!$AA$2:$AA$21,8)) | I39: =IF(INDEX(drops!$A$2:$A$21,8)="","",INDEX(drops!$Z$2:$Z$21,8)) | J39: =IF(INDEX(drops!$A$2:$A$21,8)="","",INDEX(drops!$AB$2:$AB$21,8)) | K39: =IF(INDEX(drops!$A$2:$A$21,8)="","",INDEX(drops!$AC$2:$AC$21,8)) | L39: =IF(INDEX(drops!$A$2:$A$21,8)="","",INDEX(drops!$AG$2:$AG$21,8)) | M39: =IF(INDEX(drops!$A$2:$A$21,8)="","",INDEX(drops!$AH$2:$AH$21,8)) | N39: =IF(INDEX(drops!$A$2:$A$21,8)="","",INDEX(drops!$AI$2:$AI$21,8)) | O39: =IF(INDEX(drops!$A$2:$A$21,8)="","",INDEX(drops!$AJ$2:$AJ$21,8)) | P39: =IF(INDEX(drops!$A$2:$A$21,8)="","",INDEX(drops!$AK$2:$AK$21,8)) | Q39: =IF(INDEX(drops!$A$2:$A$21,8)="","",INDEX(drops!$AL$2:$AL$21,8)) | R39: =IF(INDEX(drops!$A$2:$A$21,8)="","",INDEX(drops!$AM$2:$AM$21,8)) | S39: =IF(INDEX(drops!$A$2:$A$21,8)="","",INDEX(drops!$AN$2:$AN$21,8)) | T39: =IF(INDEX(drops!$A$2:$A$21,8)="","",INDEX(drops!$AO$2:$AO$21,8))
A40: =IF(INDEX(drops!$A$2:$A$21,9)="","",INDEX(drops!$A$2:$A$21,9)) | B40: =IF(INDEX(drops!$A$2:$A$21,9)="","",INDEX(drops!$B$2:$B$21,9)) | C40: =IF(INDEX(drops!$A$2:$A$21,9)="","",INDEX(drops!$C$2:$C$21,9)) | D40: =IF(INDEX(drops!$A$2:$A$21,9)="","",INDEX(drops!$D$2:$D$21,9)) | E40: =IF(INDEX(drops!$A$2:$A$21,9)="","",INDEX(drops!$I$2:$I$21,9)) | F40: =IF(INDEX(drops!$A$2:$A$21,9)="","",INDEX(drops!$X$2:$X$21,9)) | G40: =IF(INDEX(drops!$A$2:$A$21,9)="","",INDEX(drops!$Y$2:$Y$21,9)) | H40: =IF(INDEX(drops!$A$2:$A$21,9)="","",INDEX(drops!$AA$2:$AA$21,9)) | I40: =IF(INDEX(drops!$A$2:$A$21,9)="","",INDEX(drops!$Z$2:$Z$21,9)) | J40: =IF(INDEX(drops!$A$2:$A$21,9)="","",INDEX(drops!$AB$2:$AB$21,9)) | K40: =IF(INDEX(drops!$A$2:$A$21,9)="","",INDEX(drops!$AC$2:$AC$21,9)) | L40: =IF(INDEX(drops!$A$2:$A$21,9)="","",INDEX(drops!$AG$2:$AG$21,9)) | M40: =IF(INDEX(drops!$A$2:$A$21,9)="","",INDEX(drops!$AH$2:$AH$21,9)) | N40: =IF(INDEX(drops!$A$2:$A$21,9)="","",INDEX(drops!$AI$2:$AI$21,9)) | O40: =IF(INDEX(drops!$A$2:$A$21,9)="","",INDEX(drops!$AJ$2:$AJ$21,9)) | P40: =IF(INDEX(drops!$A$2:$A$21,9)="","",INDEX(drops!$AK$2:$AK$21,9)) | Q40: =IF(INDEX(drops!$A$2:$A$21,9)="","",INDEX(drops!$AL$2:$AL$21,9)) | R40: =IF(INDEX(drops!$A$2:$A$21,9)="","",INDEX(drops!$AM$2:$AM$21,9)) | S40: =IF(INDEX(drops!$A$2:$A$21,9)="","",INDEX(drops!$AN$2:$AN$21,9)) | T40: =IF(INDEX(drops!$A$2:$A$21,9)="","",INDEX(drops!$AO$2:$AO$21,9))
A41: =IF(INDEX(drops!$A$2:$A$21,10)="","",INDEX(drops!$A$2:$A$21,10)) | B41: =IF(INDEX(drops!$A$2:$A$21,10)="","",INDEX(drops!$B$2:$B$21,10)) | C41: =IF(INDEX(drops!$A$2:$A$21,10)="","",INDEX(drops!$C$2:$C$21,10)) | D41: =IF(INDEX(drops!$A$2:$A$21,10)="","",INDEX(drops!$D$2:$D$21,10)) | E41: =IF(INDEX(drops!$A$2:$A$21,10)="","",INDEX(drops!$I$2:$I$21,10)) | F41: =IF(INDEX(drops!$A$2:$A$21,10)="","",INDEX(drops!$X$2:$X$21,10)) | G41: =IF(INDEX(drops!$A$2:$A$21,10)="","",INDEX(drops!$Y$2:$Y$21,10)) | H41: =IF(INDEX(drops!$A$2:$A$21,10)="","",INDEX(drops!$AA$2:$AA$21,10)) | I41: =IF(INDEX(drops!$A$2:$A$21,10)="","",INDEX(drops!$Z$2:$Z$21,10)) | J41: =IF(INDEX(drops!$A$2:$A$21,10)="","",INDEX(drops!$AB$2:$AB$21,10)) | K41: =IF(INDEX(drops!$A$2:$A$21,10)="","",INDEX(drops!$AC$2:$AC$21,10)) | L41: =IF(INDEX(drops!$A$2:$A$21,10)="","",INDEX(drops!$AG$2:$AG$21,10)) | M41: =IF(INDEX(drops!$A$2:$A$21,10)="","",INDEX(drops!$AH$2:$AH$21,10)) | N41: =IF(INDEX(drops!$A$2:$A$21,10)="","",INDEX(drops!$AI$2:$AI$21,10)) | O41: =IF(INDEX(drops!$A$2:$A$21,10)="","",INDEX(drops!$AJ$2:$AJ$21,10)) | P41: =IF(INDEX(drops!$A$2:$A$21,10)="","",INDEX(drops!$AK$2:$AK$21,10)) | Q41: =IF(INDEX(drops!$A$2:$A$21,10)="","",INDEX(drops!$AL$2:$AL$21,10)) | R41: =IF(INDEX(drops!$A$2:$A$21,10)="","",INDEX(drops!$AM$2:$AM$21,10)) | S41: =IF(INDEX(drops!$A$2:$A$21,10)="","",INDEX(drops!$AN$2:$AN$21,10)) | T41: =IF(INDEX(drops!$A$2:$A$21,10)="","",INDEX(drops!$AO$2:$AO$21,10))
A42: =IF(INDEX(drops!$A$2:$A$21,11)="","",INDEX(drops!$A$2:$A$21,11)) | B42: =IF(INDEX(drops!$A$2:$A$21,11)="","",INDEX(drops!$B$2:$B$21,11)) | C42: =IF(INDEX(drops!$A$2:$A$21,11)="","",INDEX(drops!$C$2:$C$21,11)) | D42: =IF(INDEX(drops!$A$2:$A$21,11)="","",INDEX(drops!$D$2:$D$21,11)) | E42: =IF(INDEX(drops!$A$2:$A$21,11)="","",INDEX(drops!$I$2:$I$21,11)) | F42: =IF(INDEX(drops!$A$2:$A$21,11)="","",INDEX(drops!$X$2:$X$21,11)) | G42: =IF(INDEX(drops!$A$2:$A$21,11)="","",INDEX(drops!$Y$2:$Y$21,11)) | H42: =IF(INDEX(drops!$A$2:$A$21,11)="","",INDEX(drops!$AA$2:$AA$21,11)) | I42: =IF(INDEX(drops!$A$2:$A$21,11)="","",INDEX(drops!$Z$2:$Z$21,11)) | J42: =IF(INDEX(drops!$A$2:$A$21,11)="","",INDEX(drops!$AB$2:$AB$21,11)) | K42: =IF(INDEX(drops!$A$2:$A$21,11)="","",INDEX(drops!$AC$2:$AC$21,11)) | L42: =IF(INDEX(drops!$A$2:$A$21,11)="","",INDEX(drops!$AG$2:$AG$21,11)) | M42: =IF(INDEX(drops!$A$2:$A$21,11)="","",INDEX(drops!$AH$2:$AH$21,11)) | N42: =IF(INDEX(drops!$A$2:$A$21,11)="","",INDEX(drops!$AI$2:$AI$21,11)) | O42: =IF(INDEX(drops!$A$2:$A$21,11)="","",INDEX(drops!$AJ$2:$AJ$21,11)) | P42: =IF(INDEX(drops!$A$2:$A$21,11)="","",INDEX(drops!$AK$2:$AK$21,11)) | Q42: =IF(INDEX(drops!$A$2:$A$21,11)="","",INDEX(drops!$AL$2:$AL$21,11)) | R42: =IF(INDEX(drops!$A$2:$A$21,11)="","",INDEX(drops!$AM$2:$AM$21,11)) | S42: =IF(INDEX(drops!$A$2:$A$21,11)="","",INDEX(drops!$AN$2:$AN$21,11)) | T42: =IF(INDEX(drops!$A$2:$A$21,11)="","",INDEX(drops!$AO$2:$AO$21,11))
...

Sheet survey_dashboard
A1: Survey responses
A2: Campaign | B2: =IF(INDEX(campaigns!$A$2:$A$51,1)="","",INDEX(campaigns!$A$2:$A$51,1)) -> SAMPLE-CMP-001 | C2: Type a campaign_id over B2 to switch. Counts are live from the campaign's form tab, inside the window T to T+4 only.
A3: =IF(LEFT($B$2,6)="SAMPLE","SAMPLE DATA. Illustrative placeholders, not results.","") -> SAMPLE DATA. Illustrative placeholders, not results.
A4: =IF($B$2="","",IFERROR(INDEX(campaigns!$BE$2:$BE$51,MATCH($B$2,campaigns!$A$2:$A$51,0)),"")&" · drop "&TEXT(IFERROR(INDEX(campaigns!$BG$2:$BG$51,MATCH($B$2,campaigns!$A$2:$A$51,0)),""),"ddd yyyy-mm-dd")&" · window closes "&TEXT(IFERROR(INDEX(drops!$R$2:$R$21,MATCH(IFERROR(INDEX(campaigns!$B$2:$B$51,MATCH($B$2,campaigns!$A$2:$A$51,0)),""),drops!$A$2:$A$21,0)),""),"ddd yyyy-mm-dd")) -> SAMPLE Brightside · drop Tue 2027-01-12 · window closes Tue 2027-01-19
A6: office | B6: company | C6: responses | D6: said they tried | E6: didn't see it | F6: not for me | G6: gone when they looked | H6: ratings | I6: avg rating | J6: would buy: yes | K6: maybe | L6: no | M6: comments | N6: status
A7: =IFERROR(INDEX(approvals!$M$2:$M$251,MATCH($B$2&"|"&1,approvals!$AZ$2:$AZ$251,0)),"") -> A | B7: =IFERROR(INDEX(approvals!$K$2:$K$251,MATCH($B$2&"|"&1,approvals!$AZ$2:$AZ$251,0)),"") -> SAMPLE Northpoint Software | C7: =IFERROR(INDEX(approvals!$AL$2:$AL$251,MATCH($B$2&"|"&1,approvals!$AZ$2:$AZ$251,0)),"") -> 9 | D7: =IFERROR(INDEX(approvals!$AM$2:$AM$251,MATCH($B$2&"|"&1,approvals!$AZ$2:$AZ$251,0)),"") -> 8 | E7: =IFERROR(INDEX(approvals!$AQ$2:$AQ$251,MATCH($B$2&"|"&1,approvals!$AZ$2:$AZ$251,0)),"") -> 1 | F7: =IFERROR(INDEX(approvals!$AR$2:$AR$251,MATCH($B$2&"|"&1,approvals!$AZ$2:$AZ$251,0)),"") -> 0 | G7: =IFERROR(INDEX(approvals!$AS$2:$AS$251,MATCH($B$2&"|"&1,approvals!$AZ$2:$AZ$251,0)),"") -> 0 | H7: =IFERROR(INDEX(approvals!$AT$2:$AT$251,MATCH($B$2&"|"&1,approvals!$AZ$2:$AZ$251,0)),"") -> 8 | I7: =IFERROR(IF(INDEX(approvals!$AT$2:$AT$251,MATCH($B$2&"|"&1,approvals!$AZ$2:$AZ$251,0))=0,"",ROUND(INDEX(approvals!$AU$2:$AU$251,MATCH($B$2&"|"&1,approvals!$AZ$2:$AZ$251,0))/INDEX(approvals!$AT$2:$AT$251,MATCH($B$2&"|"&1,approvals!$AZ$2:$AZ$251,0)),1)),"") -> 3.9 | J7: =IFERROR(INDEX(approvals!$AV$2:$AV$251,MATCH($B$2&"|"&1,approvals!$AZ$2:$AZ$251,0)),"") -> 2 | K7: =IFERROR(INDEX(approvals!$AW$2:$AW$251,MATCH($B$2&"|"&1,approvals!$AZ$2:$AZ$251,0)),"") -> 3 | L7: =IFERROR(INDEX(approvals!$AX$2:$AX$251,MATCH($B$2&"|"&1,approvals!$AZ$2:$AZ$251,0)),"") -> 3 | M7: =IFERROR(INDEX(approvals!$AY$2:$AY$251,MATCH($B$2&"|"&1,approvals!$AZ$2:$AZ$251,0)),"") -> 5 | N7: =IFERROR(IF(INDEX(approvals!$AL$2:$AL$251,MATCH($B$2&"|"&1,approvals!$AZ$2:$AZ$251,0))>=config!$B$30,"OK","under "&config!$B$30&": ask the owner to re-post"),"") -> OK
A8: =IFERROR(INDEX(approvals!$M$2:$M$251,MATCH($B$2&"|"&2,approvals!$AZ$2:$AZ$251,0)),"") -> B | B8: =IFERROR(INDEX(approvals!$K$2:$K$251,MATCH($B$2&"|"&2,approvals!$AZ$2:$AZ$251,0)),"") -> SAMPLE Ferro Architecture | C8: =IFERROR(INDEX(approvals!$AL$2:$AL$251,MATCH($B$2&"|"&2,approvals!$AZ$2:$AZ$251,0)),"") -> 6 | D8: =IFERROR(INDEX(approvals!$AM$2:$AM$251,MATCH($B$2&"|"&2,approvals!$AZ$2:$AZ$251,0)),"") -> 5 | E8: =IFERROR(INDEX(approvals!$AQ$2:$AQ$251,MATCH($B$2&"|"&2,approvals!$AZ$2:$AZ$251,0)),"") -> 0 | F8: =IFERROR(INDEX(approvals!$AR$2:$AR$251,MATCH($B$2&"|"&2,approvals!$AZ$2:$AZ$251,0)),"") -> 1 | G8: =IFERROR(INDEX(approvals!$AS$2:$AS$251,MATCH($B$2&"|"&2,approvals!$AZ$2:$AZ$251,0)),"") -> 0 | H8: =IFERROR(INDEX(approvals!$AT$2:$AT$251,MATCH($B$2&"|"&2,approvals!$AZ$2:$AZ$251,0)),"") -> 5 | I8: =IFERROR(IF(INDEX(approvals!$AT$2:$AT$251,MATCH($B$2&"|"&2,approvals!$AZ$2:$AZ$251,0))=0,"",ROUND(INDEX(approvals!$AU$2:$AU$251,MATCH($B$2&"|"&2,approvals!$AZ$2:$AZ$251,0))/INDEX(approvals!$AT$2:$AT$251,MATCH($B$2&"|"&2,approvals!$AZ$2:$AZ$251,0)),1)),"") -> 4.8 | J8: =IFERROR(INDEX(approvals!$AV$2:$AV$251,MATCH($B$2&"|"&2,approvals!$AZ$2:$AZ$251,0)),"") -> 3 | K8: =IFERROR(INDEX(approvals!$AW$2:$AW$251,MATCH($B$2&"|"&2,approvals!$AZ$2:$AZ$251,0)),"") -> 1 | L8: =IFERROR(INDEX(approvals!$AX$2:$AX$251,MATCH($B$2&"|"&2,approvals!$AZ$2:$AZ$251,0)),"") -> 1 | M8: =IFERROR(INDEX(approvals!$AY$2:$AY$251,MATCH($B$2&"|"&2,approvals!$AZ$2:$AZ$251,0)),"") -> 3 | N8: =IFERROR(IF(INDEX(approvals!$AL$2:$AL$251,MATCH($B$2&"|"&2,approvals!$AZ$2:$AZ$251,0))>=config!$B$30,"OK","under "&config!$B$30&": ask the owner to re-post"),"") -> OK
A9: =IFERROR(INDEX(approvals!$M$2:$M$251,MATCH($B$2&"|"&3,approvals!$AZ$2:$AZ$251,0)),"") -> C | B9: =IFERROR(INDEX(approvals!$K$2:$K$251,MATCH($B$2&"|"&3,approvals!$AZ$2:$AZ$251,0)),"") -> SAMPLE Halcyon Media | C9: =IFERROR(INDEX(approvals!$AL$2:$AL$251,MATCH($B$2&"|"&3,approvals!$AZ$2:$AZ$251,0)),"") -> 8 | D9: =IFERROR(INDEX(approvals!$AM$2:$AM$251,MATCH($B$2&"|"&3,approvals!$AZ$2:$AZ$251,0)),"") -> 3 | E9: =IFERROR(INDEX(approvals!$AQ$2:$AQ$251,MATCH($B$2&"|"&3,approvals!$AZ$2:$AZ$251,0)),"") -> 3 | F9: =IFERROR(INDEX(approvals!$AR$2:$AR$251,MATCH($B$2&"|"&3,approvals!$AZ$2:$AZ$251,0)),"") -> 1 | G9: =IFERROR(INDEX(approvals!$AS$2:$AS$251,MATCH($B$2&"|"&3,approvals!$AZ$2:$AZ$251,0)),"") -> 1 | H9: =IFERROR(INDEX(approvals!$AT$2:$AT$251,MATCH($B$2&"|"&3,approvals!$AZ$2:$AZ$251,0)),"") -> 3 | I9: =IFERROR(IF(INDEX(approvals!$AT$2:$AT$251,MATCH($B$2&"|"&3,approvals!$AZ$2:$AZ$251,0))=0,"",ROUND(INDEX(approvals!$AU$2:$AU$251,MATCH($B$2&"|"&3,approvals!$AZ$2:$AZ$251,0))/INDEX(approvals!$AT$2:$AT$251,MATCH($B$2&"|"&3,approvals!$AZ$2:$AZ$251,0)),1)),"") -> 4.3 | J9: =IFERROR(INDEX(approvals!$AV$2:$AV$251,MATCH($B$2&"|"&3,approvals!$AZ$2:$AZ$251,0)),"") -> 2 | K9: =IFERROR(INDEX(approvals!$AW$2:$AW$251,MATCH($B$2&"|"&3,approvals!$AZ$2:$AZ$251,0)),"") -> 0 | L9: =IFERROR(INDEX(approvals!$AX$2:$AX$251,MATCH($B$2&"|"&3,approvals!$AZ$2:$AZ$251,0)),"") -> 1 | M9: =IFERROR(INDEX(approvals!$AY$2:$AY$251,MATCH($B$2&"|"&3,approvals!$AZ$2:$AZ$251,0)),"") -> 5 | N9: =IFERROR(IF(INDEX(approvals!$AL$2:$AL$251,MATCH($B$2&"|"&3,approvals!$AZ$2:$AZ$251,0))>=config!$B$30,"OK","under "&config!$B$30&": ask the owner to re-post"),"") -> OK
A10: =IFERROR(INDEX(approvals!$M$2:$M$251,MATCH($B$2&"|"&4,approvals!$AZ$2:$AZ$251,0)),"") -> D | B10: =IFERROR(INDEX(approvals!$K$2:$K$251,MATCH($B$2&"|"&4,approvals!$AZ$2:$AZ$251,0)),"") -> SAMPLE Union Food Fund | C10: =IFERROR(INDEX(approvals!$AL$2:$AL$251,MATCH($B$2&"|"&4,approvals!$AZ$2:$AZ$251,0)),"") -> 4 | D10: =IFERROR(INDEX(approvals!$AM$2:$AM$251,MATCH($B$2&"|"&4,approvals!$AZ$2:$AZ$251,0)),"") -> 2 | E10: =IFERROR(INDEX(approvals!$AQ$2:$AQ$251,MATCH($B$2&"|"&4,approvals!$AZ$2:$AZ$251,0)),"") -> 1 | F10: =IFERROR(INDEX(approvals!$AR$2:$AR$251,MATCH($B$2&"|"&4,approvals!$AZ$2:$AZ$251,0)),"") -> 0 | G10: =IFERROR(INDEX(approvals!$AS$2:$AS$251,MATCH($B$2&"|"&4,approvals!$AZ$2:$AZ$251,0)),"") -> 1 | H10: =IFERROR(INDEX(approvals!$AT$2:$AT$251,MATCH($B$2&"|"&4,approvals!$AZ$2:$AZ$251,0)),"") -> 2 | I10: =IFERROR(IF(INDEX(approvals!$AT$2:$AT$251,MATCH($B$2&"|"&4,approvals!$AZ$2:$AZ$251,0))=0,"",ROUND(INDEX(approvals!$AU$2:$AU$251,MATCH($B$2&"|"&4,approvals!$AZ$2:$AZ$251,0))/INDEX(approvals!$AT$2:$AT$251,MATCH($B$2&"|"&4,approvals!$AZ$2:$AZ$251,0)),1)),"") -> 4 | J10: =IFERROR(INDEX(approvals!$AV$2:$AV$251,MATCH($B$2&"|"&4,approvals!$AZ$2:$AZ$251,0)),"") -> 1 | K10: =IFERROR(INDEX(approvals!$AW$2:$AW$251,MATCH($B$2&"|"&4,approvals!$AZ$2:$AZ$251,0)),"") -> 1 | L10: =IFERROR(INDEX(approvals!$AX$2:$AX$251,MATCH($B$2&"|"&4,approvals!$AZ$2:$AZ$251,0)),"") -> 0 | M10: =IFERROR(INDEX(approvals!$AY$2:$AY$251,MATCH($B$2&"|"&4,approvals!$AZ$2:$AZ$251,0)),"") -> 3 | N10: =IFERROR(IF(INDEX(approvals!$AL$2:$AL$251,MATCH($B$2&"|"&4,approvals!$AZ$2:$AZ$251,0))>=config!$B$30,"OK","under "&config!$B$30&": ask the owner to re-post"),"") -> under 5: ask the owner to re-post
A11: =IFERROR(INDEX(approvals!$M$2:$M$251,MATCH($B$2&"|"&5,approvals!$AZ$2:$AZ$251,0)),"") -> E | B11: =IFERROR(INDEX(approvals!$K$2:$K$251,MATCH($B$2&"|"&5,approvals!$AZ$2:$AZ$251,0)),"") -> SAMPLE Studio Marlow | C11: =IFERROR(INDEX(approvals!$AL$2:$AL$251,MATCH($B$2&"|"&5,approvals!$AZ$2:$AZ$251,0)),"") -> 7 | D11: =IFERROR(INDEX(approvals!$AM$2:$AM$251,MATCH($B$2&"|"&5,approvals!$AZ$2:$AZ$251,0)),"") -> 7 | E11: =IFERROR(INDEX(approvals!$AQ$2:$AQ$251,MATCH($B$2&"|"&5,approvals!$AZ$2:$AZ$251,0)),"") -> 0 | F11: =IFERROR(INDEX(approvals!$AR$2:$AR$251,MATCH($B$2&"|"&5,approvals!$AZ$2:$AZ$251,0)),"") -> 0 | G11: =IFERROR(INDEX(approvals!$AS$2:$AS$251,MATCH($B$2&"|"&5,approvals!$AZ$2:$AZ$251,0)),"") -> 0 | H11: =IFERROR(INDEX(approvals!$AT$2:$AT$251,MATCH($B$2&"|"&5,approvals!$AZ$2:$AZ$251,0)),"") -> 7 | I11: =IFERROR(IF(INDEX(approvals!$AT$2:$AT$251,MATCH($B$2&"|"&5,approvals!$AZ$2:$AZ$251,0))=0,"",ROUND(INDEX(approvals!$AU$2:$AU$251,MATCH($B$2&"|"&5,approvals!$AZ$2:$AZ$251,0))/INDEX(approvals!$AT$2:$AT$251,MATCH($B$2&"|"&5,approvals!$AZ$2:$AZ$251,0)),1)),"") -> 4.3 | J11: =IFERROR(INDEX(approvals!$AV$2:$AV$251,MATCH($B$2&"|"&5,approvals!$AZ$2:$AZ$251,0)),"") -> 2 | K11: =IFERROR(INDEX(approvals!$AW$2:$AW$251,MATCH($B$2&"|"&5,approvals!$AZ$2:$AZ$251,0)),"") -> 3 | L11: =IFERROR(INDEX(approvals!$AX$2:$AX$251,MATCH($B$2&"|"&5,approvals!$AZ$2:$AZ$251,0)),"") -> 2 | M11: =IFERROR(INDEX(approvals!$AY$2:$AY$251,MATCH($B$2&"|"&5,approvals!$AZ$2:$AZ$251,0)),"") -> 2 | N11: =IFERROR(IF(INDEX(approvals!$AL$2:$AL$251,MATCH($B$2&"|"&5,approvals!$AZ$2:$AZ$251,0))>=config!$B$30,"OK","under "&config!$B$30&": ask the owner to re-post"),"") -> OK
A12: =IFERROR(INDEX(approvals!$M$2:$M$251,MATCH($B$2&"|"&6,approvals!$AZ$2:$AZ$251,0)),"") | B12: =IFERROR(INDEX(approvals!$K$2:$K$251,MATCH($B$2&"|"&6,approvals!$AZ$2:$AZ$251,0)),"") | C12: =IFERROR(INDEX(approvals!$AL$2:$AL$251,MATCH($B$2&"|"&6,approvals!$AZ$2:$AZ$251,0)),"") | D12: =IFERROR(INDEX(approvals!$AM$2:$AM$251,MATCH($B$2&"|"&6,approvals!$AZ$2:$AZ$251,0)),"") | E12: =IFERROR(INDEX(approvals!$AQ$2:$AQ$251,MATCH($B$2&"|"&6,approvals!$AZ$2:$AZ$251,0)),"") | F12: =IFERROR(INDEX(approvals!$AR$2:$AR$251,MATCH($B$2&"|"&6,approvals!$AZ$2:$AZ$251,0)),"") | G12: =IFERROR(INDEX(approvals!$AS$2:$AS$251,MATCH($B$2&"|"&6,approvals!$AZ$2:$AZ$251,0)),"") | H12: =IFERROR(INDEX(approvals!$AT$2:$AT$251,MATCH($B$2&"|"&6,approvals!$AZ$2:$AZ$251,0)),"") | I12: =IFERROR(IF(INDEX(approvals!$AT$2:$AT$251,MATCH($B$2&"|"&6,approvals!$AZ$2:$AZ$251,0))=0,"",ROUND(INDEX(approvals!$AU$2:$AU$251,MATCH($B$2&"|"&6,approvals!$AZ$2:$AZ$251,0))/INDEX(approvals!$AT$2:$AT$251,MATCH($B$2&"|"&6,approvals!$AZ$2:$AZ$251,0)),1)),"") | J12: =IFERROR(INDEX(approvals!$AV$2:$AV$251,MATCH($B$2&"|"&6,approvals!$AZ$2:$AZ$251,0)),"") | K12: =IFERROR(INDEX(approvals!$AW$2:$AW$251,MATCH($B$2&"|"&6,approvals!$AZ$2:$AZ$251,0)),"") | L12: =IFERROR(INDEX(approvals!$AX$2:$AX$251,MATCH($B$2&"|"&6,approvals!$AZ$2:$AZ$251,0)),"") | M12: =IFERROR(INDEX(approvals!$AY$2:$AY$251,MATCH($B$2&"|"&6,approvals!$AZ$2:$AZ$251,0)),"") | N12: =IFERROR(IF(INDEX(approvals!$AL$2:$AL$251,MATCH($B$2&"|"&6,approvals!$AZ$2:$AZ$251,0))>=config!$B$30,"OK","under "&config!$B$30&": ask the owner to re-post"),"")
A13: =IFERROR(INDEX(approvals!$M$2:$M$251,MATCH($B$2&"|"&7,approvals!$AZ$2:$AZ$251,0)),"") | B13: =IFERROR(INDEX(approvals!$K$2:$K$251,MATCH($B$2&"|"&7,approvals!$AZ$2:$AZ$251,0)),"") | C13: =IFERROR(INDEX(approvals!$AL$2:$AL$251,MATCH($B$2&"|"&7,approvals!$AZ$2:$AZ$251,0)),"") | D13: =IFERROR(INDEX(approvals!$AM$2:$AM$251,MATCH($B$2&"|"&7,approvals!$AZ$2:$AZ$251,0)),"") | E13: =IFERROR(INDEX(approvals!$AQ$2:$AQ$251,MATCH($B$2&"|"&7,approvals!$AZ$2:$AZ$251,0)),"") | F13: =IFERROR(INDEX(approvals!$AR$2:$AR$251,MATCH($B$2&"|"&7,approvals!$AZ$2:$AZ$251,0)),"") | G13: =IFERROR(INDEX(approvals!$AS$2:$AS$251,MATCH($B$2&"|"&7,approvals!$AZ$2:$AZ$251,0)),"") | H13: =IFERROR(INDEX(approvals!$AT$2:$AT$251,MATCH($B$2&"|"&7,approvals!$AZ$2:$AZ$251,0)),"") | I13: =IFERROR(IF(INDEX(approvals!$AT$2:$AT$251,MATCH($B$2&"|"&7,approvals!$AZ$2:$AZ$251,0))=0,"",ROUND(INDEX(approvals!$AU$2:$AU$251,MATCH($B$2&"|"&7,approvals!$AZ$2:$AZ$251,0))/INDEX(approvals!$AT$2:$AT$251,MATCH($B$2&"|"&7,approvals!$AZ$2:$AZ$251,0)),1)),"") | J13: =IFERROR(INDEX(approvals!$AV$2:$AV$251,MATCH($B$2&"|"&7,approvals!$AZ$2:$AZ$251,0)),"") | K13: =IFERROR(INDEX(approvals!$AW$2:$AW$251,MATCH($B$2&"|"&7,approvals!$AZ$2:$AZ$251,0)),"") | L13: =IFERROR(INDEX(approvals!$AX$2:$AX$251,MATCH($B$2&"|"&7,approvals!$AZ$2:$AZ$251,0)),"") | M13: =IFERROR(INDEX(approvals!$AY$2:$AY$251,MATCH($B$2&"|"&7,approvals!$AZ$2:$AZ$251,0)),"") | N13: =IFERROR(IF(INDEX(approvals!$AL$2:$AL$251,MATCH($B$2&"|"&7,approvals!$AZ$2:$AZ$251,0))>=config!$B$30,"OK","under "&config!$B$30&": ask the owner to re-post"),"")
A14: =IFERROR(INDEX(approvals!$M$2:$M$251,MATCH($B$2&"|"&8,approvals!$AZ$2:$AZ$251,0)),"") | B14: =IFERROR(INDEX(approvals!$K$2:$K$251,MATCH($B$2&"|"&8,approvals!$AZ$2:$AZ$251,0)),"") | C14: =IFERROR(INDEX(approvals!$AL$2:$AL$251,MATCH($B$2&"|"&8,approvals!$AZ$2:$AZ$251,0)),"") | D14: =IFERROR(INDEX(approvals!$AM$2:$AM$251,MATCH($B$2&"|"&8,approvals!$AZ$2:$AZ$251,0)),"") | E14: =IFERROR(INDEX(approvals!$AQ$2:$AQ$251,MATCH($B$2&"|"&8,approvals!$AZ$2:$AZ$251,0)),"") | F14: =IFERROR(INDEX(approvals!$AR$2:$AR$251,MATCH($B$2&"|"&8,approvals!$AZ$2:$AZ$251,0)),"") | G14: =IFERROR(INDEX(approvals!$AS$2:$AS$251,MATCH($B$2&"|"&8,approvals!$AZ$2:$AZ$251,0)),"") | H14: =IFERROR(INDEX(approvals!$AT$2:$AT$251,MATCH($B$2&"|"&8,approvals!$AZ$2:$AZ$251,0)),"") | I14: =IFERROR(IF(INDEX(approvals!$AT$2:$AT$251,MATCH($B$2&"|"&8,approvals!$AZ$2:$AZ$251,0))=0,"",ROUND(INDEX(approvals!$AU$2:$AU$251,MATCH($B$2&"|"&8,approvals!$AZ$2:$AZ$251,0))/INDEX(approvals!$AT$2:$AT$251,MATCH($B$2&"|"&8,approvals!$AZ$2:$AZ$251,0)),1)),"") | J14: =IFERROR(INDEX(approvals!$AV$2:$AV$251,MATCH($B$2&"|"&8,approvals!$AZ$2:$AZ$251,0)),"") | K14: =IFERROR(INDEX(approvals!$AW$2:$AW$251,MATCH($B$2&"|"&8,approvals!$AZ$2:$AZ$251,0)),"") | L14: =IFERROR(INDEX(approvals!$AX$2:$AX$251,MATCH($B$2&"|"&8,approvals!$AZ$2:$AZ$251,0)),"") | M14: =IFERROR(INDEX(approvals!$AY$2:$AY$251,MATCH($B$2&"|"&8,approvals!$AZ$2:$AZ$251,0)),"") | N14: =IFERROR(IF(INDEX(approvals!$AL$2:$AL$251,MATCH($B$2&"|"&8,approvals!$AZ$2:$AZ$251,0))>=config!$B$30,"OK","under "&config!$B$30&": ask the owner to re-post"),"")
A15: =IFERROR(INDEX(approvals!$M$2:$M$251,MATCH($B$2&"|"&9,approvals!$AZ$2:$AZ$251,0)),"") | B15: =IFERROR(INDEX(approvals!$K$2:$K$251,MATCH($B$2&"|"&9,approvals!$AZ$2:$AZ$251,0)),"") | C15: =IFERROR(INDEX(approvals!$AL$2:$AL$251,MATCH($B$2&"|"&9,approvals!$AZ$2:$AZ$251,0)),"") | D15: =IFERROR(INDEX(approvals!$AM$2:$AM$251,MATCH($B$2&"|"&9,approvals!$AZ$2:$AZ$251,0)),"") | E15: =IFERROR(INDEX(approvals!$AQ$2:$AQ$251,MATCH($B$2&"|"&9,approvals!$AZ$2:$AZ$251,0)),"") | F15: =IFERROR(INDEX(approvals!$AR$2:$AR$251,MATCH($B$2&"|"&9,approvals!$AZ$2:$AZ$251,0)),"") | G15: =IFERROR(INDEX(approvals!$AS$2:$AS$251,MATCH($B$2&"|"&9,approvals!$AZ$2:$AZ$251,0)),"") | H15: =IFERROR(INDEX(approvals!$AT$2:$AT$251,MATCH($B$2&"|"&9,approvals!$AZ$2:$AZ$251,0)),"") | I15: =IFERROR(IF(INDEX(approvals!$AT$2:$AT$251,MATCH($B$2&"|"&9,approvals!$AZ$2:$AZ$251,0))=0,"",ROUND(INDEX(approvals!$AU$2:$AU$251,MATCH($B$2&"|"&9,approvals!$AZ$2:$AZ$251,0))/INDEX(approvals!$AT$2:$AT$251,MATCH($B$2&"|"&9,approvals!$AZ$2:$AZ$251,0)),1)),"") | J15: =IFERROR(INDEX(approvals!$AV$2:$AV$251,MATCH($B$2&"|"&9,approvals!$AZ$2:$AZ$251,0)),"") | K15: =IFERROR(INDEX(approvals!$AW$2:$AW$251,MATCH($B$2&"|"&9,approvals!$AZ$2:$AZ$251,0)),"") | L15: =IFERROR(INDEX(approvals!$AX$2:$AX$251,MATCH($B$2&"|"&9,approvals!$AZ$2:$AZ$251,0)),"") | M15: =IFERROR(INDEX(approvals!$AY$2:$AY$251,MATCH($B$2&"|"&9,approvals!$AZ$2:$AZ$251,0)),"") | N15: =IFERROR(IF(INDEX(approvals!$AL$2:$AL$251,MATCH($B$2&"|"&9,approvals!$AZ$2:$AZ$251,0))>=config!$B$30,"OK","under "&config!$B$30&": ask the owner to re-post"),"")
A16: =IFERROR(INDEX(approvals!$M$2:$M$251,MATCH($B$2&"|"&10,approvals!$AZ$2:$AZ$251,0)),"") | B16: =IFERROR(INDEX(approvals!$K$2:$K$251,MATCH($B$2&"|"&10,approvals!$AZ$2:$AZ$251,0)),"") | C16: =IFERROR(INDEX(approvals!$AL$2:$AL$251,MATCH($B$2&"|"&10,approvals!$AZ$2:$AZ$251,0)),"") | D16: =IFERROR(INDEX(approvals!$AM$2:$AM$251,MATCH($B$2&"|"&10,approvals!$AZ$2:$AZ$251,0)),"") | E16: =IFERROR(INDEX(approvals!$AQ$2:$AQ$251,MATCH($B$2&"|"&10,approvals!$AZ$2:$AZ$251,0)),"") | F16: =IFERROR(INDEX(approvals!$AR$2:$AR$251,MATCH($B$2&"|"&10,approvals!$AZ$2:$AZ$251,0)),"") | G16: =IFERROR(INDEX(approvals!$AS$2:$AS$251,MATCH($B$2&"|"&10,approvals!$AZ$2:$AZ$251,0)),"") | H16: =IFERROR(INDEX(approvals!$AT$2:$AT$251,MATCH($B$2&"|"&10,approvals!$AZ$2:$AZ$251,0)),"") | I16: =IFERROR(IF(INDEX(approvals!$AT$2:$AT$251,MATCH($B$2&"|"&10,approvals!$AZ$2:$AZ$251,0))=0,"",ROUND(INDEX(approvals!$AU$2:$AU$251,MATCH($B$2&"|"&10,approvals!$AZ$2:$AZ$251,0))/INDEX(approvals!$AT$2:$AT$251,MATCH($B$2&"|"&10,approvals!$AZ$2:$AZ$251,0)),1)),"") | J16: =IFERROR(INDEX(approvals!$AV$2:$AV$251,MATCH($B$2&"|"&10,approvals!$AZ$2:$AZ$251,0)),"") | K16: =IFERROR(INDEX(approvals!$AW$2:$AW$251,MATCH($B$2&"|"&10,approvals!$AZ$2:$AZ$251,0)),"") | L16: =IFERROR(INDEX(approvals!$AX$2:$AX$251,MATCH($B$2&"|"&10,approvals!$AZ$2:$AZ$251,0)),"") | M16: =IFERROR(INDEX(approvals!$AY$2:$AY$251,MATCH($B$2&"|"&10,approvals!$AZ$2:$AZ$251,0)),"") | N16: =IFERROR(IF(INDEX(approvals!$AL$2:$AL$251,MATCH($B$2&"|"&10,approvals!$AZ$2:$AZ$251,0))>=config!$B$30,"OK","under "&config!$B$30&": ask the owner to re-post"),"")
A17: =IFERROR(INDEX(approvals!$M$2:$M$251,MATCH($B$2&"|"&11,approvals!$AZ$2:$AZ$251,0)),"") | B17: =IFERROR(INDEX(approvals!$K$2:$K$251,MATCH($B$2&"|"&11,approvals!$AZ$2:$AZ$251,0)),"") | C17: =IFERROR(INDEX(approvals!$AL$2:$AL$251,MATCH($B$2&"|"&11,approvals!$AZ$2:$AZ$251,0)),"") | D17: =IFERROR(INDEX(approvals!$AM$2:$AM$251,MATCH($B$2&"|"&11,approvals!$AZ$2:$AZ$251,0)),"") | E17: =IFERROR(INDEX(approvals!$AQ$2:$AQ$251,MATCH($B$2&"|"&11,approvals!$AZ$2:$AZ$251,0)),"") | F17: =IFERROR(INDEX(approvals!$AR$2:$AR$251,MATCH($B$2&"|"&11,approvals!$AZ$2:$AZ$251,0)),"") | G17: =IFERROR(INDEX(approvals!$AS$2:$AS$251,MATCH($B$2&"|"&11,approvals!$AZ$2:$AZ$251,0)),"") | H17: =IFERROR(INDEX(approvals!$AT$2:$AT$251,MATCH($B$2&"|"&11,approvals!$AZ$2:$AZ$251,0)),"") | I17: =IFERROR(IF(INDEX(approvals!$AT$2:$AT$251,MATCH($B$2&"|"&11,approvals!$AZ$2:$AZ$251,0))=0,"",ROUND(INDEX(approvals!$AU$2:$AU$251,MATCH($B$2&"|"&11,approvals!$AZ$2:$AZ$251,0))/INDEX(approvals!$AT$2:$AT$251,MATCH($B$2&"|"&11,approvals!$AZ$2:$AZ$251,0)),1)),"") | J17: =IFERROR(INDEX(approvals!$AV$2:$AV$251,MATCH($B$2&"|"&11,approvals!$AZ$2:$AZ$251,0)),"") | K17: =IFERROR(INDEX(approvals!$AW$2:$AW$251,MATCH($B$2&"|"&11,approvals!$AZ$2:$AZ$251,0)),"") | L17: =IFERROR(INDEX(approvals!$AX$2:$AX$251,MATCH($B$2&"|"&11,approvals!$AZ$2:$AZ$251,0)),"") | M17: =IFERROR(INDEX(approvals!$AY$2:$AY$251,MATCH($B$2&"|"&11,approvals!$AZ$2:$AZ$251,0)),"") | N17: =IFERROR(IF(INDEX(approvals!$AL$2:$AL$251,MATCH($B$2&"|"&11,approvals!$AZ$2:$AZ$251,0))>=config!$B$30,"OK","under "&config!$B$30&": ask the owner to re-post"),"")
A18: =IFERROR(INDEX(approvals!$M$2:$M$251,MATCH($B$2&"|"&12,approvals!$AZ$2:$AZ$251,0)),"") | B18: =IFERROR(INDEX(approvals!$K$2:$K$251,MATCH($B$2&"|"&12,approvals!$AZ$2:$AZ$251,0)),"") | C18: =IFERROR(INDEX(approvals!$AL$2:$AL$251,MATCH($B$2&"|"&12,approvals!$AZ$2:$AZ$251,0)),"") | D18: =IFERROR(INDEX(approvals!$AM$2:$AM$251,MATCH($B$2&"|"&12,approvals!$AZ$2:$AZ$251,0)),"") | E18: =IFERROR(INDEX(approvals!$AQ$2:$AQ$251,MATCH($B$2&"|"&12,approvals!$AZ$2:$AZ$251,0)),"") | F18: =IFERROR(INDEX(approvals!$AR$2:$AR$251,MATCH($B$2&"|"&12,approvals!$AZ$2:$AZ$251,0)),"") | G18: =IFERROR(INDEX(approvals!$AS$2:$AS$251,MATCH($B$2&"|"&12,approvals!$AZ$2:$AZ$251,0)),"") | H18: =IFERROR(INDEX(approvals!$AT$2:$AT$251,MATCH($B$2&"|"&12,approvals!$AZ$2:$AZ$251,0)),"") | I18: =IFERROR(IF(INDEX(approvals!$AT$2:$AT$251,MATCH($B$2&"|"&12,approvals!$AZ$2:$AZ$251,0))=0,"",ROUND(INDEX(approvals!$AU$2:$AU$251,MATCH($B$2&"|"&12,approvals!$AZ$2:$AZ$251,0))/INDEX(approvals!$AT$2:$AT$251,MATCH($B$2&"|"&12,approvals!$AZ$2:$AZ$251,0)),1)),"") | J18: =IFERROR(INDEX(approvals!$AV$2:$AV$251,MATCH($B$2&"|"&12,approvals!$AZ$2:$AZ$251,0)),"") | K18: =IFERROR(INDEX(approvals!$AW$2:$AW$251,MATCH($B$2&"|"&12,approvals!$AZ$2:$AZ$251,0)),"") | L18: =IFERROR(INDEX(approvals!$AX$2:$AX$251,MATCH($B$2&"|"&12,approvals!$AZ$2:$AZ$251,0)),"") | M18: =IFERROR(INDEX(approvals!$AY$2:$AY$251,MATCH($B$2&"|"&12,approvals!$AZ$2:$AZ$251,0)),"") | N18: =IFERROR(IF(INDEX(approvals!$AL$2:$AL$251,MATCH($B$2&"|"&12,approvals!$AZ$2:$AZ$251,0))>=config!$B$30,"OK","under "&config!$B$30&": ask the owner to re-post"),"")
A19: total | C19: =SUM(C7:C18) -> 34 | D19: =SUM(D7:D18) -> 25 | E19: =SUM(E7:E18) -> 5 | F19: =SUM(F7:F18) -> 2 | G19: =SUM(G7:G18) -> 2 | H19: =SUM(H7:H18) -> 25 | I19: =IFERROR(IFERROR(INDEX(campaigns!$CP$2:$CP$51,MATCH($B$2,campaigns!$A$2:$A$51,0)),""),"") -> 4.2 | J19: =SUM(J7:J18) -> 10 | K19: =SUM(K7:K18) -> 8 | L19: =SUM(L7:L18) -> 7 | M19: =SUM(M7:M18) -> 18
A21: Not counted
A22: outside the window (before T or after T+4) | C22: =IFERROR(INDEX(campaigns!$CU$2:$CU$51,MATCH($B$2,campaigns!$A$2:$A$51,0)),"") -> 2
A23: card code matches no office on this campaign | C23: =IFERROR(INDEX(campaigns!$CV$2:$CV$51,MATCH($B$2,campaigns!$A$2:$A$51,0)),"") -> 1
A24: from an office not on the drop (it said no, or turned the brand away at the door) | C24: =IFERROR(INDEX(campaigns!$CW$2:$CW$51,MATCH($B$2,campaigns!$A$2:$A$51,0)),"") -> 0
A26: Who sees what (legal pack file 13, D6 and D9): this sheet is the founder's only. The brand gets totals and at most three comments word for word; each office gets its own summary, never answers row by row. No email address is ever in this file: newsletter sign-ups live only in the campaign's separate sign-up form.

Sheet report
A1: =IF(LEFT($B$2,6)="SAMPLE","SAMPLE DATA. Illustrative placeholders, not results.","") -> SAMPLE DATA. Illustrative placeholders, not results.
A2: Campaign | B2: =IF(INDEX(campaigns!$A$2:$A$51,1)="","",INDEX(campaigns!$A$2:$A$51,1)) -> SAMPLE-CMP-001 | D2: Type a campaign_id over B2. Everything below is formulas over the logged rows: nothing is retyped. The PDF comes from tools/make_report.py.
A4: =IF($B$2="","",IFERROR(INDEX(campaigns!$BE$2:$BE$51,MATCH($B$2,campaigns!$A$2:$A$51,0)),"")&IF(IFERROR(INDEX(campaigns!$J$2:$J$51,MATCH($B$2,campaigns!$A$2:$A$51,0)),"")<>""," · "&IFERROR(INDEX(campaigns!$J$2:$J$51,MATCH($B$2,campaigns!$A$2:$A$51,0)),""),"")&" · "&config!$B$11&" · Drop "&TEXT(IFERROR(INDEX(campaigns!$BG$2:$BG$51,MATCH($B$2,campaigns!$A$2:$A$51,0)),""),"ddd yyyy-mm-dd")&" · Window "&TEXT(IFERROR(INDEX(campaigns!$BG$2:$BG$51,MATCH($B$2,campaigns!$A$2:$A$51,0)),""),"ddd yyyy-mm-dd")&" to "&TEXT(IFERROR(INDEX(drops!$R$2:$R$21,MATCH(IFERROR(INDEX(campaigns!$B$2:$B$51,MATCH($B$2,campaigns!$A$2:$A$51,0)),""),drops!$A$2:$A$21,0)),""),"ddd yyyy-mm-dd")) -> SAMPLE Brightside · SAMPLE Sea Salt Lentil Crisps, 1 oz bags · Flatiron, NoMad and Union Square · Drop Tue 2027-01-12 · Window Tue 2027-01-12 to Tue 2027-01-19
A6: Delivered | B6: Placed | C6: Depleted | D6: Responded | E6: Scanned | F6: Purchased | G6: Incremental
A7: =IFERROR(INDEX(campaigns!$CB$2:$CB$51,MATCH($B$2,campaigns!$A$2:$A$51,0)),"") -> 250 | B7: =IFERROR(INDEX(campaigns!$CC$2:$CC$51,MATCH($B$2,campaigns!$A$2:$A$51,0)),"") -> 248 | C7: =IFERROR(INDEX(campaigns!$CG$2:$CG$51,MATCH($B$2,campaigns!$A$2:$A$51,0)),"") -> 200 | D7: =IFERROR(INDEX(campaigns!$CH$2:$CH$51,MATCH($B$2,campaigns!$A$2:$A$51,0)),"") -> 34 | E7: =IFERROR(INDEX(campaigns!$CX$2:$CX$51,MATCH($B$2,campaigns!$A$2:$A$51,0)),"") -> 45 | F7: =IFERROR(INDEX(campaigns!$CZ$2:$CZ$51,MATCH($B$2,campaigns!$A$2:$A$51,0)),"") -> 11 | G7: ="not measured" -> not measured
A8: =IF($B$2="","","handed over on the drop day") -> handed over on the drop day | B8: =IF($B$2="","","within one business day: "&IFERROR(INDEX(campaigns!$CD$2:$CD$51,MATCH($B$2,campaigns!$A$2:$A$51,0)),"")&" of "&IFERROR(INDEX(campaigns!$CB$2:$CB$51,MATCH($B$2,campaigns!$A$2:$A$51,0)),"")&IF(IFERROR(INDEX(campaigns!$CE$2:$CE$51,MATCH($B$2,campaigns!$A$2:$A$51,0)),"")="",""," ("&TEXT(IFERROR(INDEX(campaigns!$CE$2:$CE$51,MATCH($B$2,campaigns!$A$2:$A$51,0)),""),"0%")&")")) -> within one business day: 198 of 250 (79%) | C8: =IF($B$2="","","gone by day 5; plus "&IFERROR(INDEX(campaigns!$CF$2:$CF$51,MATCH($B$2,campaigns!$A$2:$A$51,0)),"")&" day-3 top-ups from reserve") -> gone by day 5; plus 5 day-3 top-ups from reserve | D8: =IF($B$2="","","survey responses; "&IFERROR(INDEX(campaigns!$CK$2:$CK$51,MATCH($B$2,campaigns!$A$2:$A$51,0)),"")&" said they tried it") -> survey responses; 25 said they tried it | E8: =IF($B$2="","","QR scans, T to T+4") -> QR scans, T to T+4 | F8: =IF($B$2="","","code redemptions reported by the brand"&IF(IFERROR(INDEX(campaigns!$DA$2:$DA$51,MATCH($B$2,campaigns!$A$2:$A$51,0)),"")="",""," as of "&TEXT(IFERROR(INDEX(campaigns!$DA$2:$DA$51,MATCH($B$2,campaigns!$A$2:$A$51,0)),""),"yyyy-mm-dd"))) -> code redemptions reported by the brand as of 2027-02-11 | G8: =IF($B$2="","","this report does not show whether the campaign caused any sale") -> this report does not show whether the campaign caused any sale
A10: Office | B10: Industry | C10: Tuesday headcount | D10: Units delivered | E10: Units placed | F10: Topped up | G10: Gone by day 5 | H10: Responses | I10: QR scans | J10: Placement photo | K10: Later photo
A11: =IFERROR(INDEX(approvals!$M$2:$M$251,MATCH($B$2&"|"&1,approvals!$AZ$2:$AZ$251,0))&IF(INDEX(approvals!$AB$2:$AB$251,MATCH($B$2&"|"&1,approvals!$AZ$2:$AZ$251,0))="N","*",""),"") -> A | B11: =IFERROR(INDEX(offices!$AI$2:$AI$61,MATCH(INDEX(approvals!$B$2:$B$251,MATCH($B$2&"|"&1,approvals!$AZ$2:$AZ$251,0)),offices!$A$2:$A$61,0)),"") -> SAMPLE Software | C11: =IFERROR(SUBSTITUTE(INDEX(offices!$AK$2:$AK$61,MATCH(INDEX(approvals!$B$2:$B$251,MATCH($B$2&"|"&1,approvals!$AZ$2:$AZ$251,0)),offices!$A$2:$A$61,0)),"-"," to "),"") -> 40 to 75 | D11: =IFERROR(INDEX(approvals!$U$2:$U$251,MATCH($B$2&"|"&1,approvals!$AZ$2:$AZ$251,0)),"") -> 40 | E11: =IFERROR(INDEX(approvals!$AA$2:$AA$251,MATCH($B$2&"|"&1,approvals!$AZ$2:$AZ$251,0)),"") -> 40 | F11: =IFERROR(INDEX(approvals!$AD$2:$AD$251,MATCH($B$2&"|"&1,approvals!$AZ$2:$AZ$251,0)),"") -> 5 | G11: =IFERROR(INDEX(approvals!$AG$2:$AG$251,MATCH($B$2&"|"&1,approvals!$AZ$2:$AZ$251,0)),"") -> 44 | H11: =IFERROR(INDEX(approvals!$AL$2:$AL$251,MATCH($B$2&"|"&1,approvals!$AZ$2:$AZ$251,0)),"") -> 9 | I11: =IFERROR(INDEX(approvals!$AN$2:$AN$251,MATCH($B$2&"|"&1,approvals!$AZ$2:$AZ$251,0)),"") -> 14 | J11: =IFERROR(IF(INDEX(approvals!$Y$2:$Y$251,MATCH($B$2&"|"&1,approvals!$AZ$2:$AZ$251,0))="","none received",TEXT(INDEX(approvals!$Y$2:$Y$251,MATCH($B$2&"|"&1,approvals!$AZ$2:$AZ$251,0)),"yyyy-mm-dd")),"") -> 2027-01-12 | K11: =IFERROR(IF(INDEX(approvals!$AI$2:$AI$251,MATCH($B$2&"|"&1,approvals!$AZ$2:$AZ$251,0))="","none received",TEXT(INDEX(approvals!$AI$2:$AI$251,MATCH($B$2&"|"&1,approvals!$AZ$2:$AZ$251,0)),"yyyy-mm-dd")),"") -> 2027-01-19
A12: =IFERROR(INDEX(approvals!$M$2:$M$251,MATCH($B$2&"|"&2,approvals!$AZ$2:$AZ$251,0))&IF(INDEX(approvals!$AB$2:$AB$251,MATCH($B$2&"|"&2,approvals!$AZ$2:$AZ$251,0))="N","*",""),"") -> B | B12: =IFERROR(INDEX(offices!$AI$2:$AI$61,MATCH(INDEX(approvals!$B$2:$B$251,MATCH($B$2&"|"&2,approvals!$AZ$2:$AZ$251,0)),offices!$A$2:$A$61,0)),"") -> SAMPLE Architecture | C12: =IFERROR(SUBSTITUTE(INDEX(offices!$AK$2:$AK$61,MATCH(INDEX(approvals!$B$2:$B$251,MATCH($B$2&"|"&2,approvals!$AZ$2:$AZ$251,0)),offices!$A$2:$A$61,0)),"-"," to "),"") -> 40 to 75 | D12: =IFERROR(INDEX(approvals!$U$2:$U$251,MATCH($B$2&"|"&2,approvals!$AZ$2:$AZ$251,0)),"") -> 40 | E12: =IFERROR(INDEX(approvals!$AA$2:$AA$251,MATCH($B$2&"|"&2,approvals!$AZ$2:$AZ$251,0)),"") -> 38 | F12: =IFERROR(INDEX(approvals!$AD$2:$AD$251,MATCH($B$2&"|"&2,approvals!$AZ$2:$AZ$251,0)),"") -> 0 | G12: =IFERROR(INDEX(approvals!$AG$2:$AG$251,MATCH($B$2&"|"&2,approvals!$AZ$2:$AZ$251,0)),"") -> 31 | H12: =IFERROR(INDEX(approvals!$AL$2:$AL$251,MATCH($B$2&"|"&2,approvals!$AZ$2:$AZ$251,0)),"") -> 6 | I12: =IFERROR(INDEX(approvals!$AN$2:$AN$251,MATCH($B$2&"|"&2,approvals!$AZ$2:$AZ$251,0)),"") -> 7 | J12: =IFERROR(IF(INDEX(approvals!$Y$2:$Y$251,MATCH($B$2&"|"&2,approvals!$AZ$2:$AZ$251,0))="","none received",TEXT(INDEX(approvals!$Y$2:$Y$251,MATCH($B$2&"|"&2,approvals!$AZ$2:$AZ$251,0)),"yyyy-mm-dd")),"") -> 2027-01-12 | K12: =IFERROR(IF(INDEX(approvals!$AI$2:$AI$251,MATCH($B$2&"|"&2,approvals!$AZ$2:$AZ$251,0))="","none received",TEXT(INDEX(approvals!$AI$2:$AI$251,MATCH($B$2&"|"&2,approvals!$AZ$2:$AZ$251,0)),"yyyy-mm-dd")),"") -> 2027-01-19
A13: =IFERROR(INDEX(approvals!$M$2:$M$251,MATCH($B$2&"|"&3,approvals!$AZ$2:$AZ$251,0))&IF(INDEX(approvals!$AB$2:$AB$251,MATCH($B$2&"|"&3,approvals!$AZ$2:$AZ$251,0))="N","*",""),"") -> C | B13: =IFERROR(INDEX(offices!$AI$2:$AI$61,MATCH(INDEX(approvals!$B$2:$B$251,MATCH($B$2&"|"&3,approvals!$AZ$2:$AZ$251,0)),offices!$A$2:$A$61,0)),"") -> SAMPLE Media | C13: =IFERROR(SUBSTITUTE(INDEX(offices!$AK$2:$AK$61,MATCH(INDEX(approvals!$B$2:$B$251,MATCH($B$2&"|"&3,approvals!$AZ$2:$AZ$251,0)),offices!$A$2:$A$61,0)),"-"," to "),"") -> 76 to 150 | D13: =IFERROR(INDEX(approvals!$U$2:$U$251,MATCH($B$2&"|"&3,approvals!$AZ$2:$AZ$251,0)),"") -> 50 | E13: =IFERROR(INDEX(approvals!$AA$2:$AA$251,MATCH($B$2&"|"&3,approvals!$AZ$2:$AZ$251,0)),"") -> 50 | F13: =IFERROR(INDEX(approvals!$AD$2:$AD$251,MATCH($B$2&"|"&3,approvals!$AZ$2:$AZ$251,0)),"") -> 0 | G13: =IFERROR(INDEX(approvals!$AG$2:$AG$251,MATCH($B$2&"|"&3,approvals!$AZ$2:$AZ$251,0)),"") -> 41 | H13: =IFERROR(INDEX(approvals!$AL$2:$AL$251,MATCH($B$2&"|"&3,approvals!$AZ$2:$AZ$251,0)),"") -> 8 | I13: =IFERROR(INDEX(approvals!$AN$2:$AN$251,MATCH($B$2&"|"&3,approvals!$AZ$2:$AZ$251,0)),"") -> 11 | J13: =IFERROR(IF(INDEX(approvals!$Y$2:$Y$251,MATCH($B$2&"|"&3,approvals!$AZ$2:$AZ$251,0))="","none received",TEXT(INDEX(approvals!$Y$2:$Y$251,MATCH($B$2&"|"&3,approvals!$AZ$2:$AZ$251,0)),"yyyy-mm-dd")),"") -> 2027-01-12 | K13: =IFERROR(IF(INDEX(approvals!$AI$2:$AI$251,MATCH($B$2&"|"&3,approvals!$AZ$2:$AZ$251,0))="","none received",TEXT(INDEX(approvals!$AI$2:$AI$251,MATCH($B$2&"|"&3,approvals!$AZ$2:$AZ$251,0)),"yyyy-mm-dd")),"") -> 2027-01-19
A14: =IFERROR(INDEX(approvals!$M$2:$M$251,MATCH($B$2&"|"&4,approvals!$AZ$2:$AZ$251,0))&IF(INDEX(approvals!$AB$2:$AB$251,MATCH($B$2&"|"&4,approvals!$AZ$2:$AZ$251,0))="N","*",""),"") -> D* | B14: =IFERROR(INDEX(offices!$AI$2:$AI$61,MATCH(INDEX(approvals!$B$2:$B$251,MATCH($B$2&"|"&4,approvals!$AZ$2:$AZ$251,0)),offices!$A$2:$A$61,0)),"") -> SAMPLE Nonprofit | C14: =IFERROR(SUBSTITUTE(INDEX(offices!$AK$2:$AK$61,MATCH(INDEX(approvals!$B$2:$B$251,MATCH($B$2&"|"&4,approvals!$AZ$2:$AZ$251,0)),offices!$A$2:$A$61,0)),"-"," to "),"") -> 76 to 150 | D14: =IFERROR(INDEX(approvals!$U$2:$U$251,MATCH($B$2&"|"&4,approvals!$AZ$2:$AZ$251,0)),"") -> 50 | E14: =IFERROR(INDEX(approvals!$AA$2:$AA$251,MATCH($B$2&"|"&4,approvals!$AZ$2:$AZ$251,0)),"") -> 50 | F14: =IFERROR(INDEX(approvals!$AD$2:$AD$251,MATCH($B$2&"|"&4,approvals!$AZ$2:$AZ$251,0)),"") -> 0 | G14: =IFERROR(INDEX(approvals!$AG$2:$AG$251,MATCH($B$2&"|"&4,approvals!$AZ$2:$AZ$251,0)),"") -> 22 | H14: =IFERROR(INDEX(approvals!$AL$2:$AL$251,MATCH($B$2&"|"&4,approvals!$AZ$2:$AZ$251,0)),"") -> 4 | I14: =IFERROR(INDEX(approvals!$AN$2:$AN$251,MATCH($B$2&"|"&4,approvals!$AZ$2:$AZ$251,0)),"") -> 4 | J14: =IFERROR(IF(INDEX(approvals!$Y$2:$Y$251,MATCH($B$2&"|"&4,approvals!$AZ$2:$AZ$251,0))="","none received",TEXT(INDEX(approvals!$Y$2:$Y$251,MATCH($B$2&"|"&4,approvals!$AZ$2:$AZ$251,0)),"yyyy-mm-dd")),"") -> 2027-01-14 | K14: =IFERROR(IF(INDEX(approvals!$AI$2:$AI$251,MATCH($B$2&"|"&4,approvals!$AZ$2:$AZ$251,0))="","none received",TEXT(INDEX(approvals!$AI$2:$AI$251,MATCH($B$2&"|"&4,approvals!$AZ$2:$AZ$251,0)),"yyyy-mm-dd")),"") -> 2027-01-19
A15: =IFERROR(INDEX(approvals!$M$2:$M$251,MATCH($B$2&"|"&5,approvals!$AZ$2:$AZ$251,0))&IF(INDEX(approvals!$AB$2:$AB$251,MATCH($B$2&"|"&5,approvals!$AZ$2:$AZ$251,0))="N","*",""),"") -> E | B15: =IFERROR(INDEX(offices!$AI$2:$AI$61,MATCH(INDEX(approvals!$B$2:$B$251,MATCH($B$2&"|"&5,approvals!$AZ$2:$AZ$251,0)),offices!$A$2:$A$61,0)),"") -> SAMPLE Design studio | C15: =IFERROR(SUBSTITUTE(INDEX(offices!$AK$2:$AK$61,MATCH(INDEX(approvals!$B$2:$B$251,MATCH($B$2&"|"&5,approvals!$AZ$2:$AZ$251,0)),offices!$A$2:$A$61,0)),"-"," to "),"") -> 151 to 250 | D15: =IFERROR(INDEX(approvals!$U$2:$U$251,MATCH($B$2&"|"&5,approvals!$AZ$2:$AZ$251,0)),"") -> 70 | E15: =IFERROR(INDEX(approvals!$AA$2:$AA$251,MATCH($B$2&"|"&5,approvals!$AZ$2:$AZ$251,0)),"") -> 70 | F15: =IFERROR(INDEX(approvals!$AD$2:$AD$251,MATCH($B$2&"|"&5,approvals!$AZ$2:$AZ$251,0)),"") -> 0 | G15: =IFERROR(INDEX(approvals!$AG$2:$AG$251,MATCH($B$2&"|"&5,approvals!$AZ$2:$AZ$251,0)),"") -> 62 | H15: =IFERROR(INDEX(approvals!$AL$2:$AL$251,MATCH($B$2&"|"&5,approvals!$AZ$2:$AZ$251,0)),"") -> 7 | I15: =IFERROR(INDEX(approvals!$AN$2:$AN$251,MATCH($B$2&"|"&5,approvals!$AZ$2:$AZ$251,0)),"") -> 9 | J15: =IFERROR(IF(INDEX(approvals!$Y$2:$Y$251,MATCH($B$2&"|"&5,approvals!$AZ$2:$AZ$251,0))="","none received",TEXT(INDEX(approvals!$Y$2:$Y$251,MATCH($B$2&"|"&5,approvals!$AZ$2:$AZ$251,0)),"yyyy-mm-dd")),"") -> 2027-01-12 | K15: =IFERROR(IF(INDEX(approvals!$AI$2:$AI$251,MATCH($B$2&"|"&5,approvals!$AZ$2:$AZ$251,0))="","none received",TEXT(INDEX(approvals!$AI$2:$AI$251,MATCH($B$2&"|"&5,approvals!$AZ$2:$AZ$251,0)),"yyyy-mm-dd")),"") -> 2027-01-19
A16: =IFERROR(INDEX(approvals!$M$2:$M$251,MATCH($B$2&"|"&6,approvals!$AZ$2:$AZ$251,0))&IF(INDEX(approvals!$AB$2:$AB$251,MATCH($B$2&"|"&6,approvals!$AZ$2:$AZ$251,0))="N","*",""),"") | B16: =IFERROR(INDEX(offices!$AI$2:$AI$61,MATCH(INDEX(approvals!$B$2:$B$251,MATCH($B$2&"|"&6,approvals!$AZ$2:$AZ$251,0)),offices!$A$2:$A$61,0)),"") | C16: =IFERROR(SUBSTITUTE(INDEX(offices!$AK$2:$AK$61,MATCH(INDEX(approvals!$B$2:$B$251,MATCH($B$2&"|"&6,approvals!$AZ$2:$AZ$251,0)),offices!$A$2:$A$61,0)),"-"," to "),"") | D16: =IFERROR(INDEX(approvals!$U$2:$U$251,MATCH($B$2&"|"&6,approvals!$AZ$2:$AZ$251,0)),"") | E16: =IFERROR(INDEX(approvals!$AA$2:$AA$251,MATCH($B$2&"|"&6,approvals!$AZ$2:$AZ$251,0)),"") | F16: =IFERROR(INDEX(approvals!$AD$2:$AD$251,MATCH($B$2&"|"&6,approvals!$AZ$2:$AZ$251,0)),"") | G16: =IFERROR(INDEX(approvals!$AG$2:$AG$251,MATCH($B$2&"|"&6,approvals!$AZ$2:$AZ$251,0)),"") | H16: =IFERROR(INDEX(approvals!$AL$2:$AL$251,MATCH($B$2&"|"&6,approvals!$AZ$2:$AZ$251,0)),"") | I16: =IFERROR(INDEX(approvals!$AN$2:$AN$251,MATCH($B$2&"|"&6,approvals!$AZ$2:$AZ$251,0)),"") | J16: =IFERROR(IF(INDEX(approvals!$Y$2:$Y$251,MATCH($B$2&"|"&6,approvals!$AZ$2:$AZ$251,0))="","none received",TEXT(INDEX(approvals!$Y$2:$Y$251,MATCH($B$2&"|"&6,approvals!$AZ$2:$AZ$251,0)),"yyyy-mm-dd")),"") | K16: =IFERROR(IF(INDEX(approvals!$AI$2:$AI$251,MATCH($B$2&"|"&6,approvals!$AZ$2:$AZ$251,0))="","none received",TEXT(INDEX(approvals!$AI$2:$AI$251,MATCH($B$2&"|"&6,approvals!$AZ$2:$AZ$251,0)),"yyyy-mm-dd")),"")
A17: =IFERROR(INDEX(approvals!$M$2:$M$251,MATCH($B$2&"|"&7,approvals!$AZ$2:$AZ$251,0))&IF(INDEX(approvals!$AB$2:$AB$251,MATCH($B$2&"|"&7,approvals!$AZ$2:$AZ$251,0))="N","*",""),"") | B17: =IFERROR(INDEX(offices!$AI$2:$AI$61,MATCH(INDEX(approvals!$B$2:$B$251,MATCH($B$2&"|"&7,approvals!$AZ$2:$AZ$251,0)),offices!$A$2:$A$61,0)),"") | C17: =IFERROR(SUBSTITUTE(INDEX(offices!$AK$2:$AK$61,MATCH(INDEX(approvals!$B$2:$B$251,MATCH($B$2&"|"&7,approvals!$AZ$2:$AZ$251,0)),offices!$A$2:$A$61,0)),"-"," to "),"") | D17: =IFERROR(INDEX(approvals!$U$2:$U$251,MATCH($B$2&"|"&7,approvals!$AZ$2:$AZ$251,0)),"") | E17: =IFERROR(INDEX(approvals!$AA$2:$AA$251,MATCH($B$2&"|"&7,approvals!$AZ$2:$AZ$251,0)),"") | F17: =IFERROR(INDEX(approvals!$AD$2:$AD$251,MATCH($B$2&"|"&7,approvals!$AZ$2:$AZ$251,0)),"") | G17: =IFERROR(INDEX(approvals!$AG$2:$AG$251,MATCH($B$2&"|"&7,approvals!$AZ$2:$AZ$251,0)),"") | H17: =IFERROR(INDEX(approvals!$AL$2:$AL$251,MATCH($B$2&"|"&7,approvals!$AZ$2:$AZ$251,0)),"") | I17: =IFERROR(INDEX(approvals!$AN$2:$AN$251,MATCH($B$2&"|"&7,approvals!$AZ$2:$AZ$251,0)),"") | J17: =IFERROR(IF(INDEX(approvals!$Y$2:$Y$251,MATCH($B$2&"|"&7,approvals!$AZ$2:$AZ$251,0))="","none received",TEXT(INDEX(approvals!$Y$2:$Y$251,MATCH($B$2&"|"&7,approvals!$AZ$2:$AZ$251,0)),"yyyy-mm-dd")),"") | K17: =IFERROR(IF(INDEX(approvals!$AI$2:$AI$251,MATCH($B$2&"|"&7,approvals!$AZ$2:$AZ$251,0))="","none received",TEXT(INDEX(approvals!$AI$2:$AI$251,MATCH($B$2&"|"&7,approvals!$AZ$2:$AZ$251,0)),"yyyy-mm-dd")),"")
